<?xml version="1.0" ?>
<!-- =================================================================================== -->
<!-- |    This document was autogenerated by xacro from repair_full.urdf.xacro         | -->
<!-- |    EDITING THIS FILE BY HAND IS NOT RECOMMENDED                                 | -->
<!-- =================================================================================== -->
<robot name="repair_full">
  <material name="grey">
    <color rgba="0.5 0.5 0.5 1"/>
  </material>
  <material name="dark_grey">
    <color rgba="0.3 0.3 0.3 1"/>
  </material>
  <material name="red">
    <color rgba="1.0 0.0 0.0 1"/>
  </material>
  <material name="green">
    <color rgba="0.0 1.0 0.0 1"/>
  </material>
  <material name="blue">
    <color rgba="0.13333333333333333 0.25882352941176473 0.7803921568627451 1.0"/>
  </material>
  <material name="darkblue">
    <color rgba="0.0 0.3 0.9 1"/>
  </material>
  <material name="darkred">
    <color rgba="0.55 0.0 0.0 1"/>
  </material>
  <material name="dark">
    <color rgba="0.6 0.6 0.6 1"/>
  </material>
  <material name="wood">
    <color rgba="0.522 0.369 0.259 0.8"/>
  </material>
  <material name="silver_gray">
    <color rgba="0.8 0.8 0.8 0.8"/>
  </material>
  <!-- macro for generating the urdf associated with a single arm of the RePair platform -->
  <!-- id: specifies the id of the arm (e.g. 0 for left arm and 1 for right) -->
  <!-- base_link: name of base link a the single arm -->
  <!-- is_sliding_wrist: whether to add a sliding joint along the wrist second d.o.f.
    (true -> yes), everything else -> no. This is used to generate the URDF for the optimization.  -->
  <!-- gen_coll: whether to add the approximate collision  model of the platform -->
  <!-- use_updated_wrist: visual parameter. if true, we load the latest meshes (which are adapted to the
results of the optimization), otherwise we go with the old ones (generated for a spherical wrist) -->
  <!-- w.r.t world  -->
  <!-- 0.0  -->
  <!-- 2.4405495 -->
  <!-- 7.8724534e-01 -->
  <!-- 2.8848438e+00-->
  <!-- 6.0145584e-01 -->
  <!-- 2.7650803e+00 -->
  <!-- 1.8854765e+00 -->
  <!-- 2.4405495 -->
  <!-- Origin -->
  <!-- Only when working with Gazebo Xbot Control -->
  <!-- DO NOT USE WITH ROS_CONTROL AND MOVEIT -->
  <!-- <xacro:include filename="$(find repair_urdf)/urdf/gazebo/xbot.gazebo.xacro" /> -->
  <gazebo>
    <plugin filename="libgazebo_ros_control.so" name="ros_control">
      <!--robotNamespace>/</robotNamespace-->
      <!--robotSimType>gazebo_ros_control/DefaultRobotHWSim</robotSimType-->
    </plugin>
  </gazebo>
  <link name="world"/>
  <link name="table_top_link">
    <visual>
      <origin xyz="0.0 0.0 0.975"/>
      <geometry>
        <box size="1.0 2.5 0.05"/>
      </geometry>
      <material name="wood"/>
    </visual>
    <collision>
      <origin xyz="0.0 0.0 0.975"/>
      <geometry>
        <box size="1.0 2.5 0.05"/>
      </geometry>
    </collision>
  </link>
  <joint name="table_top_link_joint" type="fixed">
    <parent link="world"/>
    <child link="table_top_link"/>
  </joint>
  <joint name="leg1_joint" type="fixed">
    <parent link="table_top_link"/>
    <origin rpy="0 0 0" xyz="0.5 1.25 1.0"/>
    <child link="leg1_link"/>
  </joint>
  <link name="leg1_link">
    <visual>
      <origin rpy="0 0 0" xyz="0.0 0.0 -0.5"/>
      <geometry>
        <cylinder length="1.0" radius="0.02"/>
      </geometry>
      <material name="silver_gray"/>
    </visual>
    <collision>
      <origin rpy="0.0 0.0 0.0" xyz="0.0 0.0 -0.5"/>
      <geometry>
        <cylinder length="1.0" radius="0.02"/>
      </geometry>
    </collision>
  </link>
  <joint name="vbar1_joint" type="fixed">
    <parent link="leg1_link"/>
    <origin rpy="0 0 0" xyz="0 0 0.485"/>
    <child link="vbar1_link"/>
  </joint>
  <link name="vbar1_link">
    <visual>
      <origin rpy="0 0 0" xyz="0.0 0.0 0"/>
      <geometry>
        <cylinder length="0.97" radius="0.02"/>
      </geometry>
      <material name="silver_gray"/>
    </visual>
    <collision>
      <origin rpy="0.0 0.0 0.0" xyz="0.0 0.0 0"/>
      <geometry>
        <cylinder length="0.97" radius="0.02"/>
      </geometry>
    </collision>
  </link>
  <joint name="leg2_joint" type="fixed">
    <parent link="table_top_link"/>
    <origin rpy="0 0 0" xyz="-0.5 1.25 1.0"/>
    <child link="leg2_link"/>
  </joint>
  <link name="leg2_link">
    <visual>
      <origin rpy="0 0 0" xyz="0.0 0.0 -0.5"/>
      <geometry>
        <cylinder length="1.0" radius="0.02"/>
      </geometry>
      <material name="silver_gray"/>
    </visual>
    <collision>
      <origin rpy="0.0 0.0 0.0" xyz="0.0 0.0 -0.5"/>
      <geometry>
        <cylinder length="1.0" radius="0.02"/>
      </geometry>
    </collision>
  </link>
  <joint name="vbar2_joint" type="fixed">
    <parent link="leg2_link"/>
    <origin rpy="0 0 0" xyz="0 0 0.485"/>
    <child link="vbar2_link"/>
  </joint>
  <link name="vbar2_link">
    <visual>
      <origin rpy="0 0 0" xyz="0.0 0.0 0"/>
      <geometry>
        <cylinder length="0.97" radius="0.02"/>
      </geometry>
      <material name="silver_gray"/>
    </visual>
    <collision>
      <origin rpy="0.0 0.0 0.0" xyz="0.0 0.0 0"/>
      <geometry>
        <cylinder length="0.97" radius="0.02"/>
      </geometry>
    </collision>
  </link>
  <joint name="leg3_joint" type="fixed">
    <parent link="table_top_link"/>
    <origin rpy="0 0 0" xyz="0.5 -1.25 1.0"/>
    <child link="leg3_link"/>
  </joint>
  <link name="leg3_link">
    <visual>
      <origin rpy="0 0 0" xyz="0.0 0.0 -0.5"/>
      <geometry>
        <cylinder length="1.0" radius="0.02"/>
      </geometry>
      <material name="silver_gray"/>
    </visual>
    <collision>
      <origin rpy="0.0 0.0 0.0" xyz="0.0 0.0 -0.5"/>
      <geometry>
        <cylinder length="1.0" radius="0.02"/>
      </geometry>
    </collision>
  </link>
  <joint name="vbar3_joint" type="fixed">
    <parent link="leg3_link"/>
    <origin rpy="0 0 0" xyz="0 0 0.485"/>
    <child link="vbar3_link"/>
  </joint>
  <link name="vbar3_link">
    <visual>
      <origin rpy="0 0 0" xyz="0.0 0.0 0"/>
      <geometry>
        <cylinder length="0.97" radius="0.02"/>
      </geometry>
      <material name="silver_gray"/>
    </visual>
    <collision>
      <origin rpy="0.0 0.0 0.0" xyz="0.0 0.0 0"/>
      <geometry>
        <cylinder length="0.97" radius="0.02"/>
      </geometry>
    </collision>
  </link>
  <joint name="leg4_joint" type="fixed">
    <parent link="table_top_link"/>
    <origin rpy="0 0 0" xyz="-0.5 -1.25 1.0"/>
    <child link="leg4_link"/>
  </joint>
  <link name="leg4_link">
    <visual>
      <origin rpy="0 0 0" xyz="0.0 0.0 -0.5"/>
      <geometry>
        <cylinder length="1.0" radius="0.02"/>
      </geometry>
      <material name="silver_gray"/>
    </visual>
    <collision>
      <origin rpy="0.0 0.0 0.0" xyz="0.0 0.0 -0.5"/>
      <geometry>
        <cylinder length="1.0" radius="0.02"/>
      </geometry>
    </collision>
  </link>
  <joint name="vbar4_joint" type="fixed">
    <parent link="leg4_link"/>
    <origin rpy="0 0 0" xyz="0 0 0.485"/>
    <child link="vbar4_link"/>
  </joint>
  <link name="vbar4_link">
    <visual>
      <origin rpy="0 0 0" xyz="0.0 0.0 0"/>
      <geometry>
        <cylinder length="0.97" radius="0.02"/>
      </geometry>
      <material name="silver_gray"/>
    </visual>
    <collision>
      <origin rpy="0.0 0.0 0.0" xyz="0.0 0.0 0"/>
      <geometry>
        <cylinder length="0.97" radius="0.02"/>
      </geometry>
    </collision>
  </link>
  <joint name="obar1_joint" type="fixed">
    <parent link="vbar1_link"/>
    <origin rpy="0 -1.57079632679 0" xyz="-0.5 0 0.485"/>
    <child link="obar1_link"/>
  </joint>
  <link name="obar1_link">
    <visual>
      <origin rpy="0 0 0" xyz="0.0 0.0 0"/>
      <geometry>
        <cylinder length="1.0" radius="0.02"/>
      </geometry>
      <material name="silver_gray"/>
    </visual>
    <collision>
      <origin rpy="0.0 0.0 0.0" xyz="0.0 0.0 0"/>
      <geometry>
        <cylinder length="1.0" radius="0.02"/>
      </geometry>
    </collision>
  </link>
  <joint name="obar2_joint" type="fixed">
    <parent link="vbar3_link"/>
    <origin rpy="0 -1.57079632679 0" xyz="-0.5 0 0.485"/>
    <child link="obar2_link"/>
  </joint>
  <link name="obar2_link">
    <visual>
      <origin rpy="0 0 0" xyz="0.0 0.0 0"/>
      <geometry>
        <cylinder length="1.0" radius="0.02"/>
      </geometry>
      <material name="silver_gray"/>
    </visual>
    <collision>
      <origin rpy="0.0 0.0 0.0" xyz="0.0 0.0 0"/>
      <geometry>
        <cylinder length="1.0" radius="0.02"/>
      </geometry>
    </collision>
  </link>
  <joint name="obar3_joint" type="fixed">
    <parent link="vbar3_link"/>
    <origin rpy="-1.57079632679 0 0" xyz="0 1.25 0.485"/>
    <child link="obar3_link"/>
  </joint>
  <link name="obar3_link">
    <visual>
      <origin rpy="0 0 0" xyz="0.0 0.0 0"/>
      <geometry>
        <cylinder length="2.5" radius="0.02"/>
      </geometry>
      <material name="silver_gray"/>
    </visual>
    <collision>
      <origin rpy="0.0 0.0 0.0" xyz="0.0 0.0 0"/>
      <geometry>
        <cylinder length="2.5" radius="0.02"/>
      </geometry>
    </collision>
  </link>
  <joint name="obar4_joint" type="fixed">
    <parent link="vbar4_link"/>
    <origin rpy="-1.57079632679 0 0" xyz="0 1.25 0.485"/>
    <child link="obar4_link"/>
  </joint>
  <link name="obar4_link">
    <!-- dummy intertia to make Gazebo urdf2sdf converter work -->
    <visual>
      <origin rpy="0 0 0" xyz="0.0 0.0 0"/>
      <geometry>
        <cylinder length="2.5" radius="0.02"/>
      </geometry>
      <material name="silver_gray"/>
    </visual>
    <collision>
      <origin rpy="0.0 0.0 0.0" xyz="0.0 0.0 0"/>
      <geometry>
        <cylinder length="2.5" radius="0.02"/>
      </geometry>
    </collision>
  </link>
  <joint name="sliding_guide_joint" type="fixed">
    <parent link="obar2_link"/>
    <origin rpy="-1.57079632679 0 0" xyz="0.0 1.25 0.3"/>
    <child link="sliding_guide_link"/>
  </joint>
  <link name="sliding_guide_link">
    <visual>
      <origin rpy="0 0 0" xyz="0.0 0.0 0"/>
      <geometry>
        <box size="0.001 0.4 2.5"/>
      </geometry>
      <material name="silver_gray"/>
    </visual>
    <collision>
      <origin rpy="0.0 0.0 0.0" xyz="0.0 0.0 0"/>
      <geometry>
        <cylinder length="2.5" radius="0.02"/>
      </geometry>
    </collision>
  </link>
  <joint name="working_surface_joint" type="fixed">
    <parent link="sliding_guide_link"/>
    <origin rpy="0.0 -1.57079632679 3.14159265359" xyz="-0.97 0 0"/>
    <child link="working_surface_link"/>
  </joint>
  <link name="working_surface_link">
    <!-- Huge inertia (does not matter, is fixed to the world)-->
    <inertial>
      <mass value="1000"/>
      <origin xyz="0 0 0"/>
      <inertia ixx="0" ixy="0" ixz="0" iyy="0" iyz="0" izz="0"/>
    </inertial>
  </link>
  <!-- <link name="dummy_prismatic_link"/> -->
  <link name="torso_1">
    <inertial>
      <origin xyz="0.0004977651 -0.00042604032 -0.16838189"/>
      <mass value="8.7077745"/>
      <inertia ixx="0.11857828999999999" ixy="2.0401988e-05" ixz="1.2279510999999998e-05" iyy="0.08073399199999999" iyz="7.0011267999999996e-06" izz="0.054100211999999995"/>
    </inertial>
    <visual>
      <geometry>
        <mesh filename="package://repair_urdf/meshes/mesh_torso-yaw.stl" scale="0.001 0.001 0.001"/>
      </geometry>
      <material name="dark"/>
    </visual>
    <collision>
      <geometry>
        <mesh filename="package://repair_urdf/meshes/simplified/mesh_torso-yaw.stl" scale="0.001 0.001 0.001"/>
      </geometry>
    </collision>
  </link>
  <!-- <joint name="j_torso_base" type="fixed">
            <xacro:insert_block name="origin" />
            <parent link="${parent}" />
            <child link="dummy_prismatic_link"/>
            <axis xyz="0 0 1"/>
            <limit lower="${j_prismatic_lower[0]/2}" upper= "${j_prismatic_upper[0]/2}" effort="${j_prismatic_torque[0]}" velocity="${j_prismatic_velocity[0]}"/>
        </joint> -->
  <!-- torso -->
  <joint name="j_torso_1" type="revolute">
    <parent link="sliding_guide_link"/>
    <child link="torso_1"/>
    <axis xyz="0 0 1"/>
    <origin rpy="1.570796326795 0.0 1.570796326795" xyz="0.0 0.0 0.0"/>
    <limit effort="147.0" lower="-2.6" upper="2.6" velocity="3.86"/>
  </joint>
  <!-- torso  -->
  <link name="arm_2_1">
    <inertial>
      <origin xyz="0.010200651000000002 -0.021560998 0.09876702500000001"/>
      <mass value="2.347"/>
      <inertia ixx="0.007192915699999999" ixy="7.854318399999999e-05" ixz="-0.00039791235999999997" iyy="0.009471160999999999" iyz="0.0012857050999999999" izz="0.0058530904"/>
    </inertial>
    <visual>
      <geometry>
        <mesh filename="package://repair_urdf/meshes/mesh_sh-pitch.stl" scale="0.001 0.001 0.001"/>
      </geometry>
      <material name="dark"/>
    </visual>
    <collision>
      <geometry>
        <mesh filename="package://repair_urdf/meshes/simplified/mesh_sh-pitch.stl" scale="0.001 0.001 0.001"/>
      </geometry>
    </collision>
  </link>
  <link name="arm_2_2">
    <inertial>
      <origin xyz="4.5955243e-05 -0.044957128 -0.030791013"/>
      <mass value="0.76"/>
      <inertia ixx="0.0027927572" ixy="-2.0135067e-06" ixz="-1.3644218e-06" iyy="0.0019288488" iyz="-0.00066693438" izz="0.0026633366"/>
    </inertial>
    <visual>
      <geometry>
        <mesh filename="package://repair_urdf/meshes/mesh_sh-roll.stl" scale="0.001 0.001 0.001"/>
      </geometry>
      <material name="dark"/>
    </visual>
    <collision>
      <geometry>
        <mesh filename="package://repair_urdf/meshes/simplified/mesh_sh-roll.stl" scale="0.001 0.001 0.001"/>
      </geometry>
    </collision>
  </link>
  <link name="arm_2_3">
    <inertial>
      <origin xyz="0.005099315 0.0059986523 -0.18011742"/>
      <mass value="3.34"/>
      <inertia ixx="0.031298784999999996" ixy="-0.00025158367" ixz="0.002371127" iyy="0.031963501" iyz="0.0018728041" izz="0.0026332359"/>
    </inertial>
    <visual>
      <geometry>
        <mesh filename="package://repair_urdf/meshes/mesh_sh-yaw.stl" scale="0.001 0.001 0.001"/>
      </geometry>
      <material name="dark"/>
    </visual>
    <collision>
      <geometry>
        <mesh filename="package://repair_urdf/meshes/simplified/mesh_sh-yaw.stl" scale="0.001 0.001 0.001"/>
      </geometry>
    </collision>
  </link>
  <link name="arm_2_4">
    <inertial>
      <origin xyz="3.332275e-06 -0.033289421 -0.023682302"/>
      <mass value="0.55"/>
      <inertia ixx="0.0016198328" ixy="-1.2642724e-06" ixz="-1.1734799e-06" iyy="0.0012266731" iyz="-0.00039531700999999997" izz="0.0016081346"/>
    </inertial>
    <visual>
      <geometry>
        <mesh filename="package://repair_urdf/meshes/mesh_elbow.stl" scale="0.001 0.001 0.001"/>
      </geometry>
      <material name="dark"/>
    </visual>
    <collision>
      <geometry>
        <mesh filename="package://repair_urdf/meshes/simplified/mesh_elbow.stl" scale="0.001 0.001 0.001"/>
      </geometry>
    </collision>
  </link>
  <link name="arm_2_5">
    <inertial>
      <origin xyz="0.00094711044 -0.048009667 -0.14331833"/>
      <mass value="2.825"/>
      <inertia ixx="0.030333275" ixy="7.3729709e-05" ixz="3.2427371e-05" iyy="0.025195444999999997" iyz="-0.0095263763" izz="0.0069975103999999995"/>
    </inertial>
    <visual>
      <geometry>
        <mesh filename="package://repair_urdf/meshes/mesh_forearm-yaw.stl" scale="0.001 0.001 0.001"/>
      </geometry>
      <material name="dark"/>
    </visual>
    <collision>
      <geometry>
        <mesh filename="package://repair_urdf/meshes/simplified/mesh_forearm-yaw.stl" scale="0.001 0.001 0.001"/>
      </geometry>
    </collision>
  </link>
  <link name="arm_2_6">
    <inertial>
      <origin xyz="0.00068559302 -0.0050299682 0.046682846"/>
      <mass value="1.861"/>
      <inertia ixx="0.0042406037" ixy="-5.5692732e-05" ixz="-9.085198200000001e-05" iyy="0.0029010805999999997" iyz="-0.00018560541" izz="0.0044989008"/>
    </inertial>
    <visual>
      <geometry>
        <mesh filename="package://repair_urdf/meshes/mesh_wrist-pitch.stl" scale="0.001 0.001 0.001"/>
      </geometry>
      <material name="dark"/>
    </visual>
    <collision>
      <geometry>
        <mesh filename="package://repair_urdf/meshes/simplified/mesh_wrist-pitch.stl" scale="0.001 0.001 0.001"/>
      </geometry>
    </collision>
  </link>
  <link name="arm_2_7">
    <inertial>
      <origin xyz="0.0 -0.0010491951 -0.010307299"/>
      <mass value="0.1416397"/>
      <inertia ixx="6.1479333e-05" ixy="-7.4023399e-11" ixz="0.0" iyy="6.4247521e-05" iyz="4.778644799999999e-07" izz="0.00011879743999999998"/>
    </inertial>
    <visual>
      <geometry>
        <mesh filename="package://repair_urdf/meshes/mesh_wrist-roll.stl" scale="0.001 0.001 0.001"/>
      </geometry>
      <material name="dark"/>
    </visual>
    <collision>
      <geometry>
        <mesh filename="package://repair_urdf/meshes/simplified/mesh_wrist-roll.stl" scale="0.001 0.001 0.001"/>
      </geometry>
    </collision>
  </link>
  <link name="arm_2_tcp">
    <inertial>
      <origin xyz="0.0 0.05 0.1"/>
      <mass value="0.5"/>
      <inertia ixx="0.001" ixy="0.0" ixz="0.0" iyy="0.001" iyz="0.0" izz="0.001"/>
    </inertial>
  </link>
  <!-- JOINTS -->
  <!-- shoulder pitch -->
  <joint name="j_arm_2_1" type="revolute">
    <parent link="torso_1"/>
    <child link="arm_2_1"/>
    <axis xyz="0 0 1"/>
    <origin rpy="1.570796326795 0.0 0.0" xyz="0.0 -0.13515 -0.24215"/>
    <limit effort="147.0" lower="-2.6" upper="2.6" velocity="3.86"/>
  </joint>
  <!-- shoulder pitch -->
  <!-- shoulder yaw -->
  <joint name="j_arm_2_2" type="revolute">
    <parent link="arm_2_1"/>
    <child link="arm_2_2"/>
    <origin rpy="0.0 -1.570796326795 0.0" xyz="-0.06 -0.03 0.1255"/>
    <axis xyz="0 0 1"/>
    <!-- -1 -->
    <limit effort="147.0" lower="-0.1" upper="2.5" velocity="3.86"/>
  </joint>
  <!-- shoulder yaw -->
  <!-- shoulder yaw -->
  <joint name="j_arm_2_3" type="revolute">
    <parent link="arm_2_2"/>
    <child link="arm_2_3"/>
    <origin rpy="-1.570796326795 1.570796326795 0.0" xyz="0.0 -0.073 -0.06015"/>
    <axis xyz="0 0 -1"/>
    <!-- -1 -->
    <limit effort="147.0" lower="-2.6" upper="2.6" velocity="6.06"/>
  </joint>
  <!-- shoulder yaw -->
  <!-- elbow -->
  <joint name="j_arm_2_4" type="revolute">
    <parent link="arm_2_3"/>
    <child link="arm_2_4"/>
    <origin rpy="1.570796326795 0.0 0.0" xyz="0.0225 -0.05015 -0.29215"/>
    <axis xyz="0 0 1"/>
    <!-- -1 -->
    <limit effort="147.0" lower="-0.8" upper="2.4" velocity="6.06"/>
  </joint>
  <!-- elbow -->
  <!-- forearm yaw -->
  <joint name="j_arm_2_5" type="revolute">
    <parent link="arm_2_4"/>
    <child link="arm_2_5"/>
    <origin rpy="-1.570796326795 0.0 0.0" xyz="0.0 -0.0725 -0.05015"/>
    <axis xyz="0 0 -1"/>
    <!-- -1 -->
    <limit effort="55.0" lower="-2.8" upper="2.8" velocity="11.72"/>
  </joint>
  <!-- forearm yaw -->
  <!-- wrist pitch-->
  <joint name="j_arm_2_6" type="revolute">
    <parent link="arm_2_5"/>
    <child link="arm_2_6"/>
    <origin rpy="-1.570796326795 0.0 0.0" xyz="0.0 -0.05 -0.2475"/>
    <axis xyz="0 0 1"/>
    <limit effort="55.0" lower="-2.8" upper="2.1" velocity="11.72"/>
  </joint>
  <!-- wrist pitch-->
  <!-- wrist roll-->
  <joint name="j_arm_2_7" type="revolute">
    <parent link="arm_2_6"/>
    <child link="arm_2_7"/>
    <origin rpy="-1.570796326795 0.3316123 0.0" xyz="0.0 0.062877 0.05"/>
    <axis xyz="0 0 1"/>
    <limit effort="55.0" lower="-2.8" upper="2.8" velocity="11.72"/>
  </joint>
  <!-- /wrist roll-->
  <!-- virtual tip-->
  <joint name="j_tcp_2" type="fixed">
    <parent link="arm_2_7"/>
    <child link="arm_2_tcp"/>
    <origin rpy="0.0 0.0 0.0" xyz="0.0 0.0 0.0"/>
  </joint>
  <!-- virtual tip-->
  <transmission name="trans_j_arm_2_1">
    <type>transmission_interface/SimpleTransmission</type>
    <joint name="j_arm_2_1">
      <hardwareInterface>hardware_interface/PositionJointInterface</hardwareInterface>
    </joint>
    <actuator name="j_arm_2_1_motor">
      <hardwareInterface>hardware_interface/PositionJointInterface</hardwareInterface>
      <mechanicalReduction>1</mechanicalReduction>
    </actuator>
  </transmission>
  <transmission name="trans_j_arm_2_2">
    <type>transmission_interface/SimpleTransmission</type>
    <joint name="j_arm_2_2">
      <hardwareInterface>hardware_interface/PositionJointInterface</hardwareInterface>
    </joint>
    <actuator name="j_arm_2_2_motor">
      <hardwareInterface>hardware_interface/PositionJointInterface</hardwareInterface>
      <mechanicalReduction>1</mechanicalReduction>
    </actuator>
  </transmission>
  <transmission name="trans_j_arm_2_3">
    <type>transmission_interface/SimpleTransmission</type>
    <joint name="j_arm_2_3">
      <hardwareInterface>hardware_interface/PositionJointInterface</hardwareInterface>
    </joint>
    <actuator name="j_arm_2_3_motor">
      <hardwareInterface>hardware_interface/PositionJointInterface</hardwareInterface>
      <mechanicalReduction>1</mechanicalReduction>
    </actuator>
  </transmission>
  <transmission name="trans_j_arm_2_4">
    <type>transmission_interface/SimpleTransmission</type>
    <joint name="j_arm_2_4">
      <hardwareInterface>hardware_interface/PositionJointInterface</hardwareInterface>
    </joint>
    <actuator name="j_arm_2_4_motor">
      <hardwareInterface>hardware_interface/PositionJointInterface</hardwareInterface>
      <mechanicalReduction>1</mechanicalReduction>
    </actuator>
  </transmission>
  <transmission name="trans_j_arm_2_5">
    <type>transmission_interface/SimpleTransmission</type>
    <joint name="j_arm_2_5">
      <hardwareInterface>hardware_interface/PositionJointInterface</hardwareInterface>
    </joint>
    <actuator name="j_arm_2_5_motor">
      <hardwareInterface>hardware_interface/PositionJointInterface</hardwareInterface>
      <mechanicalReduction>1</mechanicalReduction>
    </actuator>
  </transmission>
  <transmission name="trans_j_arm_2_6">
    <type>transmission_interface/SimpleTransmission</type>
    <joint name="j_arm_2_6">
      <hardwareInterface>hardware_interface/PositionJointInterface</hardwareInterface>
    </joint>
    <actuator name="j_arm_2_6_motor">
      <hardwareInterface>hardware_interface/PositionJointInterface</hardwareInterface>
      <mechanicalReduction>1</mechanicalReduction>
    </actuator>
  </transmission>
  <transmission name="trans_j_arm_2_7">
    <type>transmission_interface/SimpleTransmission</type>
    <joint name="j_arm_2_7">
      <hardwareInterface>hardware_interface/PositionJointInterface</hardwareInterface>
    </joint>
    <actuator name="j_arm_2_7_motor">
      <hardwareInterface>hardware_interface/PositionJointInterface</hardwareInterface>
      <mechanicalReduction>1</mechanicalReduction>
    </actuator>
  </transmission>
  <transmission name="trans_j_torso_1">
    <type>transmission_interface/SimpleTransmission</type>
    <joint name="j_torso_1">
      <hardwareInterface>hardware_interface/PositionJointInterface</hardwareInterface>
    </joint>
    <actuator name="j_torso_1_motor">
      <hardwareInterface>hardware_interface/PositionJointInterface</hardwareInterface>
      <mechanicalReduction>1</mechanicalReduction>
    </actuator>
  </transmission>
  <link name="arm_1_1">
    <inertial>
      <origin xyz="0.010200651000000002 0.021560998 0.09876702500000001"/>
      <mass value="2.347"/>
      <inertia ixx="0.007192915699999999" ixy="-7.854318399999999e-05" ixz="-0.00039791235999999997" iyy="0.009471160999999999" iyz="-0.0012857050999999999" izz="0.0058530904"/>
    </inertial>
    <visual>
      <geometry>
        <mesh filename="package://repair_urdf/meshes/mesh_sh-pitch.stl" scale="0.001 -0.001 0.001"/>
      </geometry>
      <material name="dark"/>
    </visual>
    <collision>
      <geometry>
        <mesh filename="package://repair_urdf/meshes/simplified/mesh_sh-pitch.stl" scale="0.001 -0.001 0.001"/>
      </geometry>
    </collision>
  </link>
  <link name="arm_1_2">
    <inertial>
      <origin xyz="4.5955243e-05 0.044957128 -0.030791013"/>
      <mass value="0.76"/>
      <inertia ixx="0.0027927572" ixy="2.0135067e-06" ixz="-1.3644218e-06" iyy="0.0019288488" iyz="0.00066693438" izz="0.0026633366"/>
    </inertial>
    <visual>
      <geometry>
        <mesh filename="package://repair_urdf/meshes/mesh_sh-roll.stl" scale="0.001 -0.001 0.001"/>
      </geometry>
      <material name="dark"/>
    </visual>
    <collision>
      <geometry>
        <mesh filename="package://repair_urdf/meshes/simplified/mesh_sh-roll.stl" scale="0.001 -0.001 0.001"/>
      </geometry>
    </collision>
  </link>
  <link name="arm_1_3">
    <inertial>
      <origin xyz="0.005099315 -0.0059986523 -0.18011742"/>
      <mass value="3.34"/>
      <inertia ixx="0.031298784999999996" ixy="0.00025158367" ixz="0.002371127" iyy="0.031963501" iyz="-0.0018728041" izz="0.0026332359"/>
    </inertial>
    <visual>
      <geometry>
        <mesh filename="package://repair_urdf/meshes/mesh_sh-yaw.stl" scale="0.001 -0.001 0.001"/>
      </geometry>
      <material name="dark"/>
    </visual>
    <collision>
      <geometry>
        <mesh filename="package://repair_urdf/meshes/simplified/mesh_sh-yaw.stl" scale="0.001 -0.001 0.001"/>
      </geometry>
    </collision>
  </link>
  <link name="arm_1_4">
    <inertial>
      <origin xyz="3.332275e-06 0.033289421 -0.023682302"/>
      <mass value="0.55"/>
      <inertia ixx="0.0016198328" ixy="1.2642724e-06" ixz="-1.1734799e-06" iyy="0.0012266731" iyz="0.00039531700999999997" izz="0.0016081346"/>
    </inertial>
    <visual>
      <geometry>
        <mesh filename="package://repair_urdf/meshes/mesh_elbow.stl" scale="0.001 -0.001 0.001"/>
      </geometry>
      <material name="dark"/>
    </visual>
    <collision>
      <geometry>
        <mesh filename="package://repair_urdf/meshes/simplified/mesh_elbow.stl" scale="0.001 -0.001 0.001"/>
      </geometry>
    </collision>
  </link>
  <link name="arm_1_5">
    <inertial>
      <origin xyz="0.00094711044 0.048009667 -0.14331833"/>
      <mass value="2.825"/>
      <inertia ixx="0.030333275" ixy="-7.3729709e-05" ixz="3.2427371e-05" iyy="0.025195444999999997" iyz="0.0095263763" izz="0.0069975103999999995"/>
    </inertial>
    <visual>
      <geometry>
        <mesh filename="package://repair_urdf/meshes/mesh_forearm-yaw.stl" scale="0.001 -0.001 0.001"/>
      </geometry>
      <material name="dark"/>
    </visual>
    <collision>
      <geometry>
        <mesh filename="package://repair_urdf/meshes/simplified/mesh_forearm-yaw.stl" scale="0.001 -0.001 0.001"/>
      </geometry>
    </collision>
  </link>
  <link name="arm_1_6">
    <inertial>
      <origin xyz="0.00068559302 0.0050299682 0.046682846"/>
      <mass value="1.861"/>
      <inertia ixx="0.0042406037" ixy="5.5692732e-05" ixz="-9.085198200000001e-05" iyy="0.0029010805999999997" iyz="0.00018560541" izz="0.0044989008"/>
    </inertial>
    <visual>
      <geometry>
        <mesh filename="package://repair_urdf/meshes/mesh_wrist-pitch.stl" scale="0.001 -0.001 0.001"/>
      </geometry>
      <material name="dark"/>
    </visual>
    <collision>
      <geometry>
        <mesh filename="package://repair_urdf/meshes/simplified/mesh_wrist-pitch.stl" scale="0.001 -0.001 0.001"/>
      </geometry>
    </collision>
  </link>
  <link name="arm_1_7">
    <inertial>
      <origin xyz="0.0 0.0010491951 -0.010307299"/>
      <mass value="0.1416397"/>
      <inertia ixx="6.1479333e-05" ixy="7.4023399e-11" ixz="0.0" iyy="6.4247521e-05" iyz="-4.778644799999999e-07" izz="0.00011879743999999998"/>
    </inertial>
    <visual>
      <geometry>
        <mesh filename="package://repair_urdf/meshes/mesh_wrist-roll.stl" scale="0.001 -0.001 0.001"/>
      </geometry>
      <material name="dark"/>
    </visual>
    <collision>
      <geometry>
        <mesh filename="package://repair_urdf/meshes/simplified/mesh_wrist-roll.stl" scale="0.001 -0.001 0.001"/>
      </geometry>
    </collision>
  </link>
  <link name="arm_1_tcp">
    <inertial>
      <origin xyz="0.0 0.05 0.1"/>
      <mass value="0.5"/>
      <inertia ixx="0.001" ixy="0.0" ixz="0.0" iyy="0.001" iyz="0.0" izz="0.001"/>
    </inertial>
  </link>
  <!-- JOINTS -->
  <!-- shoulder pitch -->
  <joint name="j_arm_1_1" type="revolute">
    <parent link="torso_1"/>
    <child link="arm_1_1"/>
    <axis xyz="0 0 1"/>
    <origin rpy="-1.570796326795 0.0 0.0" xyz="0.0 0.13515 -0.24215"/>
    <limit effort="147.0" lower="-2.6" upper="2.6" velocity="3.86"/>
  </joint>
  <!-- shoulder pitch -->
  <!-- shoulder yaw -->
  <joint name="j_arm_1_2" type="revolute">
    <parent link="arm_1_1"/>
    <child link="arm_1_2"/>
    <origin rpy="-0.0 -1.570796326795 0.0" xyz="-0.06 0.03 0.1255"/>
    <axis xyz="0 0 1"/>
    <!-- -1 -->
    <limit effort="147.0" lower="-2.5" upper="0.1" velocity="3.86"/>
  </joint>
  <!-- shoulder yaw -->
  <!-- shoulder yaw -->
  <joint name="j_arm_1_3" type="revolute">
    <parent link="arm_1_2"/>
    <child link="arm_1_3"/>
    <origin rpy="1.570796326795 1.570796326795 0.0" xyz="0.0 0.073 -0.06015"/>
    <axis xyz="0 0 -1"/>
    <!-- -1 -->
    <limit effort="147.0" lower="-2.6" upper="2.6" velocity="6.06"/>
  </joint>
  <!-- shoulder yaw -->
  <!-- elbow -->
  <joint name="j_arm_1_4" type="revolute">
    <parent link="arm_1_3"/>
    <child link="arm_1_4"/>
    <origin rpy="-1.570796326795 0.0 0.0" xyz="0.0225 0.05015 -0.29215"/>
    <axis xyz="0 0 1"/>
    <!-- -1 -->
    <limit effort="147.0" lower="-2.4" upper="0.8" velocity="6.06"/>
  </joint>
  <!-- elbow -->
  <!-- forearm yaw -->
  <joint name="j_arm_1_5" type="revolute">
    <parent link="arm_1_4"/>
    <child link="arm_1_5"/>
    <origin rpy="1.570796326795 0.0 0.0" xyz="0.0 0.0725 -0.05015"/>
    <axis xyz="0 0 -1"/>
    <!-- -1 -->
    <limit effort="55.0" lower="-2.8" upper="2.8" velocity="11.72"/>
  </joint>
  <!-- forearm yaw -->
  <!-- wrist pitch-->
  <joint name="j_arm_1_6" type="revolute">
    <parent link="arm_1_5"/>
    <child link="arm_1_6"/>
    <origin rpy="1.570796326795 0.0 0.0" xyz="0.0 0.05 -0.2475"/>
    <axis xyz="0 0 1"/>
    <limit effort="55.0" lower="-2.1" upper="2.8" velocity="11.72"/>
  </joint>
  <!-- wrist pitch-->
  <!-- wrist roll-->
  <joint name="j_arm_1_7" type="revolute">
    <parent link="arm_1_6"/>
    <child link="arm_1_7"/>
    <origin rpy="1.570796326795 0.3316123 0.0" xyz="0.0 -0.062877 0.05"/>
    <axis xyz="0 0 1"/>
    <limit effort="55.0" lower="-2.8" upper="2.8" velocity="11.72"/>
  </joint>
  <!-- /wrist roll-->
  <!-- virtual tip-->
  <joint name="j_tcp_1" type="fixed">
    <parent link="arm_1_7"/>
    <child link="arm_1_tcp"/>
    <origin rpy="-0.0 0.0 0.0" xyz="0.0 -0.0 0.0"/>
  </joint>
  <!-- virtual tip-->
  <transmission name="trans_j_arm_1_1">
    <type>transmission_interface/SimpleTransmission</type>
    <joint name="j_arm_1_1">
      <hardwareInterface>hardware_interface/PositionJointInterface</hardwareInterface>
    </joint>
    <actuator name="j_arm_1_1_motor">
      <hardwareInterface>hardware_interface/PositionJointInterface</hardwareInterface>
      <mechanicalReduction>1</mechanicalReduction>
    </actuator>
  </transmission>
  <transmission name="trans_j_arm_1_2">
    <type>transmission_interface/SimpleTransmission</type>
    <joint name="j_arm_1_2">
      <hardwareInterface>hardware_interface/PositionJointInterface</hardwareInterface>
    </joint>
    <actuator name="j_arm_1_2_motor">
      <hardwareInterface>hardware_interface/PositionJointInterface</hardwareInterface>
      <mechanicalReduction>1</mechanicalReduction>
    </actuator>
  </transmission>
  <transmission name="trans_j_arm_1_3">
    <type>transmission_interface/SimpleTransmission</type>
    <joint name="j_arm_1_3">
      <hardwareInterface>hardware_interface/PositionJointInterface</hardwareInterface>
    </joint>
    <actuator name="j_arm_1_3_motor">
      <hardwareInterface>hardware_interface/PositionJointInterface</hardwareInterface>
      <mechanicalReduction>1</mechanicalReduction>
    </actuator>
  </transmission>
  <transmission name="trans_j_arm_1_4">
    <type>transmission_interface/SimpleTransmission</type>
    <joint name="j_arm_1_4">
      <hardwareInterface>hardware_interface/PositionJointInterface</hardwareInterface>
    </joint>
    <actuator name="j_arm_1_4_motor">
      <hardwareInterface>hardware_interface/PositionJointInterface</hardwareInterface>
      <mechanicalReduction>1</mechanicalReduction>
    </actuator>
  </transmission>
  <transmission name="trans_j_arm_1_5">
    <type>transmission_interface/SimpleTransmission</type>
    <joint name="j_arm_1_5">
      <hardwareInterface>hardware_interface/PositionJointInterface</hardwareInterface>
    </joint>
    <actuator name="j_arm_1_5_motor">
      <hardwareInterface>hardware_interface/PositionJointInterface</hardwareInterface>
      <mechanicalReduction>1</mechanicalReduction>
    </actuator>
  </transmission>
  <transmission name="trans_j_arm_1_6">
    <type>transmission_interface/SimpleTransmission</type>
    <joint name="j_arm_1_6">
      <hardwareInterface>hardware_interface/PositionJointInterface</hardwareInterface>
    </joint>
    <actuator name="j_arm_1_6_motor">
      <hardwareInterface>hardware_interface/PositionJointInterface</hardwareInterface>
      <mechanicalReduction>1</mechanicalReduction>
    </actuator>
  </transmission>
  <transmission name="trans_j_arm_1_7">
    <type>transmission_interface/SimpleTransmission</type>
    <joint name="j_arm_1_7">
      <hardwareInterface>hardware_interface/PositionJointInterface</hardwareInterface>
    </joint>
    <actuator name="j_arm_1_7_motor">
      <hardwareInterface>hardware_interface/PositionJointInterface</hardwareInterface>
      <mechanicalReduction>1</mechanicalReduction>
    </actuator>
  </transmission>
  <transmission name="trans_j_torso_1">
    <type>transmission_interface/SimpleTransmission</type>
    <joint name="j_torso_1">
      <hardwareInterface>hardware_interface/PositionJointInterface</hardwareInterface>
    </joint>
    <actuator name="j_torso_1_motor">
      <hardwareInterface>hardware_interface/PositionJointInterface</hardwareInterface>
      <mechanicalReduction>1</mechanicalReduction>
    </actuator>
  </transmission>
  

    # Softhand VERSION 1.0
    
  

    # Softhand VERSION 1.0 SIMPLIFIED (less joints)
    
  
		# Softhand Base
		
  <joint name="left_hand_base_joint" type="fixed">
    <origin rpy="0 0.0 3.14159265359" xyz="0 0 -0.015"/>
    <parent link="arm_1_7"/>
    <child link="left_hand_v1s_palm_base"/>
  </joint>
  <link name="left_hand_v1s_palm_base"/>
  
		# RIGHT HAND
		
  
		# LEFT HAND
		
  
			# Palm
			
  <joint name="left_hand_v1s_palm_joint" type="fixed">
    <origin rpy="0 0 0" xyz="0.002 0.00695 0.0535"/>
    <parent link="left_hand_v1s_palm_base"/>
    <child link="left_hand_v1s_palm_link"/>
  </joint>
  <link name="left_hand_v1s_palm_link">
    <inertial>
      <origin xyz="-0.004568758 -0.006808116 0.027653328"/>
      <mass value="2.28"/>
      <inertia ixx="0.001" ixy="0" ixz="0" iyy="0.001" iyz="0" izz="0.001"/>
    </inertial>
    <visual>
      <geometry>
        <mesh filename="package://softhands_description/meshes/softhands/v1.0/left/palm_left_m.stl"/>
      </geometry>
    </visual>
    <collision>
      <geometry>
        <mesh filename="package://softhands_description/meshes/softhands/v1.0/left/palm_left_m.stl"/>
      </geometry>
    </collision>
    <visual>
      <origin rpy="0 0 0" xyz="-0.002 0.00695 -0.0535"/>
      <geometry>
        <mesh filename="package://softhands_description/meshes/softhands/v1.0/left/softhand_base_left_m.stl"/>
      </geometry>
    </visual>
    <collision>
      <origin rpy="0 0 0" xyz="-0.002 0.00695 -0.0535"/>
      <geometry>
        <mesh filename="package://softhands_description/meshes/softhands/v1.0/right/softhand_base_right_m.stl"/>
      </geometry>
    </collision>
  </link>
  
			# Thumb finger
			
  <!-- KNUCKLE -->
  <joint name="left_hand_v1s_thumb_knuckle_joint" type="fixed">
    <origin rpy="0.0 -0.38397275793662144 -1.5707963267948966" xyz="0.005669722 -0.029616 0.055314"/>
    <parent link="left_hand_v1s_palm_link"/>
    <child link="left_hand_v1s_thumb_knuckle_link"/>
    <axis xyz="0 0 1"/>
    <dynamics damping="0.08" friction="0.0"/>
  </joint>
  <link name="left_hand_v1s_thumb_knuckle_link">
    <inertial>
      <origin xyz="0.001285644 0 0.000425011"/>
      <mass value="0.09"/>
      <inertia ixx="0.001" ixy="0" ixz="0" iyy="0.001" iyz="0" izz="0.001"/>
    </inertial>
    <visual>
      <geometry>
        <mesh filename="package://softhands_description/meshes/softhands/v1.0/left/thumb_knuckle_left_m.stl"/>
      </geometry>
    </visual>
    <collision>
      <geometry>
        <mesh filename="package://softhands_description/meshes/softhands/v1.0/left/thumb_knuckle_left_m.stl"/>
      </geometry>
    </collision>
  </link>
  <!-- PROXIMAL PHALANGE -->
  <joint name="left_hand_v1s_thumb_proximal_joint" type="fixed">
    <origin rpy="-0.426627741408745 0 0.0" xyz="0.033500000 0.0033 0.0"/>
    <parent link="left_hand_v1s_thumb_knuckle_link"/>
    <child link="left_hand_v1s_thumb_proximal_link"/>
    <axis xyz="0 -1 0"/>
    <dynamics damping="0.08" friction="0.0"/>
  </joint>
  <link name="left_hand_v1s_thumb_proximal_link">
    <inertial>
      <origin xyz="0.005074337 0 -0.000262953"/>
      <mass value="0.05"/>
      <inertia ixx="0.001" ixy="0" ixz="0" iyy="0.001" iyz="0" izz="0.001"/>
    </inertial>
    <visual>
      <geometry>
        <mesh filename="package://softhands_description/meshes/softhands/v1.0/common/phalanx_m.stl"/>
      </geometry>
    </visual>
    <collision>
      <geometry>
        <mesh filename="package://softhands_description/meshes/softhands/v1.0/common/phalanx_m.stl"/>
      </geometry>
    </collision>
  </link>
  <!-- DISTAL PHALANGE -->
  <joint name="left_hand_v1s_thumb_distal_joint" type="fixed">
    <origin rpy="0 0 0" xyz="0.020 0 0.0"/>
    <parent link="left_hand_v1s_thumb_proximal_link"/>
    <child link="left_hand_v1s_thumb_distal_link"/>
    <axis xyz="0 -1 0"/>
    <dynamics damping="0.08" friction="0.0"/>
  </joint>
  <link name="left_hand_v1s_thumb_distal_link">
    <inertial>
      <origin xyz="0.009849094 0 0.000820286"/>
      <mass value="0.1"/>
      <inertia ixx="0.001" ixy="0" ixz="0" iyy="0.001" iyz="0" izz="0.001"/>
    </inertial>
    <visual>
      <geometry>
        <mesh filename="package://softhands_description/meshes/softhands/v1.0/common/fingertip_m.stl"/>
      </geometry>
    </visual>
    <collision>
      <geometry>
        <mesh filename="package://softhands_description/meshes/softhands/v1.0/common/fingertip_m.stl"/>
      </geometry>
    </collision>
  </link>
  
			# Index finger
			
  <!-- KNUCKLE -->
  <joint name="left_hand_v1s_index_knuckle_joint" type="fixed">
    <origin rpy="-1.5707963267948966 -1.4835299330931884 -1.5707963267948966" xyz="-0.0033 -0.0195 0.0936994"/>
    <parent link="left_hand_v1s_palm_link"/>
    <child link="left_hand_v1s_index_knuckle_link"/>
    <limit effort="30" lower="-1.57" upper="1.57" velocity="1.0"/>
    <axis xyz="0 0 -1"/>
    <dynamics damping="0.08" friction="0.0"/>
  </joint>
  <link name="left_hand_v1s_index_knuckle_link">
    <inertial>
      <origin xyz="0.001285644 0 0.000425011"/>
      <mass value="0.09"/>
      <inertia ixx="0.001" ixy="0" ixz="0" iyy="0.001" iyz="0" izz="0.001"/>
    </inertial>
    <visual>
      <geometry>
        <mesh filename="package://softhands_description/meshes/softhands/v1.0/common/knuckle_m.stl"/>
      </geometry>
    </visual>
    <collision>
      <geometry>
        <mesh filename="package://softhands_description/meshes/softhands/v1.0/common/knuckle_m.stl"/>
      </geometry>
    </collision>
  </link>
  <!-- PROXIMAL PHALANGE -->
  <joint name="left_hand_v1s_index_proximal_joint" type="fixed">
    <origin rpy="0 0 0" xyz="0.020 0 0"/>
    <parent link="left_hand_v1s_index_knuckle_link"/>
    <child link="left_hand_v1s_index_proximal_link"/>
    <limit effort="30" lower="-1.57" upper="1.57" velocity="1.0"/>
    <axis xyz="0 -1 0"/>
  </joint>
  <link name="left_hand_v1s_index_proximal_link">
    <inertial>
      <origin xyz="0.005074337 0 -0.000262953"/>
      <mass value="0.05"/>
      <inertia ixx="0.001" ixy="0" ixz="0" iyy="0.001" iyz="0" izz="0.001"/>
    </inertial>
    <visual>
      <geometry>
        <mesh filename="package://softhands_description/meshes/softhands/v1.0/common/phalanx_m.stl"/>
      </geometry>
    </visual>
    <collision>
      <geometry>
        <mesh filename="package://softhands_description/meshes/softhands/v1.0/common/phalanx_m.stl"/>
      </geometry>
    </collision>
  </link>
  <!-- MIDDLE PHALANGE -->
  <joint name="left_hand_v1s_index_middle_joint" type="fixed">
    <origin rpy="0 0 0" xyz="0.020 0 0"/>
    <parent link="left_hand_v1s_index_proximal_link"/>
    <child link="left_hand_v1s_index_middle_link"/>
    <limit effort="30" lower="-1.57" upper="1.57" velocity="1.0"/>
    <axis xyz="0 -1 0"/>
    <dynamics damping="0.08" friction="0.0"/>
  </joint>
  <link name="left_hand_v1s_index_middle_link">
    <inertial>
      <origin xyz="0.005074337 0 -0.000262953"/>
      <mass value="0.05"/>
      <inertia ixx="0.001" ixy="0" ixz="0" iyy="0.001" iyz="0" izz="0.001"/>
    </inertial>
    <visual>
      <geometry>
        <mesh filename="package://softhands_description/meshes/softhands/v1.0/common/phalanx_m.stl"/>
      </geometry>
    </visual>
    <collision>
      <geometry>
        <mesh filename="package://softhands_description/meshes/softhands/v1.0/common/phalanx_m.stl"/>
      </geometry>
    </collision>
  </link>
  <!-- DISTAL PHALANGE -->
  <joint name="left_hand_v1s_index_distal_joint" type="fixed">
    <origin rpy="0 0 0" xyz="0.020 0 0"/>
    <parent link="left_hand_v1s_index_middle_link"/>
    <child link="left_hand_v1s_index_distal_link"/>
    <limit effort="30" lower="-1.57" upper="1.57" velocity="1.0"/>
    <axis xyz="0 -1 0"/>
    <dynamics damping="0.08" friction="0.0"/>
  </joint>
  <link name="left_hand_v1s_index_distal_link">
    <inertial>
      <origin xyz="0.009849094 0 0.000820286"/>
      <mass value="0.1"/>
      <inertia ixx="0.001" ixy="0" ixz="0" iyy="0.001" iyz="0" izz="0.001"/>
    </inertial>
    <visual>
      <geometry>
        <mesh filename="package://softhands_description/meshes/softhands/v1.0/common/fingertip_m.stl"/>
      </geometry>
    </visual>
    <collision>
      <geometry>
        <mesh filename="package://softhands_description/meshes/softhands/v1.0/common/fingertip_m.stl"/>
      </geometry>
    </collision>
  </link>
  
			# Middle finger
			
  <!-- KNUCKLE -->
  <joint name="left_hand_v1s_middle_knuckle_joint" type="fixed">
    <origin rpy="3.1415 -1.5707963267948966 0.0" xyz="-0.0033 0.0 0.100699"/>
    <parent link="left_hand_v1s_palm_link"/>
    <child link="left_hand_v1s_middle_knuckle_link"/>
    <limit effort="30" lower="-1.57" upper="1.57" velocity="1.0"/>
    <axis xyz="0 0 -1"/>
    <dynamics damping="0.08" friction="0.0"/>
  </joint>
  <link name="left_hand_v1s_middle_knuckle_link">
    <inertial>
      <origin xyz="0.001285644 0 0.000425011"/>
      <mass value="0.09"/>
      <inertia ixx="0.001" ixy="0" ixz="0" iyy="0.001" iyz="0" izz="0.001"/>
    </inertial>
    <visual>
      <geometry>
        <mesh filename="package://softhands_description/meshes/softhands/v1.0/common/knuckle_m.stl"/>
      </geometry>
    </visual>
    <collision>
      <geometry>
        <mesh filename="package://softhands_description/meshes/softhands/v1.0/common/knuckle_m.stl"/>
      </geometry>
    </collision>
  </link>
  <!-- PROXIMAL PHALANGE -->
  <joint name="left_hand_v1s_middle_proximal_joint" type="fixed">
    <origin rpy="0 0 0" xyz="0.020 0 0"/>
    <parent link="left_hand_v1s_middle_knuckle_link"/>
    <child link="left_hand_v1s_middle_proximal_link"/>
    <limit effort="30" lower="-1.57" upper="1.57" velocity="1.0"/>
    <axis xyz="0 -1 0"/>
  </joint>
  <link name="left_hand_v1s_middle_proximal_link">
    <inertial>
      <origin xyz="0.005074337 0 -0.000262953"/>
      <mass value="0.05"/>
      <inertia ixx="0.001" ixy="0" ixz="0" iyy="0.001" iyz="0" izz="0.001"/>
    </inertial>
    <visual>
      <geometry>
        <mesh filename="package://softhands_description/meshes/softhands/v1.0/common/phalanx_m.stl"/>
      </geometry>
    </visual>
    <collision>
      <geometry>
        <mesh filename="package://softhands_description/meshes/softhands/v1.0/common/phalanx_m.stl"/>
      </geometry>
    </collision>
  </link>
  <!-- MIDDLE PHALANGE -->
  <joint name="left_hand_v1s_middle_middle_joint" type="fixed">
    <origin rpy="0 0 0" xyz="0.020 0 0"/>
    <parent link="left_hand_v1s_middle_proximal_link"/>
    <child link="left_hand_v1s_middle_middle_link"/>
    <limit effort="30" lower="-1.57" upper="1.57" velocity="1.0"/>
    <axis xyz="0 -1 0"/>
    <dynamics damping="0.08" friction="0.0"/>
  </joint>
  <link name="left_hand_v1s_middle_middle_link">
    <inertial>
      <origin xyz="0.005074337 0 -0.000262953"/>
      <mass value="0.05"/>
      <inertia ixx="0.001" ixy="0" ixz="0" iyy="0.001" iyz="0" izz="0.001"/>
    </inertial>
    <visual>
      <geometry>
        <mesh filename="package://softhands_description/meshes/softhands/v1.0/common/phalanx_m.stl"/>
      </geometry>
    </visual>
    <collision>
      <geometry>
        <mesh filename="package://softhands_description/meshes/softhands/v1.0/common/phalanx_m.stl"/>
      </geometry>
    </collision>
  </link>
  <!-- DISTAL PHALANGE -->
  <joint name="left_hand_v1s_middle_distal_joint" type="fixed">
    <origin rpy="0 0 0" xyz="0.020 0 0"/>
    <parent link="left_hand_v1s_middle_middle_link"/>
    <child link="left_hand_v1s_middle_distal_link"/>
    <limit effort="30" lower="-1.57" upper="1.57" velocity="1.0"/>
    <axis xyz="0 -1 0"/>
    <dynamics damping="0.08" friction="0.0"/>
  </joint>
  <link name="left_hand_v1s_middle_distal_link">
    <inertial>
      <origin xyz="0.009849094 0 0.000820286"/>
      <mass value="0.1"/>
      <inertia ixx="0.001" ixy="0" ixz="0" iyy="0.001" iyz="0" izz="0.001"/>
    </inertial>
    <visual>
      <geometry>
        <mesh filename="package://softhands_description/meshes/softhands/v1.0/common/fingertip_m.stl"/>
      </geometry>
    </visual>
    <collision>
      <geometry>
        <mesh filename="package://softhands_description/meshes/softhands/v1.0/common/fingertip_m.stl"/>
      </geometry>
    </collision>
  </link>
  
			# Ring finger
			
  <!-- KNUCKLE -->
  <joint name="left_hand_v1s_ring_knuckle_joint" type="fixed">
    <origin rpy="1.5707963267948966 -1.5184364298870514 1.5707963267948966" xyz="-0.0033 0.0195 0.0936994"/>
    <parent link="left_hand_v1s_palm_link"/>
    <child link="left_hand_v1s_ring_knuckle_link"/>
    <limit effort="30" lower="-1.57" upper="1.57" velocity="1.0"/>
    <axis xyz="0 0 -1"/>
    <dynamics damping="0.08" friction="0.0"/>
  </joint>
  <link name="left_hand_v1s_ring_knuckle_link">
    <inertial>
      <origin xyz="0.001285644 0 0.000425011"/>
      <mass value="0.09"/>
      <inertia ixx="0.001" ixy="0" ixz="0" iyy="0.001" iyz="0" izz="0.001"/>
    </inertial>
    <visual>
      <geometry>
        <mesh filename="package://softhands_description/meshes/softhands/v1.0/common/knuckle_m.stl"/>
      </geometry>
    </visual>
    <collision>
      <geometry>
        <mesh filename="package://softhands_description/meshes/softhands/v1.0/common/knuckle_m.stl"/>
      </geometry>
    </collision>
  </link>
  <!-- PROXIMAL PHALANGE -->
  <joint name="left_hand_v1s_ring_proximal_joint" type="fixed">
    <origin rpy="0 0 0" xyz="0.020 0 0"/>
    <parent link="left_hand_v1s_ring_knuckle_link"/>
    <child link="left_hand_v1s_ring_proximal_link"/>
    <limit effort="30" lower="-1.57" upper="1.57" velocity="1.0"/>
    <axis xyz="0 -1 0"/>
  </joint>
  <link name="left_hand_v1s_ring_proximal_link">
    <inertial>
      <origin xyz="0.005074337 0 -0.000262953"/>
      <mass value="0.05"/>
      <inertia ixx="0.001" ixy="0" ixz="0" iyy="0.001" iyz="0" izz="0.001"/>
    </inertial>
    <visual>
      <geometry>
        <mesh filename="package://softhands_description/meshes/softhands/v1.0/common/phalanx_m.stl"/>
      </geometry>
    </visual>
    <collision>
      <geometry>
        <mesh filename="package://softhands_description/meshes/softhands/v1.0/common/phalanx_m.stl"/>
      </geometry>
    </collision>
  </link>
  <!-- MIDDLE PHALANGE -->
  <joint name="left_hand_v1s_ring_middle_joint" type="fixed">
    <origin rpy="0 0 0" xyz="0.020 0 0"/>
    <parent link="left_hand_v1s_ring_proximal_link"/>
    <child link="left_hand_v1s_ring_middle_link"/>
    <limit effort="30" lower="-1.57" upper="1.57" velocity="1.0"/>
    <axis xyz="0 -1 0"/>
    <dynamics damping="0.08" friction="0.0"/>
  </joint>
  <link name="left_hand_v1s_ring_middle_link">
    <inertial>
      <origin xyz="0.005074337 0 -0.000262953"/>
      <mass value="0.05"/>
      <inertia ixx="0.001" ixy="0" ixz="0" iyy="0.001" iyz="0" izz="0.001"/>
    </inertial>
    <visual>
      <geometry>
        <mesh filename="package://softhands_description/meshes/softhands/v1.0/common/phalanx_m.stl"/>
      </geometry>
    </visual>
    <collision>
      <geometry>
        <mesh filename="package://softhands_description/meshes/softhands/v1.0/common/phalanx_m.stl"/>
      </geometry>
    </collision>
  </link>
  <!-- DISTAL PHALANGE -->
  <joint name="left_hand_v1s_ring_distal_joint" type="fixed">
    <origin rpy="0 0 0" xyz="0.020 0 0"/>
    <parent link="left_hand_v1s_ring_middle_link"/>
    <child link="left_hand_v1s_ring_distal_link"/>
    <limit effort="30" lower="-1.57" upper="1.57" velocity="1.0"/>
    <axis xyz="0 -1 0"/>
    <dynamics damping="0.08" friction="0.0"/>
  </joint>
  <link name="left_hand_v1s_ring_distal_link">
    <inertial>
      <origin xyz="0.009849094 0 0.000820286"/>
      <mass value="0.1"/>
      <inertia ixx="0.001" ixy="0" ixz="0" iyy="0.001" iyz="0" izz="0.001"/>
    </inertial>
    <visual>
      <geometry>
        <mesh filename="package://softhands_description/meshes/softhands/v1.0/common/fingertip_m.stl"/>
      </geometry>
    </visual>
    <collision>
      <geometry>
        <mesh filename="package://softhands_description/meshes/softhands/v1.0/common/fingertip_m.stl"/>
      </geometry>
    </collision>
  </link>
  
			# Little finger
			
  <!-- KNUCKLE -->
  <joint name="left_hand_v1s_little_knuckle_joint" type="fixed">
    <origin rpy="1.5707963267948966 -1.4835299330931884 1.5707963267948966" xyz="-0.0033 0.039 0.0836994"/>
    <parent link="left_hand_v1s_palm_link"/>
    <child link="left_hand_v1s_little_knuckle_link"/>
    <limit effort="30" lower="-1.57" upper="1.57" velocity="1.0"/>
    <axis xyz="0 0 -1"/>
    <dynamics damping="0.08" friction="0.0"/>
  </joint>
  <link name="left_hand_v1s_little_knuckle_link">
    <inertial>
      <origin xyz="0.001285644 0 0.000425011"/>
      <mass value="0.09"/>
      <inertia ixx="0.001" ixy="0" ixz="0" iyy="0.001" iyz="0" izz="0.001"/>
    </inertial>
    <visual>
      <geometry>
        <mesh filename="package://softhands_description/meshes/softhands/v1.0/common/knuckle_m.stl"/>
      </geometry>
    </visual>
    <collision>
      <geometry>
        <mesh filename="package://softhands_description/meshes/softhands/v1.0/common/knuckle_m.stl"/>
      </geometry>
    </collision>
  </link>
  <!-- PROXIMAL PHALANGE -->
  <joint name="left_hand_v1s_little_proximal_joint" type="fixed">
    <origin rpy="0 0 0" xyz="0.020 0 0"/>
    <parent link="left_hand_v1s_little_knuckle_link"/>
    <child link="left_hand_v1s_little_proximal_link"/>
    <limit effort="30" lower="-1.57" upper="1.57" velocity="1.0"/>
    <axis xyz="0 -1 0"/>
  </joint>
  <link name="left_hand_v1s_little_proximal_link">
    <inertial>
      <origin xyz="0.005074337 0 -0.000262953"/>
      <mass value="0.05"/>
      <inertia ixx="0.001" ixy="0" ixz="0" iyy="0.001" iyz="0" izz="0.001"/>
    </inertial>
    <visual>
      <geometry>
        <mesh filename="package://softhands_description/meshes/softhands/v1.0/common/phalanx_m.stl"/>
      </geometry>
    </visual>
    <collision>
      <geometry>
        <mesh filename="package://softhands_description/meshes/softhands/v1.0/common/phalanx_m.stl"/>
      </geometry>
    </collision>
  </link>
  <!-- MIDDLE PHALANGE -->
  <joint name="left_hand_v1s_little_middle_joint" type="fixed">
    <origin rpy="0 0 0" xyz="0.020 0 0"/>
    <parent link="left_hand_v1s_little_proximal_link"/>
    <child link="left_hand_v1s_little_middle_link"/>
    <limit effort="30" lower="-1.57" upper="1.57" velocity="1.0"/>
    <axis xyz="0 -1 0"/>
    <dynamics damping="0.08" friction="0.0"/>
  </joint>
  <link name="left_hand_v1s_little_middle_link">
    <inertial>
      <origin xyz="0.005074337 0 -0.000262953"/>
      <mass value="0.05"/>
      <inertia ixx="0.001" ixy="0" ixz="0" iyy="0.001" iyz="0" izz="0.001"/>
    </inertial>
    <visual>
      <geometry>
        <mesh filename="package://softhands_description/meshes/softhands/v1.0/common/phalanx_m.stl"/>
      </geometry>
    </visual>
    <collision>
      <geometry>
        <mesh filename="package://softhands_description/meshes/softhands/v1.0/common/phalanx_m.stl"/>
      </geometry>
    </collision>
  </link>
  <!-- DISTAL PHALANGE -->
  <joint name="left_hand_v1s_little_distal_joint" type="fixed">
    <origin rpy="0 0 0" xyz="0.020 0 0"/>
    <parent link="left_hand_v1s_little_middle_link"/>
    <child link="left_hand_v1s_little_distal_link"/>
    <limit effort="30" lower="-1.57" upper="1.57" velocity="1.0"/>
    <axis xyz="0 -1 0"/>
    <dynamics damping="0.08" friction="0.0"/>
  </joint>
  <link name="left_hand_v1s_little_distal_link">
    <inertial>
      <origin xyz="0.009849094 0 0.000820286"/>
      <mass value="0.1"/>
      <inertia ixx="0.001" ixy="0" ixz="0" iyy="0.001" iyz="0" izz="0.001"/>
    </inertial>
    <visual>
      <geometry>
        <mesh filename="package://softhands_description/meshes/softhands/v1.0/common/fingertip_m.stl"/>
      </geometry>
    </visual>
    <collision>
      <geometry>
        <mesh filename="package://softhands_description/meshes/softhands/v1.0/common/fingertip_m.stl"/>
      </geometry>
    </collision>
  </link>
  
		# Gazebo NEW custom synergy-plugin
		
  <gazebo>
    <plugin filename="libsofthand_plugin.so" name="synergy_plugin">
      <namespace>left_hand_v1s</namespace>
      <operation_mode>0</operation_mode>
    </plugin>
  </gazebo>
  

    # Softhand VERSION 2.0
    
  

    # Softhand VERSION 2.0 SIMPLIFIED (less joints)
    
  

    # TODO: OTHER VERSIONs

    
  <gazebo>
    <self_collide>1</self_collide>
  </gazebo>
  

    # Softhand VERSION 1.0
    
  

    # Softhand VERSION 1.0 SIMPLIFIED (less joints)
    
  
		# Softhand Base
		
  <joint name="right_hand_base_joint" type="fixed">
    <origin rpy="0 0 3.14159265359" xyz="0 -0.013900 -0.015"/>
    <parent link="arm_2_7"/>
    <child link="right_hand_v1s_palm_base"/>
  </joint>
  <link name="right_hand_v1s_palm_base"/>
  
		# RIGHT HAND
		
  
			# Palm
			
  <joint name="right_hand_v1s_palm_joint" type="fixed">
    <origin rpy="0 0 0" xyz="0.002 0.00695 0.0535"/>
    <parent link="right_hand_v1s_palm_base"/>
    <child link="right_hand_v1s_palm_link"/>
  </joint>
  <link name="right_hand_v1s_palm_link">
    <inertial>
      <origin xyz="-0.004568758 -0.006808116 0.027653328"/>
      <mass value="2.28"/>
      <inertia ixx="0.001" ixy="0" ixz="0" iyy="0.001" iyz="0" izz="0.001"/>
    </inertial>
    <visual>
      <geometry>
        <mesh filename="package://softhands_description/meshes/softhands/v1.0/right/palm_right_m.stl"/>
      </geometry>
    </visual>
    <collision>
      <geometry>
        <mesh filename="package://softhands_description/meshes/softhands/v1.0/right/palm_right_m.stl"/>
      </geometry>
    </collision>
    <visual>
      <origin rpy="0 0 0" xyz="-0.002 -0.00695 -0.0535"/>
      <geometry>
        <mesh filename="package://softhands_description/meshes/softhands/v1.0/right/softhand_base_right_m.stl"/>
      </geometry>
    </visual>
    <collision>
      <origin rpy="0 0 0" xyz="-0.002 -0.00695 -0.0535"/>
      <geometry>
        <mesh filename="package://softhands_description/meshes/softhands/v1.0/right/softhand_base_right_m.stl"/>
      </geometry>
    </collision>
  </link>
  
			# Thumb finger
			
  <!-- KNUCKLE -->
  <joint name="right_hand_v1s_thumb_knuckle_joint" type="fixed">
    <origin rpy="0.0 -0.38397275793662144 1.5707963267948966" xyz="0.00566972 0.0296160 0.0553140"/>
    <parent link="right_hand_v1s_palm_link"/>
    <child link="right_hand_v1s_thumb_knuckle_link"/>
    <axis xyz="0 0 -1"/>
    <dynamics damping="0.08" friction="0.0"/>
  </joint>
  <link name="right_hand_v1s_thumb_knuckle_link">
    <inertial>
      <origin xyz="0.001285644 0 0.000425011"/>
      <mass value="0.09"/>
      <inertia ixx="0.001" ixy="0" ixz="0" iyy="0.001" iyz="0" izz="0.001"/>
    </inertial>
    <visual>
      <geometry>
        <mesh filename="package://softhands_description/meshes/softhands/v1.0/right/thumb_knuckle_right_m.stl"/>
      </geometry>
    </visual>
    <collision>
      <geometry>
        <mesh filename="package://softhands_description/meshes/softhands/v1.0/right/thumb_knuckle_right_m.stl"/>
      </geometry>
    </collision>
  </link>
  <!-- PROXIMAL PHALANGE -->
  <joint name="right_hand_v1s_thumb_proximal_joint" type="fixed">
    <origin rpy="0.426627741408745 0 0.0" xyz="0.033500000 -0.0033 0.0"/>
    <parent link="right_hand_v1s_thumb_knuckle_link"/>
    <child link="right_hand_v1s_thumb_proximal_link"/>
    <axis xyz="0 -1 0"/>
    <dynamics damping="0.08" friction="0.0"/>
  </joint>
  <link name="right_hand_v1s_thumb_proximal_link">
    <inertial>
      <origin xyz="0.005074337 0 -0.000262953"/>
      <mass value="0.05"/>
      <inertia ixx="0.001" ixy="0" ixz="0" iyy="0.001" iyz="0" izz="0.001"/>
    </inertial>
    <visual>
      <geometry>
        <mesh filename="package://softhands_description/meshes/softhands/v1.0/common/phalanx_m.stl"/>
      </geometry>
    </visual>
    <collision>
      <geometry>
        <mesh filename="package://softhands_description/meshes/softhands/v1.0/common/phalanx_m.stl"/>
      </geometry>
    </collision>
  </link>
  <!-- DISTAL PHALANGE -->
  <joint name="right_hand_v1s_thumb_distal_joint" type="fixed">
    <origin rpy="0 0 0" xyz="0.020 0 0.0"/>
    <parent link="right_hand_v1s_thumb_proximal_link"/>
    <child link="right_hand_v1s_thumb_distal_link"/>
    <axis xyz="0 -1 0"/>
    <dynamics damping="0.08" friction="0.0"/>
  </joint>
  <link name="right_hand_v1s_thumb_distal_link">
    <inertial>
      <origin xyz="0.009849094 0 0.000820286"/>
      <mass value="0.1"/>
      <inertia ixx="0.001" ixy="0" ixz="0" iyy="0.001" iyz="0" izz="0.001"/>
    </inertial>
    <visual>
      <geometry>
        <mesh filename="package://softhands_description/meshes/softhands/v1.0/common/fingertip_m.stl"/>
      </geometry>
    </visual>
    <collision>
      <geometry>
        <mesh filename="package://softhands_description/meshes/softhands/v1.0/common/fingertip_m.stl"/>
      </geometry>
    </collision>
  </link>
  
			# Index finger
			
  <!-- KNUCKLE -->
  <joint name="right_hand_v1s_index_knuckle_joint" type="fixed">
    <origin rpy="1.5707963267948966 -1.4835299330931884 1.5707963267948966" xyz="-0.0033 0.0195 0.0936994"/>
    <parent link="right_hand_v1s_palm_link"/>
    <child link="right_hand_v1s_index_knuckle_link"/>
    <limit effort="30" lower="-1.57" upper="1.57" velocity="1.0"/>
    <axis xyz="0 0 1"/>
    <dynamics damping="0.08" friction="0.0"/>
  </joint>
  <link name="right_hand_v1s_index_knuckle_link">
    <inertial>
      <origin xyz="0.001285644 0 0.000425011"/>
      <mass value="0.09"/>
      <inertia ixx="0.001" ixy="0" ixz="0" iyy="0.001" iyz="0" izz="0.001"/>
    </inertial>
    <visual>
      <geometry>
        <mesh filename="package://softhands_description/meshes/softhands/v1.0/common/knuckle_m.stl"/>
      </geometry>
    </visual>
    <collision>
      <geometry>
        <mesh filename="package://softhands_description/meshes/softhands/v1.0/common/knuckle_m.stl"/>
      </geometry>
    </collision>
  </link>
  <!-- PROXIMAL PHALANGE -->
  <joint name="right_hand_v1s_index_proximal_joint" type="fixed">
    <origin rpy="0 0 0" xyz="0.020 0 0"/>
    <parent link="right_hand_v1s_index_knuckle_link"/>
    <child link="right_hand_v1s_index_proximal_link"/>
    <limit effort="30" lower="-1.57" upper="1.57" velocity="1.0"/>
    <axis xyz="0 -1 0"/>
  </joint>
  <link name="right_hand_v1s_index_proximal_link">
    <inertial>
      <origin xyz="0.005074337 0 -0.000262953"/>
      <mass value="0.05"/>
      <inertia ixx="0.001" ixy="0" ixz="0" iyy="0.001" iyz="0" izz="0.001"/>
    </inertial>
    <visual>
      <geometry>
        <mesh filename="package://softhands_description/meshes/softhands/v1.0/common/phalanx_m.stl"/>
      </geometry>
    </visual>
    <collision>
      <geometry>
        <mesh filename="package://softhands_description/meshes/softhands/v1.0/common/phalanx_m.stl"/>
      </geometry>
    </collision>
  </link>
  <!-- MIDDLE PHALANGE -->
  <joint name="right_hand_v1s_index_middle_joint" type="fixed">
    <origin rpy="0 0 0" xyz="0.020 0 0"/>
    <parent link="right_hand_v1s_index_proximal_link"/>
    <child link="right_hand_v1s_index_middle_link"/>
    <limit effort="30" lower="-1.57" upper="1.57" velocity="1.0"/>
    <axis xyz="0 -1 0"/>
    <dynamics damping="0.08" friction="0.0"/>
  </joint>
  <link name="right_hand_v1s_index_middle_link">
    <inertial>
      <origin xyz="0.005074337 0 -0.000262953"/>
      <mass value="0.05"/>
      <inertia ixx="0.001" ixy="0" ixz="0" iyy="0.001" iyz="0" izz="0.001"/>
    </inertial>
    <visual>
      <geometry>
        <mesh filename="package://softhands_description/meshes/softhands/v1.0/common/phalanx_m.stl"/>
      </geometry>
    </visual>
    <collision>
      <geometry>
        <mesh filename="package://softhands_description/meshes/softhands/v1.0/common/phalanx_m.stl"/>
      </geometry>
    </collision>
  </link>
  <!-- DISTAL PHALANGE -->
  <joint name="right_hand_v1s_index_distal_joint" type="fixed">
    <origin rpy="0 0 0" xyz="0.020 0 0"/>
    <parent link="right_hand_v1s_index_middle_link"/>
    <child link="right_hand_v1s_index_distal_link"/>
    <limit effort="30" lower="-1.57" upper="1.57" velocity="1.0"/>
    <axis xyz="0 -1 0"/>
    <dynamics damping="0.08" friction="0.0"/>
  </joint>
  <link name="right_hand_v1s_index_distal_link">
    <inertial>
      <origin xyz="0.009849094 0 0.000820286"/>
      <mass value="0.1"/>
      <inertia ixx="0.001" ixy="0" ixz="0" iyy="0.001" iyz="0" izz="0.001"/>
    </inertial>
    <visual>
      <geometry>
        <mesh filename="package://softhands_description/meshes/softhands/v1.0/common/fingertip_m.stl"/>
      </geometry>
    </visual>
    <collision>
      <geometry>
        <mesh filename="package://softhands_description/meshes/softhands/v1.0/common/fingertip_m.stl"/>
      </geometry>
    </collision>
  </link>
  
			# Middle finger
			
  <!-- KNUCKLE -->
  <joint name="right_hand_v1s_middle_knuckle_joint" type="fixed">
    <origin rpy="3.141592 -1.5707963267948966 0.0" xyz="-0.003300000 0.0 0.100699"/>
    <parent link="right_hand_v1s_palm_link"/>
    <child link="right_hand_v1s_middle_knuckle_link"/>
    <limit effort="30" lower="-1.57" upper="1.57" velocity="1.0"/>
    <axis xyz="0 0 1"/>
    <dynamics damping="0.08" friction="0.0"/>
  </joint>
  <link name="right_hand_v1s_middle_knuckle_link">
    <inertial>
      <origin xyz="0.001285644 0 0.000425011"/>
      <mass value="0.09"/>
      <inertia ixx="0.001" ixy="0" ixz="0" iyy="0.001" iyz="0" izz="0.001"/>
    </inertial>
    <visual>
      <geometry>
        <mesh filename="package://softhands_description/meshes/softhands/v1.0/common/knuckle_m.stl"/>
      </geometry>
    </visual>
    <collision>
      <geometry>
        <mesh filename="package://softhands_description/meshes/softhands/v1.0/common/knuckle_m.stl"/>
      </geometry>
    </collision>
  </link>
  <!-- PROXIMAL PHALANGE -->
  <joint name="right_hand_v1s_middle_proximal_joint" type="fixed">
    <origin rpy="0 0 0" xyz="0.020 0 0"/>
    <parent link="right_hand_v1s_middle_knuckle_link"/>
    <child link="right_hand_v1s_middle_proximal_link"/>
    <limit effort="30" lower="-1.57" upper="1.57" velocity="1.0"/>
    <axis xyz="0 -1 0"/>
  </joint>
  <link name="right_hand_v1s_middle_proximal_link">
    <inertial>
      <origin xyz="0.005074337 0 -0.000262953"/>
      <mass value="0.05"/>
      <inertia ixx="0.001" ixy="0" ixz="0" iyy="0.001" iyz="0" izz="0.001"/>
    </inertial>
    <visual>
      <geometry>
        <mesh filename="package://softhands_description/meshes/softhands/v1.0/common/phalanx_m.stl"/>
      </geometry>
    </visual>
    <collision>
      <geometry>
        <mesh filename="package://softhands_description/meshes/softhands/v1.0/common/phalanx_m.stl"/>
      </geometry>
    </collision>
  </link>
  <!-- MIDDLE PHALANGE -->
  <joint name="right_hand_v1s_middle_middle_joint" type="fixed">
    <origin rpy="0 0 0" xyz="0.020 0 0"/>
    <parent link="right_hand_v1s_middle_proximal_link"/>
    <child link="right_hand_v1s_middle_middle_link"/>
    <limit effort="30" lower="-1.57" upper="1.57" velocity="1.0"/>
    <axis xyz="0 -1 0"/>
    <dynamics damping="0.08" friction="0.0"/>
  </joint>
  <link name="right_hand_v1s_middle_middle_link">
    <inertial>
      <origin xyz="0.005074337 0 -0.000262953"/>
      <mass value="0.05"/>
      <inertia ixx="0.001" ixy="0" ixz="0" iyy="0.001" iyz="0" izz="0.001"/>
    </inertial>
    <visual>
      <geometry>
        <mesh filename="package://softhands_description/meshes/softhands/v1.0/common/phalanx_m.stl"/>
      </geometry>
    </visual>
    <collision>
      <geometry>
        <mesh filename="package://softhands_description/meshes/softhands/v1.0/common/phalanx_m.stl"/>
      </geometry>
    </collision>
  </link>
  <!-- DISTAL PHALANGE -->
  <joint name="right_hand_v1s_middle_distal_joint" type="fixed">
    <origin rpy="0 0 0" xyz="0.020 0 0"/>
    <parent link="right_hand_v1s_middle_middle_link"/>
    <child link="right_hand_v1s_middle_distal_link"/>
    <limit effort="30" lower="-1.57" upper="1.57" velocity="1.0"/>
    <axis xyz="0 -1 0"/>
    <dynamics damping="0.08" friction="0.0"/>
  </joint>
  <link name="right_hand_v1s_middle_distal_link">
    <inertial>
      <origin xyz="0.009849094 0 0.000820286"/>
      <mass value="0.1"/>
      <inertia ixx="0.001" ixy="0" ixz="0" iyy="0.001" iyz="0" izz="0.001"/>
    </inertial>
    <visual>
      <geometry>
        <mesh filename="package://softhands_description/meshes/softhands/v1.0/common/fingertip_m.stl"/>
      </geometry>
    </visual>
    <collision>
      <geometry>
        <mesh filename="package://softhands_description/meshes/softhands/v1.0/common/fingertip_m.stl"/>
      </geometry>
    </collision>
  </link>
  
			# Ring finger
			
  <!-- KNUCKLE -->
  <joint name="right_hand_v1s_ring_knuckle_joint" type="fixed">
    <origin rpy="-1.5707963267948966 -1.5184364298870514 -1.5707963267948966" xyz="-0.0033 -0.0195 0.0936994"/>
    <parent link="right_hand_v1s_palm_link"/>
    <child link="right_hand_v1s_ring_knuckle_link"/>
    <limit effort="30" lower="-1.57" upper="1.57" velocity="1.0"/>
    <axis xyz="0 0 1"/>
    <dynamics damping="0.08" friction="0.0"/>
  </joint>
  <link name="right_hand_v1s_ring_knuckle_link">
    <inertial>
      <origin xyz="0.001285644 0 0.000425011"/>
      <mass value="0.09"/>
      <inertia ixx="0.001" ixy="0" ixz="0" iyy="0.001" iyz="0" izz="0.001"/>
    </inertial>
    <visual>
      <geometry>
        <mesh filename="package://softhands_description/meshes/softhands/v1.0/common/knuckle_m.stl"/>
      </geometry>
    </visual>
    <collision>
      <geometry>
        <mesh filename="package://softhands_description/meshes/softhands/v1.0/common/knuckle_m.stl"/>
      </geometry>
    </collision>
  </link>
  <!-- PROXIMAL PHALANGE -->
  <joint name="right_hand_v1s_ring_proximal_joint" type="fixed">
    <origin rpy="0 0 0" xyz="0.020 0 0"/>
    <parent link="right_hand_v1s_ring_knuckle_link"/>
    <child link="right_hand_v1s_ring_proximal_link"/>
    <limit effort="30" lower="-1.57" upper="1.57" velocity="1.0"/>
    <axis xyz="0 -1 0"/>
  </joint>
  <link name="right_hand_v1s_ring_proximal_link">
    <inertial>
      <origin xyz="0.005074337 0 -0.000262953"/>
      <mass value="0.05"/>
      <inertia ixx="0.001" ixy="0" ixz="0" iyy="0.001" iyz="0" izz="0.001"/>
    </inertial>
    <visual>
      <geometry>
        <mesh filename="package://softhands_description/meshes/softhands/v1.0/common/phalanx_m.stl"/>
      </geometry>
    </visual>
    <collision>
      <geometry>
        <mesh filename="package://softhands_description/meshes/softhands/v1.0/common/phalanx_m.stl"/>
      </geometry>
    </collision>
  </link>
  <!-- MIDDLE PHALANGE -->
  <joint name="right_hand_v1s_ring_middle_joint" type="fixed">
    <origin rpy="0 0 0" xyz="0.020 0 0"/>
    <parent link="right_hand_v1s_ring_proximal_link"/>
    <child link="right_hand_v1s_ring_middle_link"/>
    <limit effort="30" lower="-1.57" upper="1.57" velocity="1.0"/>
    <axis xyz="0 -1 0"/>
    <dynamics damping="0.08" friction="0.0"/>
  </joint>
  <link name="right_hand_v1s_ring_middle_link">
    <inertial>
      <origin xyz="0.005074337 0 -0.000262953"/>
      <mass value="0.05"/>
      <inertia ixx="0.001" ixy="0" ixz="0" iyy="0.001" iyz="0" izz="0.001"/>
    </inertial>
    <visual>
      <geometry>
        <mesh filename="package://softhands_description/meshes/softhands/v1.0/common/phalanx_m.stl"/>
      </geometry>
    </visual>
    <collision>
      <geometry>
        <mesh filename="package://softhands_description/meshes/softhands/v1.0/common/phalanx_m.stl"/>
      </geometry>
    </collision>
  </link>
  <!-- DISTAL PHALANGE -->
  <joint name="right_hand_v1s_ring_distal_joint" type="fixed">
    <origin rpy="0 0 0" xyz="0.020 0 0"/>
    <parent link="right_hand_v1s_ring_middle_link"/>
    <child link="right_hand_v1s_ring_distal_link"/>
    <limit effort="30" lower="-1.57" upper="1.57" velocity="1.0"/>
    <axis xyz="0 -1 0"/>
    <dynamics damping="0.08" friction="0.0"/>
  </joint>
  <link name="right_hand_v1s_ring_distal_link">
    <inertial>
      <origin xyz="0.009849094 0 0.000820286"/>
      <mass value="0.1"/>
      <inertia ixx="0.001" ixy="0" ixz="0" iyy="0.001" iyz="0" izz="0.001"/>
    </inertial>
    <visual>
      <geometry>
        <mesh filename="package://softhands_description/meshes/softhands/v1.0/common/fingertip_m.stl"/>
      </geometry>
    </visual>
    <collision>
      <geometry>
        <mesh filename="package://softhands_description/meshes/softhands/v1.0/common/fingertip_m.stl"/>
      </geometry>
    </collision>
  </link>
  
			# Little finger
			
  <!-- KNUCKLE -->
  <joint name="right_hand_v1s_little_knuckle_joint" type="fixed">
    <origin rpy="-1.5707963267948966 -1.4835299330931884 -1.5707963267948966" xyz="-0.0033 -0.039 0.0836994"/>
    <parent link="right_hand_v1s_palm_link"/>
    <child link="right_hand_v1s_little_knuckle_link"/>
    <limit effort="30" lower="-1.57" upper="1.57" velocity="1.0"/>
    <axis xyz="0 0 1"/>
    <dynamics damping="0.08" friction="0.0"/>
  </joint>
  <link name="right_hand_v1s_little_knuckle_link">
    <inertial>
      <origin xyz="0.001285644 0 0.000425011"/>
      <mass value="0.09"/>
      <inertia ixx="0.001" ixy="0" ixz="0" iyy="0.001" iyz="0" izz="0.001"/>
    </inertial>
    <visual>
      <geometry>
        <mesh filename="package://softhands_description/meshes/softhands/v1.0/common/knuckle_m.stl"/>
      </geometry>
    </visual>
    <collision>
      <geometry>
        <mesh filename="package://softhands_description/meshes/softhands/v1.0/common/knuckle_m.stl"/>
      </geometry>
    </collision>
  </link>
  <!-- PROXIMAL PHALANGE -->
  <joint name="right_hand_v1s_little_proximal_joint" type="fixed">
    <origin rpy="0 0 0" xyz="0.020 0 0"/>
    <parent link="right_hand_v1s_little_knuckle_link"/>
    <child link="right_hand_v1s_little_proximal_link"/>
    <limit effort="30" lower="-1.57" upper="1.57" velocity="1.0"/>
    <axis xyz="0 -1 0"/>
  </joint>
  <link name="right_hand_v1s_little_proximal_link">
    <inertial>
      <origin xyz="0.005074337 0 -0.000262953"/>
      <mass value="0.05"/>
      <inertia ixx="0.001" ixy="0" ixz="0" iyy="0.001" iyz="0" izz="0.001"/>
    </inertial>
    <visual>
      <geometry>
        <mesh filename="package://softhands_description/meshes/softhands/v1.0/common/phalanx_m.stl"/>
      </geometry>
    </visual>
    <collision>
      <geometry>
        <mesh filename="package://softhands_description/meshes/softhands/v1.0/common/phalanx_m.stl"/>
      </geometry>
    </collision>
  </link>
  <!-- MIDDLE PHALANGE -->
  <joint name="right_hand_v1s_little_middle_joint" type="fixed">
    <origin rpy="0 0 0" xyz="0.020 0 0"/>
    <parent link="right_hand_v1s_little_proximal_link"/>
    <child link="right_hand_v1s_little_middle_link"/>
    <limit effort="30" lower="-1.57" upper="1.57" velocity="1.0"/>
    <axis xyz="0 -1 0"/>
    <dynamics damping="0.08" friction="0.0"/>
  </joint>
  <link name="right_hand_v1s_little_middle_link">
    <inertial>
      <origin xyz="0.005074337 0 -0.000262953"/>
      <mass value="0.05"/>
      <inertia ixx="0.001" ixy="0" ixz="0" iyy="0.001" iyz="0" izz="0.001"/>
    </inertial>
    <visual>
      <geometry>
        <mesh filename="package://softhands_description/meshes/softhands/v1.0/common/phalanx_m.stl"/>
      </geometry>
    </visual>
    <collision>
      <geometry>
        <mesh filename="package://softhands_description/meshes/softhands/v1.0/common/phalanx_m.stl"/>
      </geometry>
    </collision>
  </link>
  <!-- DISTAL PHALANGE -->
  <joint name="right_hand_v1s_little_distal_joint" type="fixed">
    <origin rpy="0 0 0" xyz="0.020 0 0"/>
    <parent link="right_hand_v1s_little_middle_link"/>
    <child link="right_hand_v1s_little_distal_link"/>
    <limit effort="30" lower="-1.57" upper="1.57" velocity="1.0"/>
    <axis xyz="0 -1 0"/>
    <dynamics damping="0.08" friction="0.0"/>
  </joint>
  <link name="right_hand_v1s_little_distal_link">
    <inertial>
      <origin xyz="0.009849094 0 0.000820286"/>
      <mass value="0.1"/>
      <inertia ixx="0.001" ixy="0" ixz="0" iyy="0.001" iyz="0" izz="0.001"/>
    </inertial>
    <visual>
      <geometry>
        <mesh filename="package://softhands_description/meshes/softhands/v1.0/common/fingertip_m.stl"/>
      </geometry>
    </visual>
    <collision>
      <geometry>
        <mesh filename="package://softhands_description/meshes/softhands/v1.0/common/fingertip_m.stl"/>
      </geometry>
    </collision>
  </link>
  
		# LEFT HAND
		
  
		# Gazebo NEW custom synergy-plugin
		
  <gazebo>
    <plugin filename="libsofthand_plugin.so" name="synergy_plugin">
      <namespace>right_hand_v1s</namespace>
      <operation_mode>0</operation_mode>
    </plugin>
  </gazebo>
  

    # Softhand VERSION 2.0
    
  

    # Softhand VERSION 2.0 SIMPLIFIED (less joints)
    
  

    # TODO: OTHER VERSIONs

    
  <gazebo>
    <self_collide>1</self_collide>
  </gazebo>
  <!-- <gazebo reference="table_top_link">
        <selfCollide> 1 </selfCollide>
    </gazebo> -->
  <transmission name="trans_left_hand_v1s_index_knuckle_joint">
    <type>transmission_interface/SimpleTransmission</type>
    <joint name="left_hand_v1s_index_knuckle_joint">
      <hardwareInterface>hardware_interface/EffortJointInterface</hardwareInterface>
    </joint>
    <actuator name="left_hand_v1s_index_knuckle_joint_motor">
      <hardwareInterface>hardware_interface/EffortJointInterface</hardwareInterface>
      <mechanicalReduction>1</mechanicalReduction>
    </actuator>
  </transmission>
  <transmission name="trans_left_hand_v1s_index_proximal_joint">
    <type>transmission_interface/SimpleTransmission</type>
    <joint name="left_hand_v1s_index_proximal_joint">
      <hardwareInterface>hardware_interface/EffortJointInterface</hardwareInterface>
    </joint>
    <actuator name="left_hand_v1s_index_proximal_joint_motor">
      <hardwareInterface>hardware_interface/EffortJointInterface</hardwareInterface>
      <mechanicalReduction>1</mechanicalReduction>
    </actuator>
  </transmission>
  <transmission name="trans_left_hand_v1s_index_middle_joint">
    <type>transmission_interface/SimpleTransmission</type>
    <joint name="left_hand_v1s_index_middle_joint">
      <hardwareInterface>hardware_interface/EffortJointInterface</hardwareInterface>
    </joint>
    <actuator name="left_hand_v1s_index_middle_joint_motor">
      <hardwareInterface>hardware_interface/EffortJointInterface</hardwareInterface>
      <mechanicalReduction>1</mechanicalReduction>
    </actuator>
  </transmission>
  <transmission name="trans_left_hand_v1s_index_distal_joint">
    <type>transmission_interface/SimpleTransmission</type>
    <joint name="left_hand_v1s_index_distal_joint">
      <hardwareInterface>hardware_interface/EffortJointInterface</hardwareInterface>
    </joint>
    <actuator name="left_hand_v1s_index_distal_joint_motor">
      <hardwareInterface>hardware_interface/EffortJointInterface</hardwareInterface>
      <mechanicalReduction>1</mechanicalReduction>
    </actuator>
  </transmission>
  <transmission name="trans_left_hand_v1s_middle_knuckle_joint">
    <type>transmission_interface/SimpleTransmission</type>
    <joint name="left_hand_v1s_middle_knuckle_joint">
      <hardwareInterface>hardware_interface/EffortJointInterface</hardwareInterface>
    </joint>
    <actuator name="left_hand_v1s_middle_knuckle_joint_motor">
      <hardwareInterface>hardware_interface/EffortJointInterface</hardwareInterface>
      <mechanicalReduction>1</mechanicalReduction>
    </actuator>
  </transmission>
  <transmission name="trans_left_hand_v1s_middle_proximal_joint">
    <type>transmission_interface/SimpleTransmission</type>
    <joint name="left_hand_v1s_middle_proximal_joint">
      <hardwareInterface>hardware_interface/EffortJointInterface</hardwareInterface>
    </joint>
    <actuator name="left_hand_v1s_middle_proximal_joint_motor">
      <hardwareInterface>hardware_interface/EffortJointInterface</hardwareInterface>
      <mechanicalReduction>1</mechanicalReduction>
    </actuator>
  </transmission>
  <transmission name="trans_left_hand_v1s_middle_middle_joint">
    <type>transmission_interface/SimpleTransmission</type>
    <joint name="left_hand_v1s_middle_middle_joint">
      <hardwareInterface>hardware_interface/EffortJointInterface</hardwareInterface>
    </joint>
    <actuator name="left_hand_v1s_middle_middle_joint_motor">
      <hardwareInterface>hardware_interface/EffortJointInterface</hardwareInterface>
      <mechanicalReduction>1</mechanicalReduction>
    </actuator>
  </transmission>
  <transmission name="trans_left_hand_v1s_middle_distal_joint">
    <type>transmission_interface/SimpleTransmission</type>
    <joint name="left_hand_v1s_middle_distal_joint">
      <hardwareInterface>hardware_interface/EffortJointInterface</hardwareInterface>
    </joint>
    <actuator name="left_hand_v1s_middle_distal_joint_motor">
      <hardwareInterface>hardware_interface/EffortJointInterface</hardwareInterface>
      <mechanicalReduction>1</mechanicalReduction>
    </actuator>
  </transmission>
  <transmission name="trans_left_hand_v1s_ring_knuckle_joint">
    <type>transmission_interface/SimpleTransmission</type>
    <joint name="left_hand_v1s_ring_knuckle_joint">
      <hardwareInterface>hardware_interface/EffortJointInterface</hardwareInterface>
    </joint>
    <actuator name="left_hand_v1s_ring_knuckle_joint_motor">
      <hardwareInterface>hardware_interface/EffortJointInterface</hardwareInterface>
      <mechanicalReduction>1</mechanicalReduction>
    </actuator>
  </transmission>
  <transmission name="trans_left_hand_v1s_ring_proximal_joint">
    <type>transmission_interface/SimpleTransmission</type>
    <joint name="left_hand_v1s_ring_proximal_joint">
      <hardwareInterface>hardware_interface/EffortJointInterface</hardwareInterface>
    </joint>
    <actuator name="left_hand_v1s_ring_proximal_joint_motor">
      <hardwareInterface>hardware_interface/EffortJointInterface</hardwareInterface>
      <mechanicalReduction>1</mechanicalReduction>
    </actuator>
  </transmission>
  <transmission name="trans_left_hand_v1s_ring_middle_joint">
    <type>transmission_interface/SimpleTransmission</type>
    <joint name="left_hand_v1s_ring_middle_joint">
      <hardwareInterface>hardware_interface/EffortJointInterface</hardwareInterface>
    </joint>
    <actuator name="left_hand_v1s_ring_middle_joint_motor">
      <hardwareInterface>hardware_interface/EffortJointInterface</hardwareInterface>
      <mechanicalReduction>1</mechanicalReduction>
    </actuator>
  </transmission>
  <transmission name="trans_left_hand_v1s_ring_distal_joint">
    <type>transmission_interface/SimpleTransmission</type>
    <joint name="left_hand_v1s_ring_distal_joint">
      <hardwareInterface>hardware_interface/EffortJointInterface</hardwareInterface>
    </joint>
    <actuator name="left_hand_v1s_ring_distal_joint_motor">
      <hardwareInterface>hardware_interface/EffortJointInterface</hardwareInterface>
      <mechanicalReduction>1</mechanicalReduction>
    </actuator>
  </transmission>
  <transmission name="trans_left_hand_v1s_little_knuckle_joint">
    <type>transmission_interface/SimpleTransmission</type>
    <joint name="left_hand_v1s_little_knuckle_joint">
      <hardwareInterface>hardware_interface/EffortJointInterface</hardwareInterface>
    </joint>
    <actuator name="left_hand_v1s_little_knuckle_joint_motor">
      <hardwareInterface>hardware_interface/EffortJointInterface</hardwareInterface>
      <mechanicalReduction>1</mechanicalReduction>
    </actuator>
  </transmission>
  <transmission name="trans_left_hand_v1s_little_proximal_joint">
    <type>transmission_interface/SimpleTransmission</type>
    <joint name="left_hand_v1s_little_proximal_joint">
      <hardwareInterface>hardware_interface/EffortJointInterface</hardwareInterface>
    </joint>
    <actuator name="left_hand_v1s_little_proximal_joint_motor">
      <hardwareInterface>hardware_interface/EffortJointInterface</hardwareInterface>
      <mechanicalReduction>1</mechanicalReduction>
    </actuator>
  </transmission>
  <transmission name="trans_left_hand_v1s_little_middle_joint">
    <type>transmission_interface/SimpleTransmission</type>
    <joint name="left_hand_v1s_little_middle_joint">
      <hardwareInterface>hardware_interface/EffortJointInterface</hardwareInterface>
    </joint>
    <actuator name="left_hand_v1s_little_middle_joint_motor">
      <hardwareInterface>hardware_interface/EffortJointInterface</hardwareInterface>
      <mechanicalReduction>1</mechanicalReduction>
    </actuator>
  </transmission>
  <transmission name="trans_left_hand_v1s_little_distal_joint">
    <type>transmission_interface/SimpleTransmission</type>
    <joint name="left_hand_v1s_little_distal_joint">
      <hardwareInterface>hardware_interface/EffortJointInterface</hardwareInterface>
    </joint>
    <actuator name="left_hand_v1s_little_distal_joint_motor">
      <hardwareInterface>hardware_interface/EffortJointInterface</hardwareInterface>
      <mechanicalReduction>1</mechanicalReduction>
    </actuator>
  </transmission>
  <transmission name="trans_left_hand_v1s_thumb_knuckle_joint">
    <type>transmission_interface/SimpleTransmission</type>
    <joint name="left_hand_v1s_thumb_knuckle_joint">
      <hardwareInterface>hardware_interface/EffortJointInterface</hardwareInterface>
    </joint>
    <actuator name="left_hand_v1s_thumb_knuckle_joint_motor">
      <hardwareInterface>hardware_interface/EffortJointInterface</hardwareInterface>
      <mechanicalReduction>1</mechanicalReduction>
    </actuator>
  </transmission>
  <transmission name="trans_left_hand_v1s_thumb_proximal_joint">
    <type>transmission_interface/SimpleTransmission</type>
    <joint name="left_hand_v1s_thumb_proximal_joint">
      <hardwareInterface>hardware_interface/EffortJointInterface</hardwareInterface>
    </joint>
    <actuator name="left_hand_v1s_thumb_proximal_joint_motor">
      <hardwareInterface>hardware_interface/EffortJointInterface</hardwareInterface>
      <mechanicalReduction>1</mechanicalReduction>
    </actuator>
  </transmission>
  <transmission name="trans_left_hand_v1s_thumb_distal_joint">
    <type>transmission_interface/SimpleTransmission</type>
    <joint name="left_hand_v1s_thumb_distal_joint">
      <hardwareInterface>hardware_interface/EffortJointInterface</hardwareInterface>
    </joint>
    <actuator name="left_hand_v1s_thumb_distal_joint_motor">
      <hardwareInterface>hardware_interface/EffortJointInterface</hardwareInterface>
      <mechanicalReduction>1</mechanicalReduction>
    </actuator>
  </transmission>
  <transmission name="trans_right_hand_v1s_index_knuckle_joint">
    <type>transmission_interface/SimpleTransmission</type>
    <joint name="right_hand_v1s_index_knuckle_joint">
      <hardwareInterface>hardware_interface/EffortJointInterface</hardwareInterface>
    </joint>
    <actuator name="right_hand_v1s_index_knuckle_joint_motor">
      <hardwareInterface>hardware_interface/EffortJointInterface</hardwareInterface>
      <mechanicalReduction>1</mechanicalReduction>
    </actuator>
  </transmission>
  <transmission name="trans_right_hand_v1s_index_proximal_joint">
    <type>transmission_interface/SimpleTransmission</type>
    <joint name="right_hand_v1s_index_proximal_joint">
      <hardwareInterface>hardware_interface/EffortJointInterface</hardwareInterface>
    </joint>
    <actuator name="right_hand_v1s_index_proximal_joint_motor">
      <hardwareInterface>hardware_interface/EffortJointInterface</hardwareInterface>
      <mechanicalReduction>1</mechanicalReduction>
    </actuator>
  </transmission>
  <transmission name="trans_right_hand_v1s_index_middle_joint">
    <type>transmission_interface/SimpleTransmission</type>
    <joint name="right_hand_v1s_index_middle_joint">
      <hardwareInterface>hardware_interface/EffortJointInterface</hardwareInterface>
    </joint>
    <actuator name="right_hand_v1s_index_middle_joint_motor">
      <hardwareInterface>hardware_interface/EffortJointInterface</hardwareInterface>
      <mechanicalReduction>1</mechanicalReduction>
    </actuator>
  </transmission>
  <transmission name="trans_right_hand_v1s_index_distal_joint">
    <type>transmission_interface/SimpleTransmission</type>
    <joint name="right_hand_v1s_index_distal_joint">
      <hardwareInterface>hardware_interface/EffortJointInterface</hardwareInterface>
    </joint>
    <actuator name="right_hand_v1s_index_distal_joint_motor">
      <hardwareInterface>hardware_interface/EffortJointInterface</hardwareInterface>
      <mechanicalReduction>1</mechanicalReduction>
    </actuator>
  </transmission>
  <transmission name="trans_right_hand_v1s_middle_knuckle_joint">
    <type>transmission_interface/SimpleTransmission</type>
    <joint name="right_hand_v1s_middle_knuckle_joint">
      <hardwareInterface>hardware_interface/EffortJointInterface</hardwareInterface>
    </joint>
    <actuator name="right_hand_v1s_middle_knuckle_joint_motor">
      <hardwareInterface>hardware_interface/EffortJointInterface</hardwareInterface>
      <mechanicalReduction>1</mechanicalReduction>
    </actuator>
  </transmission>
  <transmission name="trans_right_hand_v1s_middle_proximal_joint">
    <type>transmission_interface/SimpleTransmission</type>
    <joint name="right_hand_v1s_middle_proximal_joint">
      <hardwareInterface>hardware_interface/EffortJointInterface</hardwareInterface>
    </joint>
    <actuator name="right_hand_v1s_middle_proximal_joint_motor">
      <hardwareInterface>hardware_interface/EffortJointInterface</hardwareInterface>
      <mechanicalReduction>1</mechanicalReduction>
    </actuator>
  </transmission>
  <transmission name="trans_right_hand_v1s_middle_middle_joint">
    <type>transmission_interface/SimpleTransmission</type>
    <joint name="right_hand_v1s_middle_middle_joint">
      <hardwareInterface>hardware_interface/EffortJointInterface</hardwareInterface>
    </joint>
    <actuator name="right_hand_v1s_middle_middle_joint_motor">
      <hardwareInterface>hardware_interface/EffortJointInterface</hardwareInterface>
      <mechanicalReduction>1</mechanicalReduction>
    </actuator>
  </transmission>
  <transmission name="trans_right_hand_v1s_middle_distal_joint">
    <type>transmission_interface/SimpleTransmission</type>
    <joint name="right_hand_v1s_middle_distal_joint">
      <hardwareInterface>hardware_interface/EffortJointInterface</hardwareInterface>
    </joint>
    <actuator name="right_hand_v1s_middle_distal_joint_motor">
      <hardwareInterface>hardware_interface/EffortJointInterface</hardwareInterface>
      <mechanicalReduction>1</mechanicalReduction>
    </actuator>
  </transmission>
  <transmission name="trans_right_hand_v1s_ring_knuckle_joint">
    <type>transmission_interface/SimpleTransmission</type>
    <joint name="right_hand_v1s_ring_knuckle_joint">
      <hardwareInterface>hardware_interface/EffortJointInterface</hardwareInterface>
    </joint>
    <actuator name="right_hand_v1s_ring_knuckle_joint_motor">
      <hardwareInterface>hardware_interface/EffortJointInterface</hardwareInterface>
      <mechanicalReduction>1</mechanicalReduction>
    </actuator>
  </transmission>
  <transmission name="trans_right_hand_v1s_ring_proximal_joint">
    <type>transmission_interface/SimpleTransmission</type>
    <joint name="right_hand_v1s_ring_proximal_joint">
      <hardwareInterface>hardware_interface/EffortJointInterface</hardwareInterface>
    </joint>
    <actuator name="right_hand_v1s_ring_proximal_joint_motor">
      <hardwareInterface>hardware_interface/EffortJointInterface</hardwareInterface>
      <mechanicalReduction>1</mechanicalReduction>
    </actuator>
  </transmission>
  <transmission name="trans_right_hand_v1s_ring_middle_joint">
    <type>transmission_interface/SimpleTransmission</type>
    <joint name="right_hand_v1s_ring_middle_joint">
      <hardwareInterface>hardware_interface/EffortJointInterface</hardwareInterface>
    </joint>
    <actuator name="right_hand_v1s_ring_middle_joint_motor">
      <hardwareInterface>hardware_interface/EffortJointInterface</hardwareInterface>
      <mechanicalReduction>1</mechanicalReduction>
    </actuator>
  </transmission>
  <transmission name="trans_right_hand_v1s_ring_distal_joint">
    <type>transmission_interface/SimpleTransmission</type>
    <joint name="right_hand_v1s_ring_distal_joint">
      <hardwareInterface>hardware_interface/EffortJointInterface</hardwareInterface>
    </joint>
    <actuator name="right_hand_v1s_ring_distal_joint_motor">
      <hardwareInterface>hardware_interface/EffortJointInterface</hardwareInterface>
      <mechanicalReduction>1</mechanicalReduction>
    </actuator>
  </transmission>
  <transmission name="trans_right_hand_v1s_little_knuckle_joint">
    <type>transmission_interface/SimpleTransmission</type>
    <joint name="right_hand_v1s_little_knuckle_joint">
      <hardwareInterface>hardware_interface/EffortJointInterface</hardwareInterface>
    </joint>
    <actuator name="right_hand_v1s_little_knuckle_joint_motor">
      <hardwareInterface>hardware_interface/EffortJointInterface</hardwareInterface>
      <mechanicalReduction>1</mechanicalReduction>
    </actuator>
  </transmission>
  <transmission name="trans_right_hand_v1s_little_proximal_joint">
    <type>transmission_interface/SimpleTransmission</type>
    <joint name="right_hand_v1s_little_proximal_joint">
      <hardwareInterface>hardware_interface/EffortJointInterface</hardwareInterface>
    </joint>
    <actuator name="right_hand_v1s_little_proximal_joint_motor">
      <hardwareInterface>hardware_interface/EffortJointInterface</hardwareInterface>
      <mechanicalReduction>1</mechanicalReduction>
    </actuator>
  </transmission>
  <transmission name="trans_right_hand_v1s_little_middle_joint">
    <type>transmission_interface/SimpleTransmission</type>
    <joint name="right_hand_v1s_little_middle_joint">
      <hardwareInterface>hardware_interface/EffortJointInterface</hardwareInterface>
    </joint>
    <actuator name="right_hand_v1s_little_middle_joint_motor">
      <hardwareInterface>hardware_interface/EffortJointInterface</hardwareInterface>
      <mechanicalReduction>1</mechanicalReduction>
    </actuator>
  </transmission>
  <transmission name="trans_right_hand_v1s_little_distal_joint">
    <type>transmission_interface/SimpleTransmission</type>
    <joint name="right_hand_v1s_little_distal_joint">
      <hardwareInterface>hardware_interface/EffortJointInterface</hardwareInterface>
    </joint>
    <actuator name="right_hand_v1s_little_distal_joint_motor">
      <hardwareInterface>hardware_interface/EffortJointInterface</hardwareInterface>
      <mechanicalReduction>1</mechanicalReduction>
    </actuator>
  </transmission>
  <transmission name="trans_right_hand_v1s_thumb_knuckle_joint">
    <type>transmission_interface/SimpleTransmission</type>
    <joint name="right_hand_v1s_thumb_knuckle_joint">
      <hardwareInterface>hardware_interface/EffortJointInterface</hardwareInterface>
    </joint>
    <actuator name="right_hand_v1s_thumb_knuckle_joint_motor">
      <hardwareInterface>hardware_interface/EffortJointInterface</hardwareInterface>
      <mechanicalReduction>1</mechanicalReduction>
    </actuator>
  </transmission>
  <transmission name="trans_right_hand_v1s_thumb_proximal_joint">
    <type>transmission_interface/SimpleTransmission</type>
    <joint name="right_hand_v1s_thumb_proximal_joint">
      <hardwareInterface>hardware_interface/EffortJointInterface</hardwareInterface>
    </joint>
    <actuator name="right_hand_v1s_thumb_proximal_joint_motor">
      <hardwareInterface>hardware_interface/EffortJointInterface</hardwareInterface>
      <mechanicalReduction>1</mechanicalReduction>
    </actuator>
  </transmission>
  <transmission name="trans_right_hand_v1s_thumb_distal_joint">
    <type>transmission_interface/SimpleTransmission</type>
    <joint name="right_hand_v1s_thumb_distal_joint">
      <hardwareInterface>hardware_interface/EffortJointInterface</hardwareInterface>
    </joint>
    <actuator name="right_hand_v1s_thumb_distal_joint_motor">
      <hardwareInterface>hardware_interface/EffortJointInterface</hardwareInterface>
      <mechanicalReduction>1</mechanicalReduction>
    </actuator>
  </transmission>
</robot>
