<?xml version="1.0" ?>
<!-- =================================================================================== -->
<!-- |    This document was autogenerated by xacro from repair_arm_final.urdf.xacro    | -->
<!-- |    EDITING THIS FILE BY HAND IS NOT RECOMMENDED                                 | -->
<!-- =================================================================================== -->
<robot name="repair_arm">
  <material name="grey">
    <color rgba="0.5 0.5 0.5 1"/>
  </material>
  <material name="dark_grey">
    <color rgba="0.3 0.3 0.3 1"/>
  </material>
  <material name="red">
    <color rgba="1.0 0.0 0.0 1"/>
  </material>
  <material name="green">
    <color rgba="0.0 1.0 0.0 1"/>
  </material>
  <material name="blue">
    <color rgba="0.13333333333333333 0.25882352941176473 0.7803921568627451 1.0"/>
  </material>
  <material name="darkblue">
    <color rgba="0.0 0.3 0.9 1"/>
  </material>
  <material name="darkred">
    <color rgba="0.55 0.0 0.0 1"/>
  </material>
  <material name="dark">
    <color rgba="0.6 0.6 0.6 1"/>
  </material>
  <!-- macro for generating the urdf associated with a single arm of the RePair platform -->
  <!-- id: specifies the id of the arm (e.g. 0 for left arm and 1 for right) -->
  <!-- base_link: name of base link a the single arm -->
  <!-- is_sliding_wrist: whether to add a sliding joint along the wrist second d.o.f.
    (true -> yes), everything else -> no. This is used to generate the URDF for the optimization.  -->
  <!-- gen_coll: whether to add the approximate collision  model of the platform -->
  <!-- use_updated_wrist: visual parameter. if true, we load the latest meshes (which are adapted to the
results of the optimization), otherwise we go with the old ones (generated for a spherical wrist) -->
  <!-- 0.0  -->
  <!-- 2.4405495 -->
  <!-- 7.8724534e-01 -->
  <!-- 2.8848438e+00-->
  <!-- 6.0145584e-01 -->
  <!-- 2.7650803e+00 -->
  <!-- 1.8854765e+00 -->
  <!-- 2.4405495 -->
  <!-- Origin -->
  <!-- <xacro:property name="motor_A_velocity" value="8.8"/>
    <xacro:property name="motor_B_velocity" value="8.1"/>
    <xacro:property name="motor_C_velocity" value="20.0"/>
    
    <xacro:property name="motor_A_effort" value="304"/>
    <xacro:property name="motor_B_effort" value="147"/>
    <xacro:property name="motor_C_effort" value="35"/> -->
  <gazebo>
    <plugin filename="libxbot2_gz_joint_server.so" name="xbot2_joint_driver">
      <pid>
        <gain d="1" name="fake_mot" p="10"/>
        <gain d="10" name="small_mot" p="1000"/>
        <gain d="20" name="medium_mot" p="2000"/>
        <pid name="j_arm_1_1" profile="medium_mot"/>
        <pid name="j_arm_1_2" profile="medium_mot"/>
        <pid name="j_arm_1_3" profile="medium_mot"/>
        <pid name="j_arm_1_4" profile="medium_mot"/>
        <pid name="j_arm_1_5" profile="small_mot"/>
        <pid name="j_arm_1_6" profile="small_mot"/>
        <pid name="j_arm_1_7" profile="small_mot"/>
      </pid>
    </plugin>
  </gazebo>
  <link name="world"/>
  <!-- base -->
  <link name="base_link">
    <inertial>
      <origin xyz="0.00020548930000000002 -0.00062095789 0.077352002"/>
      <mass value="2.7764953"/>
      <inertia ixx="0.010002127" ixy="4.1468013999999995e-05" ixz="-5.1253649e-05" iyy="0.010728527" iyz="-0.00012700723" izz="0.006215603699999999"/>
    </inertial>
    <visual>
      <origin rpy="0.0 0.0 0.0" xyz="0.0 0.0 0.0"/>
      <geometry>
        <mesh filename="package://repair_urdf/meshes/mesh_base.stl" scale="0.001 0.001 0.001"/>
      </geometry>
      <material name="dark_grey"/>
    </visual>
    <collision>
      <origin rpy="0.0 0.0 0.0" xyz="0.0 0.0 0.0"/>
      <geometry>
        <mesh filename="package://repair_urdf/meshes/simplified/mesh_base.stl" scale="0.001 0.001 0.001"/>
      </geometry>
    </collision>
  </link>
  <!-- base -->
  <joint name="base_joint" type="fixed">
    <parent link="world"/>
    <child link="base_link"/>
    <origin rpy="0 0 0" xyz="0 0 0"/>
  </joint>
  <link name="arm_1_1">
    <inertial>
      <origin xyz="0.010200651000000002 -0.021560998 0.09876702500000001"/>
      <mass value="2.347"/>
      <inertia ixx="0.007192915699999999" ixy="7.854318399999999e-05" ixz="-0.00039791235999999997" iyy="0.009471160999999999" iyz="0.0012857050999999999" izz="0.0058530904"/>
    </inertial>
    <visual>
      <geometry>
        <mesh filename="package://repair_urdf/meshes/mesh_sh-pitch.stl" scale="0.001 0.001 0.001"/>
      </geometry>
      <material name="dark"/>
    </visual>
    <collision>
      <geometry>
        <mesh filename="package://repair_urdf/meshes/simplified/mesh_sh-pitch.stl" scale="0.001 0.001 0.001"/>
      </geometry>
    </collision>
  </link>
  <link name="arm_1_2">
    <inertial>
      <origin xyz="4.5955243e-05 -0.044957128 -0.030791013"/>
      <mass value="0.76"/>
      <inertia ixx="0.0027927572" ixy="-2.0135067e-06" ixz="-1.3644218e-06" iyy="0.0019288488" iyz="-0.00066693438" izz="0.0026633366"/>
    </inertial>
    <visual>
      <geometry>
        <mesh filename="package://repair_urdf/meshes/mesh_sh-roll.stl" scale="0.001 0.001 0.001"/>
      </geometry>
      <material name="dark"/>
    </visual>
    <collision>
      <geometry>
        <mesh filename="package://repair_urdf/meshes/simplified/mesh_sh-roll.stl" scale="0.001 0.001 0.001"/>
      </geometry>
    </collision>
  </link>
  <link name="arm_1_3">
    <inertial>
      <origin xyz="0.005099315 0.0059986523 -0.18011742"/>
      <mass value="3.34"/>
      <inertia ixx="0.031298784999999996" ixy="-0.00025158367" ixz="0.002371127" iyy="0.031963501" iyz="0.0018728041" izz="0.0026332359"/>
    </inertial>
    <visual>
      <geometry>
        <mesh filename="package://repair_urdf/meshes/mesh_sh-yaw.stl" scale="0.001 0.001 0.001"/>
      </geometry>
      <material name="dark"/>
    </visual>
    <collision>
      <geometry>
        <mesh filename="package://repair_urdf/meshes/simplified/mesh_sh-yaw.stl" scale="0.001 0.001 0.001"/>
      </geometry>
    </collision>
  </link>
  <link name="arm_1_4">
    <inertial>
      <origin xyz="3.332275e-06 -0.033289421 -0.023682302"/>
      <mass value="0.55"/>
      <inertia ixx="0.0016198328" ixy="-1.2642724e-06" ixz="-1.1734799e-06" iyy="0.0012266731" iyz="-0.00039531700999999997" izz="0.0016081346"/>
    </inertial>
    <visual>
      <geometry>
        <mesh filename="package://repair_urdf/meshes/mesh_elbow.stl" scale="0.001 0.001 0.001"/>
      </geometry>
      <material name="dark"/>
    </visual>
    <collision>
      <geometry>
        <mesh filename="package://repair_urdf/meshes/simplified/mesh_elbow.stl" scale="0.001 0.001 0.001"/>
      </geometry>
    </collision>
  </link>
  <link name="arm_1_5">
    <inertial>
      <origin xyz="0.00094711044 -0.048009667 -0.14331833"/>
      <mass value="2.825"/>
      <inertia ixx="0.030333275" ixy="7.3729709e-05" ixz="3.2427371e-05" iyy="0.025195444999999997" iyz="-0.0095263763" izz="0.0069975103999999995"/>
    </inertial>
    <visual>
      <geometry>
        <mesh filename="package://repair_urdf/meshes/mesh_forearm-yaw.stl" scale="0.001 0.001 0.001"/>
      </geometry>
      <material name="dark"/>
    </visual>
    <collision>
      <geometry>
        <mesh filename="package://repair_urdf/meshes/simplified/mesh_forearm-yaw.stl" scale="0.001 0.001 0.001"/>
      </geometry>
    </collision>
  </link>
  <link name="arm_1_6">
    <inertial>
      <origin xyz="0.00068559302 -0.0050299682 0.046682846"/>
      <mass value="1.861"/>
      <inertia ixx="0.0042406037" ixy="-5.5692732e-05" ixz="-9.085198200000001e-05" iyy="0.0029010805999999997" iyz="-0.00018560541" izz="0.0044989008"/>
    </inertial>
    <visual>
      <geometry>
        <mesh filename="package://repair_urdf/meshes/mesh_wrist-pitch.stl" scale="0.001 0.001 0.001"/>
      </geometry>
      <material name="dark"/>
    </visual>
    <collision>
      <geometry>
        <mesh filename="package://repair_urdf/meshes/simplified/mesh_wrist-pitch.stl" scale="0.001 0.001 0.001"/>
      </geometry>
    </collision>
  </link>
  <link name="arm_1_7">
    <inertial>
      <origin xyz="0.0 -0.0010491951 -0.010307299"/>
      <mass value="0.1416397"/>
      <inertia ixx="6.1479333e-05" ixy="-7.4023399e-11" ixz="0.0" iyy="6.4247521e-05" iyz="4.778644799999999e-07" izz="0.00011879743999999998"/>
    </inertial>
    <visual>
      <geometry>
        <mesh filename="package://repair_urdf/meshes/mesh_wrist-roll.stl" scale="0.001 0.001 0.001"/>
      </geometry>
      <material name="dark"/>
    </visual>
    <collision>
      <geometry>
        <mesh filename="package://repair_urdf/meshes/simplified/mesh_wrist-roll.stl" scale="0.001 0.001 0.001"/>
      </geometry>
    </collision>
  </link>
  <link name="arm_1_tcp">
    <inertial>
      <origin xyz="0.0 0.05 0.1"/>
      <mass value="0.5"/>
      <inertia ixx="0.001" ixy="0.0" ixz="0.0" iyy="0.001" iyz="0.0" izz="0.001"/>
    </inertial>
  </link>
  <!-- JOINTS -->
  <!-- shoulder pitch -->
  <joint name="j_arm_1_1" type="revolute">
    <parent link="base_link"/>
    <child link="arm_1_1"/>
    <axis xyz="0 0 1"/>
    <origin rpy="0.0 0.0 0.0" xyz="0.0 0.0 0.14"/>
    <limit effort="147.0" lower="-2.6" upper="2.6" velocity="3.86"/>
  </joint>
  <!-- shoulder pitch -->
  <!-- shoulder yaw -->
  <joint name="j_arm_1_2" type="revolute">
    <parent link="arm_1_1"/>
    <child link="arm_1_2"/>
    <origin rpy="0.0 -1.570796326795 0.0" xyz="-0.06 -0.03 0.1255"/>
    <axis xyz="0 0 -1"/>
    <limit effort="147.0" lower="-2.5" upper="0.1" velocity="3.86"/>
  </joint>
  <!-- shoulder yaw -->
  <!-- shoulder yaw -->
  <joint name="j_arm_1_3" type="revolute">
    <parent link="arm_1_2"/>
    <child link="arm_1_3"/>
    <origin rpy="-1.570796326795 -1.570796326795 0.0" xyz="0.0 -0.073 -0.06015"/>
    <axis xyz="0 0 -1"/>
    <limit effort="147.0" lower="-2.6" upper="2.6" velocity="6.06"/>
  </joint>
  <!-- shoulder yaw -->
  <!-- elbow -->
  <joint name="j_arm_1_4" type="revolute">
    <parent link="arm_1_3"/>
    <child link="arm_1_4"/>
    <origin rpy="1.570796326795 0.0 0.0" xyz="0.0225 -0.05015 -0.29215"/>
    <axis xyz="0 0 -1"/>
    <limit effort="147.0" lower="-2.4" upper="0.8" velocity="6.06"/>
  </joint>
  <!-- elbow -->
  <!-- forearm yaw -->
  <joint name="j_arm_1_5" type="revolute">
    <parent link="arm_1_4"/>
    <child link="arm_1_5"/>
    <origin rpy="-1.570796326795 0.0 0.0" xyz="0.0 -0.0725 -0.05015"/>
    <axis xyz="0 0 -1"/>
    <limit effort="55.0" lower="-2.8" upper="2.8" velocity="11.72"/>
  </joint>
  <!-- forearm yaw -->
  <!-- wrist pitch-->
  <joint name="j_arm_1_6" type="revolute">
    <parent link="arm_1_5"/>
    <child link="arm_1_6"/>
    <origin rpy="-1.570796326795 0.0 0.0" xyz="0.0 -0.05 -0.2475"/>
    <axis xyz="0 0 1"/>
    <limit effort="55.0" lower="-2.8" upper="2.1" velocity="11.72"/>
  </joint>
  <!-- wrist pitch-->
  <!-- wrist roll-->
  <joint name="j_arm_1_7" type="revolute">
    <parent link="arm_1_6"/>
    <child link="arm_1_7"/>
    <origin rpy="-1.570796326795 0.3316123 0.0" xyz="0.0 0.062877 0.05"/>
    <axis xyz="0 0 1"/>
    <limit effort="55.0" lower="-2.8" upper="2.8" velocity="11.72"/>
  </joint>
  <!-- /wrist roll-->
  <!-- virtual tip-->
  <joint name="j_tcp_1" type="fixed">
    <parent link="arm_1_7"/>
    <child link="arm_1_tcp"/>
    <origin rpy="0.0 0.0 0.0" xyz="0.0 0.0 0.0"/>
  </joint>
  <!-- virtual tip-->
</robot>
