<?xml version="1.0" ?>
<!-- =================================================================================== -->
<!-- |    This document was autogenerated by xacro from repair_full.urdf.xacro         | -->
<!-- |    EDITING THIS FILE BY HAND IS NOT RECOMMENDED                                 | -->
<!-- =================================================================================== -->
<robot name="repair_full">
  <material name="grey">
    <color rgba="0.5 0.5 0.5 1"/>
  </material>
  <material name="dark_grey">
    <color rgba="0.3 0.3 0.3 1"/>
  </material>
  <material name="red">
    <color rgba="1.0 0.0 0.0 1"/>
  </material>
  <material name="green">
    <color rgba="0.0 1.0 0.0 1"/>
  </material>
  <material name="blue">
    <color rgba="0.13333333333333333 0.25882352941176473 0.7803921568627451 1.0"/>
  </material>
  <material name="darkblue">
    <color rgba="0.0 0.3 0.9 1"/>
  </material>
  <material name="darkred">
    <color rgba="0.55 0.0 0.0 1"/>
  </material>
  <material name="dark">
    <color rgba="0.6 0.6 0.6 1"/>
  </material>
  <material name="wood">
    <color rgba="0.522 0.369 0.259 0.8"/>
  </material>
  <material name="silver_gray">
    <color rgba="0.8 0.8 0.8 0.8"/>
  </material>
  <!-- macro for generating the urdf associated with a single arm of the RePair platform -->
  <!-- id: specifies the id of the arm (e.g. 0 for left arm and 1 for right) -->
  <!-- base_link: name of base link a the single arm -->
  <!-- is_sliding_wrist: whether to add a sliding joint along the wrist second d.o.f.
    (true -> yes), everything else -> no. This is used to generate the URDF for the optimization.  -->
  <!-- gen_coll: whether to add the approximate collision  model of the platform -->
  <!-- use_updated_wrist: visual parameter. if true, we load the latest meshes (which are adapted to the
results of the optimization), otherwise we go with the old ones (generated for a spherical wrist) -->
  <!-- w.r.t world  -->
  <!-- 0.0  -->
  <!-- 2.4405495 -->
  <!-- 7.8724534e-01 -->
  <!-- 2.8848438e+00-->
  <!-- 6.0145584e-01 -->
  <!-- 2.7650803e+00 -->
  <!-- 1.8854765e+00 -->
  <!-- 2.4405495 -->
  <!-- Origin -->
  <!-- Only when working with Gazebo Xbot Control -->
  <!-- DO NOT USE WITH ROS_CONTROL AND MOVEIT -->
  <!-- <xacro:include filename="$(find repair_urdf)/urdf/gazebo/xbot.gazebo.xacro" /> -->
  <gazebo>
    <plugin filename="libgazebo_ros_control.so" name="ros_control">
      <!--robotNamespace>/</robotNamespace-->
      <!--robotSimType>gazebo_ros_control/DefaultRobotHWSim</robotSimType-->
    </plugin>
  </gazebo>
  <link name="world"/>
  <link name="table_top_link">
    <visual>
      <origin xyz="0.0 0.0 0.975"/>
      <geometry>
        <box size="1.0 2.5 0.05"/>
      </geometry>
      <material name="wood"/>
    </visual>
    <collision>
      <origin xyz="0.0 0.0 0.975"/>
      <geometry>
        <box size="1.0 2.5 0.05"/>
      </geometry>
    </collision>
  </link>
  <joint name="table_top_link_joint" type="fixed">
    <parent link="world"/>
    <child link="table_top_link"/>
  </joint>
  <joint name="leg1_joint" type="fixed">
    <parent link="table_top_link"/>
    <origin rpy="0 0 0" xyz="0.5 1.25 1.0"/>
    <child link="leg1_link"/>
  </joint>
  <link name="leg1_link">
    <visual>
      <origin rpy="0 0 0" xyz="0.0 0.0 -0.5"/>
      <geometry>
        <cylinder length="1.0" radius="0.02"/>
      </geometry>
      <material name="silver_gray"/>
    </visual>
    <collision>
      <origin rpy="0.0 0.0 0.0" xyz="0.0 0.0 -0.5"/>
      <geometry>
        <cylinder length="1.0" radius="0.02"/>
      </geometry>
    </collision>
  </link>
  <joint name="vbar1_joint" type="fixed">
    <parent link="leg1_link"/>
    <origin rpy="0 0 0" xyz="0 0 0.485"/>
    <child link="vbar1_link"/>
  </joint>
  <link name="vbar1_link">
    <visual>
      <origin rpy="0 0 0" xyz="0.0 0.0 0"/>
      <geometry>
        <cylinder length="0.97" radius="0.02"/>
      </geometry>
      <material name="silver_gray"/>
    </visual>
    <collision>
      <origin rpy="0.0 0.0 0.0" xyz="0.0 0.0 0"/>
      <geometry>
        <cylinder length="0.97" radius="0.02"/>
      </geometry>
    </collision>
  </link>
  <joint name="leg2_joint" type="fixed">
    <parent link="table_top_link"/>
    <origin rpy="0 0 0" xyz="-0.5 1.25 1.0"/>
    <child link="leg2_link"/>
  </joint>
  <link name="leg2_link">
    <visual>
      <origin rpy="0 0 0" xyz="0.0 0.0 -0.5"/>
      <geometry>
        <cylinder length="1.0" radius="0.02"/>
      </geometry>
      <material name="silver_gray"/>
    </visual>
    <collision>
      <origin rpy="0.0 0.0 0.0" xyz="0.0 0.0 -0.5"/>
      <geometry>
        <cylinder length="1.0" radius="0.02"/>
      </geometry>
    </collision>
  </link>
  <joint name="vbar2_joint" type="fixed">
    <parent link="leg2_link"/>
    <origin rpy="0 0 0" xyz="0 0 0.485"/>
    <child link="vbar2_link"/>
  </joint>
  <link name="vbar2_link">
    <visual>
      <origin rpy="0 0 0" xyz="0.0 0.0 0"/>
      <geometry>
        <cylinder length="0.97" radius="0.02"/>
      </geometry>
      <material name="silver_gray"/>
    </visual>
    <collision>
      <origin rpy="0.0 0.0 0.0" xyz="0.0 0.0 0"/>
      <geometry>
        <cylinder length="0.97" radius="0.02"/>
      </geometry>
    </collision>
  </link>
  <joint name="leg3_joint" type="fixed">
    <parent link="table_top_link"/>
    <origin rpy="0 0 0" xyz="0.5 -1.25 1.0"/>
    <child link="leg3_link"/>
  </joint>
  <link name="leg3_link">
    <visual>
      <origin rpy="0 0 0" xyz="0.0 0.0 -0.5"/>
      <geometry>
        <cylinder length="1.0" radius="0.02"/>
      </geometry>
      <material name="silver_gray"/>
    </visual>
    <collision>
      <origin rpy="0.0 0.0 0.0" xyz="0.0 0.0 -0.5"/>
      <geometry>
        <cylinder length="1.0" radius="0.02"/>
      </geometry>
    </collision>
  </link>
  <joint name="vbar3_joint" type="fixed">
    <parent link="leg3_link"/>
    <origin rpy="0 0 0" xyz="0 0 0.485"/>
    <child link="vbar3_link"/>
  </joint>
  <link name="vbar3_link">
    <visual>
      <origin rpy="0 0 0" xyz="0.0 0.0 0"/>
      <geometry>
        <cylinder length="0.97" radius="0.02"/>
      </geometry>
      <material name="silver_gray"/>
    </visual>
    <collision>
      <origin rpy="0.0 0.0 0.0" xyz="0.0 0.0 0"/>
      <geometry>
        <cylinder length="0.97" radius="0.02"/>
      </geometry>
    </collision>
  </link>
  <joint name="leg4_joint" type="fixed">
    <parent link="table_top_link"/>
    <origin rpy="0 0 0" xyz="-0.5 -1.25 1.0"/>
    <child link="leg4_link"/>
  </joint>
  <link name="leg4_link">
    <visual>
      <origin rpy="0 0 0" xyz="0.0 0.0 -0.5"/>
      <geometry>
        <cylinder length="1.0" radius="0.02"/>
      </geometry>
      <material name="silver_gray"/>
    </visual>
    <collision>
      <origin rpy="0.0 0.0 0.0" xyz="0.0 0.0 -0.5"/>
      <geometry>
        <cylinder length="1.0" radius="0.02"/>
      </geometry>
    </collision>
  </link>
  <joint name="vbar4_joint" type="fixed">
    <parent link="leg4_link"/>
    <origin rpy="0 0 0" xyz="0 0 0.485"/>
    <child link="vbar4_link"/>
  </joint>
  <link name="vbar4_link">
    <visual>
      <origin rpy="0 0 0" xyz="0.0 0.0 0"/>
      <geometry>
        <cylinder length="0.97" radius="0.02"/>
      </geometry>
      <material name="silver_gray"/>
    </visual>
    <collision>
      <origin rpy="0.0 0.0 0.0" xyz="0.0 0.0 0"/>
      <geometry>
        <cylinder length="0.97" radius="0.02"/>
      </geometry>
    </collision>
  </link>
  <joint name="obar1_joint" type="fixed">
    <parent link="vbar1_link"/>
    <origin rpy="0 -1.57079632679 0" xyz="-0.5 0 0.485"/>
    <child link="obar1_link"/>
  </joint>
  <link name="obar1_link">
    <visual>
      <origin rpy="0 0 0" xyz="0.0 0.0 0"/>
      <geometry>
        <cylinder length="1.0" radius="0.02"/>
      </geometry>
      <material name="silver_gray"/>
    </visual>
    <collision>
      <origin rpy="0.0 0.0 0.0" xyz="0.0 0.0 0"/>
      <geometry>
        <cylinder length="1.0" radius="0.02"/>
      </geometry>
    </collision>
  </link>
  <joint name="obar2_joint" type="fixed">
    <parent link="vbar3_link"/>
    <origin rpy="0 -1.57079632679 0" xyz="-0.5 0 0.485"/>
    <child link="obar2_link"/>
  </joint>
  <link name="obar2_link">
    <visual>
      <origin rpy="0 0 0" xyz="0.0 0.0 0"/>
      <geometry>
        <cylinder length="1.0" radius="0.02"/>
      </geometry>
      <material name="silver_gray"/>
    </visual>
    <collision>
      <origin rpy="0.0 0.0 0.0" xyz="0.0 0.0 0"/>
      <geometry>
        <cylinder length="1.0" radius="0.02"/>
      </geometry>
    </collision>
  </link>
  <joint name="obar3_joint" type="fixed">
    <parent link="vbar3_link"/>
    <origin rpy="-1.57079632679 0 0" xyz="0 1.25 0.485"/>
    <child link="obar3_link"/>
  </joint>
  <link name="obar3_link">
    <visual>
      <origin rpy="0 0 0" xyz="0.0 0.0 0"/>
      <geometry>
        <cylinder length="2.5" radius="0.02"/>
      </geometry>
      <material name="silver_gray"/>
    </visual>
    <collision>
      <origin rpy="0.0 0.0 0.0" xyz="0.0 0.0 0"/>
      <geometry>
        <cylinder length="2.5" radius="0.02"/>
      </geometry>
    </collision>
  </link>
  <joint name="obar4_joint" type="fixed">
    <parent link="vbar4_link"/>
    <origin rpy="-1.57079632679 0 0" xyz="0 1.25 0.485"/>
    <child link="obar4_link"/>
  </joint>
  <link name="obar4_link">
    <!-- dummy intertia to make Gazebo urdf2sdf converter work -->
    <visual>
      <origin rpy="0 0 0" xyz="0.0 0.0 0"/>
      <geometry>
        <cylinder length="2.5" radius="0.02"/>
      </geometry>
      <material name="silver_gray"/>
    </visual>
    <collision>
      <origin rpy="0.0 0.0 0.0" xyz="0.0 0.0 0"/>
      <geometry>
        <cylinder length="2.5" radius="0.02"/>
      </geometry>
    </collision>
  </link>
  <joint name="sliding_guide_joint" type="fixed">
    <parent link="obar2_link"/>
    <origin rpy="-1.57079632679 0 0" xyz="0.0 1.25 0.3"/>
    <child link="sliding_guide_link"/>
  </joint>
  <link name="sliding_guide_link">
    <visual>
      <origin rpy="0 0 0" xyz="0.0 0.0 0"/>
      <geometry>
        <box size="0.001 0.4 2.5"/>
      </geometry>
      <material name="silver_gray"/>
    </visual>
    <collision>
      <origin rpy="0.0 0.0 0.0" xyz="0.0 0.0 0"/>
      <geometry>
        <cylinder length="2.5" radius="0.02"/>
      </geometry>
    </collision>
  </link>
  <joint name="working_surface_joint" type="fixed">
    <parent link="sliding_guide_link"/>
    <origin rpy="0.0 -1.57079632679 3.14159265359" xyz="-0.97 0 0"/>
    <child link="working_surface_link"/>
  </joint>
  <link name="working_surface_link">
    <!-- Huge inertia (does not matter, is fixed to the world)-->
    <inertial>
      <mass value="1000"/>
      <origin xyz="0 0 0"/>
      <inertia ixx="0" ixy="0" ixz="0" iyy="0" iyz="0" izz="0"/>
    </inertial>
  </link>
  <material name="camera_aluminum">
    <color rgba="0.5 0.5 0.5 1"/>
  </material>
  <!-- camera body, with origin at bottom screw mount -->
  <joint name="camera_joint" type="fixed">
    <origin rpy="0.0009783 1.1836725 0" xyz="0.0857 0.0000476009 -0.273184"/>
    <parent link="torso_1"/>
    <child link="camera_bottom_screw_frame"/>
  </joint>
  <link name="camera_bottom_screw_frame"/>
  <joint name="camera_link_joint" type="fixed">
    <origin rpy="0 0 0" xyz="0 0.0175 0.0125"/>
    <parent link="camera_bottom_screw_frame"/>
    <child link="camera_link"/>
  </joint>
  <link name="camera_link">
    <visual>
      <origin rpy="1.5707963267948966 0 1.5707963267948966" xyz="0.0149 -0.0175 0"/>
      <geometry>
        <!-- <box size="${d435_cam_width} ${d435_cam_height} ${d435_cam_depth}"/> -->
        <mesh filename="/home/embedded/forest_ws/ros_src/repair_ros_robot/repair_urdf/meshes/d435.dae"/>
        <!--<mesh filename="package://realsense2_description/meshes/d435/d435.dae" />-->
      </geometry>
      <material name="camera_aluminum"/>
    </visual>
    <collision>
      <origin rpy="0 0 0" xyz="0 -0.0175 0"/>
      <geometry>
        <box size="0.02505 0.09 0.025"/>
      </geometry>
    </collision>
    <inertial>
      <!-- The following are not reliable values, and should not be used for modeling -->
      <mass value="0.564"/>
      <origin xyz="0 0 0"/>
      <inertia ixx="0.003881243" ixy="0.0" ixz="0.0" iyy="0.000498940" iyz="0.0" izz="0.003879257"/>
    </inertial>
  </link>
  <!-- camera depth joints and links -->
  <joint name="camera_depth_joint" type="fixed">
    <origin rpy="0 0 0" xyz="0 0 0"/>
    <parent link="camera_link"/>
    <child link="camera_depth_frame"/>
  </joint>
  <link name="camera_depth_frame"/>
  <joint name="camera_depth_optical_joint" type="fixed">
    <origin rpy="-1.5707963267948966 0 -1.5707963267948966" xyz="0 0 0"/>
    <parent link="camera_depth_frame"/>
    <child link="camera_depth_optical_frame"/>
  </joint>
  <link name="camera_depth_optical_frame"/>
  <!-- camera left IR joints and links -->
  <joint name="camera_left_ir_joint" type="fixed">
    <origin rpy="0 0 0" xyz="0 0.0 0"/>
    <parent link="camera_depth_frame"/>
    <child link="camera_left_ir_frame"/>
  </joint>
  <link name="camera_left_ir_frame"/>
  <joint name="camera_left_ir_optical_joint" type="fixed">
    <origin rpy="-1.5707963267948966 0 -1.5707963267948966" xyz="0 0 0"/>
    <parent link="camera_left_ir_frame"/>
    <child link="camera_left_ir_optical_frame"/>
  </joint>
  <link name="camera_left_ir_optical_frame"/>
  <!-- camera right IR joints and links -->
  <joint name="camera_right_ir_joint" type="fixed">
    <origin rpy="0 0 0" xyz="0 -0.05 0"/>
    <parent link="camera_depth_frame"/>
    <child link="camera_right_ir_frame"/>
  </joint>
  <link name="camera_right_ir_frame"/>
  <joint name="camera_right_ir_optical_joint" type="fixed">
    <origin rpy="-1.5707963267948966 0 -1.5707963267948966" xyz="0 0 0"/>
    <parent link="camera_right_ir_frame"/>
    <child link="camera_right_ir_optical_frame"/>
  </joint>
  <link name="camera_right_ir_optical_frame"/>
  <!-- camera color joints and links -->
  <joint name="camera_color_joint" type="fixed">
    <origin rpy="0 0 0" xyz="0 0.015 0"/>
    <parent link="camera_depth_frame"/>
    <child link="camera_color_frame"/>
  </joint>
  <link name="camera_color_frame"/>
  <joint name="camera_color_optical_joint" type="fixed">
    <origin rpy="-1.5707963267948966 0 -1.5707963267948966" xyz="0 0 0"/>
    <parent link="camera_color_frame"/>
    <child link="camera_color_optical_frame"/>
  </joint>
  <link name="camera_color_optical_frame"/>
  <gazebo reference="camera_link">
    <self_collide>0</self_collide>
    <enable_wind>0</enable_wind>
    <kinematic>0</kinematic>
    <gravity>1</gravity>
    <!--<mu>1</mu>-->
    <mu2>1</mu2>
    <fdir1>0 0 0</fdir1>
    <!--<slip1>0</slip1>
      <slip2>0</slip2>-->
    <kp>1e+13</kp>
    <kd>1</kd>
    <!--<max_vel>0.01</max_vel>
      <min_depth>0</min_depth>-->
    <sensor name="cameracolor" type="camera">
      <camera name="camera">
        <horizontal_fov>1.2112585008840648</horizontal_fov>
        <image>
          <width>640</width>
          <height>480</height>
          <format>RGB_INT8</format>
        </image>
        <clip>
          <near>0.1</near>
          <far>100</far>
        </clip>
        <noise>
          <type>gaussian</type>
          <mean>0.0</mean>
          <stddev>0.007</stddev>
        </noise>
      </camera>
      <always_on>1</always_on>
      <update_rate>30</update_rate>
      <visualize>1</visualize>
    </sensor>
    <sensor name="cameraired1" type="camera">
      <camera name="camera">
        <horizontal_fov>1.4870205226991688</horizontal_fov>
        <image>
          <width>1280</width>
          <height>720</height>
          <format>L_INT8</format>
        </image>
        <clip>
          <near>0.1</near>
          <far>100</far>
        </clip>
        <noise>
          <type>gaussian</type>
          <mean>0.0</mean>
          <stddev>0.05</stddev>
        </noise>
      </camera>
      <always_on>1</always_on>
      <update_rate>90</update_rate>
      <visualize>0</visualize>
    </sensor>
    <sensor name="cameraired2" type="camera">
      <camera name="camera">
        <horizontal_fov>1.4870205226991688</horizontal_fov>
        <image>
          <width>1280</width>
          <height>720</height>
          <format>L_INT8</format>
        </image>
        <clip>
          <near>0.1</near>
          <far>100</far>
        </clip>
        <noise>
          <type>gaussian</type>
          <mean>0.0</mean>
          <stddev>0.05</stddev>
        </noise>
      </camera>
      <always_on>1</always_on>
      <update_rate>90</update_rate>
      <visualize>0</visualize>
    </sensor>
    <sensor name="cameradepth" type="depth">
      <camera name="camera">
        <horizontal_fov>1.4870205226991688</horizontal_fov>
        <image>
          <width>1280</width>
          <height>720</height>
        </image>
        <clip>
          <near>0.1</near>
          <far>100</far>
        </clip>
        <noise>
          <type>gaussian</type>
          <mean>0.0</mean>
          <stddev>0.100</stddev>
        </noise>
      </camera>
      <always_on>1</always_on>
      <update_rate>90</update_rate>
      <visualize>0</visualize>
    </sensor>
  </gazebo>
  <gazebo>
    <plugin filename="librealsense_gazebo_plugin.so" name="camera">
      <prefix>camera</prefix>
      <depthUpdateRate>30.0</depthUpdateRate>
      <colorUpdateRate>30.0</colorUpdateRate>
      <infraredUpdateRate>30.0</infraredUpdateRate>
      <depthTopicName>depth/image_raw</depthTopicName>
      <depthCameraInfoTopicName>depth/camera_info</depthCameraInfoTopicName>
      <colorTopicName>color/image_raw</colorTopicName>
      <colorCameraInfoTopicName>color/camera_info</colorCameraInfoTopicName>
      <infrared1TopicName>infra1/image_raw</infrared1TopicName>
      <infrared1CameraInfoTopicName>infra1/camera_info</infrared1CameraInfoTopicName>
      <infrared2TopicName>infra2/image_raw</infrared2TopicName>
      <infrared2CameraInfoTopicName>infra2/camera_info</infrared2CameraInfoTopicName>
      <colorOpticalframeName>camera_color_optical_frame</colorOpticalframeName>
      <depthOpticalframeName>camera_depth_optical_frame</depthOpticalframeName>
      <infrared1OpticalframeName>camera_left_ir_optical_frame</infrared1OpticalframeName>
      <infrared2OpticalframeName>camera_right_ir_optical_frame</infrared2OpticalframeName>
      <rangeMinDepth>0.2</rangeMinDepth>
      <rangeMaxDepth>1.0</rangeMaxDepth>
      <pointCloud>True</pointCloud>
      <pointCloudTopicName>depth/color/points</pointCloudTopicName>
      <pointCloudCutoff>0.25</pointCloudCutoff>
      <pointCloudCutoffMax>1.0</pointCloudCutoffMax>
    </plugin>
  </gazebo>
  <!-- <link name="dummy_prismatic_link"/> -->
  <link name="torso_1">
    <inertial>
      <origin xyz="0.0004977651 -0.00042604032 -0.16838189"/>
      <mass value="8.7077745"/>
      <inertia ixx="0.11857828999999999" ixy="2.0401988e-05" ixz="1.2279510999999998e-05" iyy="0.08073399199999999" iyz="7.0011267999999996e-06" izz="0.054100211999999995"/>
    </inertial>
    <visual>
      <geometry>
        <mesh filename="package://repair_urdf/meshes/mesh_torso-yaw.stl" scale="0.001 0.001 0.001"/>
      </geometry>
      <material name="dark"/>
    </visual>
    <collision>
      <geometry>
        <mesh filename="package://repair_urdf/meshes/simplified/mesh_torso-yaw.stl" scale="0.001 0.001 0.001"/>
      </geometry>
    </collision>
  </link>
  <!-- <joint name="j_torso_base" type="fixed">
            <xacro:insert_block name="origin" />
            <parent link="${parent}" />
            <child link="dummy_prismatic_link"/>
            <axis xyz="0 0 1"/>
            <limit lower="${j_prismatic_lower[0]/2}" upper= "${j_prismatic_upper[0]/2}" effort="${j_prismatic_torque[0]}" velocity="${j_prismatic_velocity[0]}"/>
        </joint> -->
  <!-- torso -->
  <joint name="j_torso_1" type="revolute">
    <parent link="sliding_guide_link"/>
    <child link="torso_1"/>
    <axis xyz="0 0 1"/>
    <origin rpy="1.570796326795 0.0 1.570796326795" xyz="0.0 0.0 0.0"/>
    <limit effort="147.0" lower="-2.6" upper="2.6" velocity="3.86"/>
  </joint>
  <!-- torso  -->
  <link name="arm_2_1">
    <inertial>
      <origin xyz="0.010200651000000002 -0.021560998 0.09876702500000001"/>
      <mass value="2.347"/>
      <inertia ixx="0.007192915699999999" ixy="7.854318399999999e-05" ixz="-0.00039791235999999997" iyy="0.009471160999999999" iyz="0.0012857050999999999" izz="0.0058530904"/>
    </inertial>
    <visual>
      <geometry>
        <mesh filename="package://repair_urdf/meshes/mesh_sh-pitch.stl" scale="0.001 0.001 0.001"/>
      </geometry>
      <material name="dark"/>
    </visual>
    <collision>
      <geometry>
        <mesh filename="package://repair_urdf/meshes/simplified/mesh_sh-pitch.stl" scale="0.001 0.001 0.001"/>
      </geometry>
    </collision>
  </link>
  <link name="arm_2_2">
    <inertial>
      <origin xyz="4.5955243e-05 -0.044957128 -0.030791013"/>
      <mass value="0.76"/>
      <inertia ixx="0.0027927572" ixy="-2.0135067e-06" ixz="-1.3644218e-06" iyy="0.0019288488" iyz="-0.00066693438" izz="0.0026633366"/>
    </inertial>
    <visual>
      <geometry>
        <mesh filename="package://repair_urdf/meshes/mesh_sh-roll.stl" scale="0.001 0.001 0.001"/>
      </geometry>
      <material name="dark"/>
    </visual>
    <collision>
      <geometry>
        <mesh filename="package://repair_urdf/meshes/simplified/mesh_sh-roll.stl" scale="0.001 0.001 0.001"/>
      </geometry>
    </collision>
  </link>
  <link name="arm_2_3">
    <inertial>
      <origin xyz="0.005099315 0.0059986523 -0.18011742"/>
      <mass value="3.34"/>
      <inertia ixx="0.031298784999999996" ixy="-0.00025158367" ixz="0.002371127" iyy="0.031963501" iyz="0.0018728041" izz="0.0026332359"/>
    </inertial>
    <visual>
      <geometry>
        <mesh filename="package://repair_urdf/meshes/mesh_sh-yaw.stl" scale="0.001 0.001 0.001"/>
      </geometry>
      <material name="dark"/>
    </visual>
    <collision>
      <geometry>
        <mesh filename="package://repair_urdf/meshes/simplified/mesh_sh-yaw.stl" scale="0.001 0.001 0.001"/>
      </geometry>
    </collision>
  </link>
  <link name="arm_2_4">
    <inertial>
      <origin xyz="3.332275e-06 -0.033289421 -0.023682302"/>
      <mass value="0.55"/>
      <inertia ixx="0.0016198328" ixy="-1.2642724e-06" ixz="-1.1734799e-06" iyy="0.0012266731" iyz="-0.00039531700999999997" izz="0.0016081346"/>
    </inertial>
    <visual>
      <geometry>
        <mesh filename="package://repair_urdf/meshes/mesh_elbow.stl" scale="0.001 0.001 0.001"/>
      </geometry>
      <material name="dark"/>
    </visual>
    <collision>
      <geometry>
        <mesh filename="package://repair_urdf/meshes/simplified/mesh_elbow.stl" scale="0.001 0.001 0.001"/>
      </geometry>
    </collision>
  </link>
  <link name="arm_2_5">
    <inertial>
      <origin xyz="0.00094711044 -0.048009667 -0.14331833"/>
      <mass value="2.825"/>
      <inertia ixx="0.030333275" ixy="7.3729709e-05" ixz="3.2427371e-05" iyy="0.025195444999999997" iyz="-0.0095263763" izz="0.0069975103999999995"/>
    </inertial>
    <visual>
      <geometry>
        <mesh filename="package://repair_urdf/meshes/mesh_forearm-yaw.stl" scale="0.001 0.001 0.001"/>
      </geometry>
      <material name="dark"/>
    </visual>
    <collision>
      <geometry>
        <mesh filename="package://repair_urdf/meshes/simplified/mesh_forearm-yaw.stl" scale="0.001 0.001 0.001"/>
      </geometry>
    </collision>
  </link>
  <link name="arm_2_6">
    <inertial>
      <origin xyz="0.00068559302 -0.0050299682 0.046682846"/>
      <mass value="1.861"/>
      <inertia ixx="0.0042406037" ixy="-5.5692732e-05" ixz="-9.085198200000001e-05" iyy="0.0029010805999999997" iyz="-0.00018560541" izz="0.0044989008"/>
    </inertial>
    <visual>
      <geometry>
        <mesh filename="package://repair_urdf/meshes/mesh_wrist-pitch.stl" scale="0.001 0.001 0.001"/>
      </geometry>
      <material name="dark"/>
    </visual>
    <collision>
      <geometry>
        <mesh filename="package://repair_urdf/meshes/simplified/mesh_wrist-pitch.stl" scale="0.001 0.001 0.001"/>
      </geometry>
    </collision>
  </link>
  <link name="arm_2_7">
    <inertial>
      <origin xyz="0.0 -0.0010491951 -0.010307299"/>
      <mass value="0.1416397"/>
      <inertia ixx="6.1479333e-05" ixy="-7.4023399e-11" ixz="0.0" iyy="6.4247521e-05" iyz="4.778644799999999e-07" izz="0.00011879743999999998"/>
    </inertial>
    <visual>
      <geometry>
        <mesh filename="package://repair_urdf/meshes/mesh_wrist-roll.stl" scale="0.001 0.001 0.001"/>
      </geometry>
      <material name="dark"/>
    </visual>
    <collision>
      <geometry>
        <mesh filename="package://repair_urdf/meshes/simplified/mesh_wrist-roll.stl" scale="0.001 0.001 0.001"/>
      </geometry>
    </collision>
  </link>
  <link name="arm_2_tcp">
    <inertial>
      <origin xyz="0.0 0.05 0.1"/>
      <mass value="0.5"/>
      <inertia ixx="0.001" ixy="0.0" ixz="0.0" iyy="0.001" iyz="0.0" izz="0.001"/>
    </inertial>
  </link>
  <!-- JOINTS -->
  <!-- shoulder pitch -->
  <joint name="j_arm_2_1" type="revolute">
    <parent link="torso_1"/>
    <child link="arm_2_1"/>
    <axis xyz="0 0 1"/>
    <origin rpy="1.570796326795 0.0 0.0" xyz="0.0 -0.13515 -0.24215"/>
    <limit effort="147.0" lower="-2.6" upper="2.6" velocity="3.86"/>
  </joint>
  <!-- shoulder pitch -->
  <!-- shoulder yaw -->
  <joint name="j_arm_2_2" type="revolute">
    <parent link="arm_2_1"/>
    <child link="arm_2_2"/>
    <origin rpy="0.0 -1.570796326795 0.0" xyz="-0.06 -0.03 0.1255"/>
    <axis xyz="0 0 1"/>
    <!-- -1 -->
    <limit effort="147.0" lower="-0.1" upper="2.5" velocity="3.86"/>
  </joint>
  <!-- shoulder yaw -->
  <!-- shoulder yaw -->
  <joint name="j_arm_2_3" type="revolute">
    <parent link="arm_2_2"/>
    <child link="arm_2_3"/>
    <origin rpy="-1.570796326795 1.570796326795 0.0" xyz="0.0 -0.073 -0.06015"/>
    <axis xyz="0 0 -1"/>
    <!-- -1 -->
    <limit effort="147.0" lower="-2.6" upper="2.6" velocity="6.06"/>
  </joint>
  <!-- shoulder yaw -->
  <!-- elbow -->
  <joint name="j_arm_2_4" type="revolute">
    <parent link="arm_2_3"/>
    <child link="arm_2_4"/>
    <origin rpy="1.570796326795 0.0 0.0" xyz="0.0225 -0.05015 -0.29215"/>
    <axis xyz="0 0 1"/>
    <!-- -1 -->
    <limit effort="147.0" lower="-0.8" upper="2.4" velocity="6.06"/>
  </joint>
  <!-- elbow -->
  <!-- forearm yaw -->
  <joint name="j_arm_2_5" type="revolute">
    <parent link="arm_2_4"/>
    <child link="arm_2_5"/>
    <origin rpy="-1.570796326795 0.0 0.0" xyz="0.0 -0.0725 -0.05015"/>
    <axis xyz="0 0 -1"/>
    <!-- -1 -->
    <limit effort="55.0" lower="-2.8" upper="2.8" velocity="11.72"/>
  </joint>
  <!-- forearm yaw -->
  <!-- wrist pitch-->
  <joint name="j_arm_2_6" type="revolute">
    <parent link="arm_2_5"/>
    <child link="arm_2_6"/>
    <origin rpy="-1.570796326795 0.0 0.0" xyz="0.0 -0.05 -0.2475"/>
    <axis xyz="0 0 1"/>
    <limit effort="55.0" lower="-2.8" upper="2.1" velocity="11.72"/>
  </joint>
  <!-- wrist pitch-->
  <!-- wrist roll-->
  <joint name="j_arm_2_7" type="revolute">
    <parent link="arm_2_6"/>
    <child link="arm_2_7"/>
    <origin rpy="-1.570796326795 0.3316123 0.0" xyz="0.0 0.062877 0.05"/>
    <axis xyz="0 0 1"/>
    <limit effort="55.0" lower="-2.8" upper="2.8" velocity="11.72"/>
  </joint>
  <!-- /wrist roll-->
  <!-- virtual tip-->
  <joint name="j_tcp_2" type="fixed">
    <parent link="arm_2_7"/>
    <child link="arm_2_tcp"/>
    <origin rpy="0.0 0.0 0.0" xyz="0.0 0.0 0.0"/>
  </joint>
  <!-- virtual tip-->
  <transmission name="trans_j_arm_2_1">
    <type>transmission_interface/SimpleTransmission</type>
    <joint name="j_arm_2_1">
      <hardwareInterface>hardware_interface/PositionJointInterface</hardwareInterface>
    </joint>
    <actuator name="j_arm_2_1_motor">
      <hardwareInterface>hardware_interface/PositionJointInterface</hardwareInterface>
      <mechanicalReduction>1</mechanicalReduction>
    </actuator>
  </transmission>
  <transmission name="trans_j_arm_2_2">
    <type>transmission_interface/SimpleTransmission</type>
    <joint name="j_arm_2_2">
      <hardwareInterface>hardware_interface/PositionJointInterface</hardwareInterface>
    </joint>
    <actuator name="j_arm_2_2_motor">
      <hardwareInterface>hardware_interface/PositionJointInterface</hardwareInterface>
      <mechanicalReduction>1</mechanicalReduction>
    </actuator>
  </transmission>
  <transmission name="trans_j_arm_2_3">
    <type>transmission_interface/SimpleTransmission</type>
    <joint name="j_arm_2_3">
      <hardwareInterface>hardware_interface/PositionJointInterface</hardwareInterface>
    </joint>
    <actuator name="j_arm_2_3_motor">
      <hardwareInterface>hardware_interface/PositionJointInterface</hardwareInterface>
      <mechanicalReduction>1</mechanicalReduction>
    </actuator>
  </transmission>
  <transmission name="trans_j_arm_2_4">
    <type>transmission_interface/SimpleTransmission</type>
    <joint name="j_arm_2_4">
      <hardwareInterface>hardware_interface/PositionJointInterface</hardwareInterface>
    </joint>
    <actuator name="j_arm_2_4_motor">
      <hardwareInterface>hardware_interface/PositionJointInterface</hardwareInterface>
      <mechanicalReduction>1</mechanicalReduction>
    </actuator>
  </transmission>
  <transmission name="trans_j_arm_2_5">
    <type>transmission_interface/SimpleTransmission</type>
    <joint name="j_arm_2_5">
      <hardwareInterface>hardware_interface/PositionJointInterface</hardwareInterface>
    </joint>
    <actuator name="j_arm_2_5_motor">
      <hardwareInterface>hardware_interface/PositionJointInterface</hardwareInterface>
      <mechanicalReduction>1</mechanicalReduction>
    </actuator>
  </transmission>
  <transmission name="trans_j_arm_2_6">
    <type>transmission_interface/SimpleTransmission</type>
    <joint name="j_arm_2_6">
      <hardwareInterface>hardware_interface/PositionJointInterface</hardwareInterface>
    </joint>
    <actuator name="j_arm_2_6_motor">
      <hardwareInterface>hardware_interface/PositionJointInterface</hardwareInterface>
      <mechanicalReduction>1</mechanicalReduction>
    </actuator>
  </transmission>
  <transmission name="trans_j_arm_2_7">
    <type>transmission_interface/SimpleTransmission</type>
    <joint name="j_arm_2_7">
      <hardwareInterface>hardware_interface/PositionJointInterface</hardwareInterface>
    </joint>
    <actuator name="j_arm_2_7_motor">
      <hardwareInterface>hardware_interface/PositionJointInterface</hardwareInterface>
      <mechanicalReduction>1</mechanicalReduction>
    </actuator>
  </transmission>
  <transmission name="trans_j_torso_1">
    <type>transmission_interface/SimpleTransmission</type>
    <joint name="j_torso_1">
      <hardwareInterface>hardware_interface/PositionJointInterface</hardwareInterface>
    </joint>
    <actuator name="j_torso_1_motor">
      <hardwareInterface>hardware_interface/PositionJointInterface</hardwareInterface>
      <mechanicalReduction>1</mechanicalReduction>
    </actuator>
  </transmission>
  <link name="arm_1_1">
    <inertial>
      <origin xyz="0.010200651000000002 0.021560998 0.09876702500000001"/>
      <mass value="2.347"/>
      <inertia ixx="0.007192915699999999" ixy="-7.854318399999999e-05" ixz="-0.00039791235999999997" iyy="0.009471160999999999" iyz="-0.0012857050999999999" izz="0.0058530904"/>
    </inertial>
    <visual>
      <geometry>
        <mesh filename="package://repair_urdf/meshes/mesh_sh-pitch.stl" scale="0.001 -0.001 0.001"/>
      </geometry>
      <material name="dark"/>
    </visual>
    <collision>
      <geometry>
        <mesh filename="package://repair_urdf/meshes/simplified/mesh_sh-pitch.stl" scale="0.001 -0.001 0.001"/>
      </geometry>
    </collision>
  </link>
  <link name="arm_1_2">
    <inertial>
      <origin xyz="4.5955243e-05 0.044957128 -0.030791013"/>
      <mass value="0.76"/>
      <inertia ixx="0.0027927572" ixy="2.0135067e-06" ixz="-1.3644218e-06" iyy="0.0019288488" iyz="0.00066693438" izz="0.0026633366"/>
    </inertial>
    <visual>
      <geometry>
        <mesh filename="package://repair_urdf/meshes/mesh_sh-roll.stl" scale="0.001 -0.001 0.001"/>
      </geometry>
      <material name="dark"/>
    </visual>
    <collision>
      <geometry>
        <mesh filename="package://repair_urdf/meshes/simplified/mesh_sh-roll.stl" scale="0.001 -0.001 0.001"/>
      </geometry>
    </collision>
  </link>
  <link name="arm_1_3">
    <inertial>
      <origin xyz="0.005099315 -0.0059986523 -0.18011742"/>
      <mass value="3.34"/>
      <inertia ixx="0.031298784999999996" ixy="0.00025158367" ixz="0.002371127" iyy="0.031963501" iyz="-0.0018728041" izz="0.0026332359"/>
    </inertial>
    <visual>
      <geometry>
        <mesh filename="package://repair_urdf/meshes/mesh_sh-yaw.stl" scale="0.001 -0.001 0.001"/>
      </geometry>
      <material name="dark"/>
    </visual>
    <collision>
      <geometry>
        <mesh filename="package://repair_urdf/meshes/simplified/mesh_sh-yaw.stl" scale="0.001 -0.001 0.001"/>
      </geometry>
    </collision>
  </link>
  <link name="arm_1_4">
    <inertial>
      <origin xyz="3.332275e-06 0.033289421 -0.023682302"/>
      <mass value="0.55"/>
      <inertia ixx="0.0016198328" ixy="1.2642724e-06" ixz="-1.1734799e-06" iyy="0.0012266731" iyz="0.00039531700999999997" izz="0.0016081346"/>
    </inertial>
    <visual>
      <geometry>
        <mesh filename="package://repair_urdf/meshes/mesh_elbow.stl" scale="0.001 -0.001 0.001"/>
      </geometry>
      <material name="dark"/>
    </visual>
    <collision>
      <geometry>
        <mesh filename="package://repair_urdf/meshes/simplified/mesh_elbow.stl" scale="0.001 -0.001 0.001"/>
      </geometry>
    </collision>
  </link>
  <link name="arm_1_5">
    <inertial>
      <origin xyz="0.00094711044 0.048009667 -0.14331833"/>
      <mass value="2.825"/>
      <inertia ixx="0.030333275" ixy="-7.3729709e-05" ixz="3.2427371e-05" iyy="0.025195444999999997" iyz="0.0095263763" izz="0.0069975103999999995"/>
    </inertial>
    <visual>
      <geometry>
        <mesh filename="package://repair_urdf/meshes/mesh_forearm-yaw.stl" scale="0.001 -0.001 0.001"/>
      </geometry>
      <material name="dark"/>
    </visual>
    <collision>
      <geometry>
        <mesh filename="package://repair_urdf/meshes/simplified/mesh_forearm-yaw.stl" scale="0.001 -0.001 0.001"/>
      </geometry>
    </collision>
  </link>
  <link name="arm_1_6">
    <inertial>
      <origin xyz="0.00068559302 0.0050299682 0.046682846"/>
      <mass value="1.861"/>
      <inertia ixx="0.0042406037" ixy="5.5692732e-05" ixz="-9.085198200000001e-05" iyy="0.0029010805999999997" iyz="0.00018560541" izz="0.0044989008"/>
    </inertial>
    <visual>
      <geometry>
        <mesh filename="package://repair_urdf/meshes/mesh_wrist-pitch.stl" scale="0.001 -0.001 0.001"/>
      </geometry>
      <material name="dark"/>
    </visual>
    <collision>
      <geometry>
        <mesh filename="package://repair_urdf/meshes/simplified/mesh_wrist-pitch.stl" scale="0.001 -0.001 0.001"/>
      </geometry>
    </collision>
  </link>
  <link name="arm_1_7">
    <inertial>
      <origin xyz="0.0 0.0010491951 -0.010307299"/>
      <mass value="0.1416397"/>
      <inertia ixx="6.1479333e-05" ixy="7.4023399e-11" ixz="0.0" iyy="6.4247521e-05" iyz="-4.778644799999999e-07" izz="0.00011879743999999998"/>
    </inertial>
    <visual>
      <geometry>
        <mesh filename="package://repair_urdf/meshes/mesh_wrist-roll.stl" scale="0.001 -0.001 0.001"/>
      </geometry>
      <material name="dark"/>
    </visual>
    <collision>
      <geometry>
        <mesh filename="package://repair_urdf/meshes/simplified/mesh_wrist-roll.stl" scale="0.001 -0.001 0.001"/>
      </geometry>
    </collision>
  </link>
  <link name="arm_1_tcp">
    <inertial>
      <origin xyz="0.0 0.05 0.1"/>
      <mass value="0.5"/>
      <inertia ixx="0.001" ixy="0.0" ixz="0.0" iyy="0.001" iyz="0.0" izz="0.001"/>
    </inertial>
  </link>
  <!-- JOINTS -->
  <!-- shoulder pitch -->
  <joint name="j_arm_1_1" type="revolute">
    <parent link="torso_1"/>
    <child link="arm_1_1"/>
    <axis xyz="0 0 1"/>
    <origin rpy="-1.570796326795 0.0 0.0" xyz="0.0 0.13515 -0.24215"/>
    <limit effort="147.0" lower="-2.6" upper="2.6" velocity="3.86"/>
  </joint>
  <!-- shoulder pitch -->
  <!-- shoulder yaw -->
  <joint name="j_arm_1_2" type="revolute">
    <parent link="arm_1_1"/>
    <child link="arm_1_2"/>
    <origin rpy="-0.0 -1.570796326795 0.0" xyz="-0.06 0.03 0.1255"/>
    <axis xyz="0 0 1"/>
    <!-- -1 -->
    <limit effort="147.0" lower="-2.5" upper="0.1" velocity="3.86"/>
  </joint>
  <!-- shoulder yaw -->
  <!-- shoulder yaw -->
  <joint name="j_arm_1_3" type="revolute">
    <parent link="arm_1_2"/>
    <child link="arm_1_3"/>
    <origin rpy="1.570796326795 1.570796326795 0.0" xyz="0.0 0.073 -0.06015"/>
    <axis xyz="0 0 -1"/>
    <!-- -1 -->
    <limit effort="147.0" lower="-2.6" upper="2.6" velocity="6.06"/>
  </joint>
  <!-- shoulder yaw -->
  <!-- elbow -->
  <joint name="j_arm_1_4" type="revolute">
    <parent link="arm_1_3"/>
    <child link="arm_1_4"/>
    <origin rpy="-1.570796326795 0.0 0.0" xyz="0.0225 0.05015 -0.29215"/>
    <axis xyz="0 0 1"/>
    <!-- -1 -->
    <limit effort="147.0" lower="-2.4" upper="0.8" velocity="6.06"/>
  </joint>
  <!-- elbow -->
  <!-- forearm yaw -->
  <joint name="j_arm_1_5" type="revolute">
    <parent link="arm_1_4"/>
    <child link="arm_1_5"/>
    <origin rpy="1.570796326795 0.0 0.0" xyz="0.0 0.0725 -0.05015"/>
    <axis xyz="0 0 -1"/>
    <!-- -1 -->
    <limit effort="55.0" lower="-2.8" upper="2.8" velocity="11.72"/>
  </joint>
  <!-- forearm yaw -->
  <!-- wrist pitch-->
  <joint name="j_arm_1_6" type="revolute">
    <parent link="arm_1_5"/>
    <child link="arm_1_6"/>
    <origin rpy="1.570796326795 0.0 0.0" xyz="0.0 0.05 -0.2475"/>
    <axis xyz="0 0 1"/>
    <limit effort="55.0" lower="-2.1" upper="2.8" velocity="11.72"/>
  </joint>
  <!-- wrist pitch-->
  <!-- wrist roll-->
  <joint name="j_arm_1_7" type="revolute">
    <parent link="arm_1_6"/>
    <child link="arm_1_7"/>
    <origin rpy="1.570796326795 0.3316123 0.0" xyz="0.0 -0.062877 0.05"/>
    <axis xyz="0 0 1"/>
    <limit effort="55.0" lower="-2.8" upper="2.8" velocity="11.72"/>
  </joint>
  <!-- /wrist roll-->
  <!-- virtual tip-->
  <joint name="j_tcp_1" type="fixed">
    <parent link="arm_1_7"/>
    <child link="arm_1_tcp"/>
    <origin rpy="-0.0 0.0 0.0" xyz="0.0 -0.0 0.0"/>
  </joint>
  <!-- virtual tip-->
  <transmission name="trans_j_arm_1_1">
    <type>transmission_interface/SimpleTransmission</type>
    <joint name="j_arm_1_1">
      <hardwareInterface>hardware_interface/PositionJointInterface</hardwareInterface>
    </joint>
    <actuator name="j_arm_1_1_motor">
      <hardwareInterface>hardware_interface/PositionJointInterface</hardwareInterface>
      <mechanicalReduction>1</mechanicalReduction>
    </actuator>
  </transmission>
  <transmission name="trans_j_arm_1_2">
    <type>transmission_interface/SimpleTransmission</type>
    <joint name="j_arm_1_2">
      <hardwareInterface>hardware_interface/PositionJointInterface</hardwareInterface>
    </joint>
    <actuator name="j_arm_1_2_motor">
      <hardwareInterface>hardware_interface/PositionJointInterface</hardwareInterface>
      <mechanicalReduction>1</mechanicalReduction>
    </actuator>
  </transmission>
  <transmission name="trans_j_arm_1_3">
    <type>transmission_interface/SimpleTransmission</type>
    <joint name="j_arm_1_3">
      <hardwareInterface>hardware_interface/PositionJointInterface</hardwareInterface>
    </joint>
    <actuator name="j_arm_1_3_motor">
      <hardwareInterface>hardware_interface/PositionJointInterface</hardwareInterface>
      <mechanicalReduction>1</mechanicalReduction>
    </actuator>
  </transmission>
  <transmission name="trans_j_arm_1_4">
    <type>transmission_interface/SimpleTransmission</type>
    <joint name="j_arm_1_4">
      <hardwareInterface>hardware_interface/PositionJointInterface</hardwareInterface>
    </joint>
    <actuator name="j_arm_1_4_motor">
      <hardwareInterface>hardware_interface/PositionJointInterface</hardwareInterface>
      <mechanicalReduction>1</mechanicalReduction>
    </actuator>
  </transmission>
  <transmission name="trans_j_arm_1_5">
    <type>transmission_interface/SimpleTransmission</type>
    <joint name="j_arm_1_5">
      <hardwareInterface>hardware_interface/PositionJointInterface</hardwareInterface>
    </joint>
    <actuator name="j_arm_1_5_motor">
      <hardwareInterface>hardware_interface/PositionJointInterface</hardwareInterface>
      <mechanicalReduction>1</mechanicalReduction>
    </actuator>
  </transmission>
  <transmission name="trans_j_arm_1_6">
    <type>transmission_interface/SimpleTransmission</type>
    <joint name="j_arm_1_6">
      <hardwareInterface>hardware_interface/PositionJointInterface</hardwareInterface>
    </joint>
    <actuator name="j_arm_1_6_motor">
      <hardwareInterface>hardware_interface/PositionJointInterface</hardwareInterface>
      <mechanicalReduction>1</mechanicalReduction>
    </actuator>
  </transmission>
  <transmission name="trans_j_arm_1_7">
    <type>transmission_interface/SimpleTransmission</type>
    <joint name="j_arm_1_7">
      <hardwareInterface>hardware_interface/PositionJointInterface</hardwareInterface>
    </joint>
    <actuator name="j_arm_1_7_motor">
      <hardwareInterface>hardware_interface/PositionJointInterface</hardwareInterface>
      <mechanicalReduction>1</mechanicalReduction>
    </actuator>
  </transmission>
  <transmission name="trans_j_torso_1">
    <type>transmission_interface/SimpleTransmission</type>
    <joint name="j_torso_1">
      <hardwareInterface>hardware_interface/PositionJointInterface</hardwareInterface>
    </joint>
    <actuator name="j_torso_1_motor">
      <hardwareInterface>hardware_interface/PositionJointInterface</hardwareInterface>
      <mechanicalReduction>1</mechanicalReduction>
    </actuator>
  </transmission>
  <material name="qbhand/optional">
    <color rgba="0.0 0.5 0.8 1.0"/>
  </material>
  <material name="qbhand/base">
    <color rgba="0.35 0.35 0.35 1.0"/>
  </material>
  <material name="qbhand/palm">
    <color rgba="0.35 0.35 0.35 1.0"/>
  </material>
  <material name="qbhand/knuckle">
    <color rgba="0.35 0.35 0.35 1.0"/>
  </material>
  <material name="qbhand/proximal">
    <color rgba="0.35 0.35 0.35 1.0"/>
  </material>
  <material name="qbhand/middle">
    <color rgba="0.35 0.35 0.35 1.0"/>
  </material>
  <material name="qbhand/distal">
    <color rgba="0.35 0.35 0.35 1.0"/>
  </material>
  <material name="qbhand/default">
    <color rgba="0.35 0.35 0.35 1.0"/>
  </material>
  <!-- If you are using only the hand -->
  <!-- <link name="world"/> -->
  <gazebo>
    <plugin filename="libsofthand_mimic_plugin.so" name="synergy_plugin">
      <namespace>left_hand_v1_2_research</namespace>
      <operation_mode>0</operation_mode>
      <spring_k>5</spring_k>
      <wide>False</wide>
      <r_finger>0.0033</r_finger>
      <R_pulley>0.0053</R_pulley>
      <n_param>0.058</n_param>
      <synS_thumb_j1>3</synS_thumb_j1>
      <synS_thumb_j2>1.2</synS_thumb_j2>
      <synS_thumb_j3>1.2</synS_thumb_j3>
      <k_thumb_j1>0.8</k_thumb_j1>
      <k_thumb_j2>0.8</k_thumb_j2>
      <k_thumb_j3>0.8</k_thumb_j3>
      <synS_index_j1>-0.3</synS_index_j1>
      <synS_index_j2>1.57</synS_index_j2>
      <synS_index_j3>1.25</synS_index_j3>
      <synS_index_j4>0.8</synS_index_j4>
      <k_index_j1>0.15</k_index_j1>
      <k_index_j2>0.5</k_index_j2>
      <k_index_j3>0.5</k_index_j3>
      <k_index_j4>0.5</k_index_j4>
      <synS_middle_j1>0</synS_middle_j1>
      <synS_middle_j2>1.57</synS_middle_j2>
      <synS_middle_j3>1.25</synS_middle_j3>
      <synS_middle_j4>1.25</synS_middle_j4>
      <k_middle_j1>0.15</k_middle_j1>
      <k_middle_j2>0.5</k_middle_j2>
      <k_middle_j3>0.5</k_middle_j3>
      <k_middle_j4>0.5</k_middle_j4>
      <synS_ring_j1>0</synS_ring_j1>
      <synS_ring_j2>1.57</synS_ring_j2>
      <synS_ring_j3>1.0</synS_ring_j3>
      <synS_ring_j4>1.0</synS_ring_j4>
      <k_ring_j1>0.15</k_ring_j1>
      <k_ring_j2>0.5</k_ring_j2>
      <k_ring_j3>0.5</k_ring_j3>
      <k_ring_j4>0.5</k_ring_j4>
      <synS_little_j1>0.1</synS_little_j1>
      <synS_little_j2>1.57</synS_little_j2>
      <synS_little_j3>1.25</synS_little_j3>
      <synS_little_j4>1.0</synS_little_j4>
      <k_little_j1>0.15</k_little_j1>
      <k_little_j2>0.5</k_little_j2>
      <k_little_j3>0.5</k_little_j3>
      <k_little_j4>0.5</k_little_j4>
      <!-- Palm thumb -->
      <synS_palm_j1>1.57</synS_palm_j1>
      <k_palm_j1>0.5</k_palm_j1>
      <k_palm_j1_mimic>0.5</k_palm_j1_mimic>
      <!-- Palm little -->
      <synS_palm_j2>1.57</synS_palm_j2>
      <k_palm_j2>0.5</k_palm_j2>
      <k_palm_j2_mimic>0.5</k_palm_j2_mimic>
    </plugin>
  </gazebo>
  <!-- World to palm base -->
  <joint name="left_hand_v1_2_research_iso_joint" type="fixed">
    <parent link="arm_1_7"/>
    <child link="left_hand_v1_2_research_iso_link"/>
    <origin rpy="0 0 0" xyz="0 0 0.00"/>
  </joint>
  <link name="left_hand_v1_2_research_iso_link">
    <inertial>
      <mass value="0.205"/>
      <origin rpy="0 0 0" xyz="0.0 7.8738498e-04 1.5878899e-02"/>
      <inertia ixx="0.00012506929" ixy="0.0" ixz="0.0" iyy="0.0001338779" iyz="0.0" izz="0.00019218394"/>
    </inertial>
    <visual>
      <origin rpy="0 0 0" xyz="0 0 0"/>
      <geometry>
        <mesh filename="package://softhands_description/meshes/v1_2_research/left/flange_iso_04.stl" scale="0.001 0.001 0.001"/>
      </geometry>
      <material name="qbhand/base"/>
    </visual>
    <collision>
      <origin rpy="0 0 0" xyz="0 0 0"/>
      <geometry>
        <mesh filename="package://softhands_description/meshes/v1_2_research/left/flange_iso_04.stl" scale="0.001 0.001 0.001"/>
      </geometry>
    </collision>
  </link>
  <gazebo reference="left_hand_v1_2_research_iso_link">
    <material>Gazebo/Grey</material>
    <selfCollide>0</selfCollide>
  </gazebo>
  <!-- Fake joint and link for grasping -->
  <joint name="left_hand_v1_2_research_grasp_joint" type="fixed">
    <origin rpy="0 0 1.57" xyz="0.06 0.03 0.16"/>
    <parent link="left_hand_v1_2_research_iso_link"/>
    <child link="left_hand_v1_2_research_grasp_link"/>
  </joint>
  <link name="left_hand_v1_2_research_grasp_link"/>
  <joint name="left_hand_v1_2_research_palm_joint" type="fixed">
    <origin rpy="1.57 0  3.14" xyz="0.0045 0.0145 0.144"/>
    <parent link="left_hand_v1_2_research_iso_link"/>
    <child link="left_hand_v1_2_research_palm_link"/>
  </joint>
  <link name="left_hand_v1_2_research_palm_link">
    <inertial>
      <origin rpy="0 0 0" xyz="0.0030 -0.0449 -0.0135"/>
      <mass value="0.45"/>
      <inertia ixx="0.00045" ixy="0.0" ixz="0.0" iyy="0.00025" iyz="0.0" izz="0.0006"/>
    </inertial>
    <visual>
      <origin rpy="0 0 0" xyz="0 0 0"/>
      <geometry>
        <mesh filename="package://softhands_description/meshes/v1_2_research/left/palm_pinch.stl" scale="0.001 0.001 0.001"/>
      </geometry>
      <material name="qbhand/palm"/>
    </visual>
    <collision>
      <origin rpy="0 0 0" xyz="0 0 0"/>
      <geometry>
        <mesh filename="package://softhands_description/meshes/v1_2_research/left/palm_pinch.stl" scale="0.001 0.001 0.001"/>
      </geometry>
    </collision>
  </link>
  <gazebo reference="left_hand_v1_2_research_palm_link">
    <material>Gazebo/Grey</material>
    <selfCollide>0</selfCollide>
  </gazebo>
  <!-- Proximal JOINT -->
  <joint name="left_hand_v1_2_research_thumb_knuckle_joint" type="fixed">
    <origin rpy="-1.57 3.14 0.0" xyz="-0.044 -0.0465 0.002"/>
    <parent link="left_hand_v1_2_research_palm_link"/>
    <child link="left_hand_v1_2_research_thumb_knuckle_link"/>
    <axis xyz="0 0 1"/>
    <limit effort="30" lower="0.0" upper="1.57" velocity="10.0"/>
    <dynamics damping="3e-2" friction="0.0"/>
  </joint>
  <!-- LINK -->
  <link name="left_hand_v1_2_research_thumb_knuckle_link">
    <inertial>
      <origin rpy="0 0 0" xyz="1.3071561e-02 0.002734634 6.4090487e-04"/>
      <mass value="0.01"/>
      <inertia ixx="3.5865978e-07" ixy="-2.0944224e-07" ixz="-6.8657569e-08" iyy="1.3885564e-06" iyz="-3.2170608e-08" izz="1.3571203e-06"/>
    </inertial>
    <visual>
      <origin rpy="0 0 0" xyz="0 0 0"/>
      <geometry>
        <mesh filename="package://softhands_description/meshes/v1_2_research/left/ph_thumb.stl" scale="0.001 0.001 0.001"/>
      </geometry>
      <material name="qbhand/knuckle"/>
    </visual>
    <collision>
      <origin rpy="0 0 0" xyz="0 0 0"/>
      <geometry>
        <mesh filename="package://softhands_description/meshes/v1_2_research/left/ph_thumb.stl" scale="0.001 0.001 0.001"/>
      </geometry>
    </collision>
  </link>
  <!-- GAZEBO REF -->
  <gazebo reference="left_hand_v1_2_research_thumb_knuckle_link">
    <material>Gazebo/Grey</material>
    <selfCollide>0</selfCollide>
  </gazebo>
  <!-- GAZEBO REF -->
  <gazebo reference="left_hand_v1_2_research_thumb_knuckle_joint">
    <implicitSpringDamper>true</implicitSpringDamper>
    <springStiffness>0.4</springStiffness>
    <springReference>0</springReference>
  </gazebo>
  <!-- Inner VIRTUAL JOINT -->
  <joint name="left_hand_v1_2_research_thumb_proximal_virtual_joint" type="fixed">
    <axis xyz="0 0 -1"/>
    <origin rpy="-2 0.0 0.0" xyz="0.0255 0.0038 -0.00012"/>
    <parent link="left_hand_v1_2_research_thumb_knuckle_link"/>
    <child link="left_hand_v1_2_research_thumb_proximal_virtual_link"/>
    <limit effort="30" lower="0.0" upper="0.785398" velocity="10.0"/>
    <dynamics damping="3e-2" friction="0.0"/>
  </joint>
  <!-- VIRTUAL LINK -->
  <link name="left_hand_v1_2_research_thumb_proximal_virtual_link">
    <inertial>
      <origin rpy="0 0 0" xyz="0 0 0"/>
      <mass value="0.0063"/>
      <inertia ixx="1.8024201e-07" ixy="5.756798e-09" ixz="0.0" iyy="2.3516266e-07" iyz="0.0" izz="2.691504e-07"/>
    </inertial>
  </link>
  <!-- Outer JOINT -->
  <joint name="left_hand_v1_2_research_thumb_proximal_joint" type="fixed">
    <axis xyz="0 0 -1"/>
    <origin rpy="0 0 0" xyz="0.013 0 0"/>
    <parent link="left_hand_v1_2_research_thumb_proximal_virtual_link"/>
    <child link="left_hand_v1_2_research_thumb_proximal_link"/>
    <limit effort="30" lower="0.0" upper="0.785398" velocity="10.0"/>
    <dynamics damping="3e-2" friction="0.0"/>
  </joint>
  <!-- LINK -->
  <link name="left_hand_v1_2_research_thumb_proximal_link">
    <inertial>
      <mass value="0.0063"/>
      <inertia ixx="1.8024201e-07" ixy="5.756798e-09" ixz="0.0" iyy="2.3516266e-07" iyz="0.0" izz="2.691504e-07"/>
      <origin rpy="0 0 0" xyz="4.7601567e-03 -1.3786947e-03 0.0"/>
    </inertial>
    <visual>
      <origin rpy="0 0 0" xyz="0 0 0"/>
      <geometry>
        <mesh filename="package://softhands_description/meshes/v1_2_research/left/ph_short.stl" scale="0.001 0.001 0.001"/>
      </geometry>
      <material name="qbhand/palm"/>
    </visual>
    <collision>
      <origin rpy="0 0 0" xyz="0 0 0"/>
      <geometry>
        <mesh filename="package://softhands_description/meshes/v1_2_research/left/ph_short.stl" scale="0.001 0.001 0.001"/>
      </geometry>
    </collision>
  </link>
  <!-- GAZEBO REF -->
  <gazebo reference="left_hand_v1_2_research_thumb_proximal_link">
    <material>Gazebo/Grey</material>
    <selfCollide>0</selfCollide>
  </gazebo>
  <!-- GAZEBO REF -->
  <gazebo reference="left_hand_v1_2_research_thumb_proximal_joint">
    <implicitSpringDamper>true</implicitSpringDamper>
    <springStiffness>0.4</springStiffness>
    <springReference>0</springReference>
  </gazebo>
  <!-- GAZEBO REF -->
  <gazebo reference="left_hand_v1_2_research_thumb_proximal_virtual_joint">
    <implicitSpringDamper>true</implicitSpringDamper>
    <springStiffness>0.4</springStiffness>
    <springReference>0</springReference>
  </gazebo>
  <!-- Inner VIRTUAL JOINT -->
  <joint name="left_hand_v1_2_research_thumb_distal_virtual_joint" type="fixed">
    <axis xyz="0 0 -1"/>
    <origin rpy="0 0 0" xyz="0.009 0 0"/>
    <parent link="left_hand_v1_2_research_thumb_proximal_link"/>
    <child link="left_hand_v1_2_research_thumb_distal_virtual_link"/>
    <limit effort="30" lower="0.0" upper="0.785398" velocity="10.0"/>
    <dynamics damping="3e-2" friction="0.0"/>
  </joint>
  <!-- VIRTUAL LINK -->
  <link name="left_hand_v1_2_research_thumb_distal_virtual_link">
    <inertial>
      <origin rpy="0 0 0" xyz="0 0 0"/>
      <mass value="0.009"/>
      <inertia ixx="2.6586142e-07" ixy="1.2416847e-08" ixz="0.0" iyy="5.9935767e-07" iyz="0.0" izz="6.6781963e-07"/>
    </inertial>
  </link>
  <!-- Outer JOINT -->
  <joint name="left_hand_v1_2_research_thumb_distal_joint" type="fixed">
    <axis xyz="0 0 -1"/>
    <origin rpy="0 0 0" xyz="0.013 0 0"/>
    <parent link="left_hand_v1_2_research_thumb_distal_virtual_link"/>
    <child link="left_hand_v1_2_research_thumb_distal_link"/>
    <limit effort="30" lower="0.0" upper="0.785398" velocity="10.0"/>
    <dynamics damping="3e-2" friction="0.0"/>
  </joint>
  <!-- LINK -->
  <link name="left_hand_v1_2_research_thumb_distal_link">
    <inertial>
      <mass value="0.009"/>
      <inertia ixx="2.6586142e-07" ixy="1.2416847e-08" ixz="0.0" iyy="5.9935767e-07" iyz="0.0" izz="6.6781963e-07"/>
      <origin rpy="0 0 0" xyz="8.8025467e-03 -1.7219289e-03 0.0"/>
    </inertial>
    <visual>
      <origin rpy="0 0 0" xyz="0 0 0"/>
      <geometry>
        <mesh filename="package://softhands_description/meshes/v1_2_research/left/ph_distal.stl" scale="0.001 0.001 0.001"/>
      </geometry>
      <material name="qbhand/palm"/>
    </visual>
    <collision>
      <origin rpy="0 0 0" xyz="0 0 0"/>
      <geometry>
        <mesh filename="package://softhands_description/meshes/v1_2_research/left/ph_distal.stl" scale="0.001 0.001 0.001"/>
      </geometry>
    </collision>
  </link>
  <!-- GAZEBO REF -->
  <gazebo reference="left_hand_v1_2_research_thumb_distal_link">
    <material>Gazebo/Grey</material>
    <selfCollide>0</selfCollide>
  </gazebo>
  <!-- GAZEBO REF -->
  <gazebo reference="left_hand_v1_2_research_thumb_distal_joint">
    <implicitSpringDamper>true</implicitSpringDamper>
    <springStiffness>0.4</springStiffness>
    <springReference>0</springReference>
  </gazebo>
  <!-- GAZEBO REF -->
  <gazebo reference="left_hand_v1_2_research_thumb_distal_virtual_joint">
    <implicitSpringDamper>true</implicitSpringDamper>
    <springStiffness>0.4</springStiffness>
    <springReference>0</springReference>
  </gazebo>
  <!-- Proximal JOINT -->
  <joint name="left_hand_v1_2_research_index_knuckle_joint" type="fixed">
    <origin rpy="0 3.14 -1.57" xyz="-0.02 -0.007 -0.014"/>
    <parent link="left_hand_v1_2_research_palm_link"/>
    <child link="left_hand_v1_2_research_index_knuckle_link"/>
    <axis xyz="0 0 -1"/>
    <limit effort="30" lower="-0.524" upper="0.524" velocity="10.0"/>
    <dynamics damping="3e-2" friction="0.0"/>
  </joint>
  <!-- LINK -->
  <link name="left_hand_v1_2_research_index_knuckle_link">
    <inertial>
      <origin rpy="0 0 0" xyz="4.2753603e-04  0.0 -1.4321738e-03"/>
      <mass value="0.0095"/>
      <inertia ixx="6.4337303e-07" ixy="0.0" ixz="-3.9373913e-08" iyy="1.1253771e-06" iyz="0.0" izz="7.2336948e-07"/>
    </inertial>
    <visual>
      <origin rpy="0 0 0" xyz="0 0 0"/>
      <geometry>
        <mesh filename="package://softhands_description/meshes/v1_2_research/left/ph_knuckle.stl" scale="0.001 0.001 0.001"/>
      </geometry>
      <material name="qbhand/palm"/>
    </visual>
    <collision>
      <origin rpy="0 0 0" xyz="0 0 0"/>
      <geometry>
        <mesh filename="package://softhands_description/meshes/v1_2_research/left/ph_knuckle.stl" scale="0.001 0.001 0.001"/>
      </geometry>
    </collision>
  </link>
  <!-- GAZEBO REF -->
  <gazebo reference="left_hand_v1_2_research_index_knuckle_link">
    <material>Gazebo/Grey</material>
    <selfCollide>0</selfCollide>
  </gazebo>
  <!-- GAZEBO REF -->
  <gazebo reference="left_hand_v1_2_research_index_knuckle_joint">
    <implicitSpringDamper>true</implicitSpringDamper>
    <springStiffness>0.8</springStiffness>
    <springReference>0</springReference>
  </gazebo>
  <!-- Inner VIRTUAL JOINT -->
  <joint name="left_hand_v1_2_research_index_proximal_virtual_joint" type="fixed">
    <axis xyz="0 0 -1"/>
    <origin rpy="1.57 0 0" xyz="0.009 0 0"/>
    <parent link="left_hand_v1_2_research_index_knuckle_link"/>
    <child link="left_hand_v1_2_research_index_proximal_virtual_link"/>
    <limit effort="30" lower="0.0" upper="0.785398" velocity="10.0"/>
    <dynamics damping="3e-2" friction="0.0"/>
  </joint>
  <!-- VIRTUAL LINK -->
  <link name="left_hand_v1_2_research_index_proximal_virtual_link">
    <inertial>
      <origin rpy="0 0 0" xyz="0 0 0"/>
      <mass value="0.009"/>
      <inertia ixx="2.2722068e-07" ixy="1.1586053e-08" ixz="0.0" iyy="5.5947233e-07" iyz="0.0" izz="5.9562195e-07"/>
    </inertial>
  </link>
  <!-- Outer JOINT -->
  <joint name="left_hand_v1_2_research_index_proximal_joint" type="fixed">
    <axis xyz="0 0 -1"/>
    <origin rpy="0.0 0 0" xyz="0.013 0 0"/>
    <parent link="left_hand_v1_2_research_index_proximal_virtual_link"/>
    <child link="left_hand_v1_2_research_index_proximal_link"/>
    <limit effort="30" lower="0.0" upper="0.785398" velocity="10.0"/>
    <dynamics damping="3e-2" friction="0.0"/>
  </joint>
  <!-- LINK -->
  <link name="left_hand_v1_2_research_index_proximal_link">
    <inertial>
      <mass value="0.009"/>
      <inertia ixx="2.2722068e-07" ixy="1.1586053e-08" ixz="0.0" iyy="5.5947233e-07" iyz="0.0" izz="5.9562195e-07"/>
      <origin rpy="0 0 0" xyz="8.7707437e-03 -1.7863138e-03 0.0"/>
    </inertial>
    <visual>
      <origin rpy="0 0 0" xyz="0 0 0"/>
      <geometry>
        <mesh filename="package://softhands_description/meshes/v1_2_research/left/ph_medium.stl" scale="0.001 0.001 0.001"/>
      </geometry>
      <material name="qbhand/palm"/>
    </visual>
    <collision>
      <origin rpy="0 0 0" xyz="0 0 0"/>
      <geometry>
        <mesh filename="package://softhands_description/meshes/v1_2_research/left/ph_medium.stl" scale="0.001 0.001 0.001"/>
      </geometry>
    </collision>
  </link>
  <!-- GAZEBO REF -->
  <gazebo reference="left_hand_v1_2_research_index_proximal_link">
    <material>Gazebo/Grey</material>
    <selfCollide>0</selfCollide>
  </gazebo>
  <!-- GAZEBO REF -->
  <gazebo reference="left_hand_v1_2_research_index_proximal_joint">
    <implicitSpringDamper>true</implicitSpringDamper>
    <springStiffness>0.4</springStiffness>
    <springReference>0</springReference>
  </gazebo>
  <!-- GAZEBO REF -->
  <gazebo reference="left_hand_v1_2_research_index_proximal_virtual_joint">
    <implicitSpringDamper>true</implicitSpringDamper>
    <springStiffness>0.4</springStiffness>
    <springReference>0</springReference>
  </gazebo>
  <!-- Inner VIRTUAL JOINT -->
  <joint name="left_hand_v1_2_research_index_middle_virtual_joint" type="fixed">
    <axis xyz="0 0 -1"/>
    <origin rpy="0.0 0.0 0.0" xyz="0.013 0 0 "/>
    <parent link="left_hand_v1_2_research_index_proximal_link"/>
    <child link="left_hand_v1_2_research_index_middle_virtual_link"/>
    <limit effort="30" lower="0.0" upper="0.785398" velocity="10.0"/>
    <dynamics damping="3e-2" friction="0.0"/>
  </joint>
  <!-- VIRTUAL LINK -->
  <link name="left_hand_v1_2_research_index_middle_virtual_link">
    <inertial>
      <origin rpy="0 0 0" xyz="0 0 0"/>
      <mass value="0.0063"/>
      <inertia ixx="1.8024201e-07" ixy="5.756798e-09" ixz="0.0" iyy="2.3516266e-07" iyz="0.0" izz="2.691504e-07"/>
    </inertial>
  </link>
  <!-- Outer JOINT -->
  <joint name="left_hand_v1_2_research_index_middle_joint" type="fixed">
    <axis xyz="0 0 -1"/>
    <origin rpy="0 0 0" xyz="0.017 0 0"/>
    <parent link="left_hand_v1_2_research_index_middle_virtual_link"/>
    <child link="left_hand_v1_2_research_index_middle_link"/>
    <limit effort="30" lower="0.0" upper="0.785398" velocity="10.0"/>
    <dynamics damping="3e-2" friction="0.0"/>
  </joint>
  <!-- LINK -->
  <link name="left_hand_v1_2_research_index_middle_link">
    <inertial>
      <mass value="0.0063"/>
      <inertia ixx="1.8024201e-07" ixy="5.756798e-09" ixz="0.0" iyy="2.3516266e-07" iyz="0.0" izz="2.691504e-07"/>
      <origin rpy="0 0 0" xyz="4.7601567e-03 -1.3786947e-03 0.0"/>
    </inertial>
    <visual>
      <origin rpy="0 0 0" xyz="0 0 0"/>
      <geometry>
        <mesh filename="package://softhands_description/meshes/v1_2_research/left/ph_short.stl" scale="0.001 0.001 0.001"/>
      </geometry>
      <material name="qbhand/palm"/>
    </visual>
    <collision>
      <origin rpy="0 0 0" xyz="0 0 0"/>
      <geometry>
        <mesh filename="package://softhands_description/meshes/v1_2_research/left/ph_short.stl" scale="0.001 0.001 0.001"/>
      </geometry>
    </collision>
  </link>
  <!-- GAZEBO REF -->
  <gazebo reference="left_hand_v1_2_research_index_middle_link">
    <material>Gazebo/Grey</material>
    <selfCollide>0</selfCollide>
  </gazebo>
  <!-- GAZEBO REF -->
  <gazebo reference="left_hand_v1_2_research_index_middle_joint">
    <implicitSpringDamper>true</implicitSpringDamper>
    <springStiffness>0.4</springStiffness>
    <springReference>0</springReference>
  </gazebo>
  <!-- GAZEBO REF -->
  <gazebo reference="left_hand_v1_2_research_index_middle_virtual_joint">
    <implicitSpringDamper>true</implicitSpringDamper>
    <springStiffness>0.4</springStiffness>
    <springReference>0</springReference>
  </gazebo>
  <!-- Inner VIRTUAL JOINT -->
  <joint name="left_hand_v1_2_research_index_distal_virtual_joint" type="fixed">
    <axis xyz="0 0 -1"/>
    <origin rpy="0 0 0" xyz="0.009 0 0"/>
    <parent link="left_hand_v1_2_research_index_middle_link"/>
    <child link="left_hand_v1_2_research_index_distal_virtual_link"/>
    <limit effort="30" lower="0.0" upper="0.785398" velocity="10.0"/>
    <dynamics damping="3e-2" friction="0.0"/>
  </joint>
  <!-- VIRTUAL LINK -->
  <link name="left_hand_v1_2_research_index_distal_virtual_link">
    <inertial>
      <origin rpy="0 0 0" xyz="0 0 0"/>
      <mass value="0.009"/>
      <inertia ixx="2.6586142e-07" ixy="1.2416847e-08" ixz="0.0" iyy="5.9935767e-07" iyz="0.0" izz="6.6781963e-07"/>
    </inertial>
  </link>
  <!-- Outer JOINT -->
  <joint name="left_hand_v1_2_research_index_distal_joint" type="fixed">
    <axis xyz="0 0 -1"/>
    <origin rpy="0 0 0" xyz="0.013 0 0"/>
    <parent link="left_hand_v1_2_research_index_distal_virtual_link"/>
    <child link="left_hand_v1_2_research_index_distal_link"/>
    <limit effort="30" lower="0.0" upper="0.785398" velocity="10.0"/>
    <dynamics damping="3e-2" friction="0.0"/>
  </joint>
  <!-- LINK -->
  <link name="left_hand_v1_2_research_index_distal_link">
    <inertial>
      <mass value="0.009"/>
      <inertia ixx="2.6586142e-07" ixy="1.2416847e-08" ixz="0.0" iyy="5.9935767e-07" iyz="0.0" izz="6.6781963e-07"/>
      <origin rpy="0 0 0" xyz="8.8025467e-03 -1.7219289e-03 0.0"/>
    </inertial>
    <visual>
      <origin rpy="0 0 0" xyz="0 0 0"/>
      <geometry>
        <mesh filename="package://softhands_description/meshes/v1_2_research/left/ph_distal.stl" scale="0.001 0.001 0.001"/>
      </geometry>
      <material name="qbhand/palm"/>
    </visual>
    <collision>
      <origin rpy="0 0 0" xyz="0 0 0"/>
      <geometry>
        <mesh filename="package://softhands_description/meshes/v1_2_research/left/ph_distal.stl" scale="0.001 0.001 0.001"/>
      </geometry>
    </collision>
  </link>
  <!-- GAZEBO REF -->
  <gazebo reference="left_hand_v1_2_research_index_distal_link">
    <material>Gazebo/Grey</material>
    <selfCollide>0</selfCollide>
  </gazebo>
  <!-- GAZEBO REF -->
  <gazebo reference="left_hand_v1_2_research_index_distal_joint">
    <implicitSpringDamper>true</implicitSpringDamper>
    <springStiffness>0.4</springStiffness>
    <springReference>0</springReference>
  </gazebo>
  <!-- GAZEBO REF -->
  <gazebo reference="left_hand_v1_2_research_index_distal_virtual_joint">
    <implicitSpringDamper>true</implicitSpringDamper>
    <springStiffness>0.4</springStiffness>
    <springReference>0</springReference>
  </gazebo>
  <!-- Proximal JOINT -->
  <joint name="left_hand_v1_2_research_middle_knuckle_joint" type="fixed">
    <origin rpy="0 3.14 -1.57" xyz="0 0 -0.014"/>
    <parent link="left_hand_v1_2_research_palm_link"/>
    <child link="left_hand_v1_2_research_middle_knuckle_link"/>
    <axis xyz="0 0 -1"/>
    <limit effort="30" lower="-0.524" upper="0.524" velocity="10.0"/>
    <dynamics damping="3e-2" friction="0.0"/>
  </joint>
  <!-- LINK -->
  <link name="left_hand_v1_2_research_middle_knuckle_link">
    <inertial>
      <origin rpy="0 0 0" xyz="4.2753603e-04  0.0 -1.4321738e-03"/>
      <mass value="0.0095"/>
      <inertia ixx="6.4337303e-07" ixy="0.0" ixz="-3.9373913e-08" iyy="1.1253771e-06" iyz="0.0" izz="7.2336948e-07"/>
    </inertial>
    <visual>
      <origin rpy="0 0 0" xyz="0 0 0"/>
      <geometry>
        <mesh filename="package://softhands_description/meshes/v1_2_research/left/ph_knuckle.stl" scale="0.001 0.001 0.001"/>
      </geometry>
      <material name="qbhand/palm"/>
    </visual>
    <collision>
      <origin rpy="0 0 0" xyz="0 0 0"/>
      <geometry>
        <mesh filename="package://softhands_description/meshes/v1_2_research/left/ph_knuckle.stl" scale="0.001 0.001 0.001"/>
      </geometry>
    </collision>
  </link>
  <!-- GAZEBO REF -->
  <gazebo reference="left_hand_v1_2_research_middle_knuckle_link">
    <material>Gazebo/Grey</material>
    <selfCollide>0</selfCollide>
  </gazebo>
  <!-- GAZEBO REF -->
  <gazebo reference="left_hand_v1_2_research_middle_knuckle_joint">
    <implicitSpringDamper>true</implicitSpringDamper>
    <springStiffness>0.8</springStiffness>
    <springReference>0</springReference>
  </gazebo>
  <!-- Inner VIRTUAL JOINT -->
  <joint name="left_hand_v1_2_research_middle_proximal_virtual_joint" type="fixed">
    <axis xyz="0 0 -1"/>
    <origin rpy="1.57 0 0" xyz="0.009 0 0"/>
    <parent link="left_hand_v1_2_research_middle_knuckle_link"/>
    <child link="left_hand_v1_2_research_middle_proximal_virtual_link"/>
    <limit effort="30" lower="0.0" upper="0.785398" velocity="10.0"/>
    <dynamics damping="3e-2" friction="0.0"/>
  </joint>
  <!-- VIRTUAL LINK -->
  <link name="left_hand_v1_2_research_middle_proximal_virtual_link">
    <inertial>
      <origin rpy="0 0 0" xyz="0 0 0"/>
      <mass value="0.009"/>
      <inertia ixx="2.2722068e-07" ixy="1.1586053e-08" ixz="0.0" iyy="5.5947233e-07" iyz="0.0" izz="5.9562195e-07"/>
    </inertial>
  </link>
  <!-- Outer JOINT -->
  <joint name="left_hand_v1_2_research_middle_proximal_joint" type="fixed">
    <axis xyz="0 0 -1"/>
    <origin rpy="0.0 0 0" xyz="0.013 0 0"/>
    <parent link="left_hand_v1_2_research_middle_proximal_virtual_link"/>
    <child link="left_hand_v1_2_research_middle_proximal_link"/>
    <limit effort="30" lower="0.0" upper="0.785398" velocity="10.0"/>
    <dynamics damping="3e-2" friction="0.0"/>
  </joint>
  <!-- LINK -->
  <link name="left_hand_v1_2_research_middle_proximal_link">
    <inertial>
      <mass value="0.009"/>
      <inertia ixx="2.2722068e-07" ixy="1.1586053e-08" ixz="0.0" iyy="5.5947233e-07" iyz="0.0" izz="5.9562195e-07"/>
      <origin rpy="0 0 0" xyz="8.7707437e-03 -1.7863138e-03 0.0"/>
    </inertial>
    <visual>
      <origin rpy="0 0 0" xyz="0 0 0"/>
      <geometry>
        <mesh filename="package://softhands_description/meshes/v1_2_research/left/ph_medium.stl" scale="0.001 0.001 0.001"/>
      </geometry>
      <material name="qbhand/palm"/>
    </visual>
    <collision>
      <origin rpy="0 0 0" xyz="0 0 0"/>
      <geometry>
        <mesh filename="package://softhands_description/meshes/v1_2_research/left/ph_medium.stl" scale="0.001 0.001 0.001"/>
      </geometry>
    </collision>
  </link>
  <!-- GAZEBO REF -->
  <gazebo reference="left_hand_v1_2_research_middle_proximal_link">
    <material>Gazebo/Grey</material>
    <selfCollide>0</selfCollide>
  </gazebo>
  <!-- GAZEBO REF -->
  <gazebo reference="left_hand_v1_2_research_middle_proximal_joint">
    <implicitSpringDamper>true</implicitSpringDamper>
    <springStiffness>0.4</springStiffness>
    <springReference>0</springReference>
  </gazebo>
  <!-- GAZEBO REF -->
  <gazebo reference="left_hand_v1_2_research_middle_proximal_virtual_joint">
    <implicitSpringDamper>true</implicitSpringDamper>
    <springStiffness>0.4</springStiffness>
    <springReference>0</springReference>
  </gazebo>
  <!-- Inner VIRTUAL JOINT -->
  <joint name="left_hand_v1_2_research_middle_middle_virtual_joint" type="fixed">
    <axis xyz="0 0 -1"/>
    <origin rpy="0.0 0.0 0.0" xyz="0.013 0 0 "/>
    <parent link="left_hand_v1_2_research_middle_proximal_link"/>
    <child link="left_hand_v1_2_research_middle_middle_virtual_link"/>
    <limit effort="30" lower="0.0" upper="0.785398" velocity="10.0"/>
    <dynamics damping="3e-2" friction="0.0"/>
  </joint>
  <!-- VIRTUAL LINK -->
  <link name="left_hand_v1_2_research_middle_middle_virtual_link">
    <inertial>
      <origin rpy="0 0 0" xyz="0 0 0"/>
      <mass value="0.0063"/>
      <inertia ixx="1.8024201e-07" ixy="5.756798e-09" ixz="0.0" iyy="2.3516266e-07" iyz="0.0" izz="2.691504e-07"/>
    </inertial>
  </link>
  <!-- Outer JOINT -->
  <joint name="left_hand_v1_2_research_middle_middle_joint" type="fixed">
    <axis xyz="0 0 -1"/>
    <origin rpy="0 0 0" xyz="0.017 0 0"/>
    <parent link="left_hand_v1_2_research_middle_middle_virtual_link"/>
    <child link="left_hand_v1_2_research_middle_middle_link"/>
    <limit effort="30" lower="0.0" upper="0.785398" velocity="10.0"/>
    <dynamics damping="3e-2" friction="0.0"/>
  </joint>
  <!-- LINK -->
  <link name="left_hand_v1_2_research_middle_middle_link">
    <inertial>
      <mass value="0.0063"/>
      <inertia ixx="1.8024201e-07" ixy="5.756798e-09" ixz="0.0" iyy="2.3516266e-07" iyz="0.0" izz="2.691504e-07"/>
      <origin rpy="0 0 0" xyz="4.7601567e-03 -1.3786947e-03 0.0"/>
    </inertial>
    <visual>
      <origin rpy="0 0 0" xyz="0 0 0"/>
      <geometry>
        <mesh filename="package://softhands_description/meshes/v1_2_research/left/ph_short.stl" scale="0.001 0.001 0.001"/>
      </geometry>
      <material name="qbhand/palm"/>
    </visual>
    <collision>
      <origin rpy="0 0 0" xyz="0 0 0"/>
      <geometry>
        <mesh filename="package://softhands_description/meshes/v1_2_research/left/ph_short.stl" scale="0.001 0.001 0.001"/>
      </geometry>
    </collision>
  </link>
  <!-- GAZEBO REF -->
  <gazebo reference="left_hand_v1_2_research_middle_middle_link">
    <material>Gazebo/Grey</material>
    <selfCollide>0</selfCollide>
  </gazebo>
  <!-- GAZEBO REF -->
  <gazebo reference="left_hand_v1_2_research_middle_middle_joint">
    <implicitSpringDamper>true</implicitSpringDamper>
    <springStiffness>0.4</springStiffness>
    <springReference>0</springReference>
  </gazebo>
  <!-- GAZEBO REF -->
  <gazebo reference="left_hand_v1_2_research_middle_middle_virtual_joint">
    <implicitSpringDamper>true</implicitSpringDamper>
    <springStiffness>0.4</springStiffness>
    <springReference>0</springReference>
  </gazebo>
  <!-- Inner VIRTUAL JOINT -->
  <joint name="left_hand_v1_2_research_middle_distal_virtual_joint" type="fixed">
    <axis xyz="0 0 -1"/>
    <origin rpy="0 0 0" xyz="0.009 0 0"/>
    <parent link="left_hand_v1_2_research_middle_middle_link"/>
    <child link="left_hand_v1_2_research_middle_distal_virtual_link"/>
    <limit effort="30" lower="0.0" upper="0.785398" velocity="10.0"/>
    <dynamics damping="3e-2" friction="0.0"/>
  </joint>
  <!-- VIRTUAL LINK -->
  <link name="left_hand_v1_2_research_middle_distal_virtual_link">
    <inertial>
      <origin rpy="0 0 0" xyz="0 0 0"/>
      <mass value="0.009"/>
      <inertia ixx="2.6586142e-07" ixy="1.2416847e-08" ixz="0.0" iyy="5.9935767e-07" iyz="0.0" izz="6.6781963e-07"/>
    </inertial>
  </link>
  <!-- Outer JOINT -->
  <joint name="left_hand_v1_2_research_middle_distal_joint" type="fixed">
    <axis xyz="0 0 -1"/>
    <origin rpy="0 0 0" xyz="0.013 0 0"/>
    <parent link="left_hand_v1_2_research_middle_distal_virtual_link"/>
    <child link="left_hand_v1_2_research_middle_distal_link"/>
    <limit effort="30" lower="0.0" upper="0.785398" velocity="10.0"/>
    <dynamics damping="3e-2" friction="0.0"/>
  </joint>
  <!-- LINK -->
  <link name="left_hand_v1_2_research_middle_distal_link">
    <inertial>
      <mass value="0.009"/>
      <inertia ixx="2.6586142e-07" ixy="1.2416847e-08" ixz="0.0" iyy="5.9935767e-07" iyz="0.0" izz="6.6781963e-07"/>
      <origin rpy="0 0 0" xyz="8.8025467e-03 -1.7219289e-03 0.0"/>
    </inertial>
    <visual>
      <origin rpy="0 0 0" xyz="0 0 0"/>
      <geometry>
        <mesh filename="package://softhands_description/meshes/v1_2_research/left/ph_distal.stl" scale="0.001 0.001 0.001"/>
      </geometry>
      <material name="qbhand/palm"/>
    </visual>
    <collision>
      <origin rpy="0 0 0" xyz="0 0 0"/>
      <geometry>
        <mesh filename="package://softhands_description/meshes/v1_2_research/left/ph_distal.stl" scale="0.001 0.001 0.001"/>
      </geometry>
    </collision>
  </link>
  <!-- GAZEBO REF -->
  <gazebo reference="left_hand_v1_2_research_middle_distal_link">
    <material>Gazebo/Grey</material>
    <selfCollide>0</selfCollide>
  </gazebo>
  <!-- GAZEBO REF -->
  <gazebo reference="left_hand_v1_2_research_middle_distal_joint">
    <implicitSpringDamper>true</implicitSpringDamper>
    <springStiffness>0.4</springStiffness>
    <springReference>0</springReference>
  </gazebo>
  <!-- GAZEBO REF -->
  <gazebo reference="left_hand_v1_2_research_middle_distal_virtual_joint">
    <implicitSpringDamper>true</implicitSpringDamper>
    <springStiffness>0.4</springStiffness>
    <springReference>0</springReference>
  </gazebo>
  <!-- Proximal JOINT -->
  <joint name="left_hand_v1_2_research_ring_knuckle_joint" type="fixed">
    <origin rpy="0 3.14 -1.57" xyz="0.02 -0.007 -0.014"/>
    <parent link="left_hand_v1_2_research_palm_link"/>
    <child link="left_hand_v1_2_research_ring_knuckle_link"/>
    <axis xyz="0 0 -1"/>
    <limit effort="30" lower="-0.524" upper="0.524" velocity="10.0"/>
    <dynamics damping="3e-2" friction="0.0"/>
  </joint>
  <!-- LINK -->
  <link name="left_hand_v1_2_research_ring_knuckle_link">
    <inertial>
      <origin rpy="0 0 0" xyz="4.2753603e-04  0.0 -1.4321738e-03"/>
      <mass value="0.0095"/>
      <inertia ixx="6.4337303e-07" ixy="0.0" ixz="-3.9373913e-08" iyy="1.1253771e-06" iyz="0.0" izz="7.2336948e-07"/>
    </inertial>
    <visual>
      <origin rpy="0 0 0" xyz="0 0 0"/>
      <geometry>
        <mesh filename="package://softhands_description/meshes/v1_2_research/left/ph_knuckle.stl" scale="0.001 0.001 0.001"/>
      </geometry>
      <material name="qbhand/palm"/>
    </visual>
    <collision>
      <origin rpy="0 0 0" xyz="0 0 0"/>
      <geometry>
        <mesh filename="package://softhands_description/meshes/v1_2_research/left/ph_knuckle.stl" scale="0.001 0.001 0.001"/>
      </geometry>
    </collision>
  </link>
  <!-- GAZEBO REF -->
  <gazebo reference="left_hand_v1_2_research_ring_knuckle_link">
    <material>Gazebo/Grey</material>
    <selfCollide>0</selfCollide>
  </gazebo>
  <!-- GAZEBO REF -->
  <gazebo reference="left_hand_v1_2_research_ring_knuckle_joint">
    <implicitSpringDamper>true</implicitSpringDamper>
    <springStiffness>0.8</springStiffness>
    <springReference>0</springReference>
  </gazebo>
  <!-- Inner VIRTUAL JOINT -->
  <joint name="left_hand_v1_2_research_ring_proximal_virtual_joint" type="fixed">
    <axis xyz="0 0 -1"/>
    <origin rpy="1.57 0 0" xyz="0.009 0 0"/>
    <parent link="left_hand_v1_2_research_ring_knuckle_link"/>
    <child link="left_hand_v1_2_research_ring_proximal_virtual_link"/>
    <limit effort="30" lower="0.0" upper="0.785398" velocity="10.0"/>
    <dynamics damping="3e-2" friction="0.0"/>
  </joint>
  <!-- VIRTUAL LINK -->
  <link name="left_hand_v1_2_research_ring_proximal_virtual_link">
    <inertial>
      <origin rpy="0 0 0" xyz="0 0 0"/>
      <mass value="0.009"/>
      <inertia ixx="2.2722068e-07" ixy="1.1586053e-08" ixz="0.0" iyy="5.5947233e-07" iyz="0.0" izz="5.9562195e-07"/>
    </inertial>
  </link>
  <!-- Outer JOINT -->
  <joint name="left_hand_v1_2_research_ring_proximal_joint" type="fixed">
    <axis xyz="0 0 -1"/>
    <origin rpy="0.0 0 0" xyz="0.013 0 0"/>
    <parent link="left_hand_v1_2_research_ring_proximal_virtual_link"/>
    <child link="left_hand_v1_2_research_ring_proximal_link"/>
    <limit effort="30" lower="0.0" upper="0.785398" velocity="10.0"/>
    <dynamics damping="3e-2" friction="0.0"/>
  </joint>
  <!-- LINK -->
  <link name="left_hand_v1_2_research_ring_proximal_link">
    <inertial>
      <mass value="0.009"/>
      <inertia ixx="2.2722068e-07" ixy="1.1586053e-08" ixz="0.0" iyy="5.5947233e-07" iyz="0.0" izz="5.9562195e-07"/>
      <origin rpy="0 0 0" xyz="8.7707437e-03 -1.7863138e-03 0.0"/>
    </inertial>
    <visual>
      <origin rpy="0 0 0" xyz="0 0 0"/>
      <geometry>
        <mesh filename="package://softhands_description/meshes/v1_2_research/left/ph_medium.stl" scale="0.001 0.001 0.001"/>
      </geometry>
      <material name="qbhand/palm"/>
    </visual>
    <collision>
      <origin rpy="0 0 0" xyz="0 0 0"/>
      <geometry>
        <mesh filename="package://softhands_description/meshes/v1_2_research/left/ph_medium.stl" scale="0.001 0.001 0.001"/>
      </geometry>
    </collision>
  </link>
  <!-- GAZEBO REF -->
  <gazebo reference="left_hand_v1_2_research_ring_proximal_link">
    <material>Gazebo/Grey</material>
    <selfCollide>0</selfCollide>
  </gazebo>
  <!-- GAZEBO REF -->
  <gazebo reference="left_hand_v1_2_research_ring_proximal_joint">
    <implicitSpringDamper>true</implicitSpringDamper>
    <springStiffness>0.4</springStiffness>
    <springReference>0</springReference>
  </gazebo>
  <!-- GAZEBO REF -->
  <gazebo reference="left_hand_v1_2_research_ring_proximal_virtual_joint">
    <implicitSpringDamper>true</implicitSpringDamper>
    <springStiffness>0.4</springStiffness>
    <springReference>0</springReference>
  </gazebo>
  <!-- Inner VIRTUAL JOINT -->
  <joint name="left_hand_v1_2_research_ring_middle_virtual_joint" type="fixed">
    <axis xyz="0 0 -1"/>
    <origin rpy="0.0 0.0 0.0" xyz="0.013 0 0 "/>
    <parent link="left_hand_v1_2_research_ring_proximal_link"/>
    <child link="left_hand_v1_2_research_ring_middle_virtual_link"/>
    <limit effort="30" lower="0.0" upper="0.785398" velocity="10.0"/>
    <dynamics damping="3e-2" friction="0.0"/>
  </joint>
  <!-- VIRTUAL LINK -->
  <link name="left_hand_v1_2_research_ring_middle_virtual_link">
    <inertial>
      <origin rpy="0 0 0" xyz="0 0 0"/>
      <mass value="0.0063"/>
      <inertia ixx="1.8024201e-07" ixy="5.756798e-09" ixz="0.0" iyy="2.3516266e-07" iyz="0.0" izz="2.691504e-07"/>
    </inertial>
  </link>
  <!-- Outer JOINT -->
  <joint name="left_hand_v1_2_research_ring_middle_joint" type="fixed">
    <axis xyz="0 0 -1"/>
    <origin rpy="0 0 0" xyz="0.017 0 0"/>
    <parent link="left_hand_v1_2_research_ring_middle_virtual_link"/>
    <child link="left_hand_v1_2_research_ring_middle_link"/>
    <limit effort="30" lower="0.0" upper="0.785398" velocity="10.0"/>
    <dynamics damping="3e-2" friction="0.0"/>
  </joint>
  <!-- LINK -->
  <link name="left_hand_v1_2_research_ring_middle_link">
    <inertial>
      <mass value="0.0063"/>
      <inertia ixx="1.8024201e-07" ixy="5.756798e-09" ixz="0.0" iyy="2.3516266e-07" iyz="0.0" izz="2.691504e-07"/>
      <origin rpy="0 0 0" xyz="4.7601567e-03 -1.3786947e-03 0.0"/>
    </inertial>
    <visual>
      <origin rpy="0 0 0" xyz="0 0 0"/>
      <geometry>
        <mesh filename="package://softhands_description/meshes/v1_2_research/left/ph_short.stl" scale="0.001 0.001 0.001"/>
      </geometry>
      <material name="qbhand/palm"/>
    </visual>
    <collision>
      <origin rpy="0 0 0" xyz="0 0 0"/>
      <geometry>
        <mesh filename="package://softhands_description/meshes/v1_2_research/left/ph_short.stl" scale="0.001 0.001 0.001"/>
      </geometry>
    </collision>
  </link>
  <!-- GAZEBO REF -->
  <gazebo reference="left_hand_v1_2_research_ring_middle_link">
    <material>Gazebo/Grey</material>
    <selfCollide>0</selfCollide>
  </gazebo>
  <!-- GAZEBO REF -->
  <gazebo reference="left_hand_v1_2_research_ring_middle_joint">
    <implicitSpringDamper>true</implicitSpringDamper>
    <springStiffness>0.4</springStiffness>
    <springReference>0</springReference>
  </gazebo>
  <!-- GAZEBO REF -->
  <gazebo reference="left_hand_v1_2_research_ring_middle_virtual_joint">
    <implicitSpringDamper>true</implicitSpringDamper>
    <springStiffness>0.4</springStiffness>
    <springReference>0</springReference>
  </gazebo>
  <!-- Inner VIRTUAL JOINT -->
  <joint name="left_hand_v1_2_research_ring_distal_virtual_joint" type="fixed">
    <axis xyz="0 0 -1"/>
    <origin rpy="0 0 0" xyz="0.009 0 0"/>
    <parent link="left_hand_v1_2_research_ring_middle_link"/>
    <child link="left_hand_v1_2_research_ring_distal_virtual_link"/>
    <limit effort="30" lower="0.0" upper="0.785398" velocity="10.0"/>
    <dynamics damping="3e-2" friction="0.0"/>
  </joint>
  <!-- VIRTUAL LINK -->
  <link name="left_hand_v1_2_research_ring_distal_virtual_link">
    <inertial>
      <origin rpy="0 0 0" xyz="0 0 0"/>
      <mass value="0.009"/>
      <inertia ixx="2.6586142e-07" ixy="1.2416847e-08" ixz="0.0" iyy="5.9935767e-07" iyz="0.0" izz="6.6781963e-07"/>
    </inertial>
  </link>
  <!-- Outer JOINT -->
  <joint name="left_hand_v1_2_research_ring_distal_joint" type="fixed">
    <axis xyz="0 0 -1"/>
    <origin rpy="0 0 0" xyz="0.013 0 0"/>
    <parent link="left_hand_v1_2_research_ring_distal_virtual_link"/>
    <child link="left_hand_v1_2_research_ring_distal_link"/>
    <limit effort="30" lower="0.0" upper="0.785398" velocity="10.0"/>
    <dynamics damping="3e-2" friction="0.0"/>
  </joint>
  <!-- LINK -->
  <link name="left_hand_v1_2_research_ring_distal_link">
    <inertial>
      <mass value="0.009"/>
      <inertia ixx="2.6586142e-07" ixy="1.2416847e-08" ixz="0.0" iyy="5.9935767e-07" iyz="0.0" izz="6.6781963e-07"/>
      <origin rpy="0 0 0" xyz="8.8025467e-03 -1.7219289e-03 0.0"/>
    </inertial>
    <visual>
      <origin rpy="0 0 0" xyz="0 0 0"/>
      <geometry>
        <mesh filename="package://softhands_description/meshes/v1_2_research/left/ph_distal.stl" scale="0.001 0.001 0.001"/>
      </geometry>
      <material name="qbhand/palm"/>
    </visual>
    <collision>
      <origin rpy="0 0 0" xyz="0 0 0"/>
      <geometry>
        <mesh filename="package://softhands_description/meshes/v1_2_research/left/ph_distal.stl" scale="0.001 0.001 0.001"/>
      </geometry>
    </collision>
  </link>
  <!-- GAZEBO REF -->
  <gazebo reference="left_hand_v1_2_research_ring_distal_link">
    <material>Gazebo/Grey</material>
    <selfCollide>0</selfCollide>
  </gazebo>
  <!-- GAZEBO REF -->
  <gazebo reference="left_hand_v1_2_research_ring_distal_joint">
    <implicitSpringDamper>true</implicitSpringDamper>
    <springStiffness>0.4</springStiffness>
    <springReference>0</springReference>
  </gazebo>
  <!-- GAZEBO REF -->
  <gazebo reference="left_hand_v1_2_research_ring_distal_virtual_joint">
    <implicitSpringDamper>true</implicitSpringDamper>
    <springStiffness>0.4</springStiffness>
    <springReference>0</springReference>
  </gazebo>
  <!-- Proximal JOINT -->
  <joint name="left_hand_v1_2_research_little_knuckle_joint" type="fixed">
    <origin rpy="0 3.14 -1.57" xyz="0.04 -0.012 -0.014"/>
    <parent link="left_hand_v1_2_research_palm_link"/>
    <child link="left_hand_v1_2_research_little_knuckle_link"/>
    <axis xyz="0 0 -1"/>
    <limit effort="30" lower="-0.524" upper="0.524" velocity="10.0"/>
    <dynamics damping="3e-2" friction="0.0"/>
  </joint>
  <!-- LINK -->
  <link name="left_hand_v1_2_research_little_knuckle_link">
    <inertial>
      <origin rpy="0 0 0" xyz="4.2753603e-04  0.0 -1.4321738e-03"/>
      <mass value="0.0095"/>
      <inertia ixx="6.4337303e-07" ixy="0.0" ixz="-3.9373913e-08" iyy="1.1253771e-06" iyz="0.0" izz="7.2336948e-07"/>
    </inertial>
    <visual>
      <origin rpy="0 0 0" xyz="0 0 0"/>
      <geometry>
        <mesh filename="package://softhands_description/meshes/v1_2_research/left/ph_knuckle.stl" scale="0.001 0.001 0.001"/>
      </geometry>
      <material name="qbhand/palm"/>
    </visual>
    <collision>
      <origin rpy="0 0 0" xyz="0 0 0"/>
      <geometry>
        <mesh filename="package://softhands_description/meshes/v1_2_research/left/ph_knuckle.stl" scale="0.001 0.001 0.001"/>
      </geometry>
    </collision>
  </link>
  <!-- GAZEBO REF -->
  <gazebo reference="left_hand_v1_2_research_little_knuckle_link">
    <material>Gazebo/Grey</material>
    <selfCollide>0</selfCollide>
  </gazebo>
  <!-- GAZEBO REF -->
  <gazebo reference="left_hand_v1_2_research_little_knuckle_joint">
    <implicitSpringDamper>true</implicitSpringDamper>
    <springStiffness>0.8</springStiffness>
    <springReference>0</springReference>
  </gazebo>
  <!-- Inner VIRTUAL JOINT -->
  <joint name="left_hand_v1_2_research_little_proximal_virtual_joint" type="fixed">
    <axis xyz="0 0 -1"/>
    <origin rpy="1.57 0 0" xyz="0.009 0 0"/>
    <parent link="left_hand_v1_2_research_little_knuckle_link"/>
    <child link="left_hand_v1_2_research_little_proximal_virtual_link"/>
    <limit effort="30" lower="0.0" upper="0.785398" velocity="10.0"/>
    <dynamics damping="3e-2" friction="0.0"/>
  </joint>
  <!-- VIRTUAL LINK -->
  <link name="left_hand_v1_2_research_little_proximal_virtual_link">
    <inertial>
      <origin rpy="0 0 0" xyz="0 0 0"/>
      <mass value="0.009"/>
      <inertia ixx="2.2722068e-07" ixy="1.1586053e-08" ixz="0.0" iyy="5.5947233e-07" iyz="0.0" izz="5.9562195e-07"/>
    </inertial>
  </link>
  <!-- Outer JOINT -->
  <joint name="left_hand_v1_2_research_little_proximal_joint" type="fixed">
    <axis xyz="0 0 -1"/>
    <origin rpy="0.0 0 0" xyz="0.013 0 0"/>
    <parent link="left_hand_v1_2_research_little_proximal_virtual_link"/>
    <child link="left_hand_v1_2_research_little_proximal_link"/>
    <limit effort="30" lower="0.0" upper="0.785398" velocity="10.0"/>
    <dynamics damping="3e-2" friction="0.0"/>
  </joint>
  <!-- LINK -->
  <link name="left_hand_v1_2_research_little_proximal_link">
    <inertial>
      <mass value="0.009"/>
      <inertia ixx="2.2722068e-07" ixy="1.1586053e-08" ixz="0.0" iyy="5.5947233e-07" iyz="0.0" izz="5.9562195e-07"/>
      <origin rpy="0 0 0" xyz="8.7707437e-03 -1.7863138e-03 0.0"/>
    </inertial>
    <visual>
      <origin rpy="0 0 0" xyz="0 0 0"/>
      <geometry>
        <mesh filename="package://softhands_description/meshes/v1_2_research/left/ph_medium.stl" scale="0.001 0.001 0.001"/>
      </geometry>
      <material name="qbhand/palm"/>
    </visual>
    <collision>
      <origin rpy="0 0 0" xyz="0 0 0"/>
      <geometry>
        <mesh filename="package://softhands_description/meshes/v1_2_research/left/ph_medium.stl" scale="0.001 0.001 0.001"/>
      </geometry>
    </collision>
  </link>
  <!-- GAZEBO REF -->
  <gazebo reference="left_hand_v1_2_research_little_proximal_link">
    <material>Gazebo/Grey</material>
    <selfCollide>0</selfCollide>
  </gazebo>
  <!-- GAZEBO REF -->
  <gazebo reference="left_hand_v1_2_research_little_proximal_joint">
    <implicitSpringDamper>true</implicitSpringDamper>
    <springStiffness>0.4</springStiffness>
    <springReference>0</springReference>
  </gazebo>
  <!-- GAZEBO REF -->
  <gazebo reference="left_hand_v1_2_research_little_proximal_virtual_joint">
    <implicitSpringDamper>true</implicitSpringDamper>
    <springStiffness>0.4</springStiffness>
    <springReference>0</springReference>
  </gazebo>
  <!-- Inner VIRTUAL JOINT -->
  <joint name="left_hand_v1_2_research_little_middle_virtual_joint" type="fixed">
    <axis xyz="0 0 -1"/>
    <origin rpy="0.0 0.0 0.0" xyz="0.013 0 0 "/>
    <parent link="left_hand_v1_2_research_little_proximal_link"/>
    <child link="left_hand_v1_2_research_little_middle_virtual_link"/>
    <limit effort="30" lower="0.0" upper="0.785398" velocity="10.0"/>
    <dynamics damping="3e-2" friction="0.0"/>
  </joint>
  <!-- VIRTUAL LINK -->
  <link name="left_hand_v1_2_research_little_middle_virtual_link">
    <inertial>
      <origin rpy="0 0 0" xyz="0 0 0"/>
      <mass value="0.0063"/>
      <inertia ixx="1.8024201e-07" ixy="5.756798e-09" ixz="0.0" iyy="2.3516266e-07" iyz="0.0" izz="2.691504e-07"/>
    </inertial>
  </link>
  <!-- Outer JOINT -->
  <joint name="left_hand_v1_2_research_little_middle_joint" type="fixed">
    <axis xyz="0 0 -1"/>
    <origin rpy="0 0 0" xyz="0.017 0 0"/>
    <parent link="left_hand_v1_2_research_little_middle_virtual_link"/>
    <child link="left_hand_v1_2_research_little_middle_link"/>
    <limit effort="30" lower="0.0" upper="0.785398" velocity="10.0"/>
    <dynamics damping="3e-2" friction="0.0"/>
  </joint>
  <!-- LINK -->
  <link name="left_hand_v1_2_research_little_middle_link">
    <inertial>
      <mass value="0.0063"/>
      <inertia ixx="1.8024201e-07" ixy="5.756798e-09" ixz="0.0" iyy="2.3516266e-07" iyz="0.0" izz="2.691504e-07"/>
      <origin rpy="0 0 0" xyz="4.7601567e-03 -1.3786947e-03 0.0"/>
    </inertial>
    <visual>
      <origin rpy="0 0 0" xyz="0 0 0"/>
      <geometry>
        <mesh filename="package://softhands_description/meshes/v1_2_research/left/ph_short.stl" scale="0.001 0.001 0.001"/>
      </geometry>
      <material name="qbhand/palm"/>
    </visual>
    <collision>
      <origin rpy="0 0 0" xyz="0 0 0"/>
      <geometry>
        <mesh filename="package://softhands_description/meshes/v1_2_research/left/ph_short.stl" scale="0.001 0.001 0.001"/>
      </geometry>
    </collision>
  </link>
  <!-- GAZEBO REF -->
  <gazebo reference="left_hand_v1_2_research_little_middle_link">
    <material>Gazebo/Grey</material>
    <selfCollide>0</selfCollide>
  </gazebo>
  <!-- GAZEBO REF -->
  <gazebo reference="left_hand_v1_2_research_little_middle_joint">
    <implicitSpringDamper>true</implicitSpringDamper>
    <springStiffness>0.4</springStiffness>
    <springReference>0</springReference>
  </gazebo>
  <!-- GAZEBO REF -->
  <gazebo reference="left_hand_v1_2_research_little_middle_virtual_joint">
    <implicitSpringDamper>true</implicitSpringDamper>
    <springStiffness>0.4</springStiffness>
    <springReference>0</springReference>
  </gazebo>
  <!-- Inner VIRTUAL JOINT -->
  <joint name="left_hand_v1_2_research_little_distal_virtual_joint" type="fixed">
    <axis xyz="0 0 -1"/>
    <origin rpy="0 0 0" xyz="0.009 0 0"/>
    <parent link="left_hand_v1_2_research_little_middle_link"/>
    <child link="left_hand_v1_2_research_little_distal_virtual_link"/>
    <limit effort="30" lower="0.0" upper="0.785398" velocity="10.0"/>
    <dynamics damping="3e-2" friction="0.0"/>
  </joint>
  <!-- VIRTUAL LINK -->
  <link name="left_hand_v1_2_research_little_distal_virtual_link">
    <inertial>
      <origin rpy="0 0 0" xyz="0 0 0"/>
      <mass value="0.009"/>
      <inertia ixx="2.6586142e-07" ixy="1.2416847e-08" ixz="0.0" iyy="5.9935767e-07" iyz="0.0" izz="6.6781963e-07"/>
    </inertial>
  </link>
  <!-- Outer JOINT -->
  <joint name="left_hand_v1_2_research_little_distal_joint" type="fixed">
    <axis xyz="0 0 -1"/>
    <origin rpy="0 0 0" xyz="0.013 0 0"/>
    <parent link="left_hand_v1_2_research_little_distal_virtual_link"/>
    <child link="left_hand_v1_2_research_little_distal_link"/>
    <limit effort="30" lower="0.0" upper="0.785398" velocity="10.0"/>
    <dynamics damping="3e-2" friction="0.0"/>
  </joint>
  <!-- LINK -->
  <link name="left_hand_v1_2_research_little_distal_link">
    <inertial>
      <mass value="0.009"/>
      <inertia ixx="2.6586142e-07" ixy="1.2416847e-08" ixz="0.0" iyy="5.9935767e-07" iyz="0.0" izz="6.6781963e-07"/>
      <origin rpy="0 0 0" xyz="8.8025467e-03 -1.7219289e-03 0.0"/>
    </inertial>
    <visual>
      <origin rpy="0 0 0" xyz="0 0 0"/>
      <geometry>
        <mesh filename="package://softhands_description/meshes/v1_2_research/left/ph_distal.stl" scale="0.001 0.001 0.001"/>
      </geometry>
      <material name="qbhand/palm"/>
    </visual>
    <collision>
      <origin rpy="0 0 0" xyz="0 0 0"/>
      <geometry>
        <mesh filename="package://softhands_description/meshes/v1_2_research/left/ph_distal.stl" scale="0.001 0.001 0.001"/>
      </geometry>
    </collision>
  </link>
  <!-- GAZEBO REF -->
  <gazebo reference="left_hand_v1_2_research_little_distal_link">
    <material>Gazebo/Grey</material>
    <selfCollide>0</selfCollide>
  </gazebo>
  <!-- GAZEBO REF -->
  <gazebo reference="left_hand_v1_2_research_little_distal_joint">
    <implicitSpringDamper>true</implicitSpringDamper>
    <springStiffness>0.4</springStiffness>
    <springReference>0</springReference>
  </gazebo>
  <!-- GAZEBO REF -->
  <gazebo reference="left_hand_v1_2_research_little_distal_virtual_joint">
    <implicitSpringDamper>true</implicitSpringDamper>
    <springStiffness>0.4</springStiffness>
    <springReference>0</springReference>
  </gazebo>
  <gazebo>
    <plugin filename="libsofthand_mimic_plugin.so" name="synergy_plugin">
      <namespace>right_hand_v1_2_research</namespace>
      <operation_mode>0</operation_mode>
      <spring_k>5</spring_k>
      <wide>False</wide>
      <r_finger>0.0033</r_finger>
      <R_pulley>0.0053</R_pulley>
      <n_param>0.058</n_param>
      <synS_thumb_j1>3</synS_thumb_j1>
      <synS_thumb_j2>1.2</synS_thumb_j2>
      <synS_thumb_j3>1.2</synS_thumb_j3>
      <k_thumb_j1>0.8</k_thumb_j1>
      <k_thumb_j2>0.8</k_thumb_j2>
      <k_thumb_j3>0.8</k_thumb_j3>
      <synS_index_j1>-0.3</synS_index_j1>
      <synS_index_j2>1.57</synS_index_j2>
      <synS_index_j3>1.25</synS_index_j3>
      <synS_index_j4>0.8</synS_index_j4>
      <k_index_j1>0.15</k_index_j1>
      <k_index_j2>0.5</k_index_j2>
      <k_index_j3>0.5</k_index_j3>
      <k_index_j4>0.5</k_index_j4>
      <synS_middle_j1>0</synS_middle_j1>
      <synS_middle_j2>1.57</synS_middle_j2>
      <synS_middle_j3>1.25</synS_middle_j3>
      <synS_middle_j4>1.25</synS_middle_j4>
      <k_middle_j1>0.15</k_middle_j1>
      <k_middle_j2>0.5</k_middle_j2>
      <k_middle_j3>0.5</k_middle_j3>
      <k_middle_j4>0.5</k_middle_j4>
      <synS_ring_j1>0</synS_ring_j1>
      <synS_ring_j2>1.57</synS_ring_j2>
      <synS_ring_j3>1.0</synS_ring_j3>
      <synS_ring_j4>1.0</synS_ring_j4>
      <k_ring_j1>0.15</k_ring_j1>
      <k_ring_j2>0.5</k_ring_j2>
      <k_ring_j3>0.5</k_ring_j3>
      <k_ring_j4>0.5</k_ring_j4>
      <synS_little_j1>0.1</synS_little_j1>
      <synS_little_j2>1.57</synS_little_j2>
      <synS_little_j3>1.25</synS_little_j3>
      <synS_little_j4>1.0</synS_little_j4>
      <k_little_j1>0.15</k_little_j1>
      <k_little_j2>0.5</k_little_j2>
      <k_little_j3>0.5</k_little_j3>
      <k_little_j4>0.5</k_little_j4>
      <!-- Palm thumb -->
      <synS_palm_j1>1.57</synS_palm_j1>
      <k_palm_j1>0.5</k_palm_j1>
      <k_palm_j1_mimic>0.5</k_palm_j1_mimic>
      <!-- Palm little -->
      <synS_palm_j2>1.57</synS_palm_j2>
      <k_palm_j2>0.5</k_palm_j2>
      <k_palm_j2_mimic>0.5</k_palm_j2_mimic>
    </plugin>
  </gazebo>
  <!-- World to palm base -->
  <joint name="right_hand_v1_2_research_iso_joint" type="fixed">
    <parent link="arm_2_7"/>
    <child link="right_hand_v1_2_research_iso_link"/>
    <origin rpy="0 0 3.14" xyz="0 0.0 0.00"/>
  </joint>
  <link name="right_hand_v1_2_research_iso_link">
    <inertial>
      <mass value="0.205"/>
      <origin rpy="0 0 0" xyz="0.0 7.8738498e-04 1.5878899e-02"/>
      <inertia ixx="0.00012506929" ixy="0.0" ixz="0.0" iyy="0.0001338779" iyz="0.0" izz="0.00019218394"/>
    </inertial>
    <visual>
      <origin rpy="0 0 0" xyz="0 0 0"/>
      <geometry>
        <mesh filename="package://softhands_description/meshes/v1_2_research/right/flange_iso_04.stl" scale="0.001 0.001 0.001"/>
      </geometry>
      <material name="qbhand/base"/>
    </visual>
    <collision>
      <origin rpy="0 0 0" xyz="0 0 0"/>
      <geometry>
        <mesh filename="package://softhands_description/meshes/v1_2_research/right/flange_iso_04.stl" scale="0.001 0.001 0.001"/>
      </geometry>
    </collision>
  </link>
  <gazebo reference="right_hand_v1_2_research_iso_link">
    <material>Gazebo/Grey</material>
    <selfCollide>0</selfCollide>
  </gazebo>
  <!-- Fake joint and link for grasping -->
  <joint name="right_hand_v1_2_research_grasp_joint" type="fixed">
    <origin rpy="0 0 1.57" xyz="-0.06 0.03 0.16"/>
    <parent link="right_hand_v1_2_research_iso_link"/>
    <child link="right_hand_v1_2_research_grasp_link"/>
  </joint>
  <link name="right_hand_v1_2_research_grasp_link"/>
  <joint name="right_hand_v1_2_research_palm_joint" type="fixed">
    <origin rpy="1.57 0 0" xyz="-0.0045 0.0145 0.144"/>
    <parent link="right_hand_v1_2_research_iso_link"/>
    <child link="right_hand_v1_2_research_palm_link"/>
  </joint>
  <link name="right_hand_v1_2_research_palm_link">
    <inertial>
      <origin rpy="0 0 0" xyz="0.0030 -0.0449 0.0135"/>
      <mass value="0.45"/>
      <inertia ixx="0.00045" ixy="0.0" ixz="0.0" iyy="0.00025" iyz="0.0" izz="0.0006"/>
    </inertial>
    <visual>
      <origin rpy="0 0 0" xyz="0 0 0"/>
      <geometry>
        <mesh filename="package://softhands_description/meshes/v1_2_research/right/palm_pinch.stl" scale="0.001 0.001 0.001"/>
      </geometry>
      <material name="qbhand/palm"/>
    </visual>
    <collision>
      <origin rpy="0 0 0" xyz="0 0 0"/>
      <geometry>
        <mesh filename="package://softhands_description/meshes/v1_2_research/right/palm_pinch.stl" scale="0.001 0.001 0.001"/>
      </geometry>
    </collision>
  </link>
  <gazebo reference="right_hand_v1_2_research_palm_link">
    <material>Gazebo/Grey</material>
    <selfCollide>0</selfCollide>
  </gazebo>
  <!-- Proximal JOINT -->
  <joint name="right_hand_v1_2_research_thumb_knuckle_joint" type="fixed">
    <origin rpy="-1.57 3.14 0.0" xyz="-0.044 -0.0465 -0.002"/>
    <parent link="right_hand_v1_2_research_palm_link"/>
    <child link="right_hand_v1_2_research_thumb_knuckle_link"/>
    <axis xyz="0 0 -1"/>
    <limit effort="30" lower="0.0" upper="1.57" velocity="10.0"/>
    <dynamics damping="3e-2" friction="0.0"/>
  </joint>
  <!-- LINK -->
  <link name="right_hand_v1_2_research_thumb_knuckle_link">
    <inertial>
      <origin rpy="0 0 0" xyz="1.3071561e-02 -0.002734634 6.4090487e-04"/>
      <mass value="0.01"/>
      <inertia ixx="3.5865978e-07" ixy="2.0944224e-07" ixz="-6.8657569e-08" iyy="1.3885564e-06" iyz="3.2170608e-08" izz="1.3571203e-06"/>
    </inertial>
    <visual>
      <origin rpy="0 0 0" xyz="0 0 0"/>
      <geometry>
        <mesh filename="package://softhands_description/meshes/v1_2_research/right/ph_thumb.stl" scale="0.001 0.001 0.001"/>
      </geometry>
      <material name="qbhand/knuckle"/>
    </visual>
    <collision>
      <origin rpy="0 0 0" xyz="0 0 0"/>
      <geometry>
        <mesh filename="package://softhands_description/meshes/v1_2_research/right/ph_thumb.stl" scale="0.001 0.001 0.001"/>
      </geometry>
    </collision>
  </link>
  <!-- GAZEBO REF -->
  <gazebo reference="right_hand_v1_2_research_thumb_knuckle_link">
    <material>Gazebo/Grey</material>
    <selfCollide>0</selfCollide>
  </gazebo>
  <!-- GAZEBO REF -->
  <gazebo reference="right_hand_v1_2_research_thumb_knuckle_joint">
    <implicitSpringDamper>true</implicitSpringDamper>
    <springStiffness>0.4</springStiffness>
    <springReference>0</springReference>
  </gazebo>
  <!-- Inner VIRTUAL JOINT -->
  <joint name="right_hand_v1_2_research_thumb_proximal_virtual_joint" type="fixed">
    <axis xyz="0 0 -1"/>
    <origin rpy="-1.1415 0.0 0.0" xyz="0.0255 -0.0038 -0.00012"/>
    <parent link="right_hand_v1_2_research_thumb_knuckle_link"/>
    <child link="right_hand_v1_2_research_thumb_proximal_virtual_link"/>
    <limit effort="30" lower="0.0" upper="0.785398" velocity="10.0"/>
    <dynamics damping="3e-2" friction="0.0"/>
  </joint>
  <!-- VIRTUAL LINK -->
  <link name="right_hand_v1_2_research_thumb_proximal_virtual_link">
    <inertial>
      <origin rpy="0 0 0" xyz="0 0 0"/>
      <mass value="0.0063"/>
      <inertia ixx="1.8024201e-07" ixy="5.756798e-09" ixz="0.0" iyy="2.3516266e-07" iyz="0.0" izz="2.691504e-07"/>
    </inertial>
  </link>
  <!-- Outer JOINT -->
  <joint name="right_hand_v1_2_research_thumb_proximal_joint" type="fixed">
    <axis xyz="0 0 -1"/>
    <origin rpy="0 0 0" xyz="0.013 0 0"/>
    <parent link="right_hand_v1_2_research_thumb_proximal_virtual_link"/>
    <child link="right_hand_v1_2_research_thumb_proximal_link"/>
    <limit effort="30" lower="0.0" upper="0.785398" velocity="10.0"/>
    <dynamics damping="3e-2" friction="0.0"/>
  </joint>
  <!-- LINK -->
  <link name="right_hand_v1_2_research_thumb_proximal_link">
    <inertial>
      <mass value="0.0063"/>
      <inertia ixx="1.8024201e-07" ixy="5.756798e-09" ixz="0.0" iyy="2.3516266e-07" iyz="0.0" izz="2.691504e-07"/>
      <origin rpy="0 0 0" xyz="4.7601567e-03 -1.3786947e-03 0.0"/>
    </inertial>
    <visual>
      <origin rpy="0 0 0" xyz="0 0 0"/>
      <geometry>
        <mesh filename="package://softhands_description/meshes/v1_2_research/right/ph_short.stl" scale="0.001 0.001 0.001"/>
      </geometry>
      <material name="qbhand/palm"/>
    </visual>
    <collision>
      <origin rpy="0 0 0" xyz="0 0 0"/>
      <geometry>
        <mesh filename="package://softhands_description/meshes/v1_2_research/right/ph_short.stl" scale="0.001 0.001 0.001"/>
      </geometry>
    </collision>
  </link>
  <!-- GAZEBO REF -->
  <gazebo reference="right_hand_v1_2_research_thumb_proximal_link">
    <material>Gazebo/Grey</material>
    <selfCollide>0</selfCollide>
  </gazebo>
  <!-- GAZEBO REF -->
  <gazebo reference="right_hand_v1_2_research_thumb_proximal_joint">
    <implicitSpringDamper>true</implicitSpringDamper>
    <springStiffness>0.4</springStiffness>
    <springReference>0</springReference>
  </gazebo>
  <!-- GAZEBO REF -->
  <gazebo reference="right_hand_v1_2_research_thumb_proximal_virtual_joint">
    <implicitSpringDamper>true</implicitSpringDamper>
    <springStiffness>0.4</springStiffness>
    <springReference>0</springReference>
  </gazebo>
  <!-- Inner VIRTUAL JOINT -->
  <joint name="right_hand_v1_2_research_thumb_distal_virtual_joint" type="fixed">
    <axis xyz="0 0 -1"/>
    <origin rpy="0 0 0" xyz="0.009 0 0"/>
    <parent link="right_hand_v1_2_research_thumb_proximal_link"/>
    <child link="right_hand_v1_2_research_thumb_distal_virtual_link"/>
    <limit effort="30" lower="0.0" upper="0.785398" velocity="10.0"/>
    <dynamics damping="3e-2" friction="0.0"/>
  </joint>
  <!-- VIRTUAL LINK -->
  <link name="right_hand_v1_2_research_thumb_distal_virtual_link">
    <inertial>
      <origin rpy="0 0 0" xyz="0 0 0"/>
      <mass value="0.009"/>
      <inertia ixx="2.6586142e-07" ixy="1.2416847e-08" ixz="0.0" iyy="5.9935767e-07" iyz="0.0" izz="6.6781963e-07"/>
    </inertial>
  </link>
  <!-- Outer JOINT -->
  <joint name="right_hand_v1_2_research_thumb_distal_joint" type="fixed">
    <axis xyz="0 0 -1"/>
    <origin rpy="0 0 0" xyz="0.013 0 0"/>
    <parent link="right_hand_v1_2_research_thumb_distal_virtual_link"/>
    <child link="right_hand_v1_2_research_thumb_distal_link"/>
    <limit effort="30" lower="0.0" upper="0.785398" velocity="10.0"/>
    <dynamics damping="3e-2" friction="0.0"/>
  </joint>
  <!-- LINK -->
  <link name="right_hand_v1_2_research_thumb_distal_link">
    <inertial>
      <mass value="0.009"/>
      <inertia ixx="2.6586142e-07" ixy="1.2416847e-08" ixz="0.0" iyy="5.9935767e-07" iyz="0.0" izz="6.6781963e-07"/>
      <origin rpy="0 0 0" xyz="8.8025467e-03 -1.7219289e-03 0.0"/>
    </inertial>
    <visual>
      <origin rpy="0 0 0" xyz="0 0 0"/>
      <geometry>
        <mesh filename="package://softhands_description/meshes/v1_2_research/right/ph_distal.stl" scale="0.001 0.001 0.001"/>
      </geometry>
      <material name="qbhand/palm"/>
    </visual>
    <collision>
      <origin rpy="0 0 0" xyz="0 0 0"/>
      <geometry>
        <mesh filename="package://softhands_description/meshes/v1_2_research/right/ph_distal.stl" scale="0.001 0.001 0.001"/>
      </geometry>
    </collision>
  </link>
  <!-- GAZEBO REF -->
  <gazebo reference="right_hand_v1_2_research_thumb_distal_link">
    <material>Gazebo/Grey</material>
    <selfCollide>0</selfCollide>
  </gazebo>
  <!-- GAZEBO REF -->
  <gazebo reference="right_hand_v1_2_research_thumb_distal_joint">
    <implicitSpringDamper>true</implicitSpringDamper>
    <springStiffness>0.4</springStiffness>
    <springReference>0</springReference>
  </gazebo>
  <!-- GAZEBO REF -->
  <gazebo reference="right_hand_v1_2_research_thumb_distal_virtual_joint">
    <implicitSpringDamper>true</implicitSpringDamper>
    <springStiffness>0.4</springStiffness>
    <springReference>0</springReference>
  </gazebo>
  <!-- Proximal JOINT -->
  <joint name="right_hand_v1_2_research_index_knuckle_joint" type="fixed">
    <origin rpy="0 0 1.57" xyz="-0.02 -0.007 0.014"/>
    <parent link="right_hand_v1_2_research_palm_link"/>
    <child link="right_hand_v1_2_research_index_knuckle_link"/>
    <axis xyz="0 0 -1"/>
    <limit effort="30" lower="-0.524" upper="0.524" velocity="10.0"/>
    <dynamics damping="3e-2" friction="0.0"/>
  </joint>
  <!-- LINK -->
  <link name="right_hand_v1_2_research_index_knuckle_link">
    <inertial>
      <origin rpy="0 0 0" xyz="4.2753603e-04  0.0 -1.4321738e-03"/>
      <mass value="0.0095"/>
      <inertia ixx="6.4337303e-07" ixy="0.0" ixz="-3.9373913e-08" iyy="1.1253771e-06" iyz="0.0" izz="7.2336948e-07"/>
    </inertial>
    <visual>
      <origin rpy="0 0 0" xyz="0 0 0"/>
      <geometry>
        <mesh filename="package://softhands_description/meshes/v1_2_research/right/ph_knuckle.stl" scale="0.001 0.001 0.001"/>
      </geometry>
      <material name="qbhand/palm"/>
    </visual>
    <collision>
      <origin rpy="0 0 0" xyz="0 0 0"/>
      <geometry>
        <mesh filename="package://softhands_description/meshes/v1_2_research/right/ph_knuckle.stl" scale="0.001 0.001 0.001"/>
      </geometry>
    </collision>
  </link>
  <!-- GAZEBO REF -->
  <gazebo reference="right_hand_v1_2_research_index_knuckle_link">
    <material>Gazebo/Grey</material>
    <selfCollide>0</selfCollide>
  </gazebo>
  <!-- GAZEBO REF -->
  <gazebo reference="right_hand_v1_2_research_index_knuckle_joint">
    <implicitSpringDamper>true</implicitSpringDamper>
    <springStiffness>0.8</springStiffness>
    <springReference>0</springReference>
  </gazebo>
  <!-- Inner VIRTUAL JOINT -->
  <joint name="right_hand_v1_2_research_index_proximal_virtual_joint" type="fixed">
    <axis xyz="0 0 -1"/>
    <origin rpy="1.57 0 0" xyz="0.009 0 0"/>
    <parent link="right_hand_v1_2_research_index_knuckle_link"/>
    <child link="right_hand_v1_2_research_index_proximal_virtual_link"/>
    <limit effort="30" lower="0.0" upper="0.785398" velocity="10.0"/>
    <dynamics damping="3e-2" friction="0.0"/>
  </joint>
  <!-- VIRTUAL LINK -->
  <link name="right_hand_v1_2_research_index_proximal_virtual_link">
    <inertial>
      <origin rpy="0 0 0" xyz="0 0 0"/>
      <mass value="0.009"/>
      <inertia ixx="2.2722068e-07" ixy="1.1586053e-08" ixz="0.0" iyy="5.5947233e-07" iyz="0.0" izz="5.9562195e-07"/>
    </inertial>
  </link>
  <!-- Outer JOINT -->
  <joint name="right_hand_v1_2_research_index_proximal_joint" type="fixed">
    <axis xyz="0 0 -1"/>
    <origin rpy="0.0 0 0" xyz="0.013 0 0"/>
    <parent link="right_hand_v1_2_research_index_proximal_virtual_link"/>
    <child link="right_hand_v1_2_research_index_proximal_link"/>
    <limit effort="30" lower="0.0" upper="0.785398" velocity="10.0"/>
    <dynamics damping="3e-2" friction="0.0"/>
  </joint>
  <!-- LINK -->
  <link name="right_hand_v1_2_research_index_proximal_link">
    <inertial>
      <mass value="0.009"/>
      <inertia ixx="2.2722068e-07" ixy="1.1586053e-08" ixz="0.0" iyy="5.5947233e-07" iyz="0.0" izz="5.9562195e-07"/>
      <origin rpy="0 0 0" xyz="8.7707437e-03 -1.7863138e-03 0.0"/>
    </inertial>
    <visual>
      <origin rpy="0 0 0" xyz="0 0 0"/>
      <geometry>
        <mesh filename="package://softhands_description/meshes/v1_2_research/right/ph_medium.stl" scale="0.001 0.001 0.001"/>
      </geometry>
      <material name="qbhand/palm"/>
    </visual>
    <collision>
      <origin rpy="0 0 0" xyz="0 0 0"/>
      <geometry>
        <mesh filename="package://softhands_description/meshes/v1_2_research/right/ph_medium.stl" scale="0.001 0.001 0.001"/>
      </geometry>
    </collision>
  </link>
  <!-- GAZEBO REF -->
  <gazebo reference="right_hand_v1_2_research_index_proximal_link">
    <material>Gazebo/Grey</material>
    <selfCollide>0</selfCollide>
  </gazebo>
  <!-- GAZEBO REF -->
  <gazebo reference="right_hand_v1_2_research_index_proximal_joint">
    <implicitSpringDamper>true</implicitSpringDamper>
    <springStiffness>0.4</springStiffness>
    <springReference>0</springReference>
  </gazebo>
  <!-- GAZEBO REF -->
  <gazebo reference="right_hand_v1_2_research_index_proximal_virtual_joint">
    <implicitSpringDamper>true</implicitSpringDamper>
    <springStiffness>0.4</springStiffness>
    <springReference>0</springReference>
  </gazebo>
  <!-- Inner VIRTUAL JOINT -->
  <joint name="right_hand_v1_2_research_index_middle_virtual_joint" type="fixed">
    <axis xyz="0 0 -1"/>
    <origin rpy="0.0 0.0 0.0" xyz="0.013 0 0 "/>
    <parent link="right_hand_v1_2_research_index_proximal_link"/>
    <child link="right_hand_v1_2_research_index_middle_virtual_link"/>
    <limit effort="30" lower="0.0" upper="0.785398" velocity="10.0"/>
    <dynamics damping="3e-2" friction="0.0"/>
  </joint>
  <!-- VIRTUAL LINK -->
  <link name="right_hand_v1_2_research_index_middle_virtual_link">
    <inertial>
      <origin rpy="0 0 0" xyz="0 0 0"/>
      <mass value="0.0063"/>
      <inertia ixx="1.8024201e-07" ixy="5.756798e-09" ixz="0.0" iyy="2.3516266e-07" iyz="0.0" izz="2.691504e-07"/>
    </inertial>
  </link>
  <!-- Outer JOINT -->
  <joint name="right_hand_v1_2_research_index_middle_joint" type="fixed">
    <axis xyz="0 0 -1"/>
    <origin rpy="0 0 0" xyz="0.017 0 0"/>
    <parent link="right_hand_v1_2_research_index_middle_virtual_link"/>
    <child link="right_hand_v1_2_research_index_middle_link"/>
    <limit effort="30" lower="0.0" upper="0.785398" velocity="10.0"/>
    <dynamics damping="3e-2" friction="0.0"/>
  </joint>
  <!-- LINK -->
  <link name="right_hand_v1_2_research_index_middle_link">
    <inertial>
      <mass value="0.0063"/>
      <inertia ixx="1.8024201e-07" ixy="5.756798e-09" ixz="0.0" iyy="2.3516266e-07" iyz="0.0" izz="2.691504e-07"/>
      <origin rpy="0 0 0" xyz="4.7601567e-03 -1.3786947e-03 0.0"/>
    </inertial>
    <visual>
      <origin rpy="0 0 0" xyz="0 0 0"/>
      <geometry>
        <mesh filename="package://softhands_description/meshes/v1_2_research/right/ph_short.stl" scale="0.001 0.001 0.001"/>
      </geometry>
      <material name="qbhand/palm"/>
    </visual>
    <collision>
      <origin rpy="0 0 0" xyz="0 0 0"/>
      <geometry>
        <mesh filename="package://softhands_description/meshes/v1_2_research/right/ph_short.stl" scale="0.001 0.001 0.001"/>
      </geometry>
    </collision>
  </link>
  <!-- GAZEBO REF -->
  <gazebo reference="right_hand_v1_2_research_index_middle_link">
    <material>Gazebo/Grey</material>
    <selfCollide>0</selfCollide>
  </gazebo>
  <!-- GAZEBO REF -->
  <gazebo reference="right_hand_v1_2_research_index_middle_joint">
    <implicitSpringDamper>true</implicitSpringDamper>
    <springStiffness>0.4</springStiffness>
    <springReference>0</springReference>
  </gazebo>
  <!-- GAZEBO REF -->
  <gazebo reference="right_hand_v1_2_research_index_middle_virtual_joint">
    <implicitSpringDamper>true</implicitSpringDamper>
    <springStiffness>0.4</springStiffness>
    <springReference>0</springReference>
  </gazebo>
  <!-- Inner VIRTUAL JOINT -->
  <joint name="right_hand_v1_2_research_index_distal_virtual_joint" type="fixed">
    <axis xyz="0 0 -1"/>
    <origin rpy="0 0 0" xyz="0.009 0 0"/>
    <parent link="right_hand_v1_2_research_index_middle_link"/>
    <child link="right_hand_v1_2_research_index_distal_virtual_link"/>
    <limit effort="30" lower="0.0" upper="0.785398" velocity="10.0"/>
    <dynamics damping="3e-2" friction="0.0"/>
  </joint>
  <!-- VIRTUAL LINK -->
  <link name="right_hand_v1_2_research_index_distal_virtual_link">
    <inertial>
      <origin rpy="0 0 0" xyz="0 0 0"/>
      <mass value="0.009"/>
      <inertia ixx="2.6586142e-07" ixy="1.2416847e-08" ixz="0.0" iyy="5.9935767e-07" iyz="0.0" izz="6.6781963e-07"/>
    </inertial>
  </link>
  <!-- Outer JOINT -->
  <joint name="right_hand_v1_2_research_index_distal_joint" type="fixed">
    <axis xyz="0 0 -1"/>
    <origin rpy="0 0 0" xyz="0.013 0 0"/>
    <parent link="right_hand_v1_2_research_index_distal_virtual_link"/>
    <child link="right_hand_v1_2_research_index_distal_link"/>
    <limit effort="30" lower="0.0" upper="0.785398" velocity="10.0"/>
    <dynamics damping="3e-2" friction="0.0"/>
  </joint>
  <!-- LINK -->
  <link name="right_hand_v1_2_research_index_distal_link">
    <inertial>
      <mass value="0.009"/>
      <inertia ixx="2.6586142e-07" ixy="1.2416847e-08" ixz="0.0" iyy="5.9935767e-07" iyz="0.0" izz="6.6781963e-07"/>
      <origin rpy="0 0 0" xyz="8.8025467e-03 -1.7219289e-03 0.0"/>
    </inertial>
    <visual>
      <origin rpy="0 0 0" xyz="0 0 0"/>
      <geometry>
        <mesh filename="package://softhands_description/meshes/v1_2_research/right/ph_distal.stl" scale="0.001 0.001 0.001"/>
      </geometry>
      <material name="qbhand/palm"/>
    </visual>
    <collision>
      <origin rpy="0 0 0" xyz="0 0 0"/>
      <geometry>
        <mesh filename="package://softhands_description/meshes/v1_2_research/right/ph_distal.stl" scale="0.001 0.001 0.001"/>
      </geometry>
    </collision>
  </link>
  <!-- GAZEBO REF -->
  <gazebo reference="right_hand_v1_2_research_index_distal_link">
    <material>Gazebo/Grey</material>
    <selfCollide>0</selfCollide>
  </gazebo>
  <!-- GAZEBO REF -->
  <gazebo reference="right_hand_v1_2_research_index_distal_joint">
    <implicitSpringDamper>true</implicitSpringDamper>
    <springStiffness>0.4</springStiffness>
    <springReference>0</springReference>
  </gazebo>
  <!-- GAZEBO REF -->
  <gazebo reference="right_hand_v1_2_research_index_distal_virtual_joint">
    <implicitSpringDamper>true</implicitSpringDamper>
    <springStiffness>0.4</springStiffness>
    <springReference>0</springReference>
  </gazebo>
  <!-- Proximal JOINT -->
  <joint name="right_hand_v1_2_research_middle_knuckle_joint" type="fixed">
    <origin rpy="0 0 1.57" xyz="0 0 0.014"/>
    <parent link="right_hand_v1_2_research_palm_link"/>
    <child link="right_hand_v1_2_research_middle_knuckle_link"/>
    <axis xyz="0 0 -1"/>
    <limit effort="30" lower="-0.524" upper="0.524" velocity="10.0"/>
    <dynamics damping="3e-2" friction="0.0"/>
  </joint>
  <!-- LINK -->
  <link name="right_hand_v1_2_research_middle_knuckle_link">
    <inertial>
      <origin rpy="0 0 0" xyz="4.2753603e-04  0.0 -1.4321738e-03"/>
      <mass value="0.0095"/>
      <inertia ixx="6.4337303e-07" ixy="0.0" ixz="-3.9373913e-08" iyy="1.1253771e-06" iyz="0.0" izz="7.2336948e-07"/>
    </inertial>
    <visual>
      <origin rpy="0 0 0" xyz="0 0 0"/>
      <geometry>
        <mesh filename="package://softhands_description/meshes/v1_2_research/right/ph_knuckle.stl" scale="0.001 0.001 0.001"/>
      </geometry>
      <material name="qbhand/palm"/>
    </visual>
    <collision>
      <origin rpy="0 0 0" xyz="0 0 0"/>
      <geometry>
        <mesh filename="package://softhands_description/meshes/v1_2_research/right/ph_knuckle.stl" scale="0.001 0.001 0.001"/>
      </geometry>
    </collision>
  </link>
  <!-- GAZEBO REF -->
  <gazebo reference="right_hand_v1_2_research_middle_knuckle_link">
    <material>Gazebo/Grey</material>
    <selfCollide>0</selfCollide>
  </gazebo>
  <!-- GAZEBO REF -->
  <gazebo reference="right_hand_v1_2_research_middle_knuckle_joint">
    <implicitSpringDamper>true</implicitSpringDamper>
    <springStiffness>0.8</springStiffness>
    <springReference>0</springReference>
  </gazebo>
  <!-- Inner VIRTUAL JOINT -->
  <joint name="right_hand_v1_2_research_middle_proximal_virtual_joint" type="fixed">
    <axis xyz="0 0 -1"/>
    <origin rpy="1.57 0 0" xyz="0.009 0 0"/>
    <parent link="right_hand_v1_2_research_middle_knuckle_link"/>
    <child link="right_hand_v1_2_research_middle_proximal_virtual_link"/>
    <limit effort="30" lower="0.0" upper="0.785398" velocity="10.0"/>
    <dynamics damping="3e-2" friction="0.0"/>
  </joint>
  <!-- VIRTUAL LINK -->
  <link name="right_hand_v1_2_research_middle_proximal_virtual_link">
    <inertial>
      <origin rpy="0 0 0" xyz="0 0 0"/>
      <mass value="0.009"/>
      <inertia ixx="2.2722068e-07" ixy="1.1586053e-08" ixz="0.0" iyy="5.5947233e-07" iyz="0.0" izz="5.9562195e-07"/>
    </inertial>
  </link>
  <!-- Outer JOINT -->
  <joint name="right_hand_v1_2_research_middle_proximal_joint" type="fixed">
    <axis xyz="0 0 -1"/>
    <origin rpy="0.0 0 0" xyz="0.013 0 0"/>
    <parent link="right_hand_v1_2_research_middle_proximal_virtual_link"/>
    <child link="right_hand_v1_2_research_middle_proximal_link"/>
    <limit effort="30" lower="0.0" upper="0.785398" velocity="10.0"/>
    <dynamics damping="3e-2" friction="0.0"/>
  </joint>
  <!-- LINK -->
  <link name="right_hand_v1_2_research_middle_proximal_link">
    <inertial>
      <mass value="0.009"/>
      <inertia ixx="2.2722068e-07" ixy="1.1586053e-08" ixz="0.0" iyy="5.5947233e-07" iyz="0.0" izz="5.9562195e-07"/>
      <origin rpy="0 0 0" xyz="8.7707437e-03 -1.7863138e-03 0.0"/>
    </inertial>
    <visual>
      <origin rpy="0 0 0" xyz="0 0 0"/>
      <geometry>
        <mesh filename="package://softhands_description/meshes/v1_2_research/right/ph_medium.stl" scale="0.001 0.001 0.001"/>
      </geometry>
      <material name="qbhand/palm"/>
    </visual>
    <collision>
      <origin rpy="0 0 0" xyz="0 0 0"/>
      <geometry>
        <mesh filename="package://softhands_description/meshes/v1_2_research/right/ph_medium.stl" scale="0.001 0.001 0.001"/>
      </geometry>
    </collision>
  </link>
  <!-- GAZEBO REF -->
  <gazebo reference="right_hand_v1_2_research_middle_proximal_link">
    <material>Gazebo/Grey</material>
    <selfCollide>0</selfCollide>
  </gazebo>
  <!-- GAZEBO REF -->
  <gazebo reference="right_hand_v1_2_research_middle_proximal_joint">
    <implicitSpringDamper>true</implicitSpringDamper>
    <springStiffness>0.4</springStiffness>
    <springReference>0</springReference>
  </gazebo>
  <!-- GAZEBO REF -->
  <gazebo reference="right_hand_v1_2_research_middle_proximal_virtual_joint">
    <implicitSpringDamper>true</implicitSpringDamper>
    <springStiffness>0.4</springStiffness>
    <springReference>0</springReference>
  </gazebo>
  <!-- Inner VIRTUAL JOINT -->
  <joint name="right_hand_v1_2_research_middle_middle_virtual_joint" type="fixed">
    <axis xyz="0 0 -1"/>
    <origin rpy="0.0 0.0 0.0" xyz="0.013 0 0 "/>
    <parent link="right_hand_v1_2_research_middle_proximal_link"/>
    <child link="right_hand_v1_2_research_middle_middle_virtual_link"/>
    <limit effort="30" lower="0.0" upper="0.785398" velocity="10.0"/>
    <dynamics damping="3e-2" friction="0.0"/>
  </joint>
  <!-- VIRTUAL LINK -->
  <link name="right_hand_v1_2_research_middle_middle_virtual_link">
    <inertial>
      <origin rpy="0 0 0" xyz="0 0 0"/>
      <mass value="0.0063"/>
      <inertia ixx="1.8024201e-07" ixy="5.756798e-09" ixz="0.0" iyy="2.3516266e-07" iyz="0.0" izz="2.691504e-07"/>
    </inertial>
  </link>
  <!-- Outer JOINT -->
  <joint name="right_hand_v1_2_research_middle_middle_joint" type="fixed">
    <axis xyz="0 0 -1"/>
    <origin rpy="0 0 0" xyz="0.017 0 0"/>
    <parent link="right_hand_v1_2_research_middle_middle_virtual_link"/>
    <child link="right_hand_v1_2_research_middle_middle_link"/>
    <limit effort="30" lower="0.0" upper="0.785398" velocity="10.0"/>
    <dynamics damping="3e-2" friction="0.0"/>
  </joint>
  <!-- LINK -->
  <link name="right_hand_v1_2_research_middle_middle_link">
    <inertial>
      <mass value="0.0063"/>
      <inertia ixx="1.8024201e-07" ixy="5.756798e-09" ixz="0.0" iyy="2.3516266e-07" iyz="0.0" izz="2.691504e-07"/>
      <origin rpy="0 0 0" xyz="4.7601567e-03 -1.3786947e-03 0.0"/>
    </inertial>
    <visual>
      <origin rpy="0 0 0" xyz="0 0 0"/>
      <geometry>
        <mesh filename="package://softhands_description/meshes/v1_2_research/right/ph_short.stl" scale="0.001 0.001 0.001"/>
      </geometry>
      <material name="qbhand/palm"/>
    </visual>
    <collision>
      <origin rpy="0 0 0" xyz="0 0 0"/>
      <geometry>
        <mesh filename="package://softhands_description/meshes/v1_2_research/right/ph_short.stl" scale="0.001 0.001 0.001"/>
      </geometry>
    </collision>
  </link>
  <!-- GAZEBO REF -->
  <gazebo reference="right_hand_v1_2_research_middle_middle_link">
    <material>Gazebo/Grey</material>
    <selfCollide>0</selfCollide>
  </gazebo>
  <!-- GAZEBO REF -->
  <gazebo reference="right_hand_v1_2_research_middle_middle_joint">
    <implicitSpringDamper>true</implicitSpringDamper>
    <springStiffness>0.4</springStiffness>
    <springReference>0</springReference>
  </gazebo>
  <!-- GAZEBO REF -->
  <gazebo reference="right_hand_v1_2_research_middle_middle_virtual_joint">
    <implicitSpringDamper>true</implicitSpringDamper>
    <springStiffness>0.4</springStiffness>
    <springReference>0</springReference>
  </gazebo>
  <!-- Inner VIRTUAL JOINT -->
  <joint name="right_hand_v1_2_research_middle_distal_virtual_joint" type="fixed">
    <axis xyz="0 0 -1"/>
    <origin rpy="0 0 0" xyz="0.009 0 0"/>
    <parent link="right_hand_v1_2_research_middle_middle_link"/>
    <child link="right_hand_v1_2_research_middle_distal_virtual_link"/>
    <limit effort="30" lower="0.0" upper="0.785398" velocity="10.0"/>
    <dynamics damping="3e-2" friction="0.0"/>
  </joint>
  <!-- VIRTUAL LINK -->
  <link name="right_hand_v1_2_research_middle_distal_virtual_link">
    <inertial>
      <origin rpy="0 0 0" xyz="0 0 0"/>
      <mass value="0.009"/>
      <inertia ixx="2.6586142e-07" ixy="1.2416847e-08" ixz="0.0" iyy="5.9935767e-07" iyz="0.0" izz="6.6781963e-07"/>
    </inertial>
  </link>
  <!-- Outer JOINT -->
  <joint name="right_hand_v1_2_research_middle_distal_joint" type="fixed">
    <axis xyz="0 0 -1"/>
    <origin rpy="0 0 0" xyz="0.013 0 0"/>
    <parent link="right_hand_v1_2_research_middle_distal_virtual_link"/>
    <child link="right_hand_v1_2_research_middle_distal_link"/>
    <limit effort="30" lower="0.0" upper="0.785398" velocity="10.0"/>
    <dynamics damping="3e-2" friction="0.0"/>
  </joint>
  <!-- LINK -->
  <link name="right_hand_v1_2_research_middle_distal_link">
    <inertial>
      <mass value="0.009"/>
      <inertia ixx="2.6586142e-07" ixy="1.2416847e-08" ixz="0.0" iyy="5.9935767e-07" iyz="0.0" izz="6.6781963e-07"/>
      <origin rpy="0 0 0" xyz="8.8025467e-03 -1.7219289e-03 0.0"/>
    </inertial>
    <visual>
      <origin rpy="0 0 0" xyz="0 0 0"/>
      <geometry>
        <mesh filename="package://softhands_description/meshes/v1_2_research/right/ph_distal.stl" scale="0.001 0.001 0.001"/>
      </geometry>
      <material name="qbhand/palm"/>
    </visual>
    <collision>
      <origin rpy="0 0 0" xyz="0 0 0"/>
      <geometry>
        <mesh filename="package://softhands_description/meshes/v1_2_research/right/ph_distal.stl" scale="0.001 0.001 0.001"/>
      </geometry>
    </collision>
  </link>
  <!-- GAZEBO REF -->
  <gazebo reference="right_hand_v1_2_research_middle_distal_link">
    <material>Gazebo/Grey</material>
    <selfCollide>0</selfCollide>
  </gazebo>
  <!-- GAZEBO REF -->
  <gazebo reference="right_hand_v1_2_research_middle_distal_joint">
    <implicitSpringDamper>true</implicitSpringDamper>
    <springStiffness>0.4</springStiffness>
    <springReference>0</springReference>
  </gazebo>
  <!-- GAZEBO REF -->
  <gazebo reference="right_hand_v1_2_research_middle_distal_virtual_joint">
    <implicitSpringDamper>true</implicitSpringDamper>
    <springStiffness>0.4</springStiffness>
    <springReference>0</springReference>
  </gazebo>
  <!-- Proximal JOINT -->
  <joint name="right_hand_v1_2_research_ring_knuckle_joint" type="fixed">
    <origin rpy="0 0 1.57" xyz="0.02 -0.007 0.014"/>
    <parent link="right_hand_v1_2_research_palm_link"/>
    <child link="right_hand_v1_2_research_ring_knuckle_link"/>
    <axis xyz="0 0 -1"/>
    <limit effort="30" lower="-0.524" upper="0.524" velocity="10.0"/>
    <dynamics damping="3e-2" friction="0.0"/>
  </joint>
  <!-- LINK -->
  <link name="right_hand_v1_2_research_ring_knuckle_link">
    <inertial>
      <origin rpy="0 0 0" xyz="4.2753603e-04  0.0 -1.4321738e-03"/>
      <mass value="0.0095"/>
      <inertia ixx="6.4337303e-07" ixy="0.0" ixz="-3.9373913e-08" iyy="1.1253771e-06" iyz="0.0" izz="7.2336948e-07"/>
    </inertial>
    <visual>
      <origin rpy="0 0 0" xyz="0 0 0"/>
      <geometry>
        <mesh filename="package://softhands_description/meshes/v1_2_research/right/ph_knuckle.stl" scale="0.001 0.001 0.001"/>
      </geometry>
      <material name="qbhand/palm"/>
    </visual>
    <collision>
      <origin rpy="0 0 0" xyz="0 0 0"/>
      <geometry>
        <mesh filename="package://softhands_description/meshes/v1_2_research/right/ph_knuckle.stl" scale="0.001 0.001 0.001"/>
      </geometry>
    </collision>
  </link>
  <!-- GAZEBO REF -->
  <gazebo reference="right_hand_v1_2_research_ring_knuckle_link">
    <material>Gazebo/Grey</material>
    <selfCollide>0</selfCollide>
  </gazebo>
  <!-- GAZEBO REF -->
  <gazebo reference="right_hand_v1_2_research_ring_knuckle_joint">
    <implicitSpringDamper>true</implicitSpringDamper>
    <springStiffness>0.8</springStiffness>
    <springReference>0</springReference>
  </gazebo>
  <!-- Inner VIRTUAL JOINT -->
  <joint name="right_hand_v1_2_research_ring_proximal_virtual_joint" type="fixed">
    <axis xyz="0 0 -1"/>
    <origin rpy="1.57 0 0" xyz="0.009 0 0"/>
    <parent link="right_hand_v1_2_research_ring_knuckle_link"/>
    <child link="right_hand_v1_2_research_ring_proximal_virtual_link"/>
    <limit effort="30" lower="0.0" upper="0.785398" velocity="10.0"/>
    <dynamics damping="3e-2" friction="0.0"/>
  </joint>
  <!-- VIRTUAL LINK -->
  <link name="right_hand_v1_2_research_ring_proximal_virtual_link">
    <inertial>
      <origin rpy="0 0 0" xyz="0 0 0"/>
      <mass value="0.009"/>
      <inertia ixx="2.2722068e-07" ixy="1.1586053e-08" ixz="0.0" iyy="5.5947233e-07" iyz="0.0" izz="5.9562195e-07"/>
    </inertial>
  </link>
  <!-- Outer JOINT -->
  <joint name="right_hand_v1_2_research_ring_proximal_joint" type="fixed">
    <axis xyz="0 0 -1"/>
    <origin rpy="0.0 0 0" xyz="0.013 0 0"/>
    <parent link="right_hand_v1_2_research_ring_proximal_virtual_link"/>
    <child link="right_hand_v1_2_research_ring_proximal_link"/>
    <limit effort="30" lower="0.0" upper="0.785398" velocity="10.0"/>
    <dynamics damping="3e-2" friction="0.0"/>
  </joint>
  <!-- LINK -->
  <link name="right_hand_v1_2_research_ring_proximal_link">
    <inertial>
      <mass value="0.009"/>
      <inertia ixx="2.2722068e-07" ixy="1.1586053e-08" ixz="0.0" iyy="5.5947233e-07" iyz="0.0" izz="5.9562195e-07"/>
      <origin rpy="0 0 0" xyz="8.7707437e-03 -1.7863138e-03 0.0"/>
    </inertial>
    <visual>
      <origin rpy="0 0 0" xyz="0 0 0"/>
      <geometry>
        <mesh filename="package://softhands_description/meshes/v1_2_research/right/ph_medium.stl" scale="0.001 0.001 0.001"/>
      </geometry>
      <material name="qbhand/palm"/>
    </visual>
    <collision>
      <origin rpy="0 0 0" xyz="0 0 0"/>
      <geometry>
        <mesh filename="package://softhands_description/meshes/v1_2_research/right/ph_medium.stl" scale="0.001 0.001 0.001"/>
      </geometry>
    </collision>
  </link>
  <!-- GAZEBO REF -->
  <gazebo reference="right_hand_v1_2_research_ring_proximal_link">
    <material>Gazebo/Grey</material>
    <selfCollide>0</selfCollide>
  </gazebo>
  <!-- GAZEBO REF -->
  <gazebo reference="right_hand_v1_2_research_ring_proximal_joint">
    <implicitSpringDamper>true</implicitSpringDamper>
    <springStiffness>0.4</springStiffness>
    <springReference>0</springReference>
  </gazebo>
  <!-- GAZEBO REF -->
  <gazebo reference="right_hand_v1_2_research_ring_proximal_virtual_joint">
    <implicitSpringDamper>true</implicitSpringDamper>
    <springStiffness>0.4</springStiffness>
    <springReference>0</springReference>
  </gazebo>
  <!-- Inner VIRTUAL JOINT -->
  <joint name="right_hand_v1_2_research_ring_middle_virtual_joint" type="fixed">
    <axis xyz="0 0 -1"/>
    <origin rpy="0.0 0.0 0.0" xyz="0.013 0 0 "/>
    <parent link="right_hand_v1_2_research_ring_proximal_link"/>
    <child link="right_hand_v1_2_research_ring_middle_virtual_link"/>
    <limit effort="30" lower="0.0" upper="0.785398" velocity="10.0"/>
    <dynamics damping="3e-2" friction="0.0"/>
  </joint>
  <!-- VIRTUAL LINK -->
  <link name="right_hand_v1_2_research_ring_middle_virtual_link">
    <inertial>
      <origin rpy="0 0 0" xyz="0 0 0"/>
      <mass value="0.0063"/>
      <inertia ixx="1.8024201e-07" ixy="5.756798e-09" ixz="0.0" iyy="2.3516266e-07" iyz="0.0" izz="2.691504e-07"/>
    </inertial>
  </link>
  <!-- Outer JOINT -->
  <joint name="right_hand_v1_2_research_ring_middle_joint" type="fixed">
    <axis xyz="0 0 -1"/>
    <origin rpy="0 0 0" xyz="0.017 0 0"/>
    <parent link="right_hand_v1_2_research_ring_middle_virtual_link"/>
    <child link="right_hand_v1_2_research_ring_middle_link"/>
    <limit effort="30" lower="0.0" upper="0.785398" velocity="10.0"/>
    <dynamics damping="3e-2" friction="0.0"/>
  </joint>
  <!-- LINK -->
  <link name="right_hand_v1_2_research_ring_middle_link">
    <inertial>
      <mass value="0.0063"/>
      <inertia ixx="1.8024201e-07" ixy="5.756798e-09" ixz="0.0" iyy="2.3516266e-07" iyz="0.0" izz="2.691504e-07"/>
      <origin rpy="0 0 0" xyz="4.7601567e-03 -1.3786947e-03 0.0"/>
    </inertial>
    <visual>
      <origin rpy="0 0 0" xyz="0 0 0"/>
      <geometry>
        <mesh filename="package://softhands_description/meshes/v1_2_research/right/ph_short.stl" scale="0.001 0.001 0.001"/>
      </geometry>
      <material name="qbhand/palm"/>
    </visual>
    <collision>
      <origin rpy="0 0 0" xyz="0 0 0"/>
      <geometry>
        <mesh filename="package://softhands_description/meshes/v1_2_research/right/ph_short.stl" scale="0.001 0.001 0.001"/>
      </geometry>
    </collision>
  </link>
  <!-- GAZEBO REF -->
  <gazebo reference="right_hand_v1_2_research_ring_middle_link">
    <material>Gazebo/Grey</material>
    <selfCollide>0</selfCollide>
  </gazebo>
  <!-- GAZEBO REF -->
  <gazebo reference="right_hand_v1_2_research_ring_middle_joint">
    <implicitSpringDamper>true</implicitSpringDamper>
    <springStiffness>0.4</springStiffness>
    <springReference>0</springReference>
  </gazebo>
  <!-- GAZEBO REF -->
  <gazebo reference="right_hand_v1_2_research_ring_middle_virtual_joint">
    <implicitSpringDamper>true</implicitSpringDamper>
    <springStiffness>0.4</springStiffness>
    <springReference>0</springReference>
  </gazebo>
  <!-- Inner VIRTUAL JOINT -->
  <joint name="right_hand_v1_2_research_ring_distal_virtual_joint" type="fixed">
    <axis xyz="0 0 -1"/>
    <origin rpy="0 0 0" xyz="0.009 0 0"/>
    <parent link="right_hand_v1_2_research_ring_middle_link"/>
    <child link="right_hand_v1_2_research_ring_distal_virtual_link"/>
    <limit effort="30" lower="0.0" upper="0.785398" velocity="10.0"/>
    <dynamics damping="3e-2" friction="0.0"/>
  </joint>
  <!-- VIRTUAL LINK -->
  <link name="right_hand_v1_2_research_ring_distal_virtual_link">
    <inertial>
      <origin rpy="0 0 0" xyz="0 0 0"/>
      <mass value="0.009"/>
      <inertia ixx="2.6586142e-07" ixy="1.2416847e-08" ixz="0.0" iyy="5.9935767e-07" iyz="0.0" izz="6.6781963e-07"/>
    </inertial>
  </link>
  <!-- Outer JOINT -->
  <joint name="right_hand_v1_2_research_ring_distal_joint" type="fixed">
    <axis xyz="0 0 -1"/>
    <origin rpy="0 0 0" xyz="0.013 0 0"/>
    <parent link="right_hand_v1_2_research_ring_distal_virtual_link"/>
    <child link="right_hand_v1_2_research_ring_distal_link"/>
    <limit effort="30" lower="0.0" upper="0.785398" velocity="10.0"/>
    <dynamics damping="3e-2" friction="0.0"/>
  </joint>
  <!-- LINK -->
  <link name="right_hand_v1_2_research_ring_distal_link">
    <inertial>
      <mass value="0.009"/>
      <inertia ixx="2.6586142e-07" ixy="1.2416847e-08" ixz="0.0" iyy="5.9935767e-07" iyz="0.0" izz="6.6781963e-07"/>
      <origin rpy="0 0 0" xyz="8.8025467e-03 -1.7219289e-03 0.0"/>
    </inertial>
    <visual>
      <origin rpy="0 0 0" xyz="0 0 0"/>
      <geometry>
        <mesh filename="package://softhands_description/meshes/v1_2_research/right/ph_distal.stl" scale="0.001 0.001 0.001"/>
      </geometry>
      <material name="qbhand/palm"/>
    </visual>
    <collision>
      <origin rpy="0 0 0" xyz="0 0 0"/>
      <geometry>
        <mesh filename="package://softhands_description/meshes/v1_2_research/right/ph_distal.stl" scale="0.001 0.001 0.001"/>
      </geometry>
    </collision>
  </link>
  <!-- GAZEBO REF -->
  <gazebo reference="right_hand_v1_2_research_ring_distal_link">
    <material>Gazebo/Grey</material>
    <selfCollide>0</selfCollide>
  </gazebo>
  <!-- GAZEBO REF -->
  <gazebo reference="right_hand_v1_2_research_ring_distal_joint">
    <implicitSpringDamper>true</implicitSpringDamper>
    <springStiffness>0.4</springStiffness>
    <springReference>0</springReference>
  </gazebo>
  <!-- GAZEBO REF -->
  <gazebo reference="right_hand_v1_2_research_ring_distal_virtual_joint">
    <implicitSpringDamper>true</implicitSpringDamper>
    <springStiffness>0.4</springStiffness>
    <springReference>0</springReference>
  </gazebo>
  <!-- Proximal JOINT -->
  <joint name="right_hand_v1_2_research_little_knuckle_joint" type="fixed">
    <origin rpy="0 0 1.57" xyz="0.04 -0.012 0.014"/>
    <parent link="right_hand_v1_2_research_palm_link"/>
    <child link="right_hand_v1_2_research_little_knuckle_link"/>
    <axis xyz="0 0 -1"/>
    <limit effort="30" lower="-0.524" upper="0.524" velocity="10.0"/>
    <dynamics damping="3e-2" friction="0.0"/>
  </joint>
  <!-- LINK -->
  <link name="right_hand_v1_2_research_little_knuckle_link">
    <inertial>
      <origin rpy="0 0 0" xyz="4.2753603e-04  0.0 -1.4321738e-03"/>
      <mass value="0.0095"/>
      <inertia ixx="6.4337303e-07" ixy="0.0" ixz="-3.9373913e-08" iyy="1.1253771e-06" iyz="0.0" izz="7.2336948e-07"/>
    </inertial>
    <visual>
      <origin rpy="0 0 0" xyz="0 0 0"/>
      <geometry>
        <mesh filename="package://softhands_description/meshes/v1_2_research/right/ph_knuckle.stl" scale="0.001 0.001 0.001"/>
      </geometry>
      <material name="qbhand/palm"/>
    </visual>
    <collision>
      <origin rpy="0 0 0" xyz="0 0 0"/>
      <geometry>
        <mesh filename="package://softhands_description/meshes/v1_2_research/right/ph_knuckle.stl" scale="0.001 0.001 0.001"/>
      </geometry>
    </collision>
  </link>
  <!-- GAZEBO REF -->
  <gazebo reference="right_hand_v1_2_research_little_knuckle_link">
    <material>Gazebo/Grey</material>
    <selfCollide>0</selfCollide>
  </gazebo>
  <!-- GAZEBO REF -->
  <gazebo reference="right_hand_v1_2_research_little_knuckle_joint">
    <implicitSpringDamper>true</implicitSpringDamper>
    <springStiffness>0.8</springStiffness>
    <springReference>0</springReference>
  </gazebo>
  <!-- Inner VIRTUAL JOINT -->
  <joint name="right_hand_v1_2_research_little_proximal_virtual_joint" type="fixed">
    <axis xyz="0 0 -1"/>
    <origin rpy="1.57 0 0" xyz="0.009 0 0"/>
    <parent link="right_hand_v1_2_research_little_knuckle_link"/>
    <child link="right_hand_v1_2_research_little_proximal_virtual_link"/>
    <limit effort="30" lower="0.0" upper="0.785398" velocity="10.0"/>
    <dynamics damping="3e-2" friction="0.0"/>
  </joint>
  <!-- VIRTUAL LINK -->
  <link name="right_hand_v1_2_research_little_proximal_virtual_link">
    <inertial>
      <origin rpy="0 0 0" xyz="0 0 0"/>
      <mass value="0.009"/>
      <inertia ixx="2.2722068e-07" ixy="1.1586053e-08" ixz="0.0" iyy="5.5947233e-07" iyz="0.0" izz="5.9562195e-07"/>
    </inertial>
  </link>
  <!-- Outer JOINT -->
  <joint name="right_hand_v1_2_research_little_proximal_joint" type="fixed">
    <axis xyz="0 0 -1"/>
    <origin rpy="0.0 0 0" xyz="0.013 0 0"/>
    <parent link="right_hand_v1_2_research_little_proximal_virtual_link"/>
    <child link="right_hand_v1_2_research_little_proximal_link"/>
    <limit effort="30" lower="0.0" upper="0.785398" velocity="10.0"/>
    <dynamics damping="3e-2" friction="0.0"/>
  </joint>
  <!-- LINK -->
  <link name="right_hand_v1_2_research_little_proximal_link">
    <inertial>
      <mass value="0.009"/>
      <inertia ixx="2.2722068e-07" ixy="1.1586053e-08" ixz="0.0" iyy="5.5947233e-07" iyz="0.0" izz="5.9562195e-07"/>
      <origin rpy="0 0 0" xyz="8.7707437e-03 -1.7863138e-03 0.0"/>
    </inertial>
    <visual>
      <origin rpy="0 0 0" xyz="0 0 0"/>
      <geometry>
        <mesh filename="package://softhands_description/meshes/v1_2_research/right/ph_medium.stl" scale="0.001 0.001 0.001"/>
      </geometry>
      <material name="qbhand/palm"/>
    </visual>
    <collision>
      <origin rpy="0 0 0" xyz="0 0 0"/>
      <geometry>
        <mesh filename="package://softhands_description/meshes/v1_2_research/right/ph_medium.stl" scale="0.001 0.001 0.001"/>
      </geometry>
    </collision>
  </link>
  <!-- GAZEBO REF -->
  <gazebo reference="right_hand_v1_2_research_little_proximal_link">
    <material>Gazebo/Grey</material>
    <selfCollide>0</selfCollide>
  </gazebo>
  <!-- GAZEBO REF -->
  <gazebo reference="right_hand_v1_2_research_little_proximal_joint">
    <implicitSpringDamper>true</implicitSpringDamper>
    <springStiffness>0.4</springStiffness>
    <springReference>0</springReference>
  </gazebo>
  <!-- GAZEBO REF -->
  <gazebo reference="right_hand_v1_2_research_little_proximal_virtual_joint">
    <implicitSpringDamper>true</implicitSpringDamper>
    <springStiffness>0.4</springStiffness>
    <springReference>0</springReference>
  </gazebo>
  <!-- Inner VIRTUAL JOINT -->
  <joint name="right_hand_v1_2_research_little_middle_virtual_joint" type="fixed">
    <axis xyz="0 0 -1"/>
    <origin rpy="0.0 0.0 0.0" xyz="0.013 0 0 "/>
    <parent link="right_hand_v1_2_research_little_proximal_link"/>
    <child link="right_hand_v1_2_research_little_middle_virtual_link"/>
    <limit effort="30" lower="0.0" upper="0.785398" velocity="10.0"/>
    <dynamics damping="3e-2" friction="0.0"/>
  </joint>
  <!-- VIRTUAL LINK -->
  <link name="right_hand_v1_2_research_little_middle_virtual_link">
    <inertial>
      <origin rpy="0 0 0" xyz="0 0 0"/>
      <mass value="0.0063"/>
      <inertia ixx="1.8024201e-07" ixy="5.756798e-09" ixz="0.0" iyy="2.3516266e-07" iyz="0.0" izz="2.691504e-07"/>
    </inertial>
  </link>
  <!-- Outer JOINT -->
  <joint name="right_hand_v1_2_research_little_middle_joint" type="fixed">
    <axis xyz="0 0 -1"/>
    <origin rpy="0 0 0" xyz="0.017 0 0"/>
    <parent link="right_hand_v1_2_research_little_middle_virtual_link"/>
    <child link="right_hand_v1_2_research_little_middle_link"/>
    <limit effort="30" lower="0.0" upper="0.785398" velocity="10.0"/>
    <dynamics damping="3e-2" friction="0.0"/>
  </joint>
  <!-- LINK -->
  <link name="right_hand_v1_2_research_little_middle_link">
    <inertial>
      <mass value="0.0063"/>
      <inertia ixx="1.8024201e-07" ixy="5.756798e-09" ixz="0.0" iyy="2.3516266e-07" iyz="0.0" izz="2.691504e-07"/>
      <origin rpy="0 0 0" xyz="4.7601567e-03 -1.3786947e-03 0.0"/>
    </inertial>
    <visual>
      <origin rpy="0 0 0" xyz="0 0 0"/>
      <geometry>
        <mesh filename="package://softhands_description/meshes/v1_2_research/right/ph_short.stl" scale="0.001 0.001 0.001"/>
      </geometry>
      <material name="qbhand/palm"/>
    </visual>
    <collision>
      <origin rpy="0 0 0" xyz="0 0 0"/>
      <geometry>
        <mesh filename="package://softhands_description/meshes/v1_2_research/right/ph_short.stl" scale="0.001 0.001 0.001"/>
      </geometry>
    </collision>
  </link>
  <!-- GAZEBO REF -->
  <gazebo reference="right_hand_v1_2_research_little_middle_link">
    <material>Gazebo/Grey</material>
    <selfCollide>0</selfCollide>
  </gazebo>
  <!-- GAZEBO REF -->
  <gazebo reference="right_hand_v1_2_research_little_middle_joint">
    <implicitSpringDamper>true</implicitSpringDamper>
    <springStiffness>0.4</springStiffness>
    <springReference>0</springReference>
  </gazebo>
  <!-- GAZEBO REF -->
  <gazebo reference="right_hand_v1_2_research_little_middle_virtual_joint">
    <implicitSpringDamper>true</implicitSpringDamper>
    <springStiffness>0.4</springStiffness>
    <springReference>0</springReference>
  </gazebo>
  <!-- Inner VIRTUAL JOINT -->
  <joint name="right_hand_v1_2_research_little_distal_virtual_joint" type="fixed">
    <axis xyz="0 0 -1"/>
    <origin rpy="0 0 0" xyz="0.009 0 0"/>
    <parent link="right_hand_v1_2_research_little_middle_link"/>
    <child link="right_hand_v1_2_research_little_distal_virtual_link"/>
    <limit effort="30" lower="0.0" upper="0.785398" velocity="10.0"/>
    <dynamics damping="3e-2" friction="0.0"/>
  </joint>
  <!-- VIRTUAL LINK -->
  <link name="right_hand_v1_2_research_little_distal_virtual_link">
    <inertial>
      <origin rpy="0 0 0" xyz="0 0 0"/>
      <mass value="0.009"/>
      <inertia ixx="2.6586142e-07" ixy="1.2416847e-08" ixz="0.0" iyy="5.9935767e-07" iyz="0.0" izz="6.6781963e-07"/>
    </inertial>
  </link>
  <!-- Outer JOINT -->
  <joint name="right_hand_v1_2_research_little_distal_joint" type="fixed">
    <axis xyz="0 0 -1"/>
    <origin rpy="0 0 0" xyz="0.013 0 0"/>
    <parent link="right_hand_v1_2_research_little_distal_virtual_link"/>
    <child link="right_hand_v1_2_research_little_distal_link"/>
    <limit effort="30" lower="0.0" upper="0.785398" velocity="10.0"/>
    <dynamics damping="3e-2" friction="0.0"/>
  </joint>
  <!-- LINK -->
  <link name="right_hand_v1_2_research_little_distal_link">
    <inertial>
      <mass value="0.009"/>
      <inertia ixx="2.6586142e-07" ixy="1.2416847e-08" ixz="0.0" iyy="5.9935767e-07" iyz="0.0" izz="6.6781963e-07"/>
      <origin rpy="0 0 0" xyz="8.8025467e-03 -1.7219289e-03 0.0"/>
    </inertial>
    <visual>
      <origin rpy="0 0 0" xyz="0 0 0"/>
      <geometry>
        <mesh filename="package://softhands_description/meshes/v1_2_research/right/ph_distal.stl" scale="0.001 0.001 0.001"/>
      </geometry>
      <material name="qbhand/palm"/>
    </visual>
    <collision>
      <origin rpy="0 0 0" xyz="0 0 0"/>
      <geometry>
        <mesh filename="package://softhands_description/meshes/v1_2_research/right/ph_distal.stl" scale="0.001 0.001 0.001"/>
      </geometry>
    </collision>
  </link>
  <!-- GAZEBO REF -->
  <gazebo reference="right_hand_v1_2_research_little_distal_link">
    <material>Gazebo/Grey</material>
    <selfCollide>0</selfCollide>
  </gazebo>
  <!-- GAZEBO REF -->
  <gazebo reference="right_hand_v1_2_research_little_distal_joint">
    <implicitSpringDamper>true</implicitSpringDamper>
    <springStiffness>0.4</springStiffness>
    <springReference>0</springReference>
  </gazebo>
  <!-- GAZEBO REF -->
  <gazebo reference="right_hand_v1_2_research_little_distal_virtual_joint">
    <implicitSpringDamper>true</implicitSpringDamper>
    <springStiffness>0.4</springStiffness>
    <springReference>0</springReference>
  </gazebo>
  <!-- IF VERSION == 1_wide -->
  <gazebo reference="table_top_link">
    <selfCollide>0</selfCollide>
  </gazebo>
  <!-- <xacro:repair_hand_transmission id="left" />

    <xacro:repair_hand_transmission id="right" /> -->
</robot>
