<?xml version="1.0" ?>
<!-- =================================================================================== -->
<!-- |    This document was autogenerated by xacro from repair_full.urdf.xacro         | -->
<!-- |    EDITING THIS FILE BY HAND IS NOT RECOMMENDED                                 | -->
<!-- =================================================================================== -->
<!-- xacro for generating the full urdf of the RePair platform (cage + bimanual robot) -->
<!-- is_sliding_wrist: whether to add a sliding joint along the wrist second d.o.f.
    (true -> yes), everything else -> no. This is used to generate the URDF for the optimization.  -->
<!-- gen_coll: whether to add the approximate collision  model of the platform -->
<!-- load_sol: whether to generate the URDF without the additional d.o.f. used by the co-design optimization.
Setting it to "true", allow to fix the additional d.o.f. to desired values 
(specified in the repair_urdf/config/arm_opt_mount_vals.yaml file) -->
<!-- use_updated_wrist: visual parameter. if true, we load the latest meshes (which are adapted to the
results of the optimization), otherwise we go with the old ones (generated for a spherical wrist) -->
<robot name="repair_full">
  <!-- below this value, Gazebo parser ignores links
To give some  perspective, a grain of sand weights  0.0000045 grams. So this corresponds to less than 1/4 of a grain of sand of
fake inertia -> it is acceptable. -->
  <!-- color -->
  <material name="darkblue">
    <color rgba="0.0 0.3 0.9 1"/>
  </material>
  <material name="darkred">
    <color rgba="0.55 0.0 0.0 1"/>
  </material>
  <material name="dark">
    <color rgba="0.6 0.6 0.6 1"/>
  </material>
  <!-- <xacro:include filename="$(find softhands_description)/urdf/utils.urdf.xacro" /> -->
  <!-- Reading some parameters from a YAML config file for the approximate collision model for RePair.
Links are approximated as spheres with hand-tuned radii and positions -->
  <material name="wood">
    <color rgba="0.522 0.369 0.259 0.8"/>
  </material>
  <material name="silver_gray">
    <color rgba="0.8 0.8 0.8 0.8"/>
  </material>
  <link name="world">
  </link>
  <joint name="world_joint" type="fixed">
    <parent link="world"/>
    <origin rpy="0 0 0" xyz="0 0 0"/>
    <child link="table_top_link"/>
  </joint>
  <link name="table_top_link">
    <visual>
      <origin xyz="0.98 0.0 0.475"/>
      <geometry>
        <box size="1.5 2.5 0.05"/>
      </geometry>
      <material name="wood"/>
    </visual>
    <collision>
      <origin xyz="0.98 0.0 0.475"/>
      <geometry>
        <box size="1.5 2.5 0.05"/>
      </geometry>
    </collision>
  </link>
  <joint name="leg1_joint" type="fixed">
    <parent link="table_top_link"/>
    <origin rpy="0 0 0" xyz="1.73 1.25 0.5"/>
    <child link="leg1_link"/>
  </joint>
  <link name="leg1_link">
    <visual>
      <origin rpy="0 0 0" xyz="0.0 0.0 -0.25"/>
      <geometry>
        <cylinder length="0.5" radius="0.02"/>
      </geometry>
      <material name="silver_gray"/>
    </visual>
    <collision>
      <origin rpy="0.0 0.0 0.0" xyz="0.0 0.0 -0.25"/>
      <geometry>
        <cylinder length="0.5" radius="0.02"/>
      </geometry>
    </collision>
  </link>
  <joint name="vbar1_joint" type="fixed">
    <parent link="leg1_link"/>
    <origin rpy="0 0 0" xyz="0 0 0.5"/>
    <child link="vbar1_link"/>
  </joint>
  <link name="vbar1_link">
    <visual>
      <origin rpy="0 0 0" xyz="0.0 0.0 0"/>
      <geometry>
        <cylinder length="1.0" radius="0.02"/>
      </geometry>
      <material name="silver_gray"/>
    </visual>
    <collision>
      <origin rpy="0.0 0.0 0.0" xyz="0.0 0.0 0"/>
      <geometry>
        <cylinder length="1.0" radius="0.02"/>
      </geometry>
    </collision>
  </link>
  <joint name="leg2_joint" type="fixed">
    <parent link="table_top_link"/>
    <origin rpy="0 0 0" xyz="0.22999999999999998 1.25 0.5"/>
    <child link="leg2_link"/>
  </joint>
  <link name="leg2_link">
    <visual>
      <origin rpy="0 0 0" xyz="0.0 0.0 -0.25"/>
      <geometry>
        <cylinder length="0.5" radius="0.02"/>
      </geometry>
      <material name="silver_gray"/>
    </visual>
    <collision>
      <origin rpy="0.0 0.0 0.0" xyz="0.0 0.0 -0.25"/>
      <geometry>
        <cylinder length="0.5" radius="0.02"/>
      </geometry>
    </collision>
  </link>
  <joint name="vbar2_joint" type="fixed">
    <parent link="leg2_link"/>
    <origin rpy="0 0 0" xyz="0 0 0.5"/>
    <child link="vbar2_link"/>
  </joint>
  <link name="vbar2_link">
    <visual>
      <origin rpy="0 0 0" xyz="0.0 0.0 0"/>
      <geometry>
        <cylinder length="1.0" radius="0.02"/>
      </geometry>
      <material name="silver_gray"/>
    </visual>
    <collision>
      <origin rpy="0.0 0.0 0.0" xyz="0.0 0.0 0"/>
      <geometry>
        <cylinder length="1.0" radius="0.02"/>
      </geometry>
    </collision>
  </link>
  <joint name="leg3_joint" type="fixed">
    <parent link="table_top_link"/>
    <origin rpy="0 0 0" xyz="1.73 -1.25 0.5"/>
    <child link="leg3_link"/>
  </joint>
  <link name="leg3_link">
    <visual>
      <origin rpy="0 0 0" xyz="0.0 0.0 -0.25"/>
      <geometry>
        <cylinder length="0.5" radius="0.02"/>
      </geometry>
      <material name="silver_gray"/>
    </visual>
    <collision>
      <origin rpy="0.0 0.0 0.0" xyz="0.0 0.0 -0.25"/>
      <geometry>
        <cylinder length="0.5" radius="0.02"/>
      </geometry>
    </collision>
  </link>
  <joint name="vbar3_joint" type="fixed">
    <parent link="leg3_link"/>
    <origin rpy="0 0 0" xyz="0 0 0.5"/>
    <child link="vbar3_link"/>
  </joint>
  <link name="vbar3_link">
    <visual>
      <origin rpy="0 0 0" xyz="0.0 0.0 0"/>
      <geometry>
        <cylinder length="1.0" radius="0.02"/>
      </geometry>
      <material name="silver_gray"/>
    </visual>
    <collision>
      <origin rpy="0.0 0.0 0.0" xyz="0.0 0.0 0"/>
      <geometry>
        <cylinder length="1.0" radius="0.02"/>
      </geometry>
    </collision>
  </link>
  <joint name="leg4_joint" type="fixed">
    <parent link="table_top_link"/>
    <origin rpy="0 0 0" xyz="0.22999999999999998 -1.25 0.5"/>
    <child link="leg4_link"/>
  </joint>
  <link name="leg4_link">
    <visual>
      <origin rpy="0 0 0" xyz="0.0 0.0 -0.25"/>
      <geometry>
        <cylinder length="0.5" radius="0.02"/>
      </geometry>
      <material name="silver_gray"/>
    </visual>
    <collision>
      <origin rpy="0.0 0.0 0.0" xyz="0.0 0.0 -0.25"/>
      <geometry>
        <cylinder length="0.5" radius="0.02"/>
      </geometry>
    </collision>
  </link>
  <joint name="vbar4_joint" type="fixed">
    <parent link="leg4_link"/>
    <origin rpy="0 0 0" xyz="0 0 0.5"/>
    <child link="vbar4_link"/>
  </joint>
  <link name="vbar4_link">
    <visual>
      <origin rpy="0 0 0" xyz="0.0 0.0 0"/>
      <geometry>
        <cylinder length="1.0" radius="0.02"/>
      </geometry>
      <material name="silver_gray"/>
    </visual>
    <collision>
      <origin rpy="0.0 0.0 0.0" xyz="0.0 0.0 0"/>
      <geometry>
        <cylinder length="1.0" radius="0.02"/>
      </geometry>
    </collision>
  </link>
  <joint name="obar1_joint" type="fixed">
    <parent link="vbar1_link"/>
    <origin rpy="0 -1.57079632679 0" xyz="-0.75 0 0.5"/>
    <child link="obar1_link"/>
  </joint>
  <link name="obar1_link">
    <visual>
      <origin rpy="0 0 0" xyz="0.0 0.0 0"/>
      <geometry>
        <cylinder length="1.5" radius="0.02"/>
      </geometry>
      <material name="silver_gray"/>
    </visual>
    <collision>
      <origin rpy="0.0 0.0 0.0" xyz="0.0 0.0 0"/>
      <geometry>
        <cylinder length="1.5" radius="0.02"/>
      </geometry>
    </collision>
  </link>
  <joint name="obar2_joint" type="fixed">
    <parent link="vbar3_link"/>
    <origin rpy="0 -1.57079632679 0" xyz="-0.75 0 0.5"/>
    <child link="obar2_link"/>
  </joint>
  <link name="obar2_link">
    <visual>
      <origin rpy="0 0 0" xyz="0.0 0.0 0"/>
      <geometry>
        <cylinder length="1.5" radius="0.02"/>
      </geometry>
      <material name="silver_gray"/>
    </visual>
    <collision>
      <origin rpy="0.0 0.0 0.0" xyz="0.0 0.0 0"/>
      <geometry>
        <cylinder length="1.5" radius="0.02"/>
      </geometry>
    </collision>
  </link>
  <joint name="obar3_joint" type="fixed">
    <parent link="vbar3_link"/>
    <origin rpy="-1.57079632679 0 0" xyz="0 1.25 0.5"/>
    <child link="obar3_link"/>
  </joint>
  <link name="obar3_link">
    <visual>
      <origin rpy="0 0 0" xyz="0.0 0.0 0"/>
      <geometry>
        <cylinder length="2.5" radius="0.02"/>
      </geometry>
      <material name="silver_gray"/>
    </visual>
    <collision>
      <origin rpy="0.0 0.0 0.0" xyz="0.0 0.0 0"/>
      <geometry>
        <cylinder length="2.5" radius="0.02"/>
      </geometry>
    </collision>
  </link>
  <joint name="obar4_joint" type="fixed">
    <parent link="vbar4_link"/>
    <origin rpy="-1.57079632679 0 0" xyz="0 1.25 0.5"/>
    <child link="obar4_link"/>
  </joint>
  <link name="obar4_link">
    <!-- dummy intertia to make Gazebo urdf2sdf converter work -->
    <visual>
      <origin rpy="0 0 0" xyz="0.0 0.0 0"/>
      <geometry>
        <cylinder length="2.5" radius="0.02"/>
      </geometry>
      <material name="silver_gray"/>
    </visual>
    <collision>
      <origin rpy="0.0 0.0 0.0" xyz="0.0 0.0 0"/>
      <geometry>
        <cylinder length="2.5" radius="0.02"/>
      </geometry>
    </collision>
  </link>
  <joint name="sliding_guide_joint" type="fixed">
    <parent link="obar2_link"/>
    <origin rpy="-1.57079632679 0 0" xyz="0 1.25 0"/>
    <child link="sliding_guide_link"/>
  </joint>
  <link name="sliding_guide_link">
    <visual>
      <origin rpy="0 0 0" xyz="0.0 0.0 0"/>
      <geometry>
        <box size="0.001 0.2 2.5"/>
      </geometry>
      <material name="silver_gray"/>
    </visual>
    <collision>
      <origin rpy="0.0 0.0 0.0" xyz="0.0 0.0 0"/>
      <geometry>
        <cylinder length="2.5" radius="0.02"/>
      </geometry>
    </collision>
  </link>
  <joint name="working_surface_joint" type="fixed">
    <parent link="sliding_guide_link"/>
    <origin rpy="0.0 -1.57079632679 3.14159265359" xyz="-1.0 0 0"/>
    <child link="working_surface_link"/>
  </joint>
  <link name="working_surface_link">
    <!-- Huge inertia (does not matter, is fixed to the world)-->
    <inertial>
      <mass value="1000"/>
      <origin xyz="0 0 0"/>
      <inertia ixx="0" ixy="0" ixz="0" iyy="0" iyz="0" izz="0"/>
    </inertial>
  </link>
  <gazebo reference="table_top_link">
    <material>Gazebo/Wood </material>
  </gazebo>
  <gazebo reference="leg1_link">
    <material>Gazebo/Grey </material>
  </gazebo>
  <gazebo reference="leg2_link">
    <material>Gazebo/Grey </material>
  </gazebo>
  <gazebo reference="leg3_link">
    <material>Gazebo/Grey </material>
  </gazebo>
  <gazebo reference="leg4_link">
    <material>Gazebo/Grey </material>
  </gazebo>
  <gazebo reference="vbar1_link">
    <material>Gazebo/Grey </material>
  </gazebo>
  <gazebo reference="vbar2_link">
    <material>Gazebo/Grey </material>
  </gazebo>
  <gazebo reference="vbar3_link">
    <material>Gazebo/Grey </material>
  </gazebo>
  <gazebo reference="vbar4_link">
    <material>Gazebo/Grey </material>
  </gazebo>
  <gazebo reference="obar1_link">
    <material>Gazebo/Grey </material>
  </gazebo>
  <gazebo reference="obar2_link">
    <material>Gazebo/Grey </material>
  </gazebo>
  <gazebo reference="obar3_link">
    <material>Gazebo/Grey </material>
  </gazebo>
  <gazebo reference="obar4_link">
    <material>Gazebo/Grey </material>
  </gazebo>
  <gazebo reference="sliding_guide_link">
    <material>Gazebo/Grey </material>
  </gazebo>
  <!-- Reading mounting paramters from YAML file -->
  <!-- xbot2 joint device driver-->
  <gazebo>
    <!--GROUPS: Representation of a set of joints and links. This can be useful for specifying DOF to plan for, defining arms, end effectors, etc-->
    <!--LINKS: When a link is specified, the parent joint of that link (if it exists) is automatically included-->
    <!--JOINTS: When a joint is specified, the child link of that joint (which will always exist) is automatically included-->
    <!--CHAINS: When a chain is specified, all the links along the chain (including endpoints) are included in the group. Additionally, all the joints that are parents to included links are also included. This means that joints along the chain and the parent joint of the base link are included in the group-->
    <!--SUBGROUPS: Groups can also be formed by referencing to already defined group names-->
    <plugin filename="libxbot2_gz_joint_server.so" name="xbot2_gz_joint_server">
      <pid>
        <gain d="5" name="lowpwr_mot" p="50"/>
        <gain d="10" name="small_mot" p="1000"/>
        <gain d="40" name="medium_mot" p="4000"/>
        <gain d="50" name="big_mot" p="8000"/>
        <gain d="70" name="hugr_mot" p="12000"/>
        <gain d="50" name="guide_motor" p="8000"/>
        <pid name="x_joint" profile="guide_motor"/>
        <pid name="arm_1_joint_1" profile="big_mot"/>
        <pid name="arm_1_joint_2" profile="big_mot"/>
        <pid name="arm_1_joint_3" profile="big_mot"/>
        <pid name="arm_1_joint_4" profile="big_mot"/>
        <pid name="arm_1_joint_5" profile="big_mot"/>
        <pid name="arm_1_joint_6" profile="big_mot"/>
        <pid name="arm_1_joint_7" profile="big_mot"/>
        <pid name="arm_2_joint_1" profile="big_mot"/>
        <pid name="arm_2_joint_2" profile="big_mot"/>
        <pid name="arm_2_joint_3" profile="big_mot"/>
        <pid name="arm_2_joint_4" profile="big_mot"/>
        <pid name="arm_2_joint_5" profile="big_mot"/>
        <pid name="arm_2_joint_6" profile="big_mot"/>
        <pid name="arm_2_joint_7" profile="big_mot"/>
      </pid>
      <ignore_joints>
        <joint name="right_hand_v1s_thumb_knuckle_joint"/>
        <joint name="right_hand_v1s_thumb_proximal_joint"/>
        <joint name="right_hand_v1s_thumb_distal_joint"/>
        <joint name="right_hand_v1s_index_distal_joint"/>
        <joint name="right_hand_v1s_index_proximal_joint"/>
        <joint name="right_hand_v1s_index_middle_joint"/>
        <joint name="right_hand_v1s_index_distal_joint"/>
        <joint name="right_hand_v1s_middle_distal_joint"/>
        <joint name="right_hand_v1s_middle_proximal_joint"/>
        <joint name="right_hand_v1s_middle_middle_joint"/>
        <joint name="right_hand_v1s_middle_distal_joint"/>
        <joint name="right_hand_v1s_ring_distal_joint"/>
        <joint name="right_hand_v1s_ring_proximal_joint"/>
        <joint name="right_hand_v1s_ring_middle_joint"/>
        <joint name="right_hand_v1s_ring_distal_joint"/>
        <joint name="right_hand_v1s_little_distal_joint"/>
        <joint name="right_hand_v1s_little_proximal_joint"/>
        <joint name="right_hand_v1s_little_middle_joint"/>
        <joint name="right_hand_v1s_little_distal_joint"/>
        <joint name="left_hand_v1s_thumb_knuckle_joint"/>
        <joint name="left_hand_v1s_thumb_proximal_joint"/>
        <joint name="left_hand_v1s_thumb_distal_joint"/>
        <joint name="left_hand_v1s_index_distal_joint"/>
        <joint name="left_hand_v1s_index_proximal_joint"/>
        <joint name="left_hand_v1s_index_middle_joint"/>
        <joint name="left_hand_v1s_index_distal_joint"/>
        <joint name="left_hand_v1s_middle_distal_joint"/>
        <joint name="left_hand_v1s_middle_proximal_joint"/>
        <joint name="left_hand_v1s_middle_middle_joint"/>
        <joint name="left_hand_v1s_middle_distal_joint"/>
        <joint name="left_hand_v1s_ring_distal_joint"/>
        <joint name="left_hand_v1s_ring_proximal_joint"/>
        <joint name="left_hand_v1s_ring_middle_joint"/>
        <joint name="left_hand_v1s_ring_distal_joint"/>
        <joint name="left_hand_v1s_little_distal_joint"/>
        <joint name="left_hand_v1s_little_proximal_joint"/>
        <joint name="left_hand_v1s_little_middle_joint"/>
        <joint name="left_hand_v1s_little_distal_joint"/>
      </ignore_joints>
    </plugin>
  </gazebo>
  <gazebo>
    <plugin filename="libxbot2_gz_ft_server.so" name="xbot2_ft_driver"/>
  </gazebo>
  <joint name="x_joint" type="prismatic">
    <origin rpy="0.0 0.0 0.0" xyz="0.0 0.0 0.7293"/>
    <parent link="working_surface_link"/>
    <child link="base_link"/>
    <axis xyz="1 0 0"/>
    <limit effort="1000.0" lower="-1.15" upper="1.15" velocity="20.0"/>
  </joint>
  <link name="base_link">
    <!-- torso inertias + stuff attached to the sliding guide -->
    <inertial>
      <mass value="5.0"/>
      <origin xyz="0 0 0"/>
      <inertia ixx="0" ixy="0" ixz="0" iyy="0" iyz="0" izz="0"/>
    </inertial>
  </link>
  <joint name="r_arm_mount_joint" type="fixed">
    <origin rpy="0 0 0" xyz="0.0 -0.233 0.0"/>
    <parent link="base_link"/>
    <child link="dummy_r"/>
  </joint>
  <joint name="l_arm_mount_joint" type="fixed">
    <origin rpy="0 0 0" xyz="0.0 0.233 0.0"/>
    <parent link="base_link"/>
    <child link="dummy_l"/>
  </joint>
  <link name="dummy_r">
    </link>
  <link name="dummy_l">
    </link>
  <joint name="roll_r" type="fixed">
    <origin rpy="0.6283 0.0 0.0" xyz="0 0.0 0.0"/>
    <parent link="dummy_r"/>
    <child link="r_arm_mount_frame"/>
  </joint>
  <joint name="roll_l" type="fixed">
    <origin rpy="-0.6283 0.0 0.0" xyz="0 0.0 0.0"/>
    <parent link="dummy_l"/>
    <child link="l_arm_mount_frame"/>
  </joint>
  <link name="r_arm_mount_frame">
    <!-- dummy intertia to make Gazebo urdf2sdf converter work -->
    <inertial>
      <mass value="1.00000000000001e-06"/>
      <origin xyz="0 0 0"/>
      <inertia ixx="0" ixy="0" ixz="0" iyy="0" iyz="0" izz="0"/>
    </inertial>
  </link>
  <link name="l_arm_mount_frame">
    <!-- dummy intertia to make Gazebo urdf2sdf converter work -->
    <inertial>
      <mass value="1.00000000000001e-06"/>
      <origin xyz="0 0 0"/>
      <inertia ixx="0" ixy="0" ixz="0" iyy="0" iyz="0" izz="0"/>
    </inertial>
  </link>
  <!-- id: 1 for right arm, everything else is considered left arm -->
  <!-- base_link: name of base link a the single arm -->
  <!-- is_sliding_wrist: whether to add a sliding joint along the axis of wrist's second d.o.f.
    (true -> yes), everything else -> no -->
  <joint name="arm_1_joint_1" type="revolute">
    <origin rpy="1.57079632679 0 0" xyz="0 0 0"/>
    <parent link="r_arm_mount_frame"/>
    <child link="arm_1_link_1"/>
    <axis xyz="0 0 1"/>
    <limit effort="200.0" lower="-2.6179938779916667" upper="2.6179938779916667" velocity="10.0"/>
  </joint>
  <link name="arm_1_link_1">
    <inertial>
      <mass value="2"/>
      <inertia ixx="0.0015" ixy="-9.999999999999999e-05" ixz="0.0" iyy="0.0026999999999999997" iyz="9.999999999999999e-05" izz="0.0028"/>
      <origin xyz="0 0 -0.01"/>
    </inertial>
    <collision name="arm_1_link_1_collision">
      <geometry>
        <mesh filename="package://repair_urdf/meshes/base_meshes/link_1.stl" scale="0.001 0.001 0.001"/>
      </geometry>
      <material name="dark"/>
    </collision>
    <visual name="arm_1_link_1_visual">
      <geometry>
        <mesh filename="package://repair_urdf/meshes/base_meshes/link_1.stl" scale="0.001 0.001 0.001"/>
      </geometry>
      <material name="dark"/>
    </visual>
  </link>
  <joint name="arm_1_joint_2" type="revolute">
    <origin rpy="0 -1.57079632679 -3.14159265359" xyz="0.0385 -0.023 0"/>
    <parent link="arm_1_link_1"/>
    <child link="arm_1_link_2"/>
    <axis xyz="0 0 1"/>
    <limit effort="200.0" lower="-1.3962634015955555" upper="2.1816615649930555" velocity="10.0"/>
  </joint>
  <link name="arm_1_link_2">
    <inertial>
      <mass value="0.4"/>
      <inertia ixx="0.00067" ixy="0.0" ixz="0.00017999999999999998" iyy="0.0009699999999999999" iyz="0.0" izz="0.001"/>
      <origin xyz="0.04 0.0 0.035"/>
    </inertial>
    <collision name="arm_1_link_2_collision">
      <geometry>
        <mesh filename="package://repair_urdf/meshes/base_meshes/link_2.stl" scale="0.001 0.001 0.001"/>
      </geometry>
      <material name="dark"/>
    </collision>
    <visual name="arm_1_link_2_visual">
      <geometry>
        <mesh filename="package://repair_urdf/meshes/base_meshes/link_2.stl" scale="0.001 0.001 0.001"/>
      </geometry>
      <material name="dark"/>
    </visual>
  </link>
  <joint name="arm_1_joint_3" type="revolute">
    <origin rpy="0 1.57079632679 0" xyz="0.005 0 0"/>
    <origin rpy="0 -1.57079632679 -3.14159265359" xyz="0.005 0 0"/>
    <parent link="arm_1_link_2"/>
    <child link="arm_1_link_3"/>
    <axis xyz="0 0 1"/>
    <limit effort="200.0" lower="-2.6179938779916667" upper="2.6179938779916667" velocity="10.0"/>
  </joint>
  <link name="arm_1_link_3">
    <inertial>
      <mass value="3.3"/>
      <inertia ixx="0.024999999999999998" ixy="0.0" ixz="0.0" iyy="0.026" iyz="0.0" izz="0.022"/>
      <origin xyz="0.0 -0.025 0.23"/>
    </inertial>
    <collision name="arm_1_link_3_collision">
      <geometry>
        <mesh filename="package://repair_urdf/meshes/base_meshes/link_3.stl" scale="0.001 0.001 0.001"/>
      </geometry>
      <material name="dark"/>
    </collision>
    <visual name="arm_1_link_3_visual">
      <geometry>
        <mesh filename="package://repair_urdf/meshes/base_meshes/link_3.stl" scale="0.001 0.001 0.001"/>
      </geometry>
      <material name="dark"/>
    </visual>
  </link>
  <joint name="arm_1_joint_4" type="revolute">
    <origin rpy="0 -1.57079632679 -3.14159265359" xyz="0 0.0225 0.36014999999999997"/>
    <parent link="arm_1_link_3"/>
    <child link="arm_1_link_4"/>
    <axis xyz="0 0 1"/>
    <limit effort="200.0" lower="-2.6179938779916667" upper="1.0471975511966667" velocity="10.0"/>
  </joint>
  <link name="arm_1_link_4">
    <inertial>
      <mass value="0.4"/>
      <inertia ixx="0.00067" ixy="0.0" ixz="0.00017999999999999998" iyy="0.0009699999999999999" iyz="0.0" izz="0.001"/>
      <origin xyz="0.04 0.0 0.035"/>
    </inertial>
    <collision name="arm_1_link_4_collision">
      <geometry>
        <mesh filename="package://repair_urdf/meshes/base_meshes/link_4.stl" scale="0.001 0.001 0.001"/>
      </geometry>
      <material name="dark"/>
    </collision>
    <visual name="arm_1_link_4_visual">
      <geometry>
        <mesh filename="package://repair_urdf/meshes/base_meshes/link_4.stl" scale="0.001 0.001 0.001"/>
      </geometry>
      <material name="dark"/>
    </visual>
  </link>
  <joint name="arm_1_joint_5" type="revolute">
    <origin rpy="-1.57079632679 0 -1.57079632679" xyz="0.005 0 0"/>
    <parent link="arm_1_link_4"/>
    <child link="arm_1_link_5"/>
    <axis xyz="0 0 1"/>
    <limit effort="200.0" lower="-2.6179938779916667" upper="2.6179938779916667" velocity="10.0"/>
  </joint>
  <link name="arm_1_link_5">
    <inertial>
      <mass value="2.8"/>
      <inertia ixx="0.032" ixy="0.0" ixz="0.0017" iyy="0.033999999999999996" iyz="0.0" izz="0.028999999999999998"/>
      <origin xyz="-0.005 0.0 0.2"/>
    </inertial>
    <collision name="arm_1_link_5_collision">
      <origin rpy="0 0 0" xyz="0 0 0"/>
      <geometry>
        <mesh filename="package://repair_urdf/meshes/base_meshes/link_5.stl" scale="0.001 0.001 0.001"/>
      </geometry>
      <material name="dark"/>
    </collision>
    <visual name="arm_1_link_5_visual">
      <origin rpy="0 0 0" xyz="0 0 0"/>
      <geometry>
        <mesh filename="package://repair_urdf/meshes/base_meshes/link_5.stl" scale="0.001 0.001 0.001"/>
      </geometry>
      <material name="dark"/>
    </visual>
  </link>
  <joint name="arm_1_joint_6" type="revolute">
    <origin rpy="0 -1.57079632679 0" xyz="0 0.0 0.321 "/>
    <axis xyz="0 0 1"/>
    <parent link="arm_1_link_5"/>
    <child link="dummy_sliding_wrist1_link"/>
    <limit effort="200.0" lower="-2.6179938779916667" upper="2.6179938779916667" velocity="10.0"/>
  </joint>
  <link name="dummy_sliding_wrist1_link">
    
    </link>
  <joint name="dummy_sliding_wrist1_joint" type="fixed">
    <origin rpy="0 0 0" xyz="0.0 0.0 -0.0"/>
    <parent link="dummy_sliding_wrist1_link"/>
    <child link="arm_1_link_6"/>
  </joint>
  <link name="arm_1_link_6">
    <inertial>
      <mass value="1.8"/>
      <inertia ixx="0.0017" ixy="0.0" ixz="0.0" iyy="0.0025" iyz="9.999999999999999e-05" izz="0.0026999999999999997"/>
      <origin xyz="0.0 0.0 0.0"/>
    </inertial>
    <collision name="arm_1_link_6_collision">
      <origin rpy="0 0 0" xyz="0 0 0"/>
      <geometry>
        <mesh filename="package://repair_urdf/meshes/base_meshes/link_6.stl" scale="0.001 0.001 0.001"/>
      </geometry>
      <material name="dark"/>
    </collision>
    <visual name="arm_1_link_6_visual">
      <origin rpy="0 0 0" xyz="0 0 0"/>
      <geometry>
        <mesh filename="package://repair_urdf/meshes/base_meshes/link_6.stl" scale="0.001 0.001 0.001"/>
      </geometry>
      <material name="dark"/>
    </visual>
  </link>
  <joint name="arm_1_joint_7" type="revolute">
    <origin rpy="1.57079632679 0 1.57079632679" xyz="0.08 0 0"/>
    <parent link="arm_1_link_6"/>
    <child link="arm_1_link_7"/>
    <axis xyz="0 0 1"/>
    <limit effort="200.0" lower="-2.6179938779916667" upper="2.6179938779916667" velocity="10.0"/>
  </joint>
  <link name="arm_1_link_7">
    <inertial>
      <mass value="1.5"/>
      <inertia ixx="0.024999999999999998" ixy="0.0" ixz="0.0" iyy="0.024999999999999998" iyz="9.999999999999999e-05" izz="0.023"/>
      <origin xyz="0.0 0.0 0.0"/>
    </inertial>
  </link>
  

    # Softhand VERSION 1.0
    
  

    # Softhand VERSION 1.0 SIMPLIFIED (less joints)
    
  
		# Softhand Base
		
  <joint name="right_hand_base_joint" type="fixed">
    <origin rpy="0 0 0" xyz="0 -0.015 0"/>
    <parent link="arm_1_link_7"/>
    <child link="right_hand_v1s_palm_base"/>
  </joint>
  <link name="right_hand_v1s_palm_base"/>
  
		# RIGHT HAND
		
  
			# Palm
			
  <joint name="right_hand_v1s_palm_joint" type="fixed">
    <origin rpy="0 0 0" xyz="0.002 0.00695 0.0535"/>
    <parent link="right_hand_v1s_palm_base"/>
    <child link="right_hand_v1s_palm_link"/>
  </joint>
  <link name="right_hand_v1s_palm_link">
    <inertial>
      <origin xyz="-0.004568758 -0.006808116 0.027653328"/>
      <mass value="2.28"/>
      <inertia ixx="0.001" ixy="0" ixz="0" iyy="0.001" iyz="0" izz="0.001"/>
    </inertial>
    <visual>
      <geometry>
        <mesh filename="package://softhands_description/meshes/softhands/v1.0/right/palm_right_m.stl"/>
      </geometry>
    </visual>
    <collision>
      <geometry>
        <mesh filename="package://softhands_description/meshes/softhands/v1.0/right/palm_right_m.stl"/>
      </geometry>
    </collision>
    <visual>
      <origin rpy="0 0 0" xyz="-0.002 -0.00695 -0.0535"/>
      <geometry>
        <mesh filename="package://softhands_description/meshes/softhands/v1.0/right/softhand_base_right_m.stl"/>
      </geometry>
    </visual>
    <collision>
      <origin rpy="0 0 0" xyz="-0.002 -0.00695 -0.0535"/>
      <geometry>
        <mesh filename="package://softhands_description/meshes/softhands/v1.0/right/softhand_base_right_m.stl"/>
      </geometry>
    </collision>
  </link>
  
			# Thumb finger
			
  <!-- KNUCKLE -->
  <joint name="right_hand_v1s_thumb_knuckle_joint" type="fixed">
    <origin rpy="0.0 -0.38397275793662144 1.5707963267948966" xyz="0.00566972 0.0296160 0.0553140"/>
    <parent link="right_hand_v1s_palm_link"/>
    <child link="right_hand_v1s_thumb_knuckle_link"/>
    <axis xyz="0 0 -1"/>
    <dynamics damping="0.08" friction="0.0"/>
  </joint>
  <link name="right_hand_v1s_thumb_knuckle_link">
    <inertial>
      <origin xyz="0.001285644 0 0.000425011"/>
      <mass value="0.09"/>
      <inertia ixx="0.001" ixy="0" ixz="0" iyy="0.001" iyz="0" izz="0.001"/>
    </inertial>
    <visual>
      <geometry>
        <mesh filename="package://softhands_description/meshes/softhands/v1.0/right/thumb_knuckle_right_m.stl"/>
      </geometry>
    </visual>
    <collision>
      <geometry>
        <mesh filename="package://softhands_description/meshes/softhands/v1.0/right/thumb_knuckle_right_m.stl"/>
      </geometry>
    </collision>
  </link>
  <!-- PROXIMAL PHALANGE -->
  <joint name="right_hand_v1s_thumb_proximal_joint" type="fixed">
    <origin rpy="0.426627741408745 0 0.0" xyz="0.033500000 -0.0033 0.0"/>
    <parent link="right_hand_v1s_thumb_knuckle_link"/>
    <child link="right_hand_v1s_thumb_proximal_link"/>
    <axis xyz="0 -1 0"/>
    <dynamics damping="0.08" friction="0.0"/>
  </joint>
  <link name="right_hand_v1s_thumb_proximal_link">
    <inertial>
      <origin xyz="0.005074337 0 -0.000262953"/>
      <mass value="0.05"/>
      <inertia ixx="0.001" ixy="0" ixz="0" iyy="0.001" iyz="0" izz="0.001"/>
    </inertial>
    <visual>
      <geometry>
        <mesh filename="package://softhands_description/meshes/softhands/v1.0/common/phalanx_m.stl"/>
      </geometry>
    </visual>
    <collision>
      <geometry>
        <mesh filename="package://softhands_description/meshes/softhands/v1.0/common/phalanx_m.stl"/>
      </geometry>
    </collision>
  </link>
  <!-- DISTAL PHALANGE -->
  <joint name="right_hand_v1s_thumb_distal_joint" type="fixed">
    <origin rpy="0 0 0" xyz="0.020 0 0.0"/>
    <parent link="right_hand_v1s_thumb_proximal_link"/>
    <child link="right_hand_v1s_thumb_distal_link"/>
    <axis xyz="0 -1 0"/>
    <dynamics damping="0.08" friction="0.0"/>
  </joint>
  <link name="right_hand_v1s_thumb_distal_link">
    <inertial>
      <origin xyz="0.009849094 0 0.000820286"/>
      <mass value="0.1"/>
      <inertia ixx="0.001" ixy="0" ixz="0" iyy="0.001" iyz="0" izz="0.001"/>
    </inertial>
    <visual>
      <geometry>
        <mesh filename="package://softhands_description/meshes/softhands/v1.0/common/fingertip_m.stl"/>
      </geometry>
    </visual>
    <collision>
      <geometry>
        <mesh filename="package://softhands_description/meshes/softhands/v1.0/common/fingertip_m.stl"/>
      </geometry>
    </collision>
  </link>
  
			# Index finger
			
  <!-- KNUCKLE -->
  <joint name="right_hand_v1s_index_knuckle_joint" type="fixed">
    <origin rpy="1.5707963267948966 -1.4835299330931884 1.5707963267948966" xyz="-0.0033 0.0195 0.0936994"/>
    <parent link="right_hand_v1s_palm_link"/>
    <child link="right_hand_v1s_index_knuckle_link"/>
    <limit effort="30" lower="-1.57" upper="1.57" velocity="1.0"/>
    <axis xyz="0 0 1"/>
    <dynamics damping="0.08" friction="0.0"/>
  </joint>
  <link name="right_hand_v1s_index_knuckle_link">
    <inertial>
      <origin xyz="0.001285644 0 0.000425011"/>
      <mass value="0.09"/>
      <inertia ixx="0.001" ixy="0" ixz="0" iyy="0.001" iyz="0" izz="0.001"/>
    </inertial>
    <visual>
      <geometry>
        <mesh filename="package://softhands_description/meshes/softhands/v1.0/common/knuckle_m.stl"/>
      </geometry>
    </visual>
    <collision>
      <geometry>
        <mesh filename="package://softhands_description/meshes/softhands/v1.0/common/knuckle_m.stl"/>
      </geometry>
    </collision>
  </link>
  <!-- PROXIMAL PHALANGE -->
  <joint name="right_hand_v1s_index_proximal_joint" type="fixed">
    <origin rpy="0 0 0" xyz="0.020 0 0"/>
    <parent link="right_hand_v1s_index_knuckle_link"/>
    <child link="right_hand_v1s_index_proximal_link"/>
    <limit effort="30" lower="-1.57" upper="1.57" velocity="1.0"/>
    <axis xyz="0 -1 0"/>
  </joint>
  <link name="right_hand_v1s_index_proximal_link">
    <inertial>
      <origin xyz="0.005074337 0 -0.000262953"/>
      <mass value="0.05"/>
      <inertia ixx="0.001" ixy="0" ixz="0" iyy="0.001" iyz="0" izz="0.001"/>
    </inertial>
    <visual>
      <geometry>
        <mesh filename="package://softhands_description/meshes/softhands/v1.0/common/phalanx_m.stl"/>
      </geometry>
    </visual>
    <collision>
      <geometry>
        <mesh filename="package://softhands_description/meshes/softhands/v1.0/common/phalanx_m.stl"/>
      </geometry>
    </collision>
  </link>
  <!-- MIDDLE PHALANGE -->
  <joint name="right_hand_v1s_index_middle_joint" type="fixed">
    <origin rpy="0 0 0" xyz="0.020 0 0"/>
    <parent link="right_hand_v1s_index_proximal_link"/>
    <child link="right_hand_v1s_index_middle_link"/>
    <limit effort="30" lower="-1.57" upper="1.57" velocity="1.0"/>
    <axis xyz="0 -1 0"/>
    <dynamics damping="0.08" friction="0.0"/>
  </joint>
  <link name="right_hand_v1s_index_middle_link">
    <inertial>
      <origin xyz="0.005074337 0 -0.000262953"/>
      <mass value="0.05"/>
      <inertia ixx="0.001" ixy="0" ixz="0" iyy="0.001" iyz="0" izz="0.001"/>
    </inertial>
    <visual>
      <geometry>
        <mesh filename="package://softhands_description/meshes/softhands/v1.0/common/phalanx_m.stl"/>
      </geometry>
    </visual>
    <collision>
      <geometry>
        <mesh filename="package://softhands_description/meshes/softhands/v1.0/common/phalanx_m.stl"/>
      </geometry>
    </collision>
  </link>
  <!-- DISTAL PHALANGE -->
  <joint name="right_hand_v1s_index_distal_joint" type="fixed">
    <origin rpy="0 0 0" xyz="0.020 0 0"/>
    <parent link="right_hand_v1s_index_middle_link"/>
    <child link="right_hand_v1s_index_distal_link"/>
    <limit effort="30" lower="-1.57" upper="1.57" velocity="1.0"/>
    <axis xyz="0 -1 0"/>
    <dynamics damping="0.08" friction="0.0"/>
  </joint>
  <link name="right_hand_v1s_index_distal_link">
    <inertial>
      <origin xyz="0.009849094 0 0.000820286"/>
      <mass value="0.1"/>
      <inertia ixx="0.001" ixy="0" ixz="0" iyy="0.001" iyz="0" izz="0.001"/>
    </inertial>
    <visual>
      <geometry>
        <mesh filename="package://softhands_description/meshes/softhands/v1.0/common/fingertip_m.stl"/>
      </geometry>
    </visual>
    <collision>
      <geometry>
        <mesh filename="package://softhands_description/meshes/softhands/v1.0/common/fingertip_m.stl"/>
      </geometry>
    </collision>
  </link>
  
			# Middle finger
			
  <!-- KNUCKLE -->
  <joint name="right_hand_v1s_middle_knuckle_joint" type="fixed">
    <origin rpy="3.141592 -1.5707963267948966 0.0" xyz="-0.003300000 0.0 0.100699"/>
    <parent link="right_hand_v1s_palm_link"/>
    <child link="right_hand_v1s_middle_knuckle_link"/>
    <limit effort="30" lower="-1.57" upper="1.57" velocity="1.0"/>
    <axis xyz="0 0 1"/>
    <dynamics damping="0.08" friction="0.0"/>
  </joint>
  <link name="right_hand_v1s_middle_knuckle_link">
    <inertial>
      <origin xyz="0.001285644 0 0.000425011"/>
      <mass value="0.09"/>
      <inertia ixx="0.001" ixy="0" ixz="0" iyy="0.001" iyz="0" izz="0.001"/>
    </inertial>
    <visual>
      <geometry>
        <mesh filename="package://softhands_description/meshes/softhands/v1.0/common/knuckle_m.stl"/>
      </geometry>
    </visual>
    <collision>
      <geometry>
        <mesh filename="package://softhands_description/meshes/softhands/v1.0/common/knuckle_m.stl"/>
      </geometry>
    </collision>
  </link>
  <!-- PROXIMAL PHALANGE -->
  <joint name="right_hand_v1s_middle_proximal_joint" type="fixed">
    <origin rpy="0 0 0" xyz="0.020 0 0"/>
    <parent link="right_hand_v1s_middle_knuckle_link"/>
    <child link="right_hand_v1s_middle_proximal_link"/>
    <limit effort="30" lower="-1.57" upper="1.57" velocity="1.0"/>
    <axis xyz="0 -1 0"/>
  </joint>
  <link name="right_hand_v1s_middle_proximal_link">
    <inertial>
      <origin xyz="0.005074337 0 -0.000262953"/>
      <mass value="0.05"/>
      <inertia ixx="0.001" ixy="0" ixz="0" iyy="0.001" iyz="0" izz="0.001"/>
    </inertial>
    <visual>
      <geometry>
        <mesh filename="package://softhands_description/meshes/softhands/v1.0/common/phalanx_m.stl"/>
      </geometry>
    </visual>
    <collision>
      <geometry>
        <mesh filename="package://softhands_description/meshes/softhands/v1.0/common/phalanx_m.stl"/>
      </geometry>
    </collision>
  </link>
  <!-- MIDDLE PHALANGE -->
  <joint name="right_hand_v1s_middle_middle_joint" type="fixed">
    <origin rpy="0 0 0" xyz="0.020 0 0"/>
    <parent link="right_hand_v1s_middle_proximal_link"/>
    <child link="right_hand_v1s_middle_middle_link"/>
    <limit effort="30" lower="-1.57" upper="1.57" velocity="1.0"/>
    <axis xyz="0 -1 0"/>
    <dynamics damping="0.08" friction="0.0"/>
  </joint>
  <link name="right_hand_v1s_middle_middle_link">
    <inertial>
      <origin xyz="0.005074337 0 -0.000262953"/>
      <mass value="0.05"/>
      <inertia ixx="0.001" ixy="0" ixz="0" iyy="0.001" iyz="0" izz="0.001"/>
    </inertial>
    <visual>
      <geometry>
        <mesh filename="package://softhands_description/meshes/softhands/v1.0/common/phalanx_m.stl"/>
      </geometry>
    </visual>
    <collision>
      <geometry>
        <mesh filename="package://softhands_description/meshes/softhands/v1.0/common/phalanx_m.stl"/>
      </geometry>
    </collision>
  </link>
  <!-- DISTAL PHALANGE -->
  <joint name="right_hand_v1s_middle_distal_joint" type="fixed">
    <origin rpy="0 0 0" xyz="0.020 0 0"/>
    <parent link="right_hand_v1s_middle_middle_link"/>
    <child link="right_hand_v1s_middle_distal_link"/>
    <limit effort="30" lower="-1.57" upper="1.57" velocity="1.0"/>
    <axis xyz="0 -1 0"/>
    <dynamics damping="0.08" friction="0.0"/>
  </joint>
  <link name="right_hand_v1s_middle_distal_link">
    <inertial>
      <origin xyz="0.009849094 0 0.000820286"/>
      <mass value="0.1"/>
      <inertia ixx="0.001" ixy="0" ixz="0" iyy="0.001" iyz="0" izz="0.001"/>
    </inertial>
    <visual>
      <geometry>
        <mesh filename="package://softhands_description/meshes/softhands/v1.0/common/fingertip_m.stl"/>
      </geometry>
    </visual>
    <collision>
      <geometry>
        <mesh filename="package://softhands_description/meshes/softhands/v1.0/common/fingertip_m.stl"/>
      </geometry>
    </collision>
  </link>
  
			# Ring finger
			
  <!-- KNUCKLE -->
  <joint name="right_hand_v1s_ring_knuckle_joint" type="fixed">
    <origin rpy="-1.5707963267948966 -1.5184364298870514 -1.5707963267948966" xyz="-0.0033 -0.0195 0.0936994"/>
    <parent link="right_hand_v1s_palm_link"/>
    <child link="right_hand_v1s_ring_knuckle_link"/>
    <limit effort="30" lower="-1.57" upper="1.57" velocity="1.0"/>
    <axis xyz="0 0 1"/>
    <dynamics damping="0.08" friction="0.0"/>
  </joint>
  <link name="right_hand_v1s_ring_knuckle_link">
    <inertial>
      <origin xyz="0.001285644 0 0.000425011"/>
      <mass value="0.09"/>
      <inertia ixx="0.001" ixy="0" ixz="0" iyy="0.001" iyz="0" izz="0.001"/>
    </inertial>
    <visual>
      <geometry>
        <mesh filename="package://softhands_description/meshes/softhands/v1.0/common/knuckle_m.stl"/>
      </geometry>
    </visual>
    <collision>
      <geometry>
        <mesh filename="package://softhands_description/meshes/softhands/v1.0/common/knuckle_m.stl"/>
      </geometry>
    </collision>
  </link>
  <!-- PROXIMAL PHALANGE -->
  <joint name="right_hand_v1s_ring_proximal_joint" type="fixed">
    <origin rpy="0 0 0" xyz="0.020 0 0"/>
    <parent link="right_hand_v1s_ring_knuckle_link"/>
    <child link="right_hand_v1s_ring_proximal_link"/>
    <limit effort="30" lower="-1.57" upper="1.57" velocity="1.0"/>
    <axis xyz="0 -1 0"/>
  </joint>
  <link name="right_hand_v1s_ring_proximal_link">
    <inertial>
      <origin xyz="0.005074337 0 -0.000262953"/>
      <mass value="0.05"/>
      <inertia ixx="0.001" ixy="0" ixz="0" iyy="0.001" iyz="0" izz="0.001"/>
    </inertial>
    <visual>
      <geometry>
        <mesh filename="package://softhands_description/meshes/softhands/v1.0/common/phalanx_m.stl"/>
      </geometry>
    </visual>
    <collision>
      <geometry>
        <mesh filename="package://softhands_description/meshes/softhands/v1.0/common/phalanx_m.stl"/>
      </geometry>
    </collision>
  </link>
  <!-- MIDDLE PHALANGE -->
  <joint name="right_hand_v1s_ring_middle_joint" type="fixed">
    <origin rpy="0 0 0" xyz="0.020 0 0"/>
    <parent link="right_hand_v1s_ring_proximal_link"/>
    <child link="right_hand_v1s_ring_middle_link"/>
    <limit effort="30" lower="-1.57" upper="1.57" velocity="1.0"/>
    <axis xyz="0 -1 0"/>
    <dynamics damping="0.08" friction="0.0"/>
  </joint>
  <link name="right_hand_v1s_ring_middle_link">
    <inertial>
      <origin xyz="0.005074337 0 -0.000262953"/>
      <mass value="0.05"/>
      <inertia ixx="0.001" ixy="0" ixz="0" iyy="0.001" iyz="0" izz="0.001"/>
    </inertial>
    <visual>
      <geometry>
        <mesh filename="package://softhands_description/meshes/softhands/v1.0/common/phalanx_m.stl"/>
      </geometry>
    </visual>
    <collision>
      <geometry>
        <mesh filename="package://softhands_description/meshes/softhands/v1.0/common/phalanx_m.stl"/>
      </geometry>
    </collision>
  </link>
  <!-- DISTAL PHALANGE -->
  <joint name="right_hand_v1s_ring_distal_joint" type="fixed">
    <origin rpy="0 0 0" xyz="0.020 0 0"/>
    <parent link="right_hand_v1s_ring_middle_link"/>
    <child link="right_hand_v1s_ring_distal_link"/>
    <limit effort="30" lower="-1.57" upper="1.57" velocity="1.0"/>
    <axis xyz="0 -1 0"/>
    <dynamics damping="0.08" friction="0.0"/>
  </joint>
  <link name="right_hand_v1s_ring_distal_link">
    <inertial>
      <origin xyz="0.009849094 0 0.000820286"/>
      <mass value="0.1"/>
      <inertia ixx="0.001" ixy="0" ixz="0" iyy="0.001" iyz="0" izz="0.001"/>
    </inertial>
    <visual>
      <geometry>
        <mesh filename="package://softhands_description/meshes/softhands/v1.0/common/fingertip_m.stl"/>
      </geometry>
    </visual>
    <collision>
      <geometry>
        <mesh filename="package://softhands_description/meshes/softhands/v1.0/common/fingertip_m.stl"/>
      </geometry>
    </collision>
  </link>
  
			# Little finger
			
  <!-- KNUCKLE -->
  <joint name="right_hand_v1s_little_knuckle_joint" type="fixed">
    <origin rpy="-1.5707963267948966 -1.4835299330931884 -1.5707963267948966" xyz="-0.0033 -0.039 0.0836994"/>
    <parent link="right_hand_v1s_palm_link"/>
    <child link="right_hand_v1s_little_knuckle_link"/>
    <limit effort="30" lower="-1.57" upper="1.57" velocity="1.0"/>
    <axis xyz="0 0 1"/>
    <dynamics damping="0.08" friction="0.0"/>
  </joint>
  <link name="right_hand_v1s_little_knuckle_link">
    <inertial>
      <origin xyz="0.001285644 0 0.000425011"/>
      <mass value="0.09"/>
      <inertia ixx="0.001" ixy="0" ixz="0" iyy="0.001" iyz="0" izz="0.001"/>
    </inertial>
    <visual>
      <geometry>
        <mesh filename="package://softhands_description/meshes/softhands/v1.0/common/knuckle_m.stl"/>
      </geometry>
    </visual>
    <collision>
      <geometry>
        <mesh filename="package://softhands_description/meshes/softhands/v1.0/common/knuckle_m.stl"/>
      </geometry>
    </collision>
  </link>
  <!-- PROXIMAL PHALANGE -->
  <joint name="right_hand_v1s_little_proximal_joint" type="fixed">
    <origin rpy="0 0 0" xyz="0.020 0 0"/>
    <parent link="right_hand_v1s_little_knuckle_link"/>
    <child link="right_hand_v1s_little_proximal_link"/>
    <limit effort="30" lower="-1.57" upper="1.57" velocity="1.0"/>
    <axis xyz="0 -1 0"/>
  </joint>
  <link name="right_hand_v1s_little_proximal_link">
    <inertial>
      <origin xyz="0.005074337 0 -0.000262953"/>
      <mass value="0.05"/>
      <inertia ixx="0.001" ixy="0" ixz="0" iyy="0.001" iyz="0" izz="0.001"/>
    </inertial>
    <visual>
      <geometry>
        <mesh filename="package://softhands_description/meshes/softhands/v1.0/common/phalanx_m.stl"/>
      </geometry>
    </visual>
    <collision>
      <geometry>
        <mesh filename="package://softhands_description/meshes/softhands/v1.0/common/phalanx_m.stl"/>
      </geometry>
    </collision>
  </link>
  <!-- MIDDLE PHALANGE -->
  <joint name="right_hand_v1s_little_middle_joint" type="fixed">
    <origin rpy="0 0 0" xyz="0.020 0 0"/>
    <parent link="right_hand_v1s_little_proximal_link"/>
    <child link="right_hand_v1s_little_middle_link"/>
    <limit effort="30" lower="-1.57" upper="1.57" velocity="1.0"/>
    <axis xyz="0 -1 0"/>
    <dynamics damping="0.08" friction="0.0"/>
  </joint>
  <link name="right_hand_v1s_little_middle_link">
    <inertial>
      <origin xyz="0.005074337 0 -0.000262953"/>
      <mass value="0.05"/>
      <inertia ixx="0.001" ixy="0" ixz="0" iyy="0.001" iyz="0" izz="0.001"/>
    </inertial>
    <visual>
      <geometry>
        <mesh filename="package://softhands_description/meshes/softhands/v1.0/common/phalanx_m.stl"/>
      </geometry>
    </visual>
    <collision>
      <geometry>
        <mesh filename="package://softhands_description/meshes/softhands/v1.0/common/phalanx_m.stl"/>
      </geometry>
    </collision>
  </link>
  <!-- DISTAL PHALANGE -->
  <joint name="right_hand_v1s_little_distal_joint" type="fixed">
    <origin rpy="0 0 0" xyz="0.020 0 0"/>
    <parent link="right_hand_v1s_little_middle_link"/>
    <child link="right_hand_v1s_little_distal_link"/>
    <limit effort="30" lower="-1.57" upper="1.57" velocity="1.0"/>
    <axis xyz="0 -1 0"/>
    <dynamics damping="0.08" friction="0.0"/>
  </joint>
  <link name="right_hand_v1s_little_distal_link">
    <inertial>
      <origin xyz="0.009849094 0 0.000820286"/>
      <mass value="0.1"/>
      <inertia ixx="0.001" ixy="0" ixz="0" iyy="0.001" iyz="0" izz="0.001"/>
    </inertial>
    <visual>
      <geometry>
        <mesh filename="package://softhands_description/meshes/softhands/v1.0/common/fingertip_m.stl"/>
      </geometry>
    </visual>
    <collision>
      <geometry>
        <mesh filename="package://softhands_description/meshes/softhands/v1.0/common/fingertip_m.stl"/>
      </geometry>
    </collision>
  </link>
  
		# LEFT HAND
		
  
		# Gazebo NEW custom synergy-plugin
		
  <gazebo>
    <plugin filename="libsofthand_plugin.so" name="synergy_plugin">
      <namespace>right_hand_v1s</namespace>
      <operation_mode>0</operation_mode>
    </plugin>
  </gazebo>
  

    # Softhand VERSION 2.0
    
  

    # Softhand VERSION 2.0 SIMPLIFIED (less joints)
    
  

    # TODO: OTHER VERSIONs

    
  <gazebo>
    <self_collide>1</self_collide>
  </gazebo>
  <gazebo reference="arm_1_link_1">
    <selfCollide> 1 </selfCollide>
  </gazebo>
  <gazebo reference="arm_1_link_2">
    <selfCollide> 1 </selfCollide>
  </gazebo>
  <gazebo reference="arm_1_link_3">
    <selfCollide> 1 </selfCollide>
  </gazebo>
  <gazebo reference="arm_1_link_4">
    <selfCollide> 1 </selfCollide>
  </gazebo>
  <gazebo reference="arm_1_link_5">
    <selfCollide> 1 </selfCollide>
  </gazebo>
  <gazebo reference="arm_1_link_6">
    <selfCollide> 1 </selfCollide>
  </gazebo>
  <!-- id: 1 for right arm, everything else is considered left arm -->
  <!-- base_link: name of base link a the single arm -->
  <!-- is_sliding_wrist: whether to add a sliding joint along the axis of wrist's second d.o.f.
    (true -> yes), everything else -> no -->
  <joint name="arm_2_joint_1" type="revolute">
    <origin rpy="-1.57079632679 0 0" xyz="0 0 0"/>
    <parent link="l_arm_mount_frame"/>
    <child link="arm_2_link_1"/>
    <axis xyz="0 0 1"/>
    <limit effort="200.0" lower="-2.6179938779916667" upper="2.6179938779916667" velocity="10.0"/>
  </joint>
  <link name="arm_2_link_1">
    <inertial>
      <mass value="2"/>
      <inertia ixx="0.0015" ixy="-9.999999999999999e-05" ixz="0.0" iyy="0.0026999999999999997" iyz="9.999999999999999e-05" izz="0.0028"/>
      <origin xyz="0 0 -0.01"/>
    </inertial>
    <collision name="arm_2_link_1_collision">
      <geometry>
        <mesh filename="package://repair_urdf/meshes/base_meshes/link_1_mirror.stl" scale="0.001 0.001 0.001"/>
      </geometry>
      <material name="dark"/>
    </collision>
    <visual name="arm_2_link_1_visual">
      <geometry>
        <mesh filename="package://repair_urdf/meshes/base_meshes/link_1_mirror.stl" scale="0.001 0.001 0.001"/>
      </geometry>
      <material name="dark"/>
    </visual>
  </link>
  <joint name="arm_2_joint_2" type="revolute">
    <origin rpy="0 -1.57079632679 -3.14159265359" xyz="0.0385 0.023 0"/>
    <parent link="arm_2_link_1"/>
    <child link="arm_2_link_2"/>
    <axis xyz="0 0 1"/>
    <limit effort="200.0" lower="-1.3962634015955555" upper="2.1816615649930555" velocity="10.0"/>
  </joint>
  <link name="arm_2_link_2">
    <inertial>
      <mass value="0.4"/>
      <inertia ixx="0.00067" ixy="0.0" ixz="0.00017999999999999998" iyy="0.0009699999999999999" iyz="0.0" izz="0.001"/>
      <origin xyz="0.04 0.0 0.035"/>
    </inertial>
    <collision name="arm_2_link_2_collision">
      <geometry>
        <mesh filename="package://repair_urdf/meshes/base_meshes/link_2.stl" scale="0.001 0.001 0.001"/>
      </geometry>
      <material name="dark"/>
    </collision>
    <visual name="arm_2_link_2_visual">
      <geometry>
        <mesh filename="package://repair_urdf/meshes/base_meshes/link_2.stl" scale="0.001 0.001 0.001"/>
      </geometry>
      <material name="dark"/>
    </visual>
  </link>
  <joint name="arm_2_joint_3" type="revolute">
    <origin rpy="0 -1.57079632679 -3.14159265359" xyz="0.005 0 0"/>
    <parent link="arm_2_link_2"/>
    <child link="arm_2_link_3"/>
    <axis xyz="0 0 1"/>
    <limit effort="200.0" lower="-2.6179938779916667" upper="2.6179938779916667" velocity="10.0"/>
  </joint>
  <link name="arm_2_link_3">
    <inertial>
      <mass value="3.3"/>
      <inertia ixx="0.024999999999999998" ixy="0.0" ixz="0.0" iyy="0.026" iyz="0.0" izz="0.022"/>
      <origin xyz="0.0 -0.025 0.23"/>
    </inertial>
    <collision name="arm_2_link_3_collision">
      <geometry>
        <mesh filename="package://repair_urdf/meshes/base_meshes/link_3.stl" scale="0.001 0.001 0.001"/>
      </geometry>
      <material name="dark"/>
    </collision>
    <visual name="arm_2_link_3_visual">
      <geometry>
        <mesh filename="package://repair_urdf/meshes/base_meshes/link_3.stl" scale="0.001 0.001 0.001"/>
      </geometry>
      <material name="dark"/>
    </visual>
  </link>
  <joint name="arm_2_joint_4" type="revolute">
    <origin rpy="0 -1.57079632679 -3.14159265359" xyz="0 0.0225 0.36014999999999997"/>
    <parent link="arm_2_link_3"/>
    <child link="arm_2_link_4"/>
    <axis xyz="0 0 1"/>
    <limit effort="200.0" lower="-2.6179938779916667" upper="1.0471975511966667" velocity="10.0"/>
  </joint>
  <link name="arm_2_link_4">
    <inertial>
      <mass value="0.4"/>
      <inertia ixx="0.00067" ixy="0.0" ixz="0.00017999999999999998" iyy="0.0009699999999999999" iyz="0.0" izz="0.001"/>
      <origin xyz="0.04 0.0 0.035"/>
    </inertial>
    <collision name="arm_2_link_4_collision">
      <geometry>
        <mesh filename="package://repair_urdf/meshes/base_meshes/link_4.stl" scale="0.001 0.001 0.001"/>
      </geometry>
      <material name="dark"/>
    </collision>
    <visual name="arm_2_link_4_visual">
      <geometry>
        <mesh filename="package://repair_urdf/meshes/base_meshes/link_4.stl" scale="0.001 0.001 0.001"/>
      </geometry>
      <material name="dark"/>
    </visual>
  </link>
  <joint name="arm_2_joint_5" type="revolute">
    <origin rpy="-1.57079632679 0 -1.57079632679" xyz="0.005 0 0"/>
    <parent link="arm_2_link_4"/>
    <child link="arm_2_link_5"/>
    <axis xyz="0 0 1"/>
    <limit effort="200.0" lower="-2.6179938779916667" upper="2.6179938779916667" velocity="10.0"/>
  </joint>
  <link name="arm_2_link_5">
    <inertial>
      <mass value="2.8"/>
      <inertia ixx="0.032" ixy="0.0" ixz="0.0017" iyy="0.033999999999999996" iyz="0.0" izz="0.028999999999999998"/>
      <origin xyz="-0.005 0.0 0.2"/>
    </inertial>
    <collision name="arm_2_link_5_collision">
      <origin rpy="0 0 0" xyz="0 0 0"/>
      <geometry>
        <mesh filename="package://repair_urdf/meshes/base_meshes/link_5.stl" scale="0.001 0.001 0.001"/>
      </geometry>
      <material name="dark"/>
    </collision>
    <visual name="arm_2_link_5_visual">
      <origin rpy="0 0 0" xyz="0 0 0"/>
      <geometry>
        <mesh filename="package://repair_urdf/meshes/base_meshes/link_5.stl" scale="0.001 0.001 0.001"/>
      </geometry>
      <material name="dark"/>
    </visual>
  </link>
  <joint name="arm_2_joint_6" type="revolute">
    <origin rpy="0 -1.57079632679 0" xyz="0 0.0 0.321 "/>
    <axis xyz="0 0 1"/>
    <parent link="arm_2_link_5"/>
    <child link="dummy_sliding_wrist2_link"/>
    <limit effort="200.0" lower="-2.6179938779916667" upper="2.6179938779916667" velocity="10.0"/>
  </joint>
  <link name="dummy_sliding_wrist2_link">
    
    </link>
  <joint name="dummy_sliding_wrist2_joint" type="fixed">
    <origin rpy="0 0 0" xyz="0.0 0.0 -0.0"/>
    <parent link="dummy_sliding_wrist2_link"/>
    <child link="arm_2_link_6"/>
  </joint>
  <link name="arm_2_link_6">
    <inertial>
      <mass value="1.8"/>
      <inertia ixx="0.0017" ixy="0.0" ixz="0.0" iyy="0.0025" iyz="9.999999999999999e-05" izz="0.0026999999999999997"/>
      <origin xyz="0.0 0.0 0.0"/>
    </inertial>
    <collision name="arm_2_link_6_collision">
      <origin rpy="0 0 0" xyz="0 0 0"/>
      <geometry>
        <mesh filename="package://repair_urdf/meshes/base_meshes/link_6.stl" scale="0.001 0.001 0.001"/>
      </geometry>
      <material name="dark"/>
    </collision>
    <visual name="arm_2_link_6_visual">
      <origin rpy="0 0 0" xyz="0 0 0"/>
      <geometry>
        <mesh filename="package://repair_urdf/meshes/base_meshes/link_6.stl" scale="0.001 0.001 0.001"/>
      </geometry>
      <material name="dark"/>
    </visual>
  </link>
  <joint name="arm_2_joint_7" type="revolute">
    <origin rpy="-1.57079632679 3.14159265359 -1.57079632679" xyz="0.08 0 0"/>
    <!-- <origin xyz="${180.000 * mmTom} 0 0" rpy="${-PI_2} 0 ${-PI_2}"/> -->
    <parent link="arm_2_link_6"/>
    <child link="arm_2_link_7"/>
    <axis xyz="0 0 1"/>
    <limit effort="200.0" lower="-2.6179938779916667" upper="2.6179938779916667" velocity="10.0"/>
  </joint>
  <link name="arm_2_link_7">
    <inertial>
      <mass value="1.5"/>
      <inertia ixx="0.024999999999999998" ixy="0.0" ixz="0.0" iyy="0.024999999999999998" iyz="9.999999999999999e-05" izz="0.023"/>
      <origin xyz="0.0 0.0 0.0"/>
    </inertial>
  </link>
  

    # Softhand VERSION 1.0
    
  

    # Softhand VERSION 1.0 SIMPLIFIED (less joints)
    
  
		# Softhand Base
		
  <joint name="left_hand_base_joint" type="fixed">
    <origin rpy="0 0 0" xyz="0 -0.015 0"/>
    <parent link="arm_2_link_7"/>
    <child link="left_hand_v1s_palm_base"/>
  </joint>
  <link name="left_hand_v1s_palm_base"/>
  
		# RIGHT HAND
		
  
		# LEFT HAND
		
  
			# Palm
			
  <joint name="left_hand_v1s_palm_joint" type="fixed">
    <origin rpy="0 0 0" xyz="0.002 0.00695 0.0535"/>
    <parent link="left_hand_v1s_palm_base"/>
    <child link="left_hand_v1s_palm_link"/>
  </joint>
  <link name="left_hand_v1s_palm_link">
    <inertial>
      <origin xyz="-0.004568758 -0.006808116 0.027653328"/>
      <mass value="2.28"/>
      <inertia ixx="0.001" ixy="0" ixz="0" iyy="0.001" iyz="0" izz="0.001"/>
    </inertial>
    <visual>
      <geometry>
        <mesh filename="package://softhands_description/meshes/softhands/v1.0/left/palm_left_m.stl"/>
      </geometry>
    </visual>
    <collision>
      <geometry>
        <mesh filename="package://softhands_description/meshes/softhands/v1.0/left/palm_left_m.stl"/>
      </geometry>
    </collision>
    <visual>
      <origin rpy="0 0 0" xyz="-0.002 0.00695 -0.0535"/>
      <geometry>
        <mesh filename="package://softhands_description/meshes/softhands/v1.0/left/softhand_base_left_m.stl"/>
      </geometry>
    </visual>
    <collision>
      <origin rpy="0 0 0" xyz="-0.002 0.00695 -0.0535"/>
      <geometry>
        <mesh filename="package://softhands_description/meshes/softhands/v1.0/right/softhand_base_right_m.stl"/>
      </geometry>
    </collision>
  </link>
  
			# Thumb finger
			
  <!-- KNUCKLE -->
  <joint name="left_hand_v1s_thumb_knuckle_joint" type="fixed">
    <origin rpy="0.0 -0.38397275793662144 -1.5707963267948966" xyz="0.005669722 -0.029616 0.055314"/>
    <parent link="left_hand_v1s_palm_link"/>
    <child link="left_hand_v1s_thumb_knuckle_link"/>
    <axis xyz="0 0 1"/>
    <dynamics damping="0.08" friction="0.0"/>
  </joint>
  <link name="left_hand_v1s_thumb_knuckle_link">
    <inertial>
      <origin xyz="0.001285644 0 0.000425011"/>
      <mass value="0.09"/>
      <inertia ixx="0.001" ixy="0" ixz="0" iyy="0.001" iyz="0" izz="0.001"/>
    </inertial>
    <visual>
      <geometry>
        <mesh filename="package://softhands_description/meshes/softhands/v1.0/left/thumb_knuckle_left_m.stl"/>
      </geometry>
    </visual>
    <collision>
      <geometry>
        <mesh filename="package://softhands_description/meshes/softhands/v1.0/left/thumb_knuckle_left_m.stl"/>
      </geometry>
    </collision>
  </link>
  <!-- PROXIMAL PHALANGE -->
  <joint name="left_hand_v1s_thumb_proximal_joint" type="fixed">
    <origin rpy="-0.426627741408745 0 0.0" xyz="0.033500000 0.0033 0.0"/>
    <parent link="left_hand_v1s_thumb_knuckle_link"/>
    <child link="left_hand_v1s_thumb_proximal_link"/>
    <axis xyz="0 -1 0"/>
    <dynamics damping="0.08" friction="0.0"/>
  </joint>
  <link name="left_hand_v1s_thumb_proximal_link">
    <inertial>
      <origin xyz="0.005074337 0 -0.000262953"/>
      <mass value="0.05"/>
      <inertia ixx="0.001" ixy="0" ixz="0" iyy="0.001" iyz="0" izz="0.001"/>
    </inertial>
    <visual>
      <geometry>
        <mesh filename="package://softhands_description/meshes/softhands/v1.0/common/phalanx_m.stl"/>
      </geometry>
    </visual>
    <collision>
      <geometry>
        <mesh filename="package://softhands_description/meshes/softhands/v1.0/common/phalanx_m.stl"/>
      </geometry>
    </collision>
  </link>
  <!-- DISTAL PHALANGE -->
  <joint name="left_hand_v1s_thumb_distal_joint" type="fixed">
    <origin rpy="0 0 0" xyz="0.020 0 0.0"/>
    <parent link="left_hand_v1s_thumb_proximal_link"/>
    <child link="left_hand_v1s_thumb_distal_link"/>
    <axis xyz="0 -1 0"/>
    <dynamics damping="0.08" friction="0.0"/>
  </joint>
  <link name="left_hand_v1s_thumb_distal_link">
    <inertial>
      <origin xyz="0.009849094 0 0.000820286"/>
      <mass value="0.1"/>
      <inertia ixx="0.001" ixy="0" ixz="0" iyy="0.001" iyz="0" izz="0.001"/>
    </inertial>
    <visual>
      <geometry>
        <mesh filename="package://softhands_description/meshes/softhands/v1.0/common/fingertip_m.stl"/>
      </geometry>
    </visual>
    <collision>
      <geometry>
        <mesh filename="package://softhands_description/meshes/softhands/v1.0/common/fingertip_m.stl"/>
      </geometry>
    </collision>
  </link>
  
			# Index finger
			
  <!-- KNUCKLE -->
  <joint name="left_hand_v1s_index_knuckle_joint" type="fixed">
    <origin rpy="-1.5707963267948966 -1.4835299330931884 -1.5707963267948966" xyz="-0.0033 -0.0195 0.0936994"/>
    <parent link="left_hand_v1s_palm_link"/>
    <child link="left_hand_v1s_index_knuckle_link"/>
    <limit effort="30" lower="-1.57" upper="1.57" velocity="1.0"/>
    <axis xyz="0 0 -1"/>
    <dynamics damping="0.08" friction="0.0"/>
  </joint>
  <link name="left_hand_v1s_index_knuckle_link">
    <inertial>
      <origin xyz="0.001285644 0 0.000425011"/>
      <mass value="0.09"/>
      <inertia ixx="0.001" ixy="0" ixz="0" iyy="0.001" iyz="0" izz="0.001"/>
    </inertial>
    <visual>
      <geometry>
        <mesh filename="package://softhands_description/meshes/softhands/v1.0/common/knuckle_m.stl"/>
      </geometry>
    </visual>
    <collision>
      <geometry>
        <mesh filename="package://softhands_description/meshes/softhands/v1.0/common/knuckle_m.stl"/>
      </geometry>
    </collision>
  </link>
  <!-- PROXIMAL PHALANGE -->
  <joint name="left_hand_v1s_index_proximal_joint" type="fixed">
    <origin rpy="0 0 0" xyz="0.020 0 0"/>
    <parent link="left_hand_v1s_index_knuckle_link"/>
    <child link="left_hand_v1s_index_proximal_link"/>
    <limit effort="30" lower="-1.57" upper="1.57" velocity="1.0"/>
    <axis xyz="0 -1 0"/>
  </joint>
  <link name="left_hand_v1s_index_proximal_link">
    <inertial>
      <origin xyz="0.005074337 0 -0.000262953"/>
      <mass value="0.05"/>
      <inertia ixx="0.001" ixy="0" ixz="0" iyy="0.001" iyz="0" izz="0.001"/>
    </inertial>
    <visual>
      <geometry>
        <mesh filename="package://softhands_description/meshes/softhands/v1.0/common/phalanx_m.stl"/>
      </geometry>
    </visual>
    <collision>
      <geometry>
        <mesh filename="package://softhands_description/meshes/softhands/v1.0/common/phalanx_m.stl"/>
      </geometry>
    </collision>
  </link>
  <!-- MIDDLE PHALANGE -->
  <joint name="left_hand_v1s_index_middle_joint" type="fixed">
    <origin rpy="0 0 0" xyz="0.020 0 0"/>
    <parent link="left_hand_v1s_index_proximal_link"/>
    <child link="left_hand_v1s_index_middle_link"/>
    <limit effort="30" lower="-1.57" upper="1.57" velocity="1.0"/>
    <axis xyz="0 -1 0"/>
    <dynamics damping="0.08" friction="0.0"/>
  </joint>
  <link name="left_hand_v1s_index_middle_link">
    <inertial>
      <origin xyz="0.005074337 0 -0.000262953"/>
      <mass value="0.05"/>
      <inertia ixx="0.001" ixy="0" ixz="0" iyy="0.001" iyz="0" izz="0.001"/>
    </inertial>
    <visual>
      <geometry>
        <mesh filename="package://softhands_description/meshes/softhands/v1.0/common/phalanx_m.stl"/>
      </geometry>
    </visual>
    <collision>
      <geometry>
        <mesh filename="package://softhands_description/meshes/softhands/v1.0/common/phalanx_m.stl"/>
      </geometry>
    </collision>
  </link>
  <!-- DISTAL PHALANGE -->
  <joint name="left_hand_v1s_index_distal_joint" type="fixed">
    <origin rpy="0 0 0" xyz="0.020 0 0"/>
    <parent link="left_hand_v1s_index_middle_link"/>
    <child link="left_hand_v1s_index_distal_link"/>
    <limit effort="30" lower="-1.57" upper="1.57" velocity="1.0"/>
    <axis xyz="0 -1 0"/>
    <dynamics damping="0.08" friction="0.0"/>
  </joint>
  <link name="left_hand_v1s_index_distal_link">
    <inertial>
      <origin xyz="0.009849094 0 0.000820286"/>
      <mass value="0.1"/>
      <inertia ixx="0.001" ixy="0" ixz="0" iyy="0.001" iyz="0" izz="0.001"/>
    </inertial>
    <visual>
      <geometry>
        <mesh filename="package://softhands_description/meshes/softhands/v1.0/common/fingertip_m.stl"/>
      </geometry>
    </visual>
    <collision>
      <geometry>
        <mesh filename="package://softhands_description/meshes/softhands/v1.0/common/fingertip_m.stl"/>
      </geometry>
    </collision>
  </link>
  
			# Middle finger
			
  <!-- KNUCKLE -->
  <joint name="left_hand_v1s_middle_knuckle_joint" type="fixed">
    <origin rpy="3.1415 -1.5707963267948966 0.0" xyz="-0.0033 0.0 0.100699"/>
    <parent link="left_hand_v1s_palm_link"/>
    <child link="left_hand_v1s_middle_knuckle_link"/>
    <limit effort="30" lower="-1.57" upper="1.57" velocity="1.0"/>
    <axis xyz="0 0 -1"/>
    <dynamics damping="0.08" friction="0.0"/>
  </joint>
  <link name="left_hand_v1s_middle_knuckle_link">
    <inertial>
      <origin xyz="0.001285644 0 0.000425011"/>
      <mass value="0.09"/>
      <inertia ixx="0.001" ixy="0" ixz="0" iyy="0.001" iyz="0" izz="0.001"/>
    </inertial>
    <visual>
      <geometry>
        <mesh filename="package://softhands_description/meshes/softhands/v1.0/common/knuckle_m.stl"/>
      </geometry>
    </visual>
    <collision>
      <geometry>
        <mesh filename="package://softhands_description/meshes/softhands/v1.0/common/knuckle_m.stl"/>
      </geometry>
    </collision>
  </link>
  <!-- PROXIMAL PHALANGE -->
  <joint name="left_hand_v1s_middle_proximal_joint" type="fixed">
    <origin rpy="0 0 0" xyz="0.020 0 0"/>
    <parent link="left_hand_v1s_middle_knuckle_link"/>
    <child link="left_hand_v1s_middle_proximal_link"/>
    <limit effort="30" lower="-1.57" upper="1.57" velocity="1.0"/>
    <axis xyz="0 -1 0"/>
  </joint>
  <link name="left_hand_v1s_middle_proximal_link">
    <inertial>
      <origin xyz="0.005074337 0 -0.000262953"/>
      <mass value="0.05"/>
      <inertia ixx="0.001" ixy="0" ixz="0" iyy="0.001" iyz="0" izz="0.001"/>
    </inertial>
    <visual>
      <geometry>
        <mesh filename="package://softhands_description/meshes/softhands/v1.0/common/phalanx_m.stl"/>
      </geometry>
    </visual>
    <collision>
      <geometry>
        <mesh filename="package://softhands_description/meshes/softhands/v1.0/common/phalanx_m.stl"/>
      </geometry>
    </collision>
  </link>
  <!-- MIDDLE PHALANGE -->
  <joint name="left_hand_v1s_middle_middle_joint" type="fixed">
    <origin rpy="0 0 0" xyz="0.020 0 0"/>
    <parent link="left_hand_v1s_middle_proximal_link"/>
    <child link="left_hand_v1s_middle_middle_link"/>
    <limit effort="30" lower="-1.57" upper="1.57" velocity="1.0"/>
    <axis xyz="0 -1 0"/>
    <dynamics damping="0.08" friction="0.0"/>
  </joint>
  <link name="left_hand_v1s_middle_middle_link">
    <inertial>
      <origin xyz="0.005074337 0 -0.000262953"/>
      <mass value="0.05"/>
      <inertia ixx="0.001" ixy="0" ixz="0" iyy="0.001" iyz="0" izz="0.001"/>
    </inertial>
    <visual>
      <geometry>
        <mesh filename="package://softhands_description/meshes/softhands/v1.0/common/phalanx_m.stl"/>
      </geometry>
    </visual>
    <collision>
      <geometry>
        <mesh filename="package://softhands_description/meshes/softhands/v1.0/common/phalanx_m.stl"/>
      </geometry>
    </collision>
  </link>
  <!-- DISTAL PHALANGE -->
  <joint name="left_hand_v1s_middle_distal_joint" type="fixed">
    <origin rpy="0 0 0" xyz="0.020 0 0"/>
    <parent link="left_hand_v1s_middle_middle_link"/>
    <child link="left_hand_v1s_middle_distal_link"/>
    <limit effort="30" lower="-1.57" upper="1.57" velocity="1.0"/>
    <axis xyz="0 -1 0"/>
    <dynamics damping="0.08" friction="0.0"/>
  </joint>
  <link name="left_hand_v1s_middle_distal_link">
    <inertial>
      <origin xyz="0.009849094 0 0.000820286"/>
      <mass value="0.1"/>
      <inertia ixx="0.001" ixy="0" ixz="0" iyy="0.001" iyz="0" izz="0.001"/>
    </inertial>
    <visual>
      <geometry>
        <mesh filename="package://softhands_description/meshes/softhands/v1.0/common/fingertip_m.stl"/>
      </geometry>
    </visual>
    <collision>
      <geometry>
        <mesh filename="package://softhands_description/meshes/softhands/v1.0/common/fingertip_m.stl"/>
      </geometry>
    </collision>
  </link>
  
			# Ring finger
			
  <!-- KNUCKLE -->
  <joint name="left_hand_v1s_ring_knuckle_joint" type="fixed">
    <origin rpy="1.5707963267948966 -1.5184364298870514 1.5707963267948966" xyz="-0.0033 0.0195 0.0936994"/>
    <parent link="left_hand_v1s_palm_link"/>
    <child link="left_hand_v1s_ring_knuckle_link"/>
    <limit effort="30" lower="-1.57" upper="1.57" velocity="1.0"/>
    <axis xyz="0 0 -1"/>
    <dynamics damping="0.08" friction="0.0"/>
  </joint>
  <link name="left_hand_v1s_ring_knuckle_link">
    <inertial>
      <origin xyz="0.001285644 0 0.000425011"/>
      <mass value="0.09"/>
      <inertia ixx="0.001" ixy="0" ixz="0" iyy="0.001" iyz="0" izz="0.001"/>
    </inertial>
    <visual>
      <geometry>
        <mesh filename="package://softhands_description/meshes/softhands/v1.0/common/knuckle_m.stl"/>
      </geometry>
    </visual>
    <collision>
      <geometry>
        <mesh filename="package://softhands_description/meshes/softhands/v1.0/common/knuckle_m.stl"/>
      </geometry>
    </collision>
  </link>
  <!-- PROXIMAL PHALANGE -->
  <joint name="left_hand_v1s_ring_proximal_joint" type="fixed">
    <origin rpy="0 0 0" xyz="0.020 0 0"/>
    <parent link="left_hand_v1s_ring_knuckle_link"/>
    <child link="left_hand_v1s_ring_proximal_link"/>
    <limit effort="30" lower="-1.57" upper="1.57" velocity="1.0"/>
    <axis xyz="0 -1 0"/>
  </joint>
  <link name="left_hand_v1s_ring_proximal_link">
    <inertial>
      <origin xyz="0.005074337 0 -0.000262953"/>
      <mass value="0.05"/>
      <inertia ixx="0.001" ixy="0" ixz="0" iyy="0.001" iyz="0" izz="0.001"/>
    </inertial>
    <visual>
      <geometry>
        <mesh filename="package://softhands_description/meshes/softhands/v1.0/common/phalanx_m.stl"/>
      </geometry>
    </visual>
    <collision>
      <geometry>
        <mesh filename="package://softhands_description/meshes/softhands/v1.0/common/phalanx_m.stl"/>
      </geometry>
    </collision>
  </link>
  <!-- MIDDLE PHALANGE -->
  <joint name="left_hand_v1s_ring_middle_joint" type="fixed">
    <origin rpy="0 0 0" xyz="0.020 0 0"/>
    <parent link="left_hand_v1s_ring_proximal_link"/>
    <child link="left_hand_v1s_ring_middle_link"/>
    <limit effort="30" lower="-1.57" upper="1.57" velocity="1.0"/>
    <axis xyz="0 -1 0"/>
    <dynamics damping="0.08" friction="0.0"/>
  </joint>
  <link name="left_hand_v1s_ring_middle_link">
    <inertial>
      <origin xyz="0.005074337 0 -0.000262953"/>
      <mass value="0.05"/>
      <inertia ixx="0.001" ixy="0" ixz="0" iyy="0.001" iyz="0" izz="0.001"/>
    </inertial>
    <visual>
      <geometry>
        <mesh filename="package://softhands_description/meshes/softhands/v1.0/common/phalanx_m.stl"/>
      </geometry>
    </visual>
    <collision>
      <geometry>
        <mesh filename="package://softhands_description/meshes/softhands/v1.0/common/phalanx_m.stl"/>
      </geometry>
    </collision>
  </link>
  <!-- DISTAL PHALANGE -->
  <joint name="left_hand_v1s_ring_distal_joint" type="fixed">
    <origin rpy="0 0 0" xyz="0.020 0 0"/>
    <parent link="left_hand_v1s_ring_middle_link"/>
    <child link="left_hand_v1s_ring_distal_link"/>
    <limit effort="30" lower="-1.57" upper="1.57" velocity="1.0"/>
    <axis xyz="0 -1 0"/>
    <dynamics damping="0.08" friction="0.0"/>
  </joint>
  <link name="left_hand_v1s_ring_distal_link">
    <inertial>
      <origin xyz="0.009849094 0 0.000820286"/>
      <mass value="0.1"/>
      <inertia ixx="0.001" ixy="0" ixz="0" iyy="0.001" iyz="0" izz="0.001"/>
    </inertial>
    <visual>
      <geometry>
        <mesh filename="package://softhands_description/meshes/softhands/v1.0/common/fingertip_m.stl"/>
      </geometry>
    </visual>
    <collision>
      <geometry>
        <mesh filename="package://softhands_description/meshes/softhands/v1.0/common/fingertip_m.stl"/>
      </geometry>
    </collision>
  </link>
  
			# Little finger
			
  <!-- KNUCKLE -->
  <joint name="left_hand_v1s_little_knuckle_joint" type="fixed">
    <origin rpy="1.5707963267948966 -1.4835299330931884 1.5707963267948966" xyz="-0.0033 0.039 0.0836994"/>
    <parent link="left_hand_v1s_palm_link"/>
    <child link="left_hand_v1s_little_knuckle_link"/>
    <limit effort="30" lower="-1.57" upper="1.57" velocity="1.0"/>
    <axis xyz="0 0 -1"/>
    <dynamics damping="0.08" friction="0.0"/>
  </joint>
  <link name="left_hand_v1s_little_knuckle_link">
    <inertial>
      <origin xyz="0.001285644 0 0.000425011"/>
      <mass value="0.09"/>
      <inertia ixx="0.001" ixy="0" ixz="0" iyy="0.001" iyz="0" izz="0.001"/>
    </inertial>
    <visual>
      <geometry>
        <mesh filename="package://softhands_description/meshes/softhands/v1.0/common/knuckle_m.stl"/>
      </geometry>
    </visual>
    <collision>
      <geometry>
        <mesh filename="package://softhands_description/meshes/softhands/v1.0/common/knuckle_m.stl"/>
      </geometry>
    </collision>
  </link>
  <!-- PROXIMAL PHALANGE -->
  <joint name="left_hand_v1s_little_proximal_joint" type="fixed">
    <origin rpy="0 0 0" xyz="0.020 0 0"/>
    <parent link="left_hand_v1s_little_knuckle_link"/>
    <child link="left_hand_v1s_little_proximal_link"/>
    <limit effort="30" lower="-1.57" upper="1.57" velocity="1.0"/>
    <axis xyz="0 -1 0"/>
  </joint>
  <link name="left_hand_v1s_little_proximal_link">
    <inertial>
      <origin xyz="0.005074337 0 -0.000262953"/>
      <mass value="0.05"/>
      <inertia ixx="0.001" ixy="0" ixz="0" iyy="0.001" iyz="0" izz="0.001"/>
    </inertial>
    <visual>
      <geometry>
        <mesh filename="package://softhands_description/meshes/softhands/v1.0/common/phalanx_m.stl"/>
      </geometry>
    </visual>
    <collision>
      <geometry>
        <mesh filename="package://softhands_description/meshes/softhands/v1.0/common/phalanx_m.stl"/>
      </geometry>
    </collision>
  </link>
  <!-- MIDDLE PHALANGE -->
  <joint name="left_hand_v1s_little_middle_joint" type="fixed">
    <origin rpy="0 0 0" xyz="0.020 0 0"/>
    <parent link="left_hand_v1s_little_proximal_link"/>
    <child link="left_hand_v1s_little_middle_link"/>
    <limit effort="30" lower="-1.57" upper="1.57" velocity="1.0"/>
    <axis xyz="0 -1 0"/>
    <dynamics damping="0.08" friction="0.0"/>
  </joint>
  <link name="left_hand_v1s_little_middle_link">
    <inertial>
      <origin xyz="0.005074337 0 -0.000262953"/>
      <mass value="0.05"/>
      <inertia ixx="0.001" ixy="0" ixz="0" iyy="0.001" iyz="0" izz="0.001"/>
    </inertial>
    <visual>
      <geometry>
        <mesh filename="package://softhands_description/meshes/softhands/v1.0/common/phalanx_m.stl"/>
      </geometry>
    </visual>
    <collision>
      <geometry>
        <mesh filename="package://softhands_description/meshes/softhands/v1.0/common/phalanx_m.stl"/>
      </geometry>
    </collision>
  </link>
  <!-- DISTAL PHALANGE -->
  <joint name="left_hand_v1s_little_distal_joint" type="fixed">
    <origin rpy="0 0 0" xyz="0.020 0 0"/>
    <parent link="left_hand_v1s_little_middle_link"/>
    <child link="left_hand_v1s_little_distal_link"/>
    <limit effort="30" lower="-1.57" upper="1.57" velocity="1.0"/>
    <axis xyz="0 -1 0"/>
    <dynamics damping="0.08" friction="0.0"/>
  </joint>
  <link name="left_hand_v1s_little_distal_link">
    <inertial>
      <origin xyz="0.009849094 0 0.000820286"/>
      <mass value="0.1"/>
      <inertia ixx="0.001" ixy="0" ixz="0" iyy="0.001" iyz="0" izz="0.001"/>
    </inertial>
    <visual>
      <geometry>
        <mesh filename="package://softhands_description/meshes/softhands/v1.0/common/fingertip_m.stl"/>
      </geometry>
    </visual>
    <collision>
      <geometry>
        <mesh filename="package://softhands_description/meshes/softhands/v1.0/common/fingertip_m.stl"/>
      </geometry>
    </collision>
  </link>
  
		# Gazebo NEW custom synergy-plugin
		
  <gazebo>
    <plugin filename="libsofthand_plugin.so" name="synergy_plugin">
      <namespace>left_hand_v1s</namespace>
      <operation_mode>0</operation_mode>
    </plugin>
  </gazebo>
  

    # Softhand VERSION 2.0
    
  

    # Softhand VERSION 2.0 SIMPLIFIED (less joints)
    
  

    # TODO: OTHER VERSIONs

    
  <gazebo>
    <self_collide>1</self_collide>
  </gazebo>
  <gazebo reference="arm_2_link_1">
    <selfCollide> 1 </selfCollide>
  </gazebo>
  <gazebo reference="arm_2_link_2">
    <selfCollide> 1 </selfCollide>
  </gazebo>
  <gazebo reference="arm_2_link_3">
    <selfCollide> 1 </selfCollide>
  </gazebo>
  <gazebo reference="arm_2_link_4">
    <selfCollide> 1 </selfCollide>
  </gazebo>
  <gazebo reference="arm_2_link_5">
    <selfCollide> 1 </selfCollide>
  </gazebo>
  <gazebo reference="arm_2_link_6">
    <selfCollide> 1 </selfCollide>
  </gazebo>
  <gazebo reference="arm_1_link_1">
    <material>Gazebo/BlackTransparent   </material>
  </gazebo>
  <gazebo reference="arm_1_link_2">
    <material>Gazebo/GreenTransparent    </material>
  </gazebo>
  <gazebo reference="arm_1_link_3">
    <material>Gazebo/BlackTransparent   </material>
  </gazebo>
  <gazebo reference="arm_1_link_4">
    <material>Gazebo/GreenTransparent    </material>
  </gazebo>
  <gazebo reference="arm_1_link_5">
    <material>Gazebo/BlackTransparent  </material>
  </gazebo>
  <gazebo reference="arm_1_link_6">
    <material>Gazebo/GreenTransparent    </material>
  </gazebo>
  <gazebo reference="arm_1_link_7">
    <material>Gazebo/BlackTransparent  </material>
  </gazebo>
  <gazebo reference="arm_1_tcp">
    <material>Gazebo/GreyTransparent    </material>
  </gazebo>
  <gazebo reference="arm_2_link_1">
    <material>Gazebo/BlackTransparent   </material>
  </gazebo>
  <gazebo reference="arm_2_link_2">
    <material>Gazebo/GreenTransparent    </material>
  </gazebo>
  <gazebo reference="arm_2_link_3">
    <material>Gazebo/BlackTransparent   </material>
  </gazebo>
  <gazebo reference="arm_2_link_4">
    <material>Gazebo/GreenTransparent    </material>
  </gazebo>
  <gazebo reference="arm_2_link_5">
    <material>Gazebo/BlackTransparent  </material>
  </gazebo>
  <gazebo reference="arm_2_link_6">
    <material>Gazebo/GreenTransparent    </material>
  </gazebo>
  <gazebo reference="arm_2_link_7">
    <material>Gazebo/BlackTransparent  </material>
  </gazebo>
  <gazebo reference="arm_2_tcp">
    <material>Gazebo/GreyTransparent    </material>
  </gazebo>
  <gazebo reference="base_link">
    <material>Gazebo/GreenTransparent   </material>
  </gazebo>
  <gazebo reference="table_top_link">
    <selfCollide> 1 </selfCollide>
  </gazebo>
</robot>
