<?xml version="1.0" ?>
<!-- =================================================================================== -->
<!-- |    This document was autogenerated by xacro from repair_full.urdf.xacro         | -->
<!-- |    EDITING THIS FILE BY HAND IS NOT RECOMMENDED                                 | -->
<!-- =================================================================================== -->
<robot name="repair_full">
  <material name="grey">
    <color rgba="0.5 0.5 0.5 1"/>
  </material>
  <material name="dark_grey">
    <color rgba="0.3 0.3 0.3 1"/>
  </material>
  <material name="red">
    <color rgba="1.0 0.0 0.0 1"/>
  </material>
  <material name="green">
    <color rgba="0.0 1.0 0.0 1"/>
  </material>
  <material name="blue">
    <color rgba="0.13333333333333333 0.25882352941176473 0.7803921568627451 1.0"/>
  </material>
  <material name="darkblue">
    <color rgba="0.0 0.3 0.9 1"/>
  </material>
  <material name="darkred">
    <color rgba="0.55 0.0 0.0 1"/>
  </material>
  <material name="dark">
    <color rgba="0.6 0.6 0.6 1"/>
  </material>
  <material name="wood">
    <color rgba="0.522 0.369 0.259 0.8"/>
  </material>
  <material name="silver_gray">
    <color rgba="0.8 0.8 0.8 0.8"/>
  </material>
  <!-- macro for generating the urdf associated with a single arm of the RePair platform -->
  <!-- id: specifies the id of the arm (e.g. 0 for left arm and 1 for right) -->
  <!-- base_link: name of base link a the single arm -->
  <!-- is_sliding_wrist: whether to add a sliding joint along the wrist second d.o.f.
    (true -> yes), everything else -> no. This is used to generate the URDF for the optimization.  -->
  <!-- gen_coll: whether to add the approximate collision  model of the platform -->
  <!-- use_updated_wrist: visual parameter. if true, we load the latest meshes (which are adapted to the
results of the optimization), otherwise we go with the old ones (generated for a spherical wrist) -->
  <!-- w.r.t world  -->
  <!-- 0.0  -->
  <!-- 2.4405495 -->
  <!-- 7.8724534e-01 -->
  <!-- 2.8848438e+00-->
  <!-- 6.0145584e-01 -->
  <!-- 2.7650803e+00 -->
  <!-- 1.8854765e+00 -->
  <!-- 2.4405495 -->
  <!-- Origin -->
  <!-- Only when working with Gazebo Xbot Control -->
  <!-- DO NOT USE WITH ROS_CONTROL AND MOVEIT -->
  <!-- <xacro:include filename="$(find repair_urdf)/urdf/gazebo/xbot.gazebo.xacro" /> -->
  <gazebo>
    <plugin filename="libgazebo_ros_control.so" name="ros_control">
      <!--robotNamespace>/</robotNamespace-->
      <!--robotSimType>gazebo_ros_control/DefaultRobotHWSim</robotSimType-->
    </plugin>
  </gazebo>
  <link name="world"/>
  <link name="table_top_link">
    <visual>
      <origin xyz="0.0 0.0 0.975"/>
      <geometry>
        <box size="1.0 2.5 0.05"/>
      </geometry>
      <material name="wood"/>
    </visual>
    <collision>
      <origin xyz="0.0 0.0 0.975"/>
      <geometry>
        <box size="1.0 2.5 0.05"/>
      </geometry>
    </collision>
  </link>
  <joint name="table_top_link_joint" type="fixed">
    <parent link="world"/>
    <child link="table_top_link"/>
  </joint>
  <joint name="leg1_joint" type="fixed">
    <parent link="table_top_link"/>
    <origin rpy="0 0 0" xyz="0.5 1.25 1.0"/>
    <child link="leg1_link"/>
  </joint>
  <link name="leg1_link">
    <visual>
      <origin rpy="0 0 0" xyz="0.0 0.0 -0.5"/>
      <geometry>
        <cylinder length="1.0" radius="0.02"/>
      </geometry>
      <material name="silver_gray"/>
    </visual>
    <collision>
      <origin rpy="0.0 0.0 0.0" xyz="0.0 0.0 -0.5"/>
      <geometry>
        <cylinder length="1.0" radius="0.02"/>
      </geometry>
    </collision>
  </link>
  <joint name="vbar1_joint" type="fixed">
    <parent link="leg1_link"/>
    <origin rpy="0 0 0" xyz="0 0 0.485"/>
    <child link="vbar1_link"/>
  </joint>
  <link name="vbar1_link">
    <visual>
      <origin rpy="0 0 0" xyz="0.0 0.0 0"/>
      <geometry>
        <cylinder length="0.97" radius="0.02"/>
      </geometry>
      <material name="silver_gray"/>
    </visual>
    <collision>
      <origin rpy="0.0 0.0 0.0" xyz="0.0 0.0 0"/>
      <geometry>
        <cylinder length="0.97" radius="0.02"/>
      </geometry>
    </collision>
  </link>
  <joint name="leg2_joint" type="fixed">
    <parent link="table_top_link"/>
    <origin rpy="0 0 0" xyz="-0.5 1.25 1.0"/>
    <child link="leg2_link"/>
  </joint>
  <link name="leg2_link">
    <visual>
      <origin rpy="0 0 0" xyz="0.0 0.0 -0.5"/>
      <geometry>
        <cylinder length="1.0" radius="0.02"/>
      </geometry>
      <material name="silver_gray"/>
    </visual>
    <collision>
      <origin rpy="0.0 0.0 0.0" xyz="0.0 0.0 -0.5"/>
      <geometry>
        <cylinder length="1.0" radius="0.02"/>
      </geometry>
    </collision>
  </link>
  <joint name="vbar2_joint" type="fixed">
    <parent link="leg2_link"/>
    <origin rpy="0 0 0" xyz="0 0 0.485"/>
    <child link="vbar2_link"/>
  </joint>
  <link name="vbar2_link">
    <visual>
      <origin rpy="0 0 0" xyz="0.0 0.0 0"/>
      <geometry>
        <cylinder length="0.97" radius="0.02"/>
      </geometry>
      <material name="silver_gray"/>
    </visual>
    <collision>
      <origin rpy="0.0 0.0 0.0" xyz="0.0 0.0 0"/>
      <geometry>
        <cylinder length="0.97" radius="0.02"/>
      </geometry>
    </collision>
  </link>
  <joint name="leg3_joint" type="fixed">
    <parent link="table_top_link"/>
    <origin rpy="0 0 0" xyz="0.5 -1.25 1.0"/>
    <child link="leg3_link"/>
  </joint>
  <link name="leg3_link">
    <visual>
      <origin rpy="0 0 0" xyz="0.0 0.0 -0.5"/>
      <geometry>
        <cylinder length="1.0" radius="0.02"/>
      </geometry>
      <material name="silver_gray"/>
    </visual>
    <collision>
      <origin rpy="0.0 0.0 0.0" xyz="0.0 0.0 -0.5"/>
      <geometry>
        <cylinder length="1.0" radius="0.02"/>
      </geometry>
    </collision>
  </link>
  <joint name="vbar3_joint" type="fixed">
    <parent link="leg3_link"/>
    <origin rpy="0 0 0" xyz="0 0 0.485"/>
    <child link="vbar3_link"/>
  </joint>
  <link name="vbar3_link">
    <visual>
      <origin rpy="0 0 0" xyz="0.0 0.0 0"/>
      <geometry>
        <cylinder length="0.97" radius="0.02"/>
      </geometry>
      <material name="silver_gray"/>
    </visual>
    <collision>
      <origin rpy="0.0 0.0 0.0" xyz="0.0 0.0 0"/>
      <geometry>
        <cylinder length="0.97" radius="0.02"/>
      </geometry>
    </collision>
  </link>
  <joint name="leg4_joint" type="fixed">
    <parent link="table_top_link"/>
    <origin rpy="0 0 0" xyz="-0.5 -1.25 1.0"/>
    <child link="leg4_link"/>
  </joint>
  <link name="leg4_link">
    <visual>
      <origin rpy="0 0 0" xyz="0.0 0.0 -0.5"/>
      <geometry>
        <cylinder length="1.0" radius="0.02"/>
      </geometry>
      <material name="silver_gray"/>
    </visual>
    <collision>
      <origin rpy="0.0 0.0 0.0" xyz="0.0 0.0 -0.5"/>
      <geometry>
        <cylinder length="1.0" radius="0.02"/>
      </geometry>
    </collision>
  </link>
  <joint name="vbar4_joint" type="fixed">
    <parent link="leg4_link"/>
    <origin rpy="0 0 0" xyz="0 0 0.485"/>
    <child link="vbar4_link"/>
  </joint>
  <link name="vbar4_link">
    <visual>
      <origin rpy="0 0 0" xyz="0.0 0.0 0"/>
      <geometry>
        <cylinder length="0.97" radius="0.02"/>
      </geometry>
      <material name="silver_gray"/>
    </visual>
    <collision>
      <origin rpy="0.0 0.0 0.0" xyz="0.0 0.0 0"/>
      <geometry>
        <cylinder length="0.97" radius="0.02"/>
      </geometry>
    </collision>
  </link>
  <joint name="obar1_joint" type="fixed">
    <parent link="vbar1_link"/>
    <origin rpy="0 -1.57079632679 0" xyz="-0.5 0 0.485"/>
    <child link="obar1_link"/>
  </joint>
  <link name="obar1_link">
    <visual>
      <origin rpy="0 0 0" xyz="0.0 0.0 0"/>
      <geometry>
        <cylinder length="1.0" radius="0.02"/>
      </geometry>
      <material name="silver_gray"/>
    </visual>
    <collision>
      <origin rpy="0.0 0.0 0.0" xyz="0.0 0.0 0"/>
      <geometry>
        <cylinder length="1.0" radius="0.02"/>
      </geometry>
    </collision>
  </link>
  <joint name="obar2_joint" type="fixed">
    <parent link="vbar3_link"/>
    <origin rpy="0 -1.57079632679 0" xyz="-0.5 0 0.485"/>
    <child link="obar2_link"/>
  </joint>
  <link name="obar2_link">
    <visual>
      <origin rpy="0 0 0" xyz="0.0 0.0 0"/>
      <geometry>
        <cylinder length="1.0" radius="0.02"/>
      </geometry>
      <material name="silver_gray"/>
    </visual>
    <collision>
      <origin rpy="0.0 0.0 0.0" xyz="0.0 0.0 0"/>
      <geometry>
        <cylinder length="1.0" radius="0.02"/>
      </geometry>
    </collision>
  </link>
  <joint name="obar3_joint" type="fixed">
    <parent link="vbar3_link"/>
    <origin rpy="-1.57079632679 0 0" xyz="0 1.25 0.485"/>
    <child link="obar3_link"/>
  </joint>
  <link name="obar3_link">
    <visual>
      <origin rpy="0 0 0" xyz="0.0 0.0 0"/>
      <geometry>
        <cylinder length="2.5" radius="0.02"/>
      </geometry>
      <material name="silver_gray"/>
    </visual>
    <collision>
      <origin rpy="0.0 0.0 0.0" xyz="0.0 0.0 0"/>
      <geometry>
        <cylinder length="2.5" radius="0.02"/>
      </geometry>
    </collision>
  </link>
  <joint name="obar4_joint" type="fixed">
    <parent link="vbar4_link"/>
    <origin rpy="-1.57079632679 0 0" xyz="0 1.25 0.485"/>
    <child link="obar4_link"/>
  </joint>
  <link name="obar4_link">
    <!-- dummy intertia to make Gazebo urdf2sdf converter work -->
    <visual>
      <origin rpy="0 0 0" xyz="0.0 0.0 0"/>
      <geometry>
        <cylinder length="2.5" radius="0.02"/>
      </geometry>
      <material name="silver_gray"/>
    </visual>
    <collision>
      <origin rpy="0.0 0.0 0.0" xyz="0.0 0.0 0"/>
      <geometry>
        <cylinder length="2.5" radius="0.02"/>
      </geometry>
    </collision>
  </link>
  <joint name="sliding_guide_joint" type="fixed">
    <parent link="obar2_link"/>
    <origin rpy="-1.57079632679 0 0" xyz="0.0 1.25 0.3"/>
    <child link="sliding_guide_link"/>
  </joint>
  <link name="sliding_guide_link">
    <visual>
      <origin rpy="0 0 0" xyz="0.0 0.0 0"/>
      <geometry>
        <box size="0.001 0.4 2.5"/>
      </geometry>
      <material name="silver_gray"/>
    </visual>
    <collision>
      <origin rpy="0.0 0.0 0.0" xyz="0.0 0.0 0"/>
      <geometry>
        <cylinder length="2.5" radius="0.02"/>
      </geometry>
    </collision>
  </link>
  <joint name="working_surface_joint" type="fixed">
    <parent link="sliding_guide_link"/>
    <origin rpy="0.0 -1.57079632679 3.14159265359" xyz="-0.97 0 0"/>
    <child link="working_surface_link"/>
  </joint>
  <link name="working_surface_link">
    <!-- Huge inertia (does not matter, is fixed to the world)-->
    <inertial>
      <mass value="1000"/>
      <origin xyz="0 0 0"/>
      <inertia ixx="0" ixy="0" ixz="0" iyy="0" iyz="0" izz="0"/>
    </inertial>
  </link>
  <material name="camera_aluminum">
    <color rgba="0.5 0.5 0.5 1"/>
  </material>
  <!-- camera body, with origin at bottom screw mount -->
  <joint name="camera_joint" type="fixed">
    <origin rpy="0.0009783 1.1836725 0" xyz="0.0857 0.0000476009 -0.273184"/>
    <parent link="torso_1"/>
    <child link="camera_bottom_screw_frame"/>
  </joint>
  <link name="camera_bottom_screw_frame"/>
  <joint name="camera_link_joint" type="fixed">
    <origin rpy="0 0 0" xyz="0 0.0175 0.0125"/>
    <parent link="camera_bottom_screw_frame"/>
    <child link="camera_link"/>
  </joint>
  <link name="camera_link">
    <visual>
      <origin rpy="1.5707963267948966 0 1.5707963267948966" xyz="0.0149 -0.0175 0"/>
      <geometry>
        <!-- <box size="${d435_cam_width} ${d435_cam_height} ${d435_cam_depth}"/> -->
        <mesh filename="/home/grosato/repair_robot_ws/src/repair_ros_robot/repair_urdf/meshes/d435.dae"/>
        <!--<mesh filename="package://realsense2_description/meshes/d435/d435.dae" />-->
      </geometry>
      <material name="camera_aluminum"/>
    </visual>
    <collision>
      <origin rpy="0 0 0" xyz="0 -0.0175 0"/>
      <geometry>
        <box size="0.02505 0.09 0.025"/>
      </geometry>
    </collision>
    <inertial>
      <!-- The following are not reliable values, and should not be used for modeling -->
      <mass value="0.564"/>
      <origin xyz="0 0 0"/>
      <inertia ixx="0.003881243" ixy="0.0" ixz="0.0" iyy="0.000498940" iyz="0.0" izz="0.003879257"/>
    </inertial>
  </link>
  <!-- camera depth joints and links -->
  <joint name="camera_depth_joint" type="fixed">
    <origin rpy="0 0 0" xyz="0 0 0"/>
    <parent link="camera_link"/>
    <child link="camera_depth_frame"/>
  </joint>
  <link name="camera_depth_frame"/>
  <joint name="camera_depth_optical_joint" type="fixed">
    <origin rpy="-1.5707963267948966 0 -1.5707963267948966" xyz="0 0 0"/>
    <parent link="camera_depth_frame"/>
    <child link="camera_depth_optical_frame"/>
  </joint>
  <link name="camera_depth_optical_frame"/>
  <!-- camera left IR joints and links -->
  <joint name="camera_left_ir_joint" type="fixed">
    <origin rpy="0 0 0" xyz="0 0.0 0"/>
    <parent link="camera_depth_frame"/>
    <child link="camera_left_ir_frame"/>
  </joint>
  <link name="camera_left_ir_frame"/>
  <joint name="camera_left_ir_optical_joint" type="fixed">
    <origin rpy="-1.5707963267948966 0 -1.5707963267948966" xyz="0 0 0"/>
    <parent link="camera_left_ir_frame"/>
    <child link="camera_left_ir_optical_frame"/>
  </joint>
  <link name="camera_left_ir_optical_frame"/>
  <!-- camera right IR joints and links -->
  <joint name="camera_right_ir_joint" type="fixed">
    <origin rpy="0 0 0" xyz="0 -0.05 0"/>
    <parent link="camera_depth_frame"/>
    <child link="camera_right_ir_frame"/>
  </joint>
  <link name="camera_right_ir_frame"/>
  <joint name="camera_right_ir_optical_joint" type="fixed">
    <origin rpy="-1.5707963267948966 0 -1.5707963267948966" xyz="0 0 0"/>
    <parent link="camera_right_ir_frame"/>
    <child link="camera_right_ir_optical_frame"/>
  </joint>
  <link name="camera_right_ir_optical_frame"/>
  <!-- camera color joints and links -->
  <joint name="camera_color_joint" type="fixed">
    <origin rpy="0 0 0" xyz="0 0.015 0"/>
    <parent link="camera_depth_frame"/>
    <child link="camera_color_frame"/>
  </joint>
  <link name="camera_color_frame"/>
  <joint name="camera_color_optical_joint" type="fixed">
    <origin rpy="-1.5707963267948966 0 -1.5707963267948966" xyz="0 0 0"/>
    <parent link="camera_color_frame"/>
    <child link="camera_color_optical_frame"/>
  </joint>
  <link name="camera_color_optical_frame"/>
  <gazebo reference="camera_link">
    <self_collide>0</self_collide>
    <enable_wind>0</enable_wind>
    <kinematic>0</kinematic>
    <gravity>1</gravity>
    <!--<mu>1</mu>-->
    <mu2>1</mu2>
    <fdir1>0 0 0</fdir1>
    <!--<slip1>0</slip1>
      <slip2>0</slip2>-->
    <kp>1e+13</kp>
    <kd>1</kd>
    <!--<max_vel>0.01</max_vel>
      <min_depth>0</min_depth>-->
    <sensor name="cameracolor" type="camera">
      <camera name="camera">
        <horizontal_fov>1.2112585008840648</horizontal_fov>
        <image>
          <width>640</width>
          <height>480</height>
          <format>RGB_INT8</format>
        </image>
        <clip>
          <near>0.1</near>
          <far>100</far>
        </clip>
        <noise>
          <type>gaussian</type>
          <mean>0.0</mean>
          <stddev>0.007</stddev>
        </noise>
      </camera>
      <always_on>1</always_on>
      <update_rate>30</update_rate>
      <visualize>1</visualize>
    </sensor>
    <sensor name="cameraired1" type="camera">
      <camera name="camera">
        <horizontal_fov>1.4870205226991688</horizontal_fov>
        <image>
          <width>1280</width>
          <height>720</height>
          <format>L_INT8</format>
        </image>
        <clip>
          <near>0.1</near>
          <far>100</far>
        </clip>
        <noise>
          <type>gaussian</type>
          <mean>0.0</mean>
          <stddev>0.05</stddev>
        </noise>
      </camera>
      <always_on>1</always_on>
      <update_rate>90</update_rate>
      <visualize>0</visualize>
    </sensor>
    <sensor name="cameraired2" type="camera">
      <camera name="camera">
        <horizontal_fov>1.4870205226991688</horizontal_fov>
        <image>
          <width>1280</width>
          <height>720</height>
          <format>L_INT8</format>
        </image>
        <clip>
          <near>0.1</near>
          <far>100</far>
        </clip>
        <noise>
          <type>gaussian</type>
          <mean>0.0</mean>
          <stddev>0.05</stddev>
        </noise>
      </camera>
      <always_on>1</always_on>
      <update_rate>90</update_rate>
      <visualize>0</visualize>
    </sensor>
    <sensor name="cameradepth" type="depth">
      <camera name="camera">
        <horizontal_fov>1.4870205226991688</horizontal_fov>
        <image>
          <width>1280</width>
          <height>720</height>
        </image>
        <clip>
          <near>0.1</near>
          <far>100</far>
        </clip>
        <noise>
          <type>gaussian</type>
          <mean>0.0</mean>
          <stddev>0.100</stddev>
        </noise>
      </camera>
      <always_on>1</always_on>
      <update_rate>90</update_rate>
      <visualize>0</visualize>
    </sensor>
  </gazebo>
  <gazebo>
    <plugin filename="librealsense_gazebo_plugin.so" name="camera">
      <prefix>camera</prefix>
      <depthUpdateRate>30.0</depthUpdateRate>
      <colorUpdateRate>30.0</colorUpdateRate>
      <infraredUpdateRate>30.0</infraredUpdateRate>
      <depthTopicName>depth/image_raw</depthTopicName>
      <depthCameraInfoTopicName>depth/camera_info</depthCameraInfoTopicName>
      <colorTopicName>color/image_raw</colorTopicName>
      <colorCameraInfoTopicName>color/camera_info</colorCameraInfoTopicName>
      <infrared1TopicName>infra1/image_raw</infrared1TopicName>
      <infrared1CameraInfoTopicName>infra1/camera_info</infrared1CameraInfoTopicName>
      <infrared2TopicName>infra2/image_raw</infrared2TopicName>
      <infrared2CameraInfoTopicName>infra2/camera_info</infrared2CameraInfoTopicName>
      <colorOpticalframeName>camera_color_optical_frame</colorOpticalframeName>
      <depthOpticalframeName>camera_depth_optical_frame</depthOpticalframeName>
      <infrared1OpticalframeName>camera_left_ir_optical_frame</infrared1OpticalframeName>
      <infrared2OpticalframeName>camera_right_ir_optical_frame</infrared2OpticalframeName>
      <rangeMinDepth>0.2</rangeMinDepth>
      <rangeMaxDepth>1.0</rangeMaxDepth>
      <pointCloud>True</pointCloud>
      <pointCloudTopicName>depth/color/points</pointCloudTopicName>
      <pointCloudCutoff>0.25</pointCloudCutoff>
      <pointCloudCutoffMax>1.0</pointCloudCutoffMax>
    </plugin>
  </gazebo>
  <!-- <link name="dummy_prismatic_link"/> -->
  <link name="torso_1">
    <inertial>
      <origin xyz="0.0004977651 -0.00042604032 -0.16838189"/>
      <mass value="8.7077745"/>
      <inertia ixx="0.11857828999999999" ixy="2.0401988e-05" ixz="1.2279510999999998e-05" iyy="0.08073399199999999" iyz="7.0011267999999996e-06" izz="0.054100211999999995"/>
    </inertial>
    <visual>
      <geometry>
        <mesh filename="package://repair_urdf/meshes/mesh_torso-yaw.stl" scale="0.001 0.001 0.001"/>
      </geometry>
      <material name="dark"/>
    </visual>
    <collision>
      <geometry>
        <mesh filename="package://repair_urdf/meshes/simplified/mesh_torso-yaw.stl" scale="0.001 0.001 0.001"/>
      </geometry>
    </collision>
  </link>
  <!-- <joint name="j_torso_base" type="fixed">
            <xacro:insert_block name="origin" />
            <parent link="${parent}" />
            <child link="dummy_prismatic_link"/>
            <axis xyz="0 0 1"/>
            <limit lower="${j_prismatic_lower[0]/2}" upper= "${j_prismatic_upper[0]/2}" effort="${j_prismatic_torque[0]}" velocity="${j_prismatic_velocity[0]}"/>
        </joint> -->
  <!-- torso -->
  <joint name="j_torso_1" type="revolute">
    <parent link="sliding_guide_link"/>
    <child link="torso_1"/>
    <axis xyz="0 0 1"/>
    <origin rpy="1.570796326795 0.0 1.570796326795" xyz="0.0 0.0 0.0"/>
    <limit effort="147.0" lower="-2.6" upper="2.6" velocity="3.86"/>
  </joint>
  <!-- torso  -->
  <link name="arm_2_1">
    <inertial>
      <origin xyz="0.010200651000000002 -0.021560998 0.09876702500000001"/>
      <mass value="2.347"/>
      <inertia ixx="0.007192915699999999" ixy="7.854318399999999e-05" ixz="-0.00039791235999999997" iyy="0.009471160999999999" iyz="0.0012857050999999999" izz="0.0058530904"/>
    </inertial>
    <visual>
      <geometry>
        <mesh filename="package://repair_urdf/meshes/mesh_sh-pitch.stl" scale="0.001 0.001 0.001"/>
      </geometry>
      <material name="dark"/>
    </visual>
    <collision>
      <geometry>
        <mesh filename="package://repair_urdf/meshes/simplified/mesh_sh-pitch.stl" scale="0.001 0.001 0.001"/>
      </geometry>
    </collision>
  </link>
  <link name="arm_2_2">
    <inertial>
      <origin xyz="4.5955243e-05 -0.044957128 -0.030791013"/>
      <mass value="0.76"/>
      <inertia ixx="0.0027927572" ixy="-2.0135067e-06" ixz="-1.3644218e-06" iyy="0.0019288488" iyz="-0.00066693438" izz="0.0026633366"/>
    </inertial>
    <visual>
      <geometry>
        <mesh filename="package://repair_urdf/meshes/mesh_sh-roll.stl" scale="0.001 0.001 0.001"/>
      </geometry>
      <material name="dark"/>
    </visual>
    <collision>
      <geometry>
        <mesh filename="package://repair_urdf/meshes/simplified/mesh_sh-roll.stl" scale="0.001 0.001 0.001"/>
      </geometry>
    </collision>
  </link>
  <link name="arm_2_3">
    <inertial>
      <origin xyz="0.005099315 0.0059986523 -0.18011742"/>
      <mass value="3.34"/>
      <inertia ixx="0.031298784999999996" ixy="-0.00025158367" ixz="0.002371127" iyy="0.031963501" iyz="0.0018728041" izz="0.0026332359"/>
    </inertial>
    <visual>
      <geometry>
        <mesh filename="package://repair_urdf/meshes/mesh_sh-yaw.stl" scale="0.001 0.001 0.001"/>
      </geometry>
      <material name="dark"/>
    </visual>
    <collision>
      <geometry>
        <mesh filename="package://repair_urdf/meshes/simplified/mesh_sh-yaw.stl" scale="0.001 0.001 0.001"/>
      </geometry>
    </collision>
  </link>
  <link name="arm_2_4">
    <inertial>
      <origin xyz="3.332275e-06 -0.033289421 -0.023682302"/>
      <mass value="0.55"/>
      <inertia ixx="0.0016198328" ixy="-1.2642724e-06" ixz="-1.1734799e-06" iyy="0.0012266731" iyz="-0.00039531700999999997" izz="0.0016081346"/>
    </inertial>
    <visual>
      <geometry>
        <mesh filename="package://repair_urdf/meshes/mesh_elbow.stl" scale="0.001 0.001 0.001"/>
      </geometry>
      <material name="dark"/>
    </visual>
    <collision>
      <geometry>
        <mesh filename="package://repair_urdf/meshes/simplified/mesh_elbow.stl" scale="0.001 0.001 0.001"/>
      </geometry>
    </collision>
  </link>
  <link name="arm_2_5">
    <inertial>
      <origin xyz="0.00094711044 -0.048009667 -0.14331833"/>
      <mass value="2.825"/>
      <inertia ixx="0.030333275" ixy="7.3729709e-05" ixz="3.2427371e-05" iyy="0.025195444999999997" iyz="-0.0095263763" izz="0.0069975103999999995"/>
    </inertial>
    <visual>
      <geometry>
        <mesh filename="package://repair_urdf/meshes/mesh_forearm-yaw.stl" scale="0.001 0.001 0.001"/>
      </geometry>
      <material name="dark"/>
    </visual>
    <collision>
      <geometry>
        <mesh filename="package://repair_urdf/meshes/simplified/mesh_forearm-yaw.stl" scale="0.001 0.001 0.001"/>
      </geometry>
    </collision>
  </link>
  <link name="arm_2_6">
    <inertial>
      <origin xyz="0.00068559302 -0.0050299682 0.046682846"/>
      <mass value="1.861"/>
      <inertia ixx="0.0042406037" ixy="-5.5692732e-05" ixz="-9.085198200000001e-05" iyy="0.0029010805999999997" iyz="-0.00018560541" izz="0.0044989008"/>
    </inertial>
    <visual>
      <geometry>
        <mesh filename="package://repair_urdf/meshes/mesh_wrist-pitch.stl" scale="0.001 0.001 0.001"/>
      </geometry>
      <material name="dark"/>
    </visual>
    <collision>
      <geometry>
        <mesh filename="package://repair_urdf/meshes/simplified/mesh_wrist-pitch.stl" scale="0.001 0.001 0.001"/>
      </geometry>
    </collision>
  </link>
  <link name="arm_2_7">
    <inertial>
      <origin xyz="0.0 -0.0010491951 -0.010307299"/>
      <mass value="0.1416397"/>
      <inertia ixx="6.1479333e-05" ixy="-7.4023399e-11" ixz="0.0" iyy="6.4247521e-05" iyz="4.778644799999999e-07" izz="0.00011879743999999998"/>
    </inertial>
    <visual>
      <geometry>
        <mesh filename="package://repair_urdf/meshes/mesh_wrist-roll.stl" scale="0.001 0.001 0.001"/>
      </geometry>
      <material name="dark"/>
    </visual>
    <collision>
      <geometry>
        <mesh filename="package://repair_urdf/meshes/simplified/mesh_wrist-roll.stl" scale="0.001 0.001 0.001"/>
      </geometry>
    </collision>
  </link>
  <link name="arm_2_tcp">
    <inertial>
      <origin xyz="0.0 0.05 0.1"/>
      <mass value="0.5"/>
      <inertia ixx="0.001" ixy="0.0" ixz="0.0" iyy="0.001" iyz="0.0" izz="0.001"/>
    </inertial>
  </link>
  <!-- JOINTS -->
  <!-- shoulder pitch -->
  <joint name="j_arm_2_1" type="revolute">
    <parent link="torso_1"/>
    <child link="arm_2_1"/>
    <axis xyz="0 0 1"/>
    <origin rpy="1.570796326795 0.0 0.0" xyz="0.0 -0.13515 -0.24215"/>
    <limit effort="147.0" lower="-2.6" upper="2.6" velocity="3.86"/>
  </joint>
  <!-- shoulder pitch -->
  <!-- shoulder yaw -->
  <joint name="j_arm_2_2" type="revolute">
    <parent link="arm_2_1"/>
    <child link="arm_2_2"/>
    <origin rpy="0.0 -1.570796326795 0.0" xyz="-0.06 -0.03 0.1255"/>
    <axis xyz="0 0 1"/>
    <!-- -1 -->
    <limit effort="147.0" lower="-0.1" upper="2.5" velocity="3.86"/>
  </joint>
  <!-- shoulder yaw -->
  <!-- shoulder yaw -->
  <joint name="j_arm_2_3" type="revolute">
    <parent link="arm_2_2"/>
    <child link="arm_2_3"/>
    <origin rpy="-1.570796326795 1.570796326795 0.0" xyz="0.0 -0.073 -0.06015"/>
    <axis xyz="0 0 -1"/>
    <!-- -1 -->
    <limit effort="147.0" lower="-2.6" upper="2.6" velocity="6.06"/>
  </joint>
  <!-- shoulder yaw -->
  <!-- elbow -->
  <joint name="j_arm_2_4" type="revolute">
    <parent link="arm_2_3"/>
    <child link="arm_2_4"/>
    <origin rpy="1.570796326795 0.0 0.0" xyz="0.0225 -0.05015 -0.29215"/>
    <axis xyz="0 0 1"/>
    <!-- -1 -->
    <limit effort="147.0" lower="-0.8" upper="2.4" velocity="6.06"/>
  </joint>
  <!-- elbow -->
  <!-- forearm yaw -->
  <joint name="j_arm_2_5" type="revolute">
    <parent link="arm_2_4"/>
    <child link="arm_2_5"/>
    <origin rpy="-1.570796326795 0.0 0.0" xyz="0.0 -0.0725 -0.05015"/>
    <axis xyz="0 0 -1"/>
    <!-- -1 -->
    <limit effort="55.0" lower="-2.8" upper="2.8" velocity="11.72"/>
  </joint>
  <!-- forearm yaw -->
  <!-- wrist pitch-->
  <joint name="j_arm_2_6" type="revolute">
    <parent link="arm_2_5"/>
    <child link="arm_2_6"/>
    <origin rpy="-1.570796326795 0.0 0.0" xyz="0.0 -0.05 -0.2475"/>
    <axis xyz="0 0 1"/>
    <limit effort="55.0" lower="-2.8" upper="2.1" velocity="11.72"/>
  </joint>
  <!-- wrist pitch-->
  <!-- wrist roll-->
  <joint name="j_arm_2_7" type="revolute">
    <parent link="arm_2_6"/>
    <child link="arm_2_7"/>
    <origin rpy="-1.570796326795 0.3316123 0.0" xyz="0.0 0.062877 0.05"/>
    <axis xyz="0 0 1"/>
    <limit effort="55.0" lower="-2.8" upper="2.8" velocity="11.72"/>
  </joint>
  <!-- /wrist roll-->
  <!-- virtual tip-->
  <joint name="j_tcp_2" type="fixed">
    <parent link="arm_2_7"/>
    <child link="arm_2_tcp"/>
    <origin rpy="0.0 0.0 0.0" xyz="0.0 0.0 0.0"/>
  </joint>
  <!-- virtual tip-->
  <transmission name="trans_j_arm_2_1">
    <type>transmission_interface/SimpleTransmission</type>
    <joint name="j_arm_2_1">
      <hardwareInterface>hardware_interface/PositionJointInterface</hardwareInterface>
    </joint>
    <actuator name="j_arm_2_1_motor">
      <hardwareInterface>hardware_interface/PositionJointInterface</hardwareInterface>
      <mechanicalReduction>1</mechanicalReduction>
    </actuator>
  </transmission>
  <transmission name="trans_j_arm_2_2">
    <type>transmission_interface/SimpleTransmission</type>
    <joint name="j_arm_2_2">
      <hardwareInterface>hardware_interface/PositionJointInterface</hardwareInterface>
    </joint>
    <actuator name="j_arm_2_2_motor">
      <hardwareInterface>hardware_interface/PositionJointInterface</hardwareInterface>
      <mechanicalReduction>1</mechanicalReduction>
    </actuator>
  </transmission>
  <transmission name="trans_j_arm_2_3">
    <type>transmission_interface/SimpleTransmission</type>
    <joint name="j_arm_2_3">
      <hardwareInterface>hardware_interface/PositionJointInterface</hardwareInterface>
    </joint>
    <actuator name="j_arm_2_3_motor">
      <hardwareInterface>hardware_interface/PositionJointInterface</hardwareInterface>
      <mechanicalReduction>1</mechanicalReduction>
    </actuator>
  </transmission>
  <transmission name="trans_j_arm_2_4">
    <type>transmission_interface/SimpleTransmission</type>
    <joint name="j_arm_2_4">
      <hardwareInterface>hardware_interface/PositionJointInterface</hardwareInterface>
    </joint>
    <actuator name="j_arm_2_4_motor">
      <hardwareInterface>hardware_interface/PositionJointInterface</hardwareInterface>
      <mechanicalReduction>1</mechanicalReduction>
    </actuator>
  </transmission>
  <transmission name="trans_j_arm_2_5">
    <type>transmission_interface/SimpleTransmission</type>
    <joint name="j_arm_2_5">
      <hardwareInterface>hardware_interface/PositionJointInterface</hardwareInterface>
    </joint>
    <actuator name="j_arm_2_5_motor">
      <hardwareInterface>hardware_interface/PositionJointInterface</hardwareInterface>
      <mechanicalReduction>1</mechanicalReduction>
    </actuator>
  </transmission>
  <transmission name="trans_j_arm_2_6">
    <type>transmission_interface/SimpleTransmission</type>
    <joint name="j_arm_2_6">
      <hardwareInterface>hardware_interface/PositionJointInterface</hardwareInterface>
    </joint>
    <actuator name="j_arm_2_6_motor">
      <hardwareInterface>hardware_interface/PositionJointInterface</hardwareInterface>
      <mechanicalReduction>1</mechanicalReduction>
    </actuator>
  </transmission>
  <transmission name="trans_j_arm_2_7">
    <type>transmission_interface/SimpleTransmission</type>
    <joint name="j_arm_2_7">
      <hardwareInterface>hardware_interface/PositionJointInterface</hardwareInterface>
    </joint>
    <actuator name="j_arm_2_7_motor">
      <hardwareInterface>hardware_interface/PositionJointInterface</hardwareInterface>
      <mechanicalReduction>1</mechanicalReduction>
    </actuator>
  </transmission>
  <transmission name="trans_j_torso_1">
    <type>transmission_interface/SimpleTransmission</type>
    <joint name="j_torso_1">
      <hardwareInterface>hardware_interface/PositionJointInterface</hardwareInterface>
    </joint>
    <actuator name="j_torso_1_motor">
      <hardwareInterface>hardware_interface/PositionJointInterface</hardwareInterface>
      <mechanicalReduction>1</mechanicalReduction>
    </actuator>
  </transmission>
  <link name="arm_1_1">
    <inertial>
      <origin xyz="0.010200651000000002 0.021560998 0.09876702500000001"/>
      <mass value="2.347"/>
      <inertia ixx="0.007192915699999999" ixy="-7.854318399999999e-05" ixz="-0.00039791235999999997" iyy="0.009471160999999999" iyz="-0.0012857050999999999" izz="0.0058530904"/>
    </inertial>
    <visual>
      <geometry>
        <mesh filename="package://repair_urdf/meshes/mesh_sh-pitch.stl" scale="0.001 -0.001 0.001"/>
      </geometry>
      <material name="dark"/>
    </visual>
    <collision>
      <geometry>
        <mesh filename="package://repair_urdf/meshes/simplified/mesh_sh-pitch.stl" scale="0.001 -0.001 0.001"/>
      </geometry>
    </collision>
  </link>
  <link name="arm_1_2">
    <inertial>
      <origin xyz="4.5955243e-05 0.044957128 -0.030791013"/>
      <mass value="0.76"/>
      <inertia ixx="0.0027927572" ixy="2.0135067e-06" ixz="-1.3644218e-06" iyy="0.0019288488" iyz="0.00066693438" izz="0.0026633366"/>
    </inertial>
    <visual>
      <geometry>
        <mesh filename="package://repair_urdf/meshes/mesh_sh-roll.stl" scale="0.001 -0.001 0.001"/>
      </geometry>
      <material name="dark"/>
    </visual>
    <collision>
      <geometry>
        <mesh filename="package://repair_urdf/meshes/simplified/mesh_sh-roll.stl" scale="0.001 -0.001 0.001"/>
      </geometry>
    </collision>
  </link>
  <link name="arm_1_3">
    <inertial>
      <origin xyz="0.005099315 -0.0059986523 -0.18011742"/>
      <mass value="3.34"/>
      <inertia ixx="0.031298784999999996" ixy="0.00025158367" ixz="0.002371127" iyy="0.031963501" iyz="-0.0018728041" izz="0.0026332359"/>
    </inertial>
    <visual>
      <geometry>
        <mesh filename="package://repair_urdf/meshes/mesh_sh-yaw.stl" scale="0.001 -0.001 0.001"/>
      </geometry>
      <material name="dark"/>
    </visual>
    <collision>
      <geometry>
        <mesh filename="package://repair_urdf/meshes/simplified/mesh_sh-yaw.stl" scale="0.001 -0.001 0.001"/>
      </geometry>
    </collision>
  </link>
  <link name="arm_1_4">
    <inertial>
      <origin xyz="3.332275e-06 0.033289421 -0.023682302"/>
      <mass value="0.55"/>
      <inertia ixx="0.0016198328" ixy="1.2642724e-06" ixz="-1.1734799e-06" iyy="0.0012266731" iyz="0.00039531700999999997" izz="0.0016081346"/>
    </inertial>
    <visual>
      <geometry>
        <mesh filename="package://repair_urdf/meshes/mesh_elbow.stl" scale="0.001 -0.001 0.001"/>
      </geometry>
      <material name="dark"/>
    </visual>
    <collision>
      <geometry>
        <mesh filename="package://repair_urdf/meshes/simplified/mesh_elbow.stl" scale="0.001 -0.001 0.001"/>
      </geometry>
    </collision>
  </link>
  <link name="arm_1_5">
    <inertial>
      <origin xyz="0.00094711044 0.048009667 -0.14331833"/>
      <mass value="2.825"/>
      <inertia ixx="0.030333275" ixy="-7.3729709e-05" ixz="3.2427371e-05" iyy="0.025195444999999997" iyz="0.0095263763" izz="0.0069975103999999995"/>
    </inertial>
    <visual>
      <geometry>
        <mesh filename="package://repair_urdf/meshes/mesh_forearm-yaw.stl" scale="0.001 -0.001 0.001"/>
      </geometry>
      <material name="dark"/>
    </visual>
    <collision>
      <geometry>
        <mesh filename="package://repair_urdf/meshes/simplified/mesh_forearm-yaw.stl" scale="0.001 -0.001 0.001"/>
      </geometry>
    </collision>
  </link>
  <link name="arm_1_6">
    <inertial>
      <origin xyz="0.00068559302 0.0050299682 0.046682846"/>
      <mass value="1.861"/>
      <inertia ixx="0.0042406037" ixy="5.5692732e-05" ixz="-9.085198200000001e-05" iyy="0.0029010805999999997" iyz="0.00018560541" izz="0.0044989008"/>
    </inertial>
    <visual>
      <geometry>
        <mesh filename="package://repair_urdf/meshes/mesh_wrist-pitch.stl" scale="0.001 -0.001 0.001"/>
      </geometry>
      <material name="dark"/>
    </visual>
    <collision>
      <geometry>
        <mesh filename="package://repair_urdf/meshes/simplified/mesh_wrist-pitch.stl" scale="0.001 -0.001 0.001"/>
      </geometry>
    </collision>
  </link>
  <link name="arm_1_7">
    <inertial>
      <origin xyz="0.0 0.0010491951 -0.010307299"/>
      <mass value="0.1416397"/>
      <inertia ixx="6.1479333e-05" ixy="7.4023399e-11" ixz="0.0" iyy="6.4247521e-05" iyz="-4.778644799999999e-07" izz="0.00011879743999999998"/>
    </inertial>
    <visual>
      <geometry>
        <mesh filename="package://repair_urdf/meshes/mesh_wrist-roll.stl" scale="0.001 -0.001 0.001"/>
      </geometry>
      <material name="dark"/>
    </visual>
    <collision>
      <geometry>
        <mesh filename="package://repair_urdf/meshes/simplified/mesh_wrist-roll.stl" scale="0.001 -0.001 0.001"/>
      </geometry>
    </collision>
  </link>
  <link name="arm_1_tcp">
    <inertial>
      <origin xyz="0.0 0.05 0.1"/>
      <mass value="0.5"/>
      <inertia ixx="0.001" ixy="0.0" ixz="0.0" iyy="0.001" iyz="0.0" izz="0.001"/>
    </inertial>
  </link>
  <!-- JOINTS -->
  <!-- shoulder pitch -->
  <joint name="j_arm_1_1" type="revolute">
    <parent link="torso_1"/>
    <child link="arm_1_1"/>
    <axis xyz="0 0 1"/>
    <origin rpy="-1.570796326795 0.0 0.0" xyz="0.0 0.13515 -0.24215"/>
    <limit effort="147.0" lower="-2.6" upper="2.6" velocity="3.86"/>
  </joint>
  <!-- shoulder pitch -->
  <!-- shoulder yaw -->
  <joint name="j_arm_1_2" type="revolute">
    <parent link="arm_1_1"/>
    <child link="arm_1_2"/>
    <origin rpy="-0.0 -1.570796326795 0.0" xyz="-0.06 0.03 0.1255"/>
    <axis xyz="0 0 1"/>
    <!-- -1 -->
    <limit effort="147.0" lower="-2.5" upper="0.1" velocity="3.86"/>
  </joint>
  <!-- shoulder yaw -->
  <!-- shoulder yaw -->
  <joint name="j_arm_1_3" type="revolute">
    <parent link="arm_1_2"/>
    <child link="arm_1_3"/>
    <origin rpy="1.570796326795 1.570796326795 0.0" xyz="0.0 0.073 -0.06015"/>
    <axis xyz="0 0 -1"/>
    <!-- -1 -->
    <limit effort="147.0" lower="-2.6" upper="2.6" velocity="6.06"/>
  </joint>
  <!-- shoulder yaw -->
  <!-- elbow -->
  <joint name="j_arm_1_4" type="revolute">
    <parent link="arm_1_3"/>
    <child link="arm_1_4"/>
    <origin rpy="-1.570796326795 0.0 0.0" xyz="0.0225 0.05015 -0.29215"/>
    <axis xyz="0 0 1"/>
    <!-- -1 -->
    <limit effort="147.0" lower="-2.4" upper="0.8" velocity="6.06"/>
  </joint>
  <!-- elbow -->
  <!-- forearm yaw -->
  <joint name="j_arm_1_5" type="revolute">
    <parent link="arm_1_4"/>
    <child link="arm_1_5"/>
    <origin rpy="1.570796326795 0.0 0.0" xyz="0.0 0.0725 -0.05015"/>
    <axis xyz="0 0 -1"/>
    <!-- -1 -->
    <limit effort="55.0" lower="-2.8" upper="2.8" velocity="11.72"/>
  </joint>
  <!-- forearm yaw -->
  <!-- wrist pitch-->
  <joint name="j_arm_1_6" type="revolute">
    <parent link="arm_1_5"/>
    <child link="arm_1_6"/>
    <origin rpy="1.570796326795 0.0 0.0" xyz="0.0 0.05 -0.2475"/>
    <axis xyz="0 0 1"/>
    <limit effort="55.0" lower="-2.1" upper="2.8" velocity="11.72"/>
  </joint>
  <!-- wrist pitch-->
  <!-- wrist roll-->
  <joint name="j_arm_1_7" type="revolute">
    <parent link="arm_1_6"/>
    <child link="arm_1_7"/>
    <origin rpy="1.570796326795 0.3316123 0.0" xyz="0.0 -0.062877 0.05"/>
    <axis xyz="0 0 1"/>
    <limit effort="55.0" lower="-2.8" upper="2.8" velocity="11.72"/>
  </joint>
  <!-- /wrist roll-->
  <!-- virtual tip-->
  <joint name="j_tcp_1" type="fixed">
    <parent link="arm_1_7"/>
    <child link="arm_1_tcp"/>
    <origin rpy="-0.0 0.0 0.0" xyz="0.0 -0.0 0.0"/>
  </joint>
  <!-- virtual tip-->
  <transmission name="trans_j_arm_1_1">
    <type>transmission_interface/SimpleTransmission</type>
    <joint name="j_arm_1_1">
      <hardwareInterface>hardware_interface/PositionJointInterface</hardwareInterface>
    </joint>
    <actuator name="j_arm_1_1_motor">
      <hardwareInterface>hardware_interface/PositionJointInterface</hardwareInterface>
      <mechanicalReduction>1</mechanicalReduction>
    </actuator>
  </transmission>
  <transmission name="trans_j_arm_1_2">
    <type>transmission_interface/SimpleTransmission</type>
    <joint name="j_arm_1_2">
      <hardwareInterface>hardware_interface/PositionJointInterface</hardwareInterface>
    </joint>
    <actuator name="j_arm_1_2_motor">
      <hardwareInterface>hardware_interface/PositionJointInterface</hardwareInterface>
      <mechanicalReduction>1</mechanicalReduction>
    </actuator>
  </transmission>
  <transmission name="trans_j_arm_1_3">
    <type>transmission_interface/SimpleTransmission</type>
    <joint name="j_arm_1_3">
      <hardwareInterface>hardware_interface/PositionJointInterface</hardwareInterface>
    </joint>
    <actuator name="j_arm_1_3_motor">
      <hardwareInterface>hardware_interface/PositionJointInterface</hardwareInterface>
      <mechanicalReduction>1</mechanicalReduction>
    </actuator>
  </transmission>
  <transmission name="trans_j_arm_1_4">
    <type>transmission_interface/SimpleTransmission</type>
    <joint name="j_arm_1_4">
      <hardwareInterface>hardware_interface/PositionJointInterface</hardwareInterface>
    </joint>
    <actuator name="j_arm_1_4_motor">
      <hardwareInterface>hardware_interface/PositionJointInterface</hardwareInterface>
      <mechanicalReduction>1</mechanicalReduction>
    </actuator>
  </transmission>
  <transmission name="trans_j_arm_1_5">
    <type>transmission_interface/SimpleTransmission</type>
    <joint name="j_arm_1_5">
      <hardwareInterface>hardware_interface/PositionJointInterface</hardwareInterface>
    </joint>
    <actuator name="j_arm_1_5_motor">
      <hardwareInterface>hardware_interface/PositionJointInterface</hardwareInterface>
      <mechanicalReduction>1</mechanicalReduction>
    </actuator>
  </transmission>
  <transmission name="trans_j_arm_1_6">
    <type>transmission_interface/SimpleTransmission</type>
    <joint name="j_arm_1_6">
      <hardwareInterface>hardware_interface/PositionJointInterface</hardwareInterface>
    </joint>
    <actuator name="j_arm_1_6_motor">
      <hardwareInterface>hardware_interface/PositionJointInterface</hardwareInterface>
      <mechanicalReduction>1</mechanicalReduction>
    </actuator>
  </transmission>
  <transmission name="trans_j_arm_1_7">
    <type>transmission_interface/SimpleTransmission</type>
    <joint name="j_arm_1_7">
      <hardwareInterface>hardware_interface/PositionJointInterface</hardwareInterface>
    </joint>
    <actuator name="j_arm_1_7_motor">
      <hardwareInterface>hardware_interface/PositionJointInterface</hardwareInterface>
      <mechanicalReduction>1</mechanicalReduction>
    </actuator>
  </transmission>
  <transmission name="trans_j_torso_1">
    <type>transmission_interface/SimpleTransmission</type>
    <joint name="j_torso_1">
      <hardwareInterface>hardware_interface/PositionJointInterface</hardwareInterface>
    </joint>
    <actuator name="j_torso_1_motor">
      <hardwareInterface>hardware_interface/PositionJointInterface</hardwareInterface>
      <mechanicalReduction>1</mechanicalReduction>
    </actuator>
  </transmission>
  <material name="qbhand/optional">
    <color rgba="0.0 0.5 0.8 1.0"/>
  </material>
  <material name="qbhand/base">
    <color rgba="0.35 0.35 0.35 1.0"/>
  </material>
  <material name="qbhand/palm">
    <color rgba="0.35 0.35 0.35 1.0"/>
  </material>
  <material name="qbhand/knuckle">
    <color rgba="0.35 0.35 0.35 1.0"/>
  </material>
  <material name="qbhand/proximal">
    <color rgba="0.35 0.35 0.35 1.0"/>
  </material>
  <material name="qbhand/middle">
    <color rgba="0.35 0.35 0.35 1.0"/>
  </material>
  <material name="qbhand/distal">
    <color rgba="0.35 0.35 0.35 1.0"/>
  </material>
  <material name="qbhand/default">
    <color rgba="0.35 0.35 0.35 1.0"/>
  </material>
  <!-- If you are using only the hand -->
  <!-- <link name="world"/> -->
  <!-- IF VERSION == 1_wide -->
  <gazebo>
    <plugin filename="libsofthand_mimic_plugin.so" name="synergy_plugin">
      <namespace>left_hand_v1_wide</namespace>
      <operation_mode>0</operation_mode>
      <spring_k>5</spring_k>
      <wide>True</wide>
      <r_finger>0.0033</r_finger>
      <R_pulley>0.0053</R_pulley>
      <n_param>0.058</n_param>
      <synS_thumb_j1>3</synS_thumb_j1>
      <synS_thumb_j2>1.2</synS_thumb_j2>
      <synS_thumb_j3>1.2</synS_thumb_j3>
      <k_thumb_j1>0.8</k_thumb_j1>
      <k_thumb_j2>0.8</k_thumb_j2>
      <k_thumb_j3>0.8</k_thumb_j3>
      <synS_index_j1>-0.3</synS_index_j1>
      <synS_index_j2>1.57</synS_index_j2>
      <synS_index_j3>1.25</synS_index_j3>
      <synS_index_j4>0.8</synS_index_j4>
      <k_index_j1>0.15</k_index_j1>
      <k_index_j2>0.5</k_index_j2>
      <k_index_j3>0.5</k_index_j3>
      <k_index_j4>0.5</k_index_j4>
      <synS_middle_j1>0</synS_middle_j1>
      <synS_middle_j2>1.57</synS_middle_j2>
      <synS_middle_j3>1.25</synS_middle_j3>
      <synS_middle_j4>1.25</synS_middle_j4>
      <k_middle_j1>0.15</k_middle_j1>
      <k_middle_j2>0.5</k_middle_j2>
      <k_middle_j3>0.5</k_middle_j3>
      <k_middle_j4>0.5</k_middle_j4>
      <synS_ring_j1>0</synS_ring_j1>
      <synS_ring_j2>1.57</synS_ring_j2>
      <synS_ring_j3>1.0</synS_ring_j3>
      <synS_ring_j4>1.0</synS_ring_j4>
      <k_ring_j1>0.15</k_ring_j1>
      <k_ring_j2>0.5</k_ring_j2>
      <k_ring_j3>0.5</k_ring_j3>
      <k_ring_j4>0.5</k_ring_j4>
      <synS_little_j1>0.1</synS_little_j1>
      <synS_little_j2>1.57</synS_little_j2>
      <synS_little_j3>1.25</synS_little_j3>
      <synS_little_j4>1.0</synS_little_j4>
      <k_little_j1>0.15</k_little_j1>
      <k_little_j2>0.5</k_little_j2>
      <k_little_j3>0.5</k_little_j3>
      <k_little_j4>0.5</k_little_j4>
      <!-- Palm thumb -->
      <synS_palm_j1>1.57</synS_palm_j1>
      <k_palm_j1>0.5</k_palm_j1>
      <k_palm_j1_mimic>0.5</k_palm_j1_mimic>
      <!-- Palm little -->
      <synS_palm_j2>1.57</synS_palm_j2>
      <k_palm_j2>0.5</k_palm_j2>
      <k_palm_j2_mimic>0.5</k_palm_j2_mimic>
    </plugin>
  </gazebo>
  <!-- World to palm base -->
  <joint name="left_hand_v1_wide_palm_central_joint" type="fixed">
    <parent link="arm_1_7"/>
    <child link="left_hand_v1_wide_palm_central_link"/>
    <origin rpy="0 0 -1.570796326795" xyz="0 0 0.0"/>
    <dynamics damping="3e-2" friction="0.0"/>
  </joint>
  <link name="left_hand_v1_wide_palm_central_link">
    <visual>
      <material name="grey"/>
      <geometry>
        <mesh filename="package://softhands_description/meshes/v1_wide/left/palm_central.stl" scale="0.001 0.001 0.001"/>
      </geometry>
      <origin rpy="0 0 0" xyz="0 0 0"/>
    </visual>
    <inertial>
      <mass value="0.55962922"/>
      <origin rpy="0 0 0" xyz="-7.3637766e-03 -0.015857667  6.7065321e-02"/>
      <inertia ixx="8.2936450e-04" ixy="1.9292962e-06" ixz="1.6410516e-05" iyy="8.0447768e-04" iyz="0.00013735281" izz="3.0664811e-04"/>
    </inertial>
    <collision>
      <geometry>
        <mesh filename="package://softhands_description/meshes/v1_wide/left/palm_central_collision.stl" scale="0.0009 0.0009 0.0009"/>
      </geometry>
      <origin rpy="0 0 0" xyz="0 0 0"/>
    </collision>
  </link>
  <!-- palm base to Thumb -->
  <joint name="left_hand_v1_wide_palm_central_thumb_joint" type="revolute">
    <axis xyz="0 0 1"/>
    <limit effort="30" lower="0" upper="0.17" velocity="0.0"/>
    <dynamics damping="3e-2" friction="0.0"/>
    <origin rpy="0.3490656 0.0 0.0" xyz=" -0.0000000021 -32.5059e-3 39.6398e-3"/>
    <parent link="left_hand_v1_wide_palm_central_link"/>
    <child link="left_hand_v1_wide_palm_central_thumb_link"/>
  </joint>
  <link name="left_hand_v1_wide_palm_central_thumb_link">
    <inertial>
      <origin rpy="0 0 0" xyz="0 0 0"/>
      <mass value="0.27981461"/>
      <inertia ixx="8.2936450e-04" ixy="1.9292962e-06" ixz="1.6410516e-05" iyy="8.0447768e-04" iyz="0.00013735281" izz="3.0664811e-04"/>
    </inertial>
  </link>
  <!-- palm base to Litte virtual -->
  <joint name="left_hand_v1_wide_palm_central_little_joint" type="revolute">
    <axis xyz="0 0 1"/>
    <dynamics damping="3e-2" friction="0.0"/>
    <limit effort="100" lower="0.0" upper="0.17" velocity="0.00"/>
    <origin rpy="3.1415927 -0.1745327 1.5707963" xyz=" -0.0000000091 10.6603e-3 66.1817e-3"/>
    <parent link="left_hand_v1_wide_palm_central_link"/>
    <child link="left_hand_v1_wide_palm_central_little_link"/>
  </joint>
  <link name="left_hand_v1_wide_palm_central_little_link">
    <inertial>
      <origin rpy="0 0 0" xyz="0 0 0"/>
      <mass value="0.55962922"/>
      <inertia ixx="8.2936450e-04" ixy="1.9292962e-06" ixz="1.6410516e-05" iyy="8.0447768e-04" iyz="0.00013735281" izz="3.0664811e-04"/>
    </inertial>
  </link>
  <gazebo reference="left_hand_v1_wide_palm_central_link">
    <selfCollide>0</selfCollide>
    <material>Gazebo/Grey</material>
  </gazebo>
  <!-- GAZEBO REF -->
  <gazebo reference="left_hand_v1_wide_palm_central_thumb_joint">
    <implicitSpringDamper>true</implicitSpringDamper>
    <springStiffness>0.4</springStiffness>
    <springReference>0</springReference>
  </gazebo>
  <!-- GAZEBO REF -->
  <gazebo reference="left_hand_v1_wide_palm_central_little_link">
    <implicitSpringDamper>true</implicitSpringDamper>
    <springStiffness>0.4</springStiffness>
    <springReference>0</springReference>
  </gazebo>
  <joint name="left_hand_v1_wide_palm_central_thumb_virtual_joint" type="revolute">
    <parent link="left_hand_v1_wide_palm_central_thumb_link"/>
    <child link="left_hand_v1_wide_palm_thumb_link"/>
    <origin rpy="0 0 0 " xyz="-0.0000454746e-3 -12e-3 0"/>
    <axis xyz="0 0 1"/>
    <limit effort="30" lower="0" upper="0.35" velocity="0.0"/>
    <dynamics damping="3e-2" friction="0.0"/>
  </joint>
  <link name="left_hand_v1_wide_palm_thumb_link">
    <material name="grey"/>
    <visual>
      <geometry>
        <mesh filename="package://softhands_description/meshes/v1_wide/left/palm_thumb.stl" scale="0.001 0.001 0.001"/>
      </geometry>
      <origin rpy="0 0 0" xyz="0 0 0"/>
    </visual>
    <inertial>
      <mass value="0.092767"/>
      <origin rpy="0 0 0" xyz=" 7.0704771e-3  -1.3888149e-2 1.1337304e-3"/>
      <inertia ixx="5.2239281e-5" ixy="2.7341002e-6" ixz="4.6570694e-6" iyy="5.2239286e-5" iyz="-6.0525011e-6" izz="2.7144565e-5"/>
    </inertial>
    <collision>
      <geometry>
        <mesh filename="package://softhands_description/meshes/v1_wide/left/palm_thumb_collision.stl" scale="0.001 0.001 0.001"/>
      </geometry>
      <origin rpy="0 0 0" xyz="0 0 0"/>
    </collision>
  </link>
  <!-- Palm thumb to thumb support -->
  <joint name="left_hand_v1_wide_palm_thumb_support_joint" type="fixed">
    <parent link="left_hand_v1_wide_palm_thumb_link"/>
    <child link="left_hand_v1_wide_palm_thumb_support_link"/>
    <origin rpy="1.5707963 -0.5235992 1.5707963" xyz="5.0e-3 -24.2343e-3 9.13010e-3"/>
  </joint>
  <link name="left_hand_v1_wide_palm_thumb_support_link">
    <material name="grey"/>
    <visual>
      <geometry>
        <mesh filename="package://softhands_description/meshes/v1_wide/left/thumb_support.stl" scale="0.001 0.001 0.001"/>
      </geometry>
      <origin rpy="0 0 0" xyz="0 0 0"/>
    </visual>
    <inertial>
      <origin rpy="0 0 0" xyz="1.1097412e-02 -4.2327979e-05 -4.7109856e-04"/>
      <mass value="1.6408860e-02"/>
      <inertia ixx="1.8835019e-06" ixy="-4.9293913e-09" ixz="-2.5700318e-08" iyy="1.2828797e-06" iyz="-4.0065947e-09" izz="2.2986135e-06"/>
    </inertial>
    <collision>
      <geometry>
        <mesh filename="package://softhands_description/meshes/v1_wide/left/thumb_support_collision.stl" scale="0.0009 0.0009 0.0009"/>
      </geometry>
      <origin rpy="0 0 0" xyz="0 0 0"/>
    </collision>
  </link>
  <gazebo reference="left_hand_v1_wide_palm_thumb_link">
    <selfCollide>0</selfCollide>
    <material>Gazebo/Grey</material>
  </gazebo>
  <gazebo reference="left_hand_v1_wide_palm_thumb_support_link">
    <selfCollide>0</selfCollide>
    <material>Gazebo/White</material>
  </gazebo>
  <joint name="left_hand_v1_wide_palm_central_little_virtual_joint" type="revolute">
    <parent link="left_hand_v1_wide_palm_central_little_link"/>
    <child link="left_hand_v1_wide_palm_little_link"/>
    <origin rpy="0 0 0 " xyz="12e-3 4.66576e-08 0"/>
    <axis xyz="0 0 1"/>
    <limit effort="30" lower="0" upper="0.35" velocity="0.0"/>
    <dynamics damping="3e-2" friction="0.0"/>
  </joint>
  <link name="left_hand_v1_wide_palm_little_link">
    <visual>
      <material name="grey"/>
      <geometry>
        <mesh filename="package://softhands_description/meshes/v1_wide/left/palm_little.stl" scale="0.001 0.001 0.001"/>
      </geometry>
      <origin rpy="0 0 0" xyz="0 0 0"/>
    </visual>
    <inertial>
      <mass value="0.17998957"/>
      <origin rpy="0 0 0" xyz="1.9466642e-02  5.5041380e-03 0.00079253974"/>
      <inertia ixx=" 2.4776164e-04" ixy="-2.2762031e-06" ixz="2.5699035e-05" iyy="2.6460918e-04" iyz=" -1.5348716e-05" izz="5.9121350e-05"/>
    </inertial>
    <collision>
      <geometry>
        <mesh filename="package://softhands_description/meshes/v1_wide/left/palm_little_collision.stl" scale="0.0009 0.0009 0.0009"/>
      </geometry>
      <origin rpy="0 0 0" xyz="0 0 0"/>
    </collision>
  </link>
  <gazebo reference="left_hand_v1_wide_palm_little_link">
    <selfCollide>0</selfCollide>
    <material>Gazebo/Grey</material>
  </gazebo>
  <!-- GAZEBO REF -->
  <gazebo reference="left_hand_v1_wide_palm_little_virtual_joint">
    <implicitSpringDamper>true</implicitSpringDamper>
    <springStiffness>0.4</springStiffness>
    <springReference>0</springReference>
  </gazebo>
  <!-- Thumb Proximal  -->
  <joint name="left_hand_v1_wide_thumb_knuckle_joint" type="revolute">
    <parent link="left_hand_v1_wide_palm_thumb_support_link"/>
    <child link="left_hand_v1_wide_thumb_knuckle_link"/>
    <origin rpy="1.5707963 0 1.5707963" xyz="0 21.9577e-3 2.8e-3"/>
    <axis xyz="0 0 1"/>
    <limit effort="30" lower="0" upper="1.57" velocity="0.0"/>
    <dynamics damping="3e-2" friction="0.0"/>
  </joint>
  <link name="left_hand_v1_wide_thumb_knuckle_link">
    <visual>
      <material name="grey"/>
      <geometry>
        <mesh filename="package://softhands_description/meshes/v1_wide/left/phalanx_pros_thumb.stl" scale="0.001 0.001 0.001"/>
      </geometry>
      <origin rpy="0 0 0" xyz="0 0 0"/>
    </visual>
    <inertial>
      <mass value="2.4657976e-02"/>
      <origin rpy="0 0 0" xyz="2.2747515e-02  4.5872045e-03 -0.0013868568  "/>
      <inertia ixx="2.6529131e-6" ixy="-2.6016685e-07" ixz="-1.3433999e-07" iyy="4.4499492e-06" iyz="7.5218787e-08" izz="5.0393400e-06"/>
    </inertial>
    <collision>
      <geometry>
        <mesh filename="package://softhands_description/meshes/v1_wide/left/phalanx_pros_thumb_collision.stl" scale="0.0009 0.0009 0.0009"/>
      </geometry>
      <origin rpy="0 0 0" xyz="0 0 0"/>
    </collision>
  </link>
  <gazebo reference="left_hand_v1_wide_thumb_knuckle_link">
    <material>Gazebo/Grey</material>
    <selfCollide>0</selfCollide>
  </gazebo>
  <!-- GAZEBO REF -->
  <gazebo reference="left_hand_v1_wide_thumb_knuckle_joint">
    <implicitSpringDamper>true</implicitSpringDamper>
    <springStiffness>0.4</springStiffness>
    <springReference>0</springReference>
  </gazebo>
  <!-- Virtual joint from thumb knuckle to thumb proximal   -->
  <joint name="left_hand_v1_wide_thumb_proximal_joint" type="revolute">
    <axis xyz="0 0 1"/>
    <limit effort="30" lower="0" upper="0.785398" velocity="0.0"/>
    <origin rpy="1.3962638 0 0" xyz="38.5e-3 4.82952e-3 0.000167417"/>
    <parent link="left_hand_v1_wide_thumb_knuckle_link"/>
    <child link="left_hand_v1_wide_thumb_proximal_virtual_link"/>
    <dynamics damping="3e-2" friction="0.0"/>
  </joint>
  <link name="left_hand_v1_wide_thumb_proximal_virtual_link">
    <inertial>
      <origin rpy="0 0 0" xyz="0 0 0"/>
      <mass value="0.033679189"/>
      <inertia ixx="4.1328993e-06" ixy="-8.6599874e-08" ixz="0.0" iyy="7.4560101e-06" iyz="-1.0265429e-09" izz="6.6161853e-06"/>
    </inertial>
  </link>
  <!-- Thumb Proximal joint  -->
  <joint name="left_hand_v1_wide_thumb_proximal_virtual_joint" type="revolute">
    <parent link="left_hand_v1_wide_thumb_proximal_virtual_link"/>
    <child link="left_hand_v1_wide_thumb_proximal_link"/>
    <origin rpy="0 0 0" xyz="9e-3 0 0 "/>
    <axis xyz="0 0 1"/>
    <limit effort="30" lower="0" upper="0.785398" velocity="0.0"/>
    <dynamics damping="3e-2" friction="0.0"/>
  </joint>
  <link name="left_hand_v1_wide_thumb_proximal_link">
    <visual>
      <material name="grey"/>
      <geometry>
        <mesh filename="package://softhands_description/meshes/v1_wide/left/phalanx_medium_thumb.stl" scale="0.001 0.001 0.001"/>
      </geometry>
      <origin rpy="0 0 0" xyz="0 0 0"/>
    </visual>
    <inertial>
      <mass value="0.033679189"/>
      <inertia ixx="4.1328993e-06" ixy="-8.6599874e-08" ixz="0.0" iyy="7.4560101e-06" iyz="-1.0265429e-09" izz="6.6161853e-06"/>
      <origin rpy="0 0 0" xyz="2.0950700e-02  1.1175133e-03 -3.7424390e-05"/>
    </inertial>
    <collision>
      <geometry>
        <mesh filename="package://softhands_description/meshes/v1_wide/left/phalanx_medium_thumb_collision.stl" scale="0.0009 0.0009 0.0009"/>
      </geometry>
      <origin rpy="0 0 0" xyz="0 0 0"/>
    </collision>
  </link>
  <gazebo reference="left_hand_v1_wide_thumb_proximal_link">
    <material>Gazebo/Grey</material>
    <selfCollide>0</selfCollide>
  </gazebo>
  <!-- GAZEBO REF -->
  <gazebo reference="left_hand_v1_wide_thumb_proximal_joint">
    <implicitSpringDamper>true</implicitSpringDamper>
    <springStiffness>0.4</springStiffness>
    <springReference>0</springReference>
  </gazebo>
  <!-- GAZEBO REF -->
  <gazebo reference="left_hand_v1_wide_thumb_proximal_virtual_joint">
    <implicitSpringDamper>true</implicitSpringDamper>
    <springStiffness>0.4</springStiffness>
    <springReference>0</springReference>
  </gazebo>
  <!-- Virtual joint from thumb proximal to thumb distal   -->
  <joint name="left_hand_v1_wide_thumb_distal_virtual_joint" type="revolute">
    <axis xyz="0 0 1"/>
    <origin rpy="0 0 0" xyz="41e-3 0 0"/>
    <parent link="left_hand_v1_wide_thumb_proximal_link"/>
    <child link="left_hand_v1_wide_thumb_distal_virtual_link"/>
    <limit effort="30" lower="0" upper="0.785398" velocity="0.0"/>
    <dynamics damping="3e-2" friction="0.0"/>
  </joint>
  <link name="left_hand_v1_wide_thumb_distal_virtual_link">
    <inertial>
      <origin rpy="0 0 0" xyz="0 0 0"/>
      <mass value="0.023674554"/>
      <inertia ixx="2.578454e-06" ixy="0.0" ixz="0.0" iyy="2.9887569e-06" iyz="0.0" izz="3.8277106e-06"/>
    </inertial>
  </link>
  <!-- Thumb middle  -->
  <joint name="left_hand_v1_wide_thumb_distal_joint" type="revolute">
    <parent link="left_hand_v1_wide_thumb_distal_virtual_link"/>
    <child link="left_hand_v1_wide_thumb_distal_link"/>
    <origin rpy="0 0.0101229 0" xyz="8.99947e-3 0 -0.0973875e-3"/>
    <axis xyz="0 0 1"/>
    <limit effort="30" lower="0" upper="0.785398" velocity="0.0"/>
    <dynamics damping="3e-2" friction="0.0"/>
  </joint>
  <link name="left_hand_v1_wide_thumb_distal_link">
    <visual>
      <material name="grey"/>
      <geometry>
        <mesh filename="package://softhands_description/meshes/v1_wide/left/phalanx_dist_thumb.stl" scale="0.001 0.001 0.001"/>
      </geometry>
      <origin rpy="0 0 0" xyz="0 0 0"/>
    </visual>
    <inertial>
      <mass value="0.023674554"/>
      <inertia ixx="2.578454e-06" ixy="0.0" ixz="0.0" iyy="2.9887569e-06" iyz="0.0" izz="3.8277106e-06"/>
      <origin rpy="0 0 0" xyz="1.6161362e-02  1.6241404e-03 -3.2684152e-05 "/>
    </inertial>
    <collision>
      <geometry>
        <mesh filename="package://softhands_description/meshes/v1_wide/left/phalanx_dist_thumb_collision.stl" scale="0.0009 0.0009 0.0009"/>
      </geometry>
      <origin rpy="0 0 0" xyz="0 0 0"/>
    </collision>
  </link>
  <!-- GAZEBO REF -->
  <gazebo reference="left_hand_v1_wide_thumb_distal_link">
    <material>Gazebo/Grey</material>
    <selfCollide>0</selfCollide>
  </gazebo>
  <!-- GAZEBO REF -->
  <gazebo reference="left_hand_v1_wide_thumb_distal_virtual_joint">
    <implicitSpringDamper>true</implicitSpringDamper>
    <springStiffness>0.4</springStiffness>
    <springReference>0</springReference>
  </gazebo>
  <!-- GAZEBO REF -->
  <gazebo reference="left_hand_v1_wide_thumb_distal_joint">
    <implicitSpringDamper>true</implicitSpringDamper>
    <springStiffness>0.4</springStiffness>
    <springReference>0</springReference>
  </gazebo>
  <!-- Support -->
  <joint name="left_hand_v1_wide_index_knuckle_joint" type="revolute">
    <axis xyz="0 1 0"/>
    <limit effort="30" lower="0.0" upper="0.01" velocity="0.0"/>
    <origin rpy="0.1748327 0 0 " xyz="5e-3 -44.8953e-3 112.230e-3"/>
    <parent link="left_hand_v1_wide_palm_central_link"/>
    <child link="left_hand_v1_wide_index_knuckle_link"/>
  </joint>
  <link name="left_hand_v1_wide_index_knuckle_link">
    <visual>
      <material name="grey"/>
      <geometry>
        <mesh filename="package://softhands_description/meshes/v1_wide/left/phalanx_pros_sup.stl" scale="0.001 0.001 0.001"/>
      </geometry>
      <origin rpy="0 0 0" xyz="0 0 0"/>
    </visual>
    <inertial>
      <mass value="7.4913242e-03"/>
      <origin rpy="0 0 0" xyz="1.8035857e-02 -4.0351343e-03 -4.4165266e-05 "/>
      <inertia ixx="5.3708642e-07" ixy="0.0" ixz="1.5304482e-07" iyy="6.1466440e-07" iyz="-4.4383298e-09" izz="5.5136271e-07"/>
    </inertial>
    <collision>
      <geometry>
        <mesh filename="package://softhands_description/meshes/v1_wide/left/phalanx_pros_sup_collision.stl" scale="0.0009 0.0009 0.0009"/>
      </geometry>
      <origin rpy="0 0 0" xyz="0 0 0"/>
    </collision>
  </link>
  <gazebo reference="left_hand_v1_wide_index_knuckle_link">
    <selfCollide>0</selfCollide>
    <material>Gazebo/White</material>
  </gazebo>
  <!-- Virtual joint from knuckle->proximal or proximal->middle   -->
  <joint name="left_hand_v1_wide_index_proximal_virtual_joint" type="revolute">
    <axis xyz="0 0 1"/>
    <limit effort="30" lower="0" upper="0.785398" velocity="0.0"/>
    <origin rpy="-1.5707963 -1.5707963 0" xyz=" -6.5e-3 0 24e-3"/>
    <parent link="left_hand_v1_wide_index_knuckle_link"/>
    <child link="left_hand_v1_wide_index_proximal_virtual_link"/>
    <dynamics damping="3e-2" friction="0.0"/>
  </joint>
  <link name="left_hand_v1_wide_index_proximal_virtual_link">
    <inertial>
      <origin rpy="0 0 0" xyz="0 0 0"/>
      <mass value="0.024190505"/>
      <inertia ixx="1.9981795e-06" ixy="-6.0806048e-08" ixz="0.0" iyy="4.7810654e-06" iyz="0.0" izz="5.0961924e-06"/>
    </inertial>
  </link>
  <!-- Proximal phalanx -->
  <joint name="left_hand_v1_wide_index_proximal_joint" type="revolute">
    <axis xyz="0 0 1"/>
    <limit effort="30" lower="0" upper="0.785398" velocity="0.0"/>
    <origin rpy="0 0 0" xyz="9e-3 0 0"/>
    <parent link="left_hand_v1_wide_index_proximal_virtual_link"/>
    <child link="left_hand_v1_wide_index_proximal_link"/>
    <dynamics damping="3e-2" friction="0.0"/>
  </joint>
  <link name="left_hand_v1_wide_index_proximal_link">
    <visual>
      <material name="grey"/>
      <geometry>
        <mesh filename="package://softhands_description/meshes/v1_wide/left/phalanx.stl" scale="0.001 0.001 0.001"/>
      </geometry>
      <origin rpy="0 0 0" xyz="0 0 0"/>
    </visual>
    <inertial>
      <mass value="0.024190505"/>
      <inertia ixx="1.9981795e-06" ixy="-6.0806048e-08" ixz="0.0" iyy="4.7810654e-06" iyz="0.0" izz="5.0961924e-06"/>
      <origin rpy="0 0 0" xyz=" 2.0923634e-02  8.4162795e-04 -5.2131884e-05"/>
    </inertial>
    <collision>
      <geometry>
        <mesh filename="package://softhands_description/meshes/v1_wide/left/phalanx_collision.stl" scale="0.0009 0.0009 0.0009"/>
      </geometry>
      <origin rpy="0 0 0" xyz="0 0 0"/>
    </collision>
  </link>
  <gazebo reference="left_hand_v1_wide_index_proximal_link">
    <material>Gazebo/Gray</material>
    <selfCollide>0</selfCollide>
  </gazebo>
  <!-- GAZEBO REF -->
  <gazebo reference="left_hand_v1_wide_index_proximal_virtual_joint">
    <implicitSpringDamper>true</implicitSpringDamper>
    <springStiffness>0.4</springStiffness>
    <springReference>0</springReference>
  </gazebo>
  <!-- GAZEBO REF -->
  <gazebo reference="left_hand_v1_wide_index_proximal_joint">
    <implicitSpringDamper>true</implicitSpringDamper>
    <springStiffness>0.4</springStiffness>
    <springReference>0</springReference>
  </gazebo>
  <!-- Virtual joint from knuckle->proximal or proximal->middle   -->
  <joint name="left_hand_v1_wide_index_middle_virtual_joint" type="revolute">
    <axis xyz="0 0 1"/>
    <limit effort="30" lower="0" upper="0.785398" velocity="0.0"/>
    <origin rpy="0 0 0" xyz="41e-3 0 0"/>
    <parent link="left_hand_v1_wide_index_proximal_link"/>
    <child link="left_hand_v1_wide_index_middle_virtual_link"/>
    <dynamics damping="3e-2" friction="0.0"/>
  </joint>
  <link name="left_hand_v1_wide_index_middle_virtual_link">
    <inertial>
      <origin rpy="0 0 0" xyz="0 0 0"/>
      <mass value="0.024190505"/>
      <inertia ixx="1.9981795e-06" ixy="-6.0806048e-08" ixz="0.0" iyy="4.7810654e-06" iyz="0.0" izz="5.0961924e-06"/>
    </inertial>
  </link>
  <!-- Proximal phalanx -->
  <joint name="left_hand_v1_wide_index_middle_joint" type="revolute">
    <axis xyz="0 0 1"/>
    <limit effort="30" lower="0" upper="0.785398" velocity="0.0"/>
    <origin rpy="0 0 0" xyz="9e-3 0 0"/>
    <parent link="left_hand_v1_wide_index_middle_virtual_link"/>
    <child link="left_hand_v1_wide_index_middle_link"/>
    <dynamics damping="3e-2" friction="0.0"/>
  </joint>
  <link name="left_hand_v1_wide_index_middle_link">
    <visual>
      <material name="grey"/>
      <geometry>
        <mesh filename="package://softhands_description/meshes/v1_wide/left/phalanx.stl" scale="0.001 0.001 0.001"/>
      </geometry>
      <origin rpy="0 0 0" xyz="0 0 0"/>
    </visual>
    <inertial>
      <mass value="0.024190505"/>
      <inertia ixx="1.9981795e-06" ixy="-6.0806048e-08" ixz="0.0" iyy="4.7810654e-06" iyz="0.0" izz="5.0961924e-06"/>
      <origin rpy="0 0 0" xyz=" 2.0923634e-02  8.4162795e-04 -5.2131884e-05"/>
    </inertial>
    <collision>
      <geometry>
        <mesh filename="package://softhands_description/meshes/v1_wide/left/phalanx_collision.stl" scale="0.0009 0.0009 0.0009"/>
      </geometry>
      <origin rpy="0 0 0" xyz="0 0 0"/>
    </collision>
  </link>
  <gazebo reference="left_hand_v1_wide_index_middle_link">
    <material>Gazebo/Gray</material>
    <selfCollide>0</selfCollide>
  </gazebo>
  <!-- GAZEBO REF -->
  <gazebo reference="left_hand_v1_wide_index_middle_virtual_joint">
    <implicitSpringDamper>true</implicitSpringDamper>
    <springStiffness>0.4</springStiffness>
    <springReference>0</springReference>
  </gazebo>
  <!-- GAZEBO REF -->
  <gazebo reference="left_hand_v1_wide_index_middle_joint">
    <implicitSpringDamper>true</implicitSpringDamper>
    <springStiffness>0.4</springStiffness>
    <springReference>0</springReference>
  </gazebo>
  <!-- Virtual joint from middle->distal   -->
  <joint name="left_hand_v1_wide_index_distal_virtual_joint" type="revolute">
    <axis xyz="0 0 1"/>
    <limit effort="30" lower="0" upper="0.785398" velocity="0.0"/>
    <origin rpy="0 0 0" xyz="41e-3 0 0"/>
    <parent link="left_hand_v1_wide_index_middle_link"/>
    <child link="left_hand_v1_wide_index_distal_virtual_link"/>
    <dynamics damping="3e-2" friction="0.0"/>
  </joint>
  <link name="left_hand_v1_wide_index_distal_virtual_link">
    <inertial>
      <origin rpy="0 0 0" xyz="0 0 0"/>
      <mass value="0.012475845"/>
      <inertia ixx="7.5548908e-07" ixy="0.0" ixz="0.0" iyy="1.2532982e-06" iyz="0.0" izz="1.3218760e-06"/>
    </inertial>
  </link>
  <!-- Proximal phalanx -->
  <joint name="left_hand_v1_wide_index_distal_joint" type="revolute">
    <axis xyz="0 0 1"/>
    <limit effort="30" lower="0" upper="0.785398" velocity="0.0"/>
    <origin rpy="0 0 0" xyz="9e-3 0 0"/>
    <parent link="left_hand_v1_wide_index_distal_virtual_link"/>
    <child link="left_hand_v1_wide_index_distal_link"/>
    <dynamics damping="3e-2" friction="0.0"/>
  </joint>
  <link name="left_hand_v1_wide_index_distal_link">
    <visual>
      <material name="grey"/>
      <geometry>
        <mesh filename="package://softhands_description/meshes/v1_wide/left/phalanx_dist.stl" scale="0.001 0.001 0.001"/>
      </geometry>
      <origin rpy="0 0 0" xyz="0 0 0"/>
    </visual>
    <inertial>
      <mass value="0.012475845"/>
      <inertia ixx="7.5548908e-07" ixy="0.0" ixz="0.0" iyy="1.2532982e-06" iyz="0.0" izz="1.3218760e-06"/>
      <origin rpy="0 0 0" xyz="1.2887396e-02 6.2001804e-05 -1.1041989e-03"/>
    </inertial>
    <collision>
      <geometry>
        <mesh filename="package://softhands_description/meshes/v1_wide/left/phalanx_dist_collision.stl" scale="0.0009 0.0009 0.0009"/>
      </geometry>
      <origin rpy="0 0 0" xyz="0 0 0"/>
    </collision>
  </link>
  <gazebo reference="left_hand_v1_wide_index_distal_link">
    <material>Gazebo/Gray</material>
    <selfCollide>0</selfCollide>
  </gazebo>
  <!-- GAZEBO REF -->
  <gazebo reference="left_hand_v1_wide_index_distal_virtual_joint">
    <implicitSpringDamper>true</implicitSpringDamper>
    <springStiffness>0.4</springStiffness>
    <springReference>0</springReference>
  </gazebo>
  <!-- GAZEBO REF -->
  <gazebo reference="left_hand_v1_wide_index_distal_joint">
    <implicitSpringDamper>true</implicitSpringDamper>
    <springStiffness>0.4</springStiffness>
    <springReference>0</springReference>
  </gazebo>
  <!-- Support -->
  <joint name="left_hand_v1_wide_middle_knuckle_joint" type="revolute">
    <axis xyz="0 1 0"/>
    <limit effort="30" lower="0.0" upper="0.01" velocity="0.0"/>
    <origin rpy="0 0 0 " xyz="5e-3 -12.5e-3 115e-3"/>
    <parent link="left_hand_v1_wide_palm_central_link"/>
    <child link="left_hand_v1_wide_middle_knuckle_link"/>
  </joint>
  <link name="left_hand_v1_wide_middle_knuckle_link">
    <visual>
      <material name="grey"/>
      <geometry>
        <mesh filename="package://softhands_description/meshes/v1_wide/left/phalanx_pros_sup.stl" scale="0.001 0.001 0.001"/>
      </geometry>
      <origin rpy="0 0 0" xyz="0 0 0"/>
    </visual>
    <inertial>
      <mass value="7.4913242e-03"/>
      <origin rpy="0 0 0" xyz="1.8035857e-02 -4.0351343e-03 -4.4165266e-05 "/>
      <inertia ixx="5.3708642e-07" ixy="0.0" ixz="1.5304482e-07" iyy="6.1466440e-07" iyz="-4.4383298e-09" izz="5.5136271e-07"/>
    </inertial>
    <collision>
      <geometry>
        <mesh filename="package://softhands_description/meshes/v1_wide/left/phalanx_pros_sup_collision.stl" scale="0.0009 0.0009 0.0009"/>
      </geometry>
      <origin rpy="0 0 0" xyz="0 0 0"/>
    </collision>
  </link>
  <gazebo reference="left_hand_v1_wide_middle_knuckle_link">
    <selfCollide>0</selfCollide>
    <material>Gazebo/White</material>
  </gazebo>
  <!-- Virtual joint from knuckle->proximal or proximal->middle   -->
  <joint name="left_hand_v1_wide_middle_proximal_virtual_joint" type="revolute">
    <axis xyz="0 0 1"/>
    <limit effort="30" lower="0" upper="0.785398" velocity="0.0"/>
    <origin rpy="-1.5707963 -1.5707963 0" xyz=" -6.5e-3 0 24e-3"/>
    <parent link="left_hand_v1_wide_middle_knuckle_link"/>
    <child link="left_hand_v1_wide_middle_proximal_virtual_link"/>
    <dynamics damping="3e-2" friction="0.0"/>
  </joint>
  <link name="left_hand_v1_wide_middle_proximal_virtual_link">
    <inertial>
      <origin rpy="0 0 0" xyz="0 0 0"/>
      <mass value="0.024190505"/>
      <inertia ixx="1.9981795e-06" ixy="-6.0806048e-08" ixz="0.0" iyy="4.7810654e-06" iyz="0.0" izz="5.0961924e-06"/>
    </inertial>
  </link>
  <!-- Proximal phalanx -->
  <joint name="left_hand_v1_wide_middle_proximal_joint" type="revolute">
    <axis xyz="0 0 1"/>
    <limit effort="30" lower="0" upper="0.785398" velocity="0.0"/>
    <origin rpy="0 0 0" xyz="9e-3 0 0"/>
    <parent link="left_hand_v1_wide_middle_proximal_virtual_link"/>
    <child link="left_hand_v1_wide_middle_proximal_link"/>
    <dynamics damping="3e-2" friction="0.0"/>
  </joint>
  <link name="left_hand_v1_wide_middle_proximal_link">
    <visual>
      <material name="grey"/>
      <geometry>
        <mesh filename="package://softhands_description/meshes/v1_wide/left/phalanx.stl" scale="0.001 0.001 0.001"/>
      </geometry>
      <origin rpy="0 0 0" xyz="0 0 0"/>
    </visual>
    <inertial>
      <mass value="0.024190505"/>
      <inertia ixx="1.9981795e-06" ixy="-6.0806048e-08" ixz="0.0" iyy="4.7810654e-06" iyz="0.0" izz="5.0961924e-06"/>
      <origin rpy="0 0 0" xyz=" 2.0923634e-02  8.4162795e-04 -5.2131884e-05"/>
    </inertial>
    <collision>
      <geometry>
        <mesh filename="package://softhands_description/meshes/v1_wide/left/phalanx_collision.stl" scale="0.0009 0.0009 0.0009"/>
      </geometry>
      <origin rpy="0 0 0" xyz="0 0 0"/>
    </collision>
  </link>
  <gazebo reference="left_hand_v1_wide_middle_proximal_link">
    <material>Gazebo/Gray</material>
    <selfCollide>0</selfCollide>
  </gazebo>
  <!-- GAZEBO REF -->
  <gazebo reference="left_hand_v1_wide_middle_proximal_virtual_joint">
    <implicitSpringDamper>true</implicitSpringDamper>
    <springStiffness>0.4</springStiffness>
    <springReference>0</springReference>
  </gazebo>
  <!-- GAZEBO REF -->
  <gazebo reference="left_hand_v1_wide_middle_proximal_joint">
    <implicitSpringDamper>true</implicitSpringDamper>
    <springStiffness>0.4</springStiffness>
    <springReference>0</springReference>
  </gazebo>
  <!-- Virtual joint from knuckle->proximal or proximal->middle   -->
  <joint name="left_hand_v1_wide_middle_middle_virtual_joint" type="revolute">
    <axis xyz="0 0 1"/>
    <limit effort="30" lower="0" upper="0.785398" velocity="0.0"/>
    <origin rpy="0 0 0" xyz="41e-3 0 0"/>
    <parent link="left_hand_v1_wide_middle_proximal_link"/>
    <child link="left_hand_v1_wide_middle_middle_virtual_link"/>
    <dynamics damping="3e-2" friction="0.0"/>
  </joint>
  <link name="left_hand_v1_wide_middle_middle_virtual_link">
    <inertial>
      <origin rpy="0 0 0" xyz="0 0 0"/>
      <mass value="0.024190505"/>
      <inertia ixx="1.9981795e-06" ixy="-6.0806048e-08" ixz="0.0" iyy="4.7810654e-06" iyz="0.0" izz="5.0961924e-06"/>
    </inertial>
  </link>
  <!-- Proximal phalanx -->
  <joint name="left_hand_v1_wide_middle_middle_joint" type="revolute">
    <axis xyz="0 0 1"/>
    <limit effort="30" lower="0" upper="0.785398" velocity="0.0"/>
    <origin rpy="0 0 0" xyz="9e-3 0 0"/>
    <parent link="left_hand_v1_wide_middle_middle_virtual_link"/>
    <child link="left_hand_v1_wide_middle_middle_link"/>
    <dynamics damping="3e-2" friction="0.0"/>
  </joint>
  <link name="left_hand_v1_wide_middle_middle_link">
    <visual>
      <material name="grey"/>
      <geometry>
        <mesh filename="package://softhands_description/meshes/v1_wide/left/phalanx.stl" scale="0.001 0.001 0.001"/>
      </geometry>
      <origin rpy="0 0 0" xyz="0 0 0"/>
    </visual>
    <inertial>
      <mass value="0.024190505"/>
      <inertia ixx="1.9981795e-06" ixy="-6.0806048e-08" ixz="0.0" iyy="4.7810654e-06" iyz="0.0" izz="5.0961924e-06"/>
      <origin rpy="0 0 0" xyz=" 2.0923634e-02  8.4162795e-04 -5.2131884e-05"/>
    </inertial>
    <collision>
      <geometry>
        <mesh filename="package://softhands_description/meshes/v1_wide/left/phalanx_collision.stl" scale="0.0009 0.0009 0.0009"/>
      </geometry>
      <origin rpy="0 0 0" xyz="0 0 0"/>
    </collision>
  </link>
  <gazebo reference="left_hand_v1_wide_middle_middle_link">
    <material>Gazebo/Gray</material>
    <selfCollide>0</selfCollide>
  </gazebo>
  <!-- GAZEBO REF -->
  <gazebo reference="left_hand_v1_wide_middle_middle_virtual_joint">
    <implicitSpringDamper>true</implicitSpringDamper>
    <springStiffness>0.4</springStiffness>
    <springReference>0</springReference>
  </gazebo>
  <!-- GAZEBO REF -->
  <gazebo reference="left_hand_v1_wide_middle_middle_joint">
    <implicitSpringDamper>true</implicitSpringDamper>
    <springStiffness>0.4</springStiffness>
    <springReference>0</springReference>
  </gazebo>
  <!-- Virtual joint from middle->distal   -->
  <joint name="left_hand_v1_wide_middle_distal_virtual_joint" type="revolute">
    <axis xyz="0 0 1"/>
    <limit effort="30" lower="0" upper="0.785398" velocity="0.0"/>
    <origin rpy="0 0 0" xyz="41e-3 0 0"/>
    <parent link="left_hand_v1_wide_middle_middle_link"/>
    <child link="left_hand_v1_wide_middle_distal_virtual_link"/>
    <dynamics damping="3e-2" friction="0.0"/>
  </joint>
  <link name="left_hand_v1_wide_middle_distal_virtual_link">
    <inertial>
      <origin rpy="0 0 0" xyz="0 0 0"/>
      <mass value="0.012475845"/>
      <inertia ixx="7.5548908e-07" ixy="0.0" ixz="0.0" iyy="1.2532982e-06" iyz="0.0" izz="1.3218760e-06"/>
    </inertial>
  </link>
  <!-- Proximal phalanx -->
  <joint name="left_hand_v1_wide_middle_distal_joint" type="revolute">
    <axis xyz="0 0 1"/>
    <limit effort="30" lower="0" upper="0.785398" velocity="0.0"/>
    <origin rpy="0 0 0" xyz="9e-3 0 0"/>
    <parent link="left_hand_v1_wide_middle_distal_virtual_link"/>
    <child link="left_hand_v1_wide_middle_distal_link"/>
    <dynamics damping="3e-2" friction="0.0"/>
  </joint>
  <link name="left_hand_v1_wide_middle_distal_link">
    <visual>
      <material name="grey"/>
      <geometry>
        <mesh filename="package://softhands_description/meshes/v1_wide/left/phalanx_dist.stl" scale="0.001 0.001 0.001"/>
      </geometry>
      <origin rpy="0 0 0" xyz="0 0 0"/>
    </visual>
    <inertial>
      <mass value="0.012475845"/>
      <inertia ixx="7.5548908e-07" ixy="0.0" ixz="0.0" iyy="1.2532982e-06" iyz="0.0" izz="1.3218760e-06"/>
      <origin rpy="0 0 0" xyz="1.2887396e-02 6.2001804e-05 -1.1041989e-03"/>
    </inertial>
    <collision>
      <geometry>
        <mesh filename="package://softhands_description/meshes/v1_wide/left/phalanx_dist_collision.stl" scale="0.0009 0.0009 0.0009"/>
      </geometry>
      <origin rpy="0 0 0" xyz="0 0 0"/>
    </collision>
  </link>
  <gazebo reference="left_hand_v1_wide_middle_distal_link">
    <material>Gazebo/Gray</material>
    <selfCollide>0</selfCollide>
  </gazebo>
  <!-- GAZEBO REF -->
  <gazebo reference="left_hand_v1_wide_middle_distal_virtual_joint">
    <implicitSpringDamper>true</implicitSpringDamper>
    <springStiffness>0.4</springStiffness>
    <springReference>0</springReference>
  </gazebo>
  <!-- GAZEBO REF -->
  <gazebo reference="left_hand_v1_wide_middle_distal_joint">
    <implicitSpringDamper>true</implicitSpringDamper>
    <springStiffness>0.4</springStiffness>
    <springReference>0</springReference>
  </gazebo>
  <!-- Support -->
  <joint name="left_hand_v1_wide_ring_knuckle_joint" type="revolute">
    <axis xyz="0 1 0"/>
    <limit effort="30" lower="0.0" upper="0.01" velocity="0.0"/>
    <origin rpy="2.8797933 0 1.5707963 " xyz=" 8.6355e-3 5e-3 -44.4863e-3"/>
    <parent link="left_hand_v1_wide_palm_little_link"/>
    <child link="left_hand_v1_wide_ring_knuckle_link"/>
  </joint>
  <link name="left_hand_v1_wide_ring_knuckle_link">
    <visual>
      <material name="grey"/>
      <geometry>
        <mesh filename="package://softhands_description/meshes/v1_wide/left/phalanx_pros_sup.stl" scale="0.001 0.001 0.001"/>
      </geometry>
      <origin rpy="0 0 0" xyz="0 0 0"/>
    </visual>
    <inertial>
      <mass value="7.4913242e-03"/>
      <origin rpy="0 0 0" xyz="1.8035857e-02 -4.0351343e-03 -4.4165266e-05 "/>
      <inertia ixx="5.3708642e-07" ixy="0.0" ixz="1.5304482e-07" iyy="6.1466440e-07" iyz="-4.4383298e-09" izz="5.5136271e-07"/>
    </inertial>
    <collision>
      <geometry>
        <mesh filename="package://softhands_description/meshes/v1_wide/left/phalanx_pros_sup_collision.stl" scale="0.0009 0.0009 0.0009"/>
      </geometry>
      <origin rpy="0 0 0" xyz="0 0 0"/>
    </collision>
  </link>
  <gazebo reference="left_hand_v1_wide_ring_knuckle_link">
    <selfCollide>0</selfCollide>
    <material>Gazebo/White</material>
  </gazebo>
  <!-- Virtual joint from knuckle->proximal or proximal->middle   -->
  <joint name="left_hand_v1_wide_ring_proximal_virtual_joint" type="revolute">
    <axis xyz="0 0 1"/>
    <limit effort="30" lower="0" upper="0.785398" velocity="0.0"/>
    <origin rpy="-1.5707963 -1.5707963 0" xyz=" -6.5e-3 0 24e-3"/>
    <parent link="left_hand_v1_wide_ring_knuckle_link"/>
    <child link="left_hand_v1_wide_ring_proximal_virtual_link"/>
    <dynamics damping="3e-2" friction="0.0"/>
  </joint>
  <link name="left_hand_v1_wide_ring_proximal_virtual_link">
    <inertial>
      <origin rpy="0 0 0" xyz="0 0 0"/>
      <mass value="0.024190505"/>
      <inertia ixx="1.9981795e-06" ixy="-6.0806048e-08" ixz="0.0" iyy="4.7810654e-06" iyz="0.0" izz="5.0961924e-06"/>
    </inertial>
  </link>
  <!-- Proximal phalanx -->
  <joint name="left_hand_v1_wide_ring_proximal_joint" type="revolute">
    <axis xyz="0 0 1"/>
    <limit effort="30" lower="0" upper="0.785398" velocity="0.0"/>
    <origin rpy="0 0 0" xyz="9e-3 0 0"/>
    <parent link="left_hand_v1_wide_ring_proximal_virtual_link"/>
    <child link="left_hand_v1_wide_ring_proximal_link"/>
    <dynamics damping="3e-2" friction="0.0"/>
  </joint>
  <link name="left_hand_v1_wide_ring_proximal_link">
    <visual>
      <material name="grey"/>
      <geometry>
        <mesh filename="package://softhands_description/meshes/v1_wide/left/phalanx.stl" scale="0.001 0.001 0.001"/>
      </geometry>
      <origin rpy="0 0 0" xyz="0 0 0"/>
    </visual>
    <inertial>
      <mass value="0.024190505"/>
      <inertia ixx="1.9981795e-06" ixy="-6.0806048e-08" ixz="0.0" iyy="4.7810654e-06" iyz="0.0" izz="5.0961924e-06"/>
      <origin rpy="0 0 0" xyz=" 2.0923634e-02  8.4162795e-04 -5.2131884e-05"/>
    </inertial>
    <collision>
      <geometry>
        <mesh filename="package://softhands_description/meshes/v1_wide/left/phalanx_collision.stl" scale="0.0009 0.0009 0.0009"/>
      </geometry>
      <origin rpy="0 0 0" xyz="0 0 0"/>
    </collision>
  </link>
  <gazebo reference="left_hand_v1_wide_ring_proximal_link">
    <material>Gazebo/Gray</material>
    <selfCollide>0</selfCollide>
  </gazebo>
  <!-- GAZEBO REF -->
  <gazebo reference="left_hand_v1_wide_ring_proximal_virtual_joint">
    <implicitSpringDamper>true</implicitSpringDamper>
    <springStiffness>0.4</springStiffness>
    <springReference>0</springReference>
  </gazebo>
  <!-- GAZEBO REF -->
  <gazebo reference="left_hand_v1_wide_ring_proximal_joint">
    <implicitSpringDamper>true</implicitSpringDamper>
    <springStiffness>0.4</springStiffness>
    <springReference>0</springReference>
  </gazebo>
  <!-- Virtual joint from knuckle->proximal or proximal->middle   -->
  <joint name="left_hand_v1_wide_ring_middle_virtual_joint" type="revolute">
    <axis xyz="0 0 1"/>
    <limit effort="30" lower="0" upper="0.785398" velocity="0.0"/>
    <origin rpy="0 0 0" xyz="41e-3 0 0"/>
    <parent link="left_hand_v1_wide_ring_proximal_link"/>
    <child link="left_hand_v1_wide_ring_middle_virtual_link"/>
    <dynamics damping="3e-2" friction="0.0"/>
  </joint>
  <link name="left_hand_v1_wide_ring_middle_virtual_link">
    <inertial>
      <origin rpy="0 0 0" xyz="0 0 0"/>
      <mass value="0.024190505"/>
      <inertia ixx="1.9981795e-06" ixy="-6.0806048e-08" ixz="0.0" iyy="4.7810654e-06" iyz="0.0" izz="5.0961924e-06"/>
    </inertial>
  </link>
  <!-- Proximal phalanx -->
  <joint name="left_hand_v1_wide_ring_middle_joint" type="revolute">
    <axis xyz="0 0 1"/>
    <limit effort="30" lower="0" upper="0.785398" velocity="0.0"/>
    <origin rpy="0 0 0" xyz="9e-3 0 0"/>
    <parent link="left_hand_v1_wide_ring_middle_virtual_link"/>
    <child link="left_hand_v1_wide_ring_middle_link"/>
    <dynamics damping="3e-2" friction="0.0"/>
  </joint>
  <link name="left_hand_v1_wide_ring_middle_link">
    <visual>
      <material name="grey"/>
      <geometry>
        <mesh filename="package://softhands_description/meshes/v1_wide/left/phalanx.stl" scale="0.001 0.001 0.001"/>
      </geometry>
      <origin rpy="0 0 0" xyz="0 0 0"/>
    </visual>
    <inertial>
      <mass value="0.024190505"/>
      <inertia ixx="1.9981795e-06" ixy="-6.0806048e-08" ixz="0.0" iyy="4.7810654e-06" iyz="0.0" izz="5.0961924e-06"/>
      <origin rpy="0 0 0" xyz=" 2.0923634e-02  8.4162795e-04 -5.2131884e-05"/>
    </inertial>
    <collision>
      <geometry>
        <mesh filename="package://softhands_description/meshes/v1_wide/left/phalanx_collision.stl" scale="0.0009 0.0009 0.0009"/>
      </geometry>
      <origin rpy="0 0 0" xyz="0 0 0"/>
    </collision>
  </link>
  <gazebo reference="left_hand_v1_wide_ring_middle_link">
    <material>Gazebo/Gray</material>
    <selfCollide>0</selfCollide>
  </gazebo>
  <!-- GAZEBO REF -->
  <gazebo reference="left_hand_v1_wide_ring_middle_virtual_joint">
    <implicitSpringDamper>true</implicitSpringDamper>
    <springStiffness>0.4</springStiffness>
    <springReference>0</springReference>
  </gazebo>
  <!-- GAZEBO REF -->
  <gazebo reference="left_hand_v1_wide_ring_middle_joint">
    <implicitSpringDamper>true</implicitSpringDamper>
    <springStiffness>0.4</springStiffness>
    <springReference>0</springReference>
  </gazebo>
  <!-- Virtual joint from middle->distal   -->
  <joint name="left_hand_v1_wide_ring_distal_virtual_joint" type="revolute">
    <axis xyz="0 0 1"/>
    <limit effort="30" lower="0" upper="0.785398" velocity="0.0"/>
    <origin rpy="0 0 0" xyz="41e-3 0 0"/>
    <parent link="left_hand_v1_wide_ring_middle_link"/>
    <child link="left_hand_v1_wide_ring_distal_virtual_link"/>
    <dynamics damping="3e-2" friction="0.0"/>
  </joint>
  <link name="left_hand_v1_wide_ring_distal_virtual_link">
    <inertial>
      <origin rpy="0 0 0" xyz="0 0 0"/>
      <mass value="0.012475845"/>
      <inertia ixx="7.5548908e-07" ixy="0.0" ixz="0.0" iyy="1.2532982e-06" iyz="0.0" izz="1.3218760e-06"/>
    </inertial>
  </link>
  <!-- Proximal phalanx -->
  <joint name="left_hand_v1_wide_ring_distal_joint" type="revolute">
    <axis xyz="0 0 1"/>
    <limit effort="30" lower="0" upper="0.785398" velocity="0.0"/>
    <origin rpy="0 0 0" xyz="9e-3 0 0"/>
    <parent link="left_hand_v1_wide_ring_distal_virtual_link"/>
    <child link="left_hand_v1_wide_ring_distal_link"/>
    <dynamics damping="3e-2" friction="0.0"/>
  </joint>
  <link name="left_hand_v1_wide_ring_distal_link">
    <visual>
      <material name="grey"/>
      <geometry>
        <mesh filename="package://softhands_description/meshes/v1_wide/left/phalanx_dist.stl" scale="0.001 0.001 0.001"/>
      </geometry>
      <origin rpy="0 0 0" xyz="0 0 0"/>
    </visual>
    <inertial>
      <mass value="0.012475845"/>
      <inertia ixx="7.5548908e-07" ixy="0.0" ixz="0.0" iyy="1.2532982e-06" iyz="0.0" izz="1.3218760e-06"/>
      <origin rpy="0 0 0" xyz="1.2887396e-02 6.2001804e-05 -1.1041989e-03"/>
    </inertial>
    <collision>
      <geometry>
        <mesh filename="package://softhands_description/meshes/v1_wide/left/phalanx_dist_collision.stl" scale="0.0009 0.0009 0.0009"/>
      </geometry>
      <origin rpy="0 0 0" xyz="0 0 0"/>
    </collision>
  </link>
  <gazebo reference="left_hand_v1_wide_ring_distal_link">
    <material>Gazebo/Gray</material>
    <selfCollide>0</selfCollide>
  </gazebo>
  <!-- GAZEBO REF -->
  <gazebo reference="left_hand_v1_wide_ring_distal_virtual_joint">
    <implicitSpringDamper>true</implicitSpringDamper>
    <springStiffness>0.4</springStiffness>
    <springReference>0</springReference>
  </gazebo>
  <!-- GAZEBO REF -->
  <gazebo reference="left_hand_v1_wide_ring_distal_joint">
    <implicitSpringDamper>true</implicitSpringDamper>
    <springStiffness>0.4</springStiffness>
    <springReference>0</springReference>
  </gazebo>
  <!-- Support -->
  <joint name="left_hand_v1_wide_little_knuckle_joint" type="revolute">
    <axis xyz="0 1 0"/>
    <limit effort="30" lower="0.0" upper="0.01" velocity="0.0"/>
    <origin rpy="2.792527 0 1.5707963 " xyz="39.2985e-3 5e-3 -34.8419e-3"/>
    <parent link="left_hand_v1_wide_palm_little_link"/>
    <child link="left_hand_v1_wide_little_knuckle_link"/>
  </joint>
  <link name="left_hand_v1_wide_little_knuckle_link">
    <visual>
      <material name="grey"/>
      <geometry>
        <mesh filename="package://softhands_description/meshes/v1_wide/left/phalanx_pros_sup.stl" scale="0.001 0.001 0.001"/>
      </geometry>
      <origin rpy="0 0 0" xyz="0 0 0"/>
    </visual>
    <inertial>
      <mass value="7.4913242e-03"/>
      <origin rpy="0 0 0" xyz="1.8035857e-02 -4.0351343e-03 -4.4165266e-05 "/>
      <inertia ixx="5.3708642e-07" ixy="0.0" ixz="1.5304482e-07" iyy="6.1466440e-07" iyz="-4.4383298e-09" izz="5.5136271e-07"/>
    </inertial>
    <collision>
      <geometry>
        <mesh filename="package://softhands_description/meshes/v1_wide/left/phalanx_pros_sup_collision.stl" scale="0.0009 0.0009 0.0009"/>
      </geometry>
      <origin rpy="0 0 0" xyz="0 0 0"/>
    </collision>
  </link>
  <gazebo reference="left_hand_v1_wide_little_knuckle_link">
    <selfCollide>0</selfCollide>
    <material>Gazebo/White</material>
  </gazebo>
  <!-- Virtual joint from knuckle->proximal or proximal->middle   -->
  <joint name="left_hand_v1_wide_little_proximal_virtual_joint" type="revolute">
    <axis xyz="0 0 1"/>
    <limit effort="30" lower="0" upper="0.785398" velocity="0.0"/>
    <origin rpy="-1.5707963 -1.5707963 0" xyz=" -6.5e-3 0 24e-3"/>
    <parent link="left_hand_v1_wide_little_knuckle_link"/>
    <child link="left_hand_v1_wide_little_proximal_virtual_link"/>
    <dynamics damping="3e-2" friction="0.0"/>
  </joint>
  <link name="left_hand_v1_wide_little_proximal_virtual_link">
    <inertial>
      <origin rpy="0 0 0" xyz="0 0 0"/>
      <mass value="0.024190505"/>
      <inertia ixx="1.9981795e-06" ixy="-6.0806048e-08" ixz="0.0" iyy="4.7810654e-06" iyz="0.0" izz="5.0961924e-06"/>
    </inertial>
  </link>
  <!-- Proximal phalanx -->
  <joint name="left_hand_v1_wide_little_proximal_joint" type="revolute">
    <axis xyz="0 0 1"/>
    <limit effort="30" lower="0" upper="0.785398" velocity="0.0"/>
    <origin rpy="0 0 0" xyz="9e-3 0 0"/>
    <parent link="left_hand_v1_wide_little_proximal_virtual_link"/>
    <child link="left_hand_v1_wide_little_proximal_link"/>
    <dynamics damping="3e-2" friction="0.0"/>
  </joint>
  <link name="left_hand_v1_wide_little_proximal_link">
    <visual>
      <material name="grey"/>
      <geometry>
        <mesh filename="package://softhands_description/meshes/v1_wide/left/phalanx.stl" scale="0.001 0.001 0.001"/>
      </geometry>
      <origin rpy="0 0 0" xyz="0 0 0"/>
    </visual>
    <inertial>
      <mass value="0.024190505"/>
      <inertia ixx="1.9981795e-06" ixy="-6.0806048e-08" ixz="0.0" iyy="4.7810654e-06" iyz="0.0" izz="5.0961924e-06"/>
      <origin rpy="0 0 0" xyz=" 2.0923634e-02  8.4162795e-04 -5.2131884e-05"/>
    </inertial>
    <collision>
      <geometry>
        <mesh filename="package://softhands_description/meshes/v1_wide/left/phalanx_collision.stl" scale="0.0009 0.0009 0.0009"/>
      </geometry>
      <origin rpy="0 0 0" xyz="0 0 0"/>
    </collision>
  </link>
  <gazebo reference="left_hand_v1_wide_little_proximal_link">
    <material>Gazebo/Gray</material>
    <selfCollide>0</selfCollide>
  </gazebo>
  <!-- GAZEBO REF -->
  <gazebo reference="left_hand_v1_wide_little_proximal_virtual_joint">
    <implicitSpringDamper>true</implicitSpringDamper>
    <springStiffness>0.4</springStiffness>
    <springReference>0</springReference>
  </gazebo>
  <!-- GAZEBO REF -->
  <gazebo reference="left_hand_v1_wide_little_proximal_joint">
    <implicitSpringDamper>true</implicitSpringDamper>
    <springStiffness>0.4</springStiffness>
    <springReference>0</springReference>
  </gazebo>
  <!-- Virtual joint from knuckle->proximal or proximal->middle   -->
  <joint name="left_hand_v1_wide_little_middle_virtual_joint" type="revolute">
    <axis xyz="0 0 1"/>
    <limit effort="30" lower="0" upper="0.785398" velocity="0.0"/>
    <origin rpy="0 0 0" xyz="41e-3 0 0"/>
    <parent link="left_hand_v1_wide_little_proximal_link"/>
    <child link="left_hand_v1_wide_little_middle_virtual_link"/>
    <dynamics damping="3e-2" friction="0.0"/>
  </joint>
  <link name="left_hand_v1_wide_little_middle_virtual_link">
    <inertial>
      <origin rpy="0 0 0" xyz="0 0 0"/>
      <mass value="0.024190505"/>
      <inertia ixx="1.9981795e-06" ixy="-6.0806048e-08" ixz="0.0" iyy="4.7810654e-06" iyz="0.0" izz="5.0961924e-06"/>
    </inertial>
  </link>
  <!-- Proximal phalanx -->
  <joint name="left_hand_v1_wide_little_middle_joint" type="revolute">
    <axis xyz="0 0 1"/>
    <limit effort="30" lower="0" upper="0.785398" velocity="0.0"/>
    <origin rpy="0 0 0" xyz="9e-3 0 0"/>
    <parent link="left_hand_v1_wide_little_middle_virtual_link"/>
    <child link="left_hand_v1_wide_little_middle_link"/>
    <dynamics damping="3e-2" friction="0.0"/>
  </joint>
  <link name="left_hand_v1_wide_little_middle_link">
    <visual>
      <material name="grey"/>
      <geometry>
        <mesh filename="package://softhands_description/meshes/v1_wide/left/phalanx.stl" scale="0.001 0.001 0.001"/>
      </geometry>
      <origin rpy="0 0 0" xyz="0 0 0"/>
    </visual>
    <inertial>
      <mass value="0.024190505"/>
      <inertia ixx="1.9981795e-06" ixy="-6.0806048e-08" ixz="0.0" iyy="4.7810654e-06" iyz="0.0" izz="5.0961924e-06"/>
      <origin rpy="0 0 0" xyz=" 2.0923634e-02  8.4162795e-04 -5.2131884e-05"/>
    </inertial>
    <collision>
      <geometry>
        <mesh filename="package://softhands_description/meshes/v1_wide/left/phalanx_collision.stl" scale="0.0009 0.0009 0.0009"/>
      </geometry>
      <origin rpy="0 0 0" xyz="0 0 0"/>
    </collision>
  </link>
  <gazebo reference="left_hand_v1_wide_little_middle_link">
    <material>Gazebo/Gray</material>
    <selfCollide>0</selfCollide>
  </gazebo>
  <!-- GAZEBO REF -->
  <gazebo reference="left_hand_v1_wide_little_middle_virtual_joint">
    <implicitSpringDamper>true</implicitSpringDamper>
    <springStiffness>0.4</springStiffness>
    <springReference>0</springReference>
  </gazebo>
  <!-- GAZEBO REF -->
  <gazebo reference="left_hand_v1_wide_little_middle_joint">
    <implicitSpringDamper>true</implicitSpringDamper>
    <springStiffness>0.4</springStiffness>
    <springReference>0</springReference>
  </gazebo>
  <!-- Virtual joint from middle->distal   -->
  <joint name="left_hand_v1_wide_little_distal_virtual_joint" type="revolute">
    <axis xyz="0 0 1"/>
    <limit effort="30" lower="0" upper="0.785398" velocity="0.0"/>
    <origin rpy="0 0 0" xyz="41e-3 0 0"/>
    <parent link="left_hand_v1_wide_little_middle_link"/>
    <child link="left_hand_v1_wide_little_distal_virtual_link"/>
    <dynamics damping="3e-2" friction="0.0"/>
  </joint>
  <link name="left_hand_v1_wide_little_distal_virtual_link">
    <inertial>
      <origin rpy="0 0 0" xyz="0 0 0"/>
      <mass value="0.012475845"/>
      <inertia ixx="7.5548908e-07" ixy="0.0" ixz="0.0" iyy="1.2532982e-06" iyz="0.0" izz="1.3218760e-06"/>
    </inertial>
  </link>
  <!-- Proximal phalanx -->
  <joint name="left_hand_v1_wide_little_distal_joint" type="revolute">
    <axis xyz="0 0 1"/>
    <limit effort="30" lower="0" upper="0.785398" velocity="0.0"/>
    <origin rpy="0 0 0" xyz="9e-3 0 0"/>
    <parent link="left_hand_v1_wide_little_distal_virtual_link"/>
    <child link="left_hand_v1_wide_little_distal_link"/>
    <dynamics damping="3e-2" friction="0.0"/>
  </joint>
  <link name="left_hand_v1_wide_little_distal_link">
    <visual>
      <material name="grey"/>
      <geometry>
        <mesh filename="package://softhands_description/meshes/v1_wide/left/phalanx_dist.stl" scale="0.001 0.001 0.001"/>
      </geometry>
      <origin rpy="0 0 0" xyz="0 0 0"/>
    </visual>
    <inertial>
      <mass value="0.012475845"/>
      <inertia ixx="7.5548908e-07" ixy="0.0" ixz="0.0" iyy="1.2532982e-06" iyz="0.0" izz="1.3218760e-06"/>
      <origin rpy="0 0 0" xyz="1.2887396e-02 6.2001804e-05 -1.1041989e-03"/>
    </inertial>
    <collision>
      <geometry>
        <mesh filename="package://softhands_description/meshes/v1_wide/left/phalanx_dist_collision.stl" scale="0.0009 0.0009 0.0009"/>
      </geometry>
      <origin rpy="0 0 0" xyz="0 0 0"/>
    </collision>
  </link>
  <gazebo reference="left_hand_v1_wide_little_distal_link">
    <material>Gazebo/Gray</material>
    <selfCollide>0</selfCollide>
  </gazebo>
  <!-- GAZEBO REF -->
  <gazebo reference="left_hand_v1_wide_little_distal_virtual_joint">
    <implicitSpringDamper>true</implicitSpringDamper>
    <springStiffness>0.4</springStiffness>
    <springReference>0</springReference>
  </gazebo>
  <!-- GAZEBO REF -->
  <gazebo reference="left_hand_v1_wide_little_distal_joint">
    <implicitSpringDamper>true</implicitSpringDamper>
    <springStiffness>0.4</springStiffness>
    <springReference>0</springReference>
  </gazebo>
  <gazebo>
    <plugin filename="libsofthand_mimic_plugin.so" name="synergy_plugin">
      <namespace>right_hand_v1_wide</namespace>
      <operation_mode>0</operation_mode>
      <spring_k>5</spring_k>
      <wide>True</wide>
      <r_finger>0.0033</r_finger>
      <R_pulley>0.0053</R_pulley>
      <n_param>0.058</n_param>
      <synS_thumb_j1>3</synS_thumb_j1>
      <synS_thumb_j2>1.2</synS_thumb_j2>
      <synS_thumb_j3>1.2</synS_thumb_j3>
      <k_thumb_j1>0.8</k_thumb_j1>
      <k_thumb_j2>0.8</k_thumb_j2>
      <k_thumb_j3>0.8</k_thumb_j3>
      <synS_index_j1>-0.3</synS_index_j1>
      <synS_index_j2>1.57</synS_index_j2>
      <synS_index_j3>1.25</synS_index_j3>
      <synS_index_j4>0.8</synS_index_j4>
      <k_index_j1>0.15</k_index_j1>
      <k_index_j2>0.5</k_index_j2>
      <k_index_j3>0.5</k_index_j3>
      <k_index_j4>0.5</k_index_j4>
      <synS_middle_j1>0</synS_middle_j1>
      <synS_middle_j2>1.57</synS_middle_j2>
      <synS_middle_j3>1.25</synS_middle_j3>
      <synS_middle_j4>1.25</synS_middle_j4>
      <k_middle_j1>0.15</k_middle_j1>
      <k_middle_j2>0.5</k_middle_j2>
      <k_middle_j3>0.5</k_middle_j3>
      <k_middle_j4>0.5</k_middle_j4>
      <synS_ring_j1>0</synS_ring_j1>
      <synS_ring_j2>1.57</synS_ring_j2>
      <synS_ring_j3>1.0</synS_ring_j3>
      <synS_ring_j4>1.0</synS_ring_j4>
      <k_ring_j1>0.15</k_ring_j1>
      <k_ring_j2>0.5</k_ring_j2>
      <k_ring_j3>0.5</k_ring_j3>
      <k_ring_j4>0.5</k_ring_j4>
      <synS_little_j1>0.1</synS_little_j1>
      <synS_little_j2>1.57</synS_little_j2>
      <synS_little_j3>1.25</synS_little_j3>
      <synS_little_j4>1.0</synS_little_j4>
      <k_little_j1>0.15</k_little_j1>
      <k_little_j2>0.5</k_little_j2>
      <k_little_j3>0.5</k_little_j3>
      <k_little_j4>0.5</k_little_j4>
      <!-- Palm thumb -->
      <synS_palm_j1>1.57</synS_palm_j1>
      <k_palm_j1>0.5</k_palm_j1>
      <k_palm_j1_mimic>0.5</k_palm_j1_mimic>
      <!-- Palm little -->
      <synS_palm_j2>1.57</synS_palm_j2>
      <k_palm_j2>0.5</k_palm_j2>
      <k_palm_j2_mimic>0.5</k_palm_j2_mimic>
    </plugin>
  </gazebo>
  <!-- World to palm base -->
  <joint name="right_hand_v1_wide_palm_central_joint" type="fixed">
    <parent link="arm_2_7"/>
    <child link="right_hand_v1_wide_palm_central_link"/>
    <origin rpy="0 0 1.570796326795" xyz="0 0 0.0"/>
    <dynamics damping="3e-2" friction="0.0"/>
  </joint>
  <link name="right_hand_v1_wide_palm_central_link">
    <visual>
      <material name="grey"/>
      <geometry>
        <mesh filename="package://softhands_description/meshes/v1_wide/right/palm_central.stl" scale="0.001 0.001 0.001"/>
      </geometry>
      <origin rpy="0 0 0" xyz="0 0 0"/>
    </visual>
    <inertial>
      <mass value="0.55962922"/>
      <origin rpy="0 0 0" xyz="-7.3637766e-03 0.015857667  6.7065321e-02"/>
      <inertia ixx="8.2936450e-04" ixy="-1.9292962e-06" ixz="1.6410516e-05" iyy="8.0447768e-04" iyz="-0.00013735281" izz="3.0664811e-04"/>
    </inertial>
    <collision>
      <geometry>
        <mesh filename="package://softhands_description/meshes/v1_wide/right/palm_central_collision.stl" scale="0.0009 0.0009 0.0009"/>
      </geometry>
      <origin rpy="0 0 0" xyz="0 0 0"/>
    </collision>
  </link>
  <!-- palm base to Thumb -->
  <joint name="right_hand_v1_wide_palm_central_thumb_joint" type="revolute">
    <axis xyz="0 0 -1"/>
    <limit effort="30" lower="0" upper="0.17" velocity="0.0"/>
    <dynamics damping="3e-2" friction="0.0"/>
    <origin rpy="0 0.3490656 1.5707963" xyz=" -0.0000000021 32.5059e-3 39.6398e-3"/>
    <parent link="right_hand_v1_wide_palm_central_link"/>
    <child link="right_hand_v1_wide_palm_central_thumb_link"/>
  </joint>
  <link name="right_hand_v1_wide_palm_central_thumb_link">
    <inertial>
      <origin rpy="0 0 0" xyz="0 0 0"/>
      <mass value="0.27981461"/>
      <inertia ixx="8.2936450e-04" ixy="-1.9292962e-06" ixz="1.6410516e-05" iyy="8.0447768e-04" iyz="-0.00013735281" izz="3.0664811e-04"/>
    </inertial>
  </link>
  <!-- palm base to Litte virtual -->
  <joint name="right_hand_v1_wide_palm_central_little_joint" type="revolute">
    <axis xyz="0 0 1"/>
    <dynamics damping="3e-2" friction="0.0"/>
    <limit effort="100" lower="0.0" upper="0.17" velocity="0.00"/>
    <origin rpy="0 -0.1745327 -1.5707963" xyz=" -0.0000000091 -10.6603e-3 66.1817e-3"/>
    <parent link="right_hand_v1_wide_palm_central_link"/>
    <child link="right_hand_v1_wide_palm_central_little_link"/>
  </joint>
  <link name="right_hand_v1_wide_palm_central_little_link">
    <inertial>
      <origin rpy="0 0 0" xyz="0 0 0"/>
      <mass value="0.55962922"/>
      <inertia ixx="8.2936450e-04" ixy="-1.9292962e-06" ixz="1.6410516e-05" iyy="8.0447768e-04" iyz="-0.00013735281" izz="3.0664811e-04"/>
    </inertial>
  </link>
  <gazebo reference="right_hand_v1_wide_palm_central_link">
    <selfCollide>0</selfCollide>
    <material>Gazebo/Grey</material>
  </gazebo>
  <!-- GAZEBO REF -->
  <gazebo reference="right_hand_v1_wide_palm_central_thumb_joint">
    <implicitSpringDamper>true</implicitSpringDamper>
    <springStiffness>0.4</springStiffness>
    <springReference>0</springReference>
  </gazebo>
  <!-- GAZEBO REF -->
  <gazebo reference="right_hand_v1_wide_palm_central_little_link">
    <implicitSpringDamper>true</implicitSpringDamper>
    <springStiffness>0.4</springStiffness>
    <springReference>0</springReference>
  </gazebo>
  <joint name="right_hand_v1_wide_palm_central_thumb_virtual_joint" type="revolute">
    <parent link="right_hand_v1_wide_palm_central_thumb_link"/>
    <child link="right_hand_v1_wide_palm_thumb_link"/>
    <origin rpy="0 0 0 " xyz="12e-3 -0.0000414746e-3 0"/>
    <axis xyz="0 0 -1"/>
    <limit effort="30" lower="0" upper="0.35" velocity="0.0"/>
    <dynamics damping="3e-2" friction="0.0"/>
  </joint>
  <link name="right_hand_v1_wide_palm_thumb_link">
    <material name="grey"/>
    <visual>
      <geometry>
        <mesh filename="package://softhands_description/meshes/v1_wide/right/palm_thumb.stl" scale="0.001 0.001 0.001"/>
      </geometry>
      <origin rpy="0 0 0" xyz="0 0 0"/>
    </visual>
    <inertial>
      <mass value="0.092767"/>
      <origin rpy="0 0 0" xyz="1.3888149e-2 -7.0704771e-3  1.1337304e-3"/>
      <inertia ixx="5.2239281e-5" ixy="2.7341002e-6" ixz="6.0525027e-6" iyy="5.5447805e-5" iyz="-4.6570702e-6" izz="2.7144559e-5"/>
    </inertial>
    <collision>
      <geometry>
        <mesh filename="package://softhands_description/meshes/v1_wide/right/palm_thumb_collision.stl" scale="0.001 0.001 0.001"/>
      </geometry>
      <origin rpy="0 0 0" xyz="0 0 0"/>
    </collision>
  </link>
  <!-- Palm thumb to thumb support -->
  <joint name="right_hand_v1_wide_palm_thumb_support_joint" type="fixed">
    <parent link="right_hand_v1_wide_palm_thumb_link"/>
    <child link="right_hand_v1_wide_palm_thumb_support_link"/>
    <origin rpy="-1.5707963 -1.0471972 0" xyz=" 24.2343e-3 -5.0e-3 9.13010e-3"/>
  </joint>
  <link name="right_hand_v1_wide_palm_thumb_support_link">
    <material name="grey"/>
    <visual>
      <geometry>
        <mesh filename="package://softhands_description/meshes/v1_wide/right/thumb_support.stl" scale="0.001 0.001 0.001"/>
      </geometry>
      <origin rpy="0 0 0" xyz="0 0 0"/>
    </visual>
    <inertial>
      <origin rpy="0 0 0" xyz="1.1097412e-02 -4.2327979e-05 -4.7109856e-04"/>
      <mass value="1.6408860e-02"/>
      <inertia ixx="1.8835019e-06" ixy="-4.9293913e-09" ixz="-2.5700318e-08" iyy="1.2828797e-06" iyz="-4.0065947e-09" izz="2.2986135e-06"/>
    </inertial>
    <collision>
      <geometry>
        <mesh filename="package://softhands_description/meshes/v1_wide/right/thumb_support_collision.stl" scale="0.0009 0.0009 0.0009"/>
      </geometry>
      <origin rpy="0 0 0" xyz="0 0 0"/>
    </collision>
  </link>
  <gazebo reference="right_hand_v1_wide_palm_thumb_link">
    <selfCollide>0</selfCollide>
    <material>Gazebo/Grey</material>
  </gazebo>
  <gazebo reference="right_hand_v1_wide_palm_thumb_support_link">
    <selfCollide>0</selfCollide>
    <material>Gazebo/White</material>
  </gazebo>
  <joint name="right_hand_v1_wide_palm_central_little_virtual_joint" type="revolute">
    <parent link="right_hand_v1_wide_palm_central_little_link"/>
    <child link="right_hand_v1_wide_palm_little_link"/>
    <origin rpy="0 0 0 " xyz="12e-3 -4.66576e-08 0"/>
    <axis xyz="0 0 1"/>
    <limit effort="30" lower="0" upper="0.35" velocity="0.0"/>
    <dynamics damping="3e-2" friction="0.0"/>
  </joint>
  <link name="right_hand_v1_wide_palm_little_link">
    <visual>
      <material name="grey"/>
      <geometry>
        <mesh filename="package://softhands_description/meshes/v1_wide/right/palm_little.stl" scale="0.001 0.001 0.001"/>
      </geometry>
      <origin rpy="0 0 0" xyz="0 0 0"/>
    </visual>
    <inertial>
      <mass value="0.17998957"/>
      <origin rpy="0 0 0" xyz="1.9466642e-02  5.5041380e-03 -0.00079253974"/>
      <inertia ixx=" 2.4776164e-04" ixy="-2.2762031e-06" ixz="-2.5699035e-05" iyy="2.6460918e-04" iyz=" 1.5348716e-05" izz="5.9121350e-05"/>
    </inertial>
    <collision>
      <geometry>
        <mesh filename="package://softhands_description/meshes/v1_wide/right/palm_little_collision.stl" scale="0.0009 0.0009 0.0009"/>
      </geometry>
      <origin rpy="0 0 0" xyz="0 0 0"/>
    </collision>
  </link>
  <gazebo reference="right_hand_v1_wide_palm_little_link">
    <selfCollide>0</selfCollide>
    <material>Gazebo/Grey</material>
  </gazebo>
  <!-- GAZEBO REF -->
  <gazebo reference="right_hand_v1_wide_palm_little_virtual_joint">
    <implicitSpringDamper>true</implicitSpringDamper>
    <springStiffness>0.4</springStiffness>
    <springReference>0</springReference>
  </gazebo>
  <!-- Thumb Proximal  -->
  <joint name="right_hand_v1_wide_thumb_knuckle_joint" type="revolute">
    <parent link="right_hand_v1_wide_palm_thumb_support_link"/>
    <child link="right_hand_v1_wide_thumb_knuckle_link"/>
    <origin rpy="-1.5707963 0 0" xyz="21.9577e-3 0 -2.8e-3"/>
    <axis xyz="0 0 1"/>
    <limit effort="30" lower="0" upper="1.57" velocity="0.0"/>
    <dynamics damping="3e-2" friction="0.0"/>
  </joint>
  <link name="right_hand_v1_wide_thumb_knuckle_link">
    <visual>
      <material name="grey"/>
      <geometry>
        <mesh filename="package://softhands_description/meshes/v1_wide/right/phalanx_pros_thumb.stl" scale="0.001 0.001 0.001"/>
      </geometry>
      <origin rpy="0 0 0" xyz="0 0 0"/>
    </visual>
    <inertial>
      <mass value="2.4657976e-02"/>
      <origin rpy="0 0 0" xyz="2.2747515e-02  4.5872045e-03 0.0013868568  "/>
      <inertia ixx="2.6529131e-6" ixy="-2.6016685e-07" ixz="1.3433999e-07" iyy="4.4499492e-06" iyz="-7.5218787e-08" izz="5.0393400e-06"/>
    </inertial>
    <collision>
      <geometry>
        <mesh filename="package://softhands_description/meshes/v1_wide/right/phalanx_pros_thumb_collision.stl" scale="0.0009 0.0009 0.0009"/>
      </geometry>
      <origin rpy="0 0 0" xyz="0 0 0"/>
    </collision>
  </link>
  <gazebo reference="right_hand_v1_wide_thumb_knuckle_link">
    <material>Gazebo/Grey</material>
    <selfCollide>0</selfCollide>
  </gazebo>
  <!-- GAZEBO REF -->
  <gazebo reference="right_hand_v1_wide_thumb_knuckle_joint">
    <implicitSpringDamper>true</implicitSpringDamper>
    <springStiffness>0.4</springStiffness>
    <springReference>0</springReference>
  </gazebo>
  <!-- Virtual joint from thumb knuckle to thumb proximal   -->
  <joint name="right_hand_v1_wide_thumb_proximal_joint" type="revolute">
    <axis xyz="0 0 1"/>
    <limit effort="30" lower="0" upper="0.785398" velocity="0.0"/>
    <origin rpy="-1.3962638 0 0" xyz="38.5e-3 4.82952e-3 -0.000167417"/>
    <parent link="right_hand_v1_wide_thumb_knuckle_link"/>
    <child link="right_hand_v1_wide_thumb_proximal_virtual_link"/>
    <dynamics damping="3e-2" friction="0.0"/>
  </joint>
  <link name="right_hand_v1_wide_thumb_proximal_virtual_link">
    <inertial>
      <origin rpy="0 0 0" xyz="0 0 0"/>
      <mass value="0.033679189"/>
      <inertia ixx="4.1328993e-06" ixy="-8.6599874e-08" ixz="0.0" iyy="7.4560101e-06" iyz="-1.0265429e-09" izz="6.6161853e-06"/>
    </inertial>
  </link>
  <!-- Thumb Proximal joint  -->
  <joint name="right_hand_v1_wide_thumb_proximal_virtual_joint" type="revolute">
    <parent link="right_hand_v1_wide_thumb_proximal_virtual_link"/>
    <child link="right_hand_v1_wide_thumb_proximal_link"/>
    <origin rpy="0 0 0" xyz="9e-3 0 0 "/>
    <axis xyz="0 0 1"/>
    <limit effort="30" lower="0" upper="0.785398" velocity="0.0"/>
    <dynamics damping="3e-2" friction="0.0"/>
  </joint>
  <link name="right_hand_v1_wide_thumb_proximal_link">
    <visual>
      <material name="grey"/>
      <geometry>
        <mesh filename="package://softhands_description/meshes/v1_wide/right/phalanx_medium_thumb.stl" scale="0.001 0.001 0.001"/>
      </geometry>
      <origin rpy="0 0 0" xyz="0 0 0"/>
    </visual>
    <inertial>
      <mass value="0.033679189"/>
      <inertia ixx="4.1328993e-06" ixy="-8.6599874e-08" ixz="0.0" iyy="7.4560101e-06" iyz="-1.0265429e-09" izz="6.6161853e-06"/>
      <origin rpy="0 0 0" xyz="2.0950700e-02  1.1175133e-03 -3.7424390e-05"/>
    </inertial>
    <collision>
      <geometry>
        <mesh filename="package://softhands_description/meshes/v1_wide/right/phalanx_medium_thumb_collision.stl" scale="0.0009 0.0009 0.0009"/>
      </geometry>
      <origin rpy="0 0 0" xyz="0 0 0"/>
    </collision>
  </link>
  <gazebo reference="right_hand_v1_wide_thumb_proximal_link">
    <material>Gazebo/Grey</material>
    <selfCollide>0</selfCollide>
  </gazebo>
  <!-- GAZEBO REF -->
  <gazebo reference="right_hand_v1_wide_thumb_proximal_joint">
    <implicitSpringDamper>true</implicitSpringDamper>
    <springStiffness>0.4</springStiffness>
    <springReference>0</springReference>
  </gazebo>
  <!-- GAZEBO REF -->
  <gazebo reference="right_hand_v1_wide_thumb_proximal_virtual_joint">
    <implicitSpringDamper>true</implicitSpringDamper>
    <springStiffness>0.4</springStiffness>
    <springReference>0</springReference>
  </gazebo>
  <!-- Virtual joint from thumb proximal to thumb distal   -->
  <joint name="right_hand_v1_wide_thumb_distal_virtual_joint" type="revolute">
    <axis xyz="0 0 1"/>
    <origin rpy="0 0 0" xyz="41e-3 0 0"/>
    <parent link="right_hand_v1_wide_thumb_proximal_link"/>
    <child link="right_hand_v1_wide_thumb_distal_virtual_link"/>
    <limit effort="30" lower="0" upper="0.785398" velocity="0.0"/>
    <dynamics damping="3e-2" friction="0.0"/>
  </joint>
  <link name="right_hand_v1_wide_thumb_distal_virtual_link">
    <inertial>
      <origin rpy="0 0 0" xyz="0 0 0"/>
      <mass value="0.023674554"/>
      <inertia ixx="2.578454e-06" ixy="0.0" ixz="0.0" iyy="2.9887569e-06" iyz="0.0" izz="3.8277106e-06"/>
    </inertial>
  </link>
  <!-- Thumb middle  -->
  <joint name="right_hand_v1_wide_thumb_distal_joint" type="revolute">
    <parent link="right_hand_v1_wide_thumb_distal_virtual_link"/>
    <child link="right_hand_v1_wide_thumb_distal_link"/>
    <origin rpy="0 0.0101229 0" xyz="8.99947e-3 0 -0.0973875e-3"/>
    <axis xyz="0 0 1"/>
    <limit effort="30" lower="0" upper="0.785398" velocity="0.0"/>
    <dynamics damping="3e-2" friction="0.0"/>
  </joint>
  <link name="right_hand_v1_wide_thumb_distal_link">
    <visual>
      <material name="grey"/>
      <geometry>
        <mesh filename="package://softhands_description/meshes/v1_wide/right/phalanx_dist_thumb.stl" scale="0.001 0.001 0.001"/>
      </geometry>
      <origin rpy="0 0 0" xyz="0 0 0"/>
    </visual>
    <inertial>
      <mass value="0.023674554"/>
      <inertia ixx="2.578454e-06" ixy="0.0" ixz="0.0" iyy="2.9887569e-06" iyz="0.0" izz="3.8277106e-06"/>
      <origin rpy="0 0 0" xyz="1.6161362e-02  1.6241404e-03 -3.2684152e-05 "/>
    </inertial>
    <collision>
      <geometry>
        <mesh filename="package://softhands_description/meshes/v1_wide/right/phalanx_dist_thumb_collision.stl" scale="0.0009 0.0009 0.0009"/>
      </geometry>
      <origin rpy="0 0 0" xyz="0 0 0"/>
    </collision>
  </link>
  <!-- GAZEBO REF -->
  <gazebo reference="right_hand_v1_wide_thumb_distal_link">
    <material>Gazebo/Grey</material>
    <selfCollide>0</selfCollide>
  </gazebo>
  <!-- GAZEBO REF -->
  <gazebo reference="right_hand_v1_wide_thumb_distal_virtual_joint">
    <implicitSpringDamper>true</implicitSpringDamper>
    <springStiffness>0.4</springStiffness>
    <springReference>0</springReference>
  </gazebo>
  <!-- GAZEBO REF -->
  <gazebo reference="right_hand_v1_wide_thumb_distal_joint">
    <implicitSpringDamper>true</implicitSpringDamper>
    <springStiffness>0.4</springStiffness>
    <springReference>0</springReference>
  </gazebo>
  <!-- Support -->
  <joint name="right_hand_v1_wide_index_knuckle_joint" type="revolute">
    <axis xyz="0 1 0"/>
    <limit effort="30" lower="0.0" upper="0.01" velocity="0.0"/>
    <origin rpy="-3.1415927  -1.396264 1.5707963" xyz="5e-3 44.8953e-3 112.230e-3"/>
    <parent link="right_hand_v1_wide_palm_central_link"/>
    <child link="right_hand_v1_wide_index_knuckle_link"/>
  </joint>
  <link name="right_hand_v1_wide_index_knuckle_link">
    <visual>
      <material name="grey"/>
      <geometry>
        <mesh filename="package://softhands_description/meshes/v1_wide/right/phalanx_pros_sup.stl" scale="0.001 0.001 0.001"/>
      </geometry>
      <origin rpy="0 0 0" xyz="0 0 0"/>
    </visual>
    <inertial>
      <mass value="7.4913242e-03"/>
      <origin rpy="0 0 0" xyz="1.8035857e-02 -4.0351343e-03 -4.4165266e-05 "/>
      <inertia ixx="5.3708642e-07" ixy="0.0" ixz="1.5304482e-07" iyy="6.1466440e-07" iyz="-4.4383298e-09" izz="5.5136271e-07"/>
    </inertial>
    <collision>
      <geometry>
        <mesh filename="package://softhands_description/meshes/v1_wide/right/phalanx_pros_sup_collision.stl" scale="0.0009 0.0009 0.0009"/>
      </geometry>
      <origin rpy="0 0 0" xyz="0 0 0"/>
    </collision>
  </link>
  <gazebo reference="right_hand_v1_wide_index_knuckle_link">
    <selfCollide>0</selfCollide>
    <material>Gazebo/White</material>
  </gazebo>
  <!-- Virtual joint from knuckle->proximal or proximal->middle   -->
  <joint name="right_hand_v1_wide_index_proximal_virtual_joint" type="revolute">
    <axis xyz="0 0 1"/>
    <limit effort="30" lower="0" upper="0.785398" velocity="0.0"/>
    <origin rpy="0 0 0" xyz="24e-3 -6.5e-3 0"/>
    <parent link="right_hand_v1_wide_index_knuckle_link"/>
    <child link="right_hand_v1_wide_index_proximal_virtual_link"/>
    <dynamics damping="3e-2" friction="0.0"/>
  </joint>
  <link name="right_hand_v1_wide_index_proximal_virtual_link">
    <inertial>
      <origin rpy="0 0 0" xyz="0 0 0"/>
      <mass value="0.024190505"/>
      <inertia ixx="1.9981795e-06" ixy="-6.0806048e-08" ixz="0.0" iyy="4.7810654e-06" iyz="0.0" izz="5.0961924e-06"/>
    </inertial>
  </link>
  <!-- Proximal phalanx -->
  <joint name="right_hand_v1_wide_index_proximal_joint" type="revolute">
    <axis xyz="0 0 1"/>
    <limit effort="30" lower="0" upper="0.785398" velocity="0.0"/>
    <origin rpy="0 0 0" xyz="9e-3 0 0"/>
    <parent link="right_hand_v1_wide_index_proximal_virtual_link"/>
    <child link="right_hand_v1_wide_index_proximal_link"/>
    <dynamics damping="3e-2" friction="0.0"/>
  </joint>
  <link name="right_hand_v1_wide_index_proximal_link">
    <visual>
      <material name="grey"/>
      <geometry>
        <mesh filename="package://softhands_description/meshes/v1_wide/right/phalanx.stl" scale="0.001 0.001 0.001"/>
      </geometry>
      <origin rpy="0 0 0" xyz="0 0 0"/>
    </visual>
    <inertial>
      <mass value="0.024190505"/>
      <inertia ixx="1.9981795e-06" ixy="-6.0806048e-08" ixz="0.0" iyy="4.7810654e-06" iyz="0.0" izz="5.0961924e-06"/>
      <origin rpy="0 0 0" xyz=" 2.0923634e-02  8.4162795e-04 -5.2131884e-05"/>
    </inertial>
    <collision>
      <geometry>
        <mesh filename="package://softhands_description/meshes/v1_wide/right/phalanx_collision.stl" scale="0.0009 0.0009 0.0009"/>
      </geometry>
      <origin rpy="0 0 0" xyz="0 0 0"/>
    </collision>
  </link>
  <gazebo reference="right_hand_v1_wide_index_proximal_link">
    <material>Gazebo/Gray</material>
    <selfCollide>0</selfCollide>
  </gazebo>
  <!-- GAZEBO REF -->
  <gazebo reference="right_hand_v1_wide_index_proximal_virtual_joint">
    <implicitSpringDamper>true</implicitSpringDamper>
    <springStiffness>0.4</springStiffness>
    <springReference>0</springReference>
  </gazebo>
  <!-- GAZEBO REF -->
  <gazebo reference="right_hand_v1_wide_index_proximal_joint">
    <implicitSpringDamper>true</implicitSpringDamper>
    <springStiffness>0.4</springStiffness>
    <springReference>0</springReference>
  </gazebo>
  <!-- Virtual joint from knuckle->proximal or proximal->middle   -->
  <joint name="right_hand_v1_wide_index_middle_virtual_joint" type="revolute">
    <axis xyz="0 0 1"/>
    <limit effort="30" lower="0" upper="0.785398" velocity="0.0"/>
    <origin rpy="0 0 0" xyz="41e-3 0 0"/>
    <parent link="right_hand_v1_wide_index_proximal_link"/>
    <child link="right_hand_v1_wide_index_middle_virtual_link"/>
    <dynamics damping="3e-2" friction="0.0"/>
  </joint>
  <link name="right_hand_v1_wide_index_middle_virtual_link">
    <inertial>
      <origin rpy="0 0 0" xyz="0 0 0"/>
      <mass value="0.024190505"/>
      <inertia ixx="1.9981795e-06" ixy="-6.0806048e-08" ixz="0.0" iyy="4.7810654e-06" iyz="0.0" izz="5.0961924e-06"/>
    </inertial>
  </link>
  <!-- Proximal phalanx -->
  <joint name="right_hand_v1_wide_index_middle_joint" type="revolute">
    <axis xyz="0 0 1"/>
    <limit effort="30" lower="0" upper="0.785398" velocity="0.0"/>
    <origin rpy="0 0 0" xyz="9e-3 0 0"/>
    <parent link="right_hand_v1_wide_index_middle_virtual_link"/>
    <child link="right_hand_v1_wide_index_middle_link"/>
    <dynamics damping="3e-2" friction="0.0"/>
  </joint>
  <link name="right_hand_v1_wide_index_middle_link">
    <visual>
      <material name="grey"/>
      <geometry>
        <mesh filename="package://softhands_description/meshes/v1_wide/right/phalanx.stl" scale="0.001 0.001 0.001"/>
      </geometry>
      <origin rpy="0 0 0" xyz="0 0 0"/>
    </visual>
    <inertial>
      <mass value="0.024190505"/>
      <inertia ixx="1.9981795e-06" ixy="-6.0806048e-08" ixz="0.0" iyy="4.7810654e-06" iyz="0.0" izz="5.0961924e-06"/>
      <origin rpy="0 0 0" xyz=" 2.0923634e-02  8.4162795e-04 -5.2131884e-05"/>
    </inertial>
    <collision>
      <geometry>
        <mesh filename="package://softhands_description/meshes/v1_wide/right/phalanx_collision.stl" scale="0.0009 0.0009 0.0009"/>
      </geometry>
      <origin rpy="0 0 0" xyz="0 0 0"/>
    </collision>
  </link>
  <gazebo reference="right_hand_v1_wide_index_middle_link">
    <material>Gazebo/Gray</material>
    <selfCollide>0</selfCollide>
  </gazebo>
  <!-- GAZEBO REF -->
  <gazebo reference="right_hand_v1_wide_index_middle_virtual_joint">
    <implicitSpringDamper>true</implicitSpringDamper>
    <springStiffness>0.4</springStiffness>
    <springReference>0</springReference>
  </gazebo>
  <!-- GAZEBO REF -->
  <gazebo reference="right_hand_v1_wide_index_middle_joint">
    <implicitSpringDamper>true</implicitSpringDamper>
    <springStiffness>0.4</springStiffness>
    <springReference>0</springReference>
  </gazebo>
  <!-- Virtual joint from middle->distal   -->
  <joint name="right_hand_v1_wide_index_distal_virtual_joint" type="revolute">
    <axis xyz="0 0 1"/>
    <limit effort="30" lower="0" upper="0.785398" velocity="0.0"/>
    <origin rpy="0 0 0" xyz="41e-3 0 0"/>
    <parent link="right_hand_v1_wide_index_middle_link"/>
    <child link="right_hand_v1_wide_index_distal_virtual_link"/>
    <dynamics damping="3e-2" friction="0.0"/>
  </joint>
  <link name="right_hand_v1_wide_index_distal_virtual_link">
    <inertial>
      <origin rpy="0 0 0" xyz="0 0 0"/>
      <mass value="0.012475845"/>
      <inertia ixx="7.5548908e-07" ixy="0.0" ixz="0.0" iyy="1.2532982e-06" iyz="0.0" izz="1.3218760e-06"/>
    </inertial>
  </link>
  <!-- Proximal phalanx -->
  <joint name="right_hand_v1_wide_index_distal_joint" type="revolute">
    <axis xyz="0 0 1"/>
    <limit effort="30" lower="0" upper="0.785398" velocity="0.0"/>
    <origin rpy="0 0 0" xyz="9e-3 0 0"/>
    <parent link="right_hand_v1_wide_index_distal_virtual_link"/>
    <child link="right_hand_v1_wide_index_distal_link"/>
    <dynamics damping="3e-2" friction="0.0"/>
  </joint>
  <link name="right_hand_v1_wide_index_distal_link">
    <visual>
      <material name="grey"/>
      <geometry>
        <mesh filename="package://softhands_description/meshes/v1_wide/right/phalanx_dist.stl" scale="0.001 0.001 0.001"/>
      </geometry>
      <origin rpy="0 0 0" xyz="0 0 0"/>
    </visual>
    <inertial>
      <mass value="0.012475845"/>
      <inertia ixx="7.5548908e-07" ixy="0.0" ixz="0.0" iyy="1.2532982e-06" iyz="0.0" izz="1.3218760e-06"/>
      <origin rpy="0 0 0" xyz="1.2887396e-02 6.2001804e-05 -1.1041989e-03"/>
    </inertial>
    <collision>
      <geometry>
        <mesh filename="package://softhands_description/meshes/v1_wide/right/phalanx_dist_collision.stl" scale="0.0009 0.0009 0.0009"/>
      </geometry>
      <origin rpy="0 0 0" xyz="0 0 0"/>
    </collision>
  </link>
  <gazebo reference="right_hand_v1_wide_index_distal_link">
    <material>Gazebo/Gray</material>
    <selfCollide>0</selfCollide>
  </gazebo>
  <!-- GAZEBO REF -->
  <gazebo reference="right_hand_v1_wide_index_distal_virtual_joint">
    <implicitSpringDamper>true</implicitSpringDamper>
    <springStiffness>0.4</springStiffness>
    <springReference>0</springReference>
  </gazebo>
  <!-- GAZEBO REF -->
  <gazebo reference="right_hand_v1_wide_index_distal_joint">
    <implicitSpringDamper>true</implicitSpringDamper>
    <springStiffness>0.4</springStiffness>
    <springReference>0</springReference>
  </gazebo>
  <!-- Support -->
  <joint name="right_hand_v1_wide_middle_knuckle_joint" type="revolute">
    <axis xyz="0 1 0"/>
    <limit effort="30" lower="0.0" upper="0.01" velocity="0.0"/>
    <origin rpy="0 -1.5707963 -1.5707963" xyz="5e-3 12.5e-3 115e-3"/>
    <parent link="right_hand_v1_wide_palm_central_link"/>
    <child link="right_hand_v1_wide_middle_knuckle_link"/>
  </joint>
  <link name="right_hand_v1_wide_middle_knuckle_link">
    <visual>
      <material name="grey"/>
      <geometry>
        <mesh filename="package://softhands_description/meshes/v1_wide/right/phalanx_pros_sup.stl" scale="0.001 0.001 0.001"/>
      </geometry>
      <origin rpy="0 0 0" xyz="0 0 0"/>
    </visual>
    <inertial>
      <mass value="7.4913242e-03"/>
      <origin rpy="0 0 0" xyz="1.8035857e-02 -4.0351343e-03 -4.4165266e-05 "/>
      <inertia ixx="5.3708642e-07" ixy="0.0" ixz="1.5304482e-07" iyy="6.1466440e-07" iyz="-4.4383298e-09" izz="5.5136271e-07"/>
    </inertial>
    <collision>
      <geometry>
        <mesh filename="package://softhands_description/meshes/v1_wide/right/phalanx_pros_sup_collision.stl" scale="0.0009 0.0009 0.0009"/>
      </geometry>
      <origin rpy="0 0 0" xyz="0 0 0"/>
    </collision>
  </link>
  <gazebo reference="right_hand_v1_wide_middle_knuckle_link">
    <selfCollide>0</selfCollide>
    <material>Gazebo/White</material>
  </gazebo>
  <!-- Virtual joint from knuckle->proximal or proximal->middle   -->
  <joint name="right_hand_v1_wide_middle_proximal_virtual_joint" type="revolute">
    <axis xyz="0 0 1"/>
    <limit effort="30" lower="0" upper="0.785398" velocity="0.0"/>
    <origin rpy="0 0 0" xyz="24e-3 -6.5e-3 0"/>
    <parent link="right_hand_v1_wide_middle_knuckle_link"/>
    <child link="right_hand_v1_wide_middle_proximal_virtual_link"/>
    <dynamics damping="3e-2" friction="0.0"/>
  </joint>
  <link name="right_hand_v1_wide_middle_proximal_virtual_link">
    <inertial>
      <origin rpy="0 0 0" xyz="0 0 0"/>
      <mass value="0.024190505"/>
      <inertia ixx="1.9981795e-06" ixy="-6.0806048e-08" ixz="0.0" iyy="4.7810654e-06" iyz="0.0" izz="5.0961924e-06"/>
    </inertial>
  </link>
  <!-- Proximal phalanx -->
  <joint name="right_hand_v1_wide_middle_proximal_joint" type="revolute">
    <axis xyz="0 0 1"/>
    <limit effort="30" lower="0" upper="0.785398" velocity="0.0"/>
    <origin rpy="0 0 0" xyz="9e-3 0 0"/>
    <parent link="right_hand_v1_wide_middle_proximal_virtual_link"/>
    <child link="right_hand_v1_wide_middle_proximal_link"/>
    <dynamics damping="3e-2" friction="0.0"/>
  </joint>
  <link name="right_hand_v1_wide_middle_proximal_link">
    <visual>
      <material name="grey"/>
      <geometry>
        <mesh filename="package://softhands_description/meshes/v1_wide/right/phalanx.stl" scale="0.001 0.001 0.001"/>
      </geometry>
      <origin rpy="0 0 0" xyz="0 0 0"/>
    </visual>
    <inertial>
      <mass value="0.024190505"/>
      <inertia ixx="1.9981795e-06" ixy="-6.0806048e-08" ixz="0.0" iyy="4.7810654e-06" iyz="0.0" izz="5.0961924e-06"/>
      <origin rpy="0 0 0" xyz=" 2.0923634e-02  8.4162795e-04 -5.2131884e-05"/>
    </inertial>
    <collision>
      <geometry>
        <mesh filename="package://softhands_description/meshes/v1_wide/right/phalanx_collision.stl" scale="0.0009 0.0009 0.0009"/>
      </geometry>
      <origin rpy="0 0 0" xyz="0 0 0"/>
    </collision>
  </link>
  <gazebo reference="right_hand_v1_wide_middle_proximal_link">
    <material>Gazebo/Gray</material>
    <selfCollide>0</selfCollide>
  </gazebo>
  <!-- GAZEBO REF -->
  <gazebo reference="right_hand_v1_wide_middle_proximal_virtual_joint">
    <implicitSpringDamper>true</implicitSpringDamper>
    <springStiffness>0.4</springStiffness>
    <springReference>0</springReference>
  </gazebo>
  <!-- GAZEBO REF -->
  <gazebo reference="right_hand_v1_wide_middle_proximal_joint">
    <implicitSpringDamper>true</implicitSpringDamper>
    <springStiffness>0.4</springStiffness>
    <springReference>0</springReference>
  </gazebo>
  <!-- Virtual joint from knuckle->proximal or proximal->middle   -->
  <joint name="right_hand_v1_wide_middle_middle_virtual_joint" type="revolute">
    <axis xyz="0 0 1"/>
    <limit effort="30" lower="0" upper="0.785398" velocity="0.0"/>
    <origin rpy="0 0 0" xyz="41e-3 0 0"/>
    <parent link="right_hand_v1_wide_middle_proximal_link"/>
    <child link="right_hand_v1_wide_middle_middle_virtual_link"/>
    <dynamics damping="3e-2" friction="0.0"/>
  </joint>
  <link name="right_hand_v1_wide_middle_middle_virtual_link">
    <inertial>
      <origin rpy="0 0 0" xyz="0 0 0"/>
      <mass value="0.024190505"/>
      <inertia ixx="1.9981795e-06" ixy="-6.0806048e-08" ixz="0.0" iyy="4.7810654e-06" iyz="0.0" izz="5.0961924e-06"/>
    </inertial>
  </link>
  <!-- Proximal phalanx -->
  <joint name="right_hand_v1_wide_middle_middle_joint" type="revolute">
    <axis xyz="0 0 1"/>
    <limit effort="30" lower="0" upper="0.785398" velocity="0.0"/>
    <origin rpy="0 0 0" xyz="9e-3 0 0"/>
    <parent link="right_hand_v1_wide_middle_middle_virtual_link"/>
    <child link="right_hand_v1_wide_middle_middle_link"/>
    <dynamics damping="3e-2" friction="0.0"/>
  </joint>
  <link name="right_hand_v1_wide_middle_middle_link">
    <visual>
      <material name="grey"/>
      <geometry>
        <mesh filename="package://softhands_description/meshes/v1_wide/right/phalanx.stl" scale="0.001 0.001 0.001"/>
      </geometry>
      <origin rpy="0 0 0" xyz="0 0 0"/>
    </visual>
    <inertial>
      <mass value="0.024190505"/>
      <inertia ixx="1.9981795e-06" ixy="-6.0806048e-08" ixz="0.0" iyy="4.7810654e-06" iyz="0.0" izz="5.0961924e-06"/>
      <origin rpy="0 0 0" xyz=" 2.0923634e-02  8.4162795e-04 -5.2131884e-05"/>
    </inertial>
    <collision>
      <geometry>
        <mesh filename="package://softhands_description/meshes/v1_wide/right/phalanx_collision.stl" scale="0.0009 0.0009 0.0009"/>
      </geometry>
      <origin rpy="0 0 0" xyz="0 0 0"/>
    </collision>
  </link>
  <gazebo reference="right_hand_v1_wide_middle_middle_link">
    <material>Gazebo/Gray</material>
    <selfCollide>0</selfCollide>
  </gazebo>
  <!-- GAZEBO REF -->
  <gazebo reference="right_hand_v1_wide_middle_middle_virtual_joint">
    <implicitSpringDamper>true</implicitSpringDamper>
    <springStiffness>0.4</springStiffness>
    <springReference>0</springReference>
  </gazebo>
  <!-- GAZEBO REF -->
  <gazebo reference="right_hand_v1_wide_middle_middle_joint">
    <implicitSpringDamper>true</implicitSpringDamper>
    <springStiffness>0.4</springStiffness>
    <springReference>0</springReference>
  </gazebo>
  <!-- Virtual joint from middle->distal   -->
  <joint name="right_hand_v1_wide_middle_distal_virtual_joint" type="revolute">
    <axis xyz="0 0 1"/>
    <limit effort="30" lower="0" upper="0.785398" velocity="0.0"/>
    <origin rpy="0 0 0" xyz="41e-3 0 0"/>
    <parent link="right_hand_v1_wide_middle_middle_link"/>
    <child link="right_hand_v1_wide_middle_distal_virtual_link"/>
    <dynamics damping="3e-2" friction="0.0"/>
  </joint>
  <link name="right_hand_v1_wide_middle_distal_virtual_link">
    <inertial>
      <origin rpy="0 0 0" xyz="0 0 0"/>
      <mass value="0.012475845"/>
      <inertia ixx="7.5548908e-07" ixy="0.0" ixz="0.0" iyy="1.2532982e-06" iyz="0.0" izz="1.3218760e-06"/>
    </inertial>
  </link>
  <!-- Proximal phalanx -->
  <joint name="right_hand_v1_wide_middle_distal_joint" type="revolute">
    <axis xyz="0 0 1"/>
    <limit effort="30" lower="0" upper="0.785398" velocity="0.0"/>
    <origin rpy="0 0 0" xyz="9e-3 0 0"/>
    <parent link="right_hand_v1_wide_middle_distal_virtual_link"/>
    <child link="right_hand_v1_wide_middle_distal_link"/>
    <dynamics damping="3e-2" friction="0.0"/>
  </joint>
  <link name="right_hand_v1_wide_middle_distal_link">
    <visual>
      <material name="grey"/>
      <geometry>
        <mesh filename="package://softhands_description/meshes/v1_wide/right/phalanx_dist.stl" scale="0.001 0.001 0.001"/>
      </geometry>
      <origin rpy="0 0 0" xyz="0 0 0"/>
    </visual>
    <inertial>
      <mass value="0.012475845"/>
      <inertia ixx="7.5548908e-07" ixy="0.0" ixz="0.0" iyy="1.2532982e-06" iyz="0.0" izz="1.3218760e-06"/>
      <origin rpy="0 0 0" xyz="1.2887396e-02 6.2001804e-05 -1.1041989e-03"/>
    </inertial>
    <collision>
      <geometry>
        <mesh filename="package://softhands_description/meshes/v1_wide/right/phalanx_dist_collision.stl" scale="0.0009 0.0009 0.0009"/>
      </geometry>
      <origin rpy="0 0 0" xyz="0 0 0"/>
    </collision>
  </link>
  <gazebo reference="right_hand_v1_wide_middle_distal_link">
    <material>Gazebo/Gray</material>
    <selfCollide>0</selfCollide>
  </gazebo>
  <!-- GAZEBO REF -->
  <gazebo reference="right_hand_v1_wide_middle_distal_virtual_joint">
    <implicitSpringDamper>true</implicitSpringDamper>
    <springStiffness>0.4</springStiffness>
    <springReference>0</springReference>
  </gazebo>
  <!-- GAZEBO REF -->
  <gazebo reference="right_hand_v1_wide_middle_distal_joint">
    <implicitSpringDamper>true</implicitSpringDamper>
    <springStiffness>0.4</springStiffness>
    <springReference>0</springReference>
  </gazebo>
  <!-- Support -->
  <joint name="right_hand_v1_wide_ring_knuckle_joint" type="revolute">
    <axis xyz="0 1 0"/>
    <limit effort="30" lower="0.0" upper="0.01" velocity="0.0"/>
    <origin rpy="0 -1.3089971 0" xyz=" 8.6355e-3 5e-3 44.4863e-3"/>
    <parent link="right_hand_v1_wide_palm_little_link"/>
    <child link="right_hand_v1_wide_ring_knuckle_link"/>
  </joint>
  <link name="right_hand_v1_wide_ring_knuckle_link">
    <visual>
      <material name="grey"/>
      <geometry>
        <mesh filename="package://softhands_description/meshes/v1_wide/right/phalanx_pros_sup.stl" scale="0.001 0.001 0.001"/>
      </geometry>
      <origin rpy="0 0 0" xyz="0 0 0"/>
    </visual>
    <inertial>
      <mass value="7.4913242e-03"/>
      <origin rpy="0 0 0" xyz="1.8035857e-02 -4.0351343e-03 -4.4165266e-05 "/>
      <inertia ixx="5.3708642e-07" ixy="0.0" ixz="1.5304482e-07" iyy="6.1466440e-07" iyz="-4.4383298e-09" izz="5.5136271e-07"/>
    </inertial>
    <collision>
      <geometry>
        <mesh filename="package://softhands_description/meshes/v1_wide/right/phalanx_pros_sup_collision.stl" scale="0.0009 0.0009 0.0009"/>
      </geometry>
      <origin rpy="0 0 0" xyz="0 0 0"/>
    </collision>
  </link>
  <gazebo reference="right_hand_v1_wide_ring_knuckle_link">
    <selfCollide>0</selfCollide>
    <material>Gazebo/White</material>
  </gazebo>
  <!-- Virtual joint from knuckle->proximal or proximal->middle   -->
  <joint name="right_hand_v1_wide_ring_proximal_virtual_joint" type="revolute">
    <axis xyz="0 0 1"/>
    <limit effort="30" lower="0" upper="0.785398" velocity="0.0"/>
    <origin rpy="0 0 0" xyz="24e-3 -6.5e-3 0"/>
    <parent link="right_hand_v1_wide_ring_knuckle_link"/>
    <child link="right_hand_v1_wide_ring_proximal_virtual_link"/>
    <dynamics damping="3e-2" friction="0.0"/>
  </joint>
  <link name="right_hand_v1_wide_ring_proximal_virtual_link">
    <inertial>
      <origin rpy="0 0 0" xyz="0 0 0"/>
      <mass value="0.024190505"/>
      <inertia ixx="1.9981795e-06" ixy="-6.0806048e-08" ixz="0.0" iyy="4.7810654e-06" iyz="0.0" izz="5.0961924e-06"/>
    </inertial>
  </link>
  <!-- Proximal phalanx -->
  <joint name="right_hand_v1_wide_ring_proximal_joint" type="revolute">
    <axis xyz="0 0 1"/>
    <limit effort="30" lower="0" upper="0.785398" velocity="0.0"/>
    <origin rpy="0 0 0" xyz="9e-3 0 0"/>
    <parent link="right_hand_v1_wide_ring_proximal_virtual_link"/>
    <child link="right_hand_v1_wide_ring_proximal_link"/>
    <dynamics damping="3e-2" friction="0.0"/>
  </joint>
  <link name="right_hand_v1_wide_ring_proximal_link">
    <visual>
      <material name="grey"/>
      <geometry>
        <mesh filename="package://softhands_description/meshes/v1_wide/right/phalanx.stl" scale="0.001 0.001 0.001"/>
      </geometry>
      <origin rpy="0 0 0" xyz="0 0 0"/>
    </visual>
    <inertial>
      <mass value="0.024190505"/>
      <inertia ixx="1.9981795e-06" ixy="-6.0806048e-08" ixz="0.0" iyy="4.7810654e-06" iyz="0.0" izz="5.0961924e-06"/>
      <origin rpy="0 0 0" xyz=" 2.0923634e-02  8.4162795e-04 -5.2131884e-05"/>
    </inertial>
    <collision>
      <geometry>
        <mesh filename="package://softhands_description/meshes/v1_wide/right/phalanx_collision.stl" scale="0.0009 0.0009 0.0009"/>
      </geometry>
      <origin rpy="0 0 0" xyz="0 0 0"/>
    </collision>
  </link>
  <gazebo reference="right_hand_v1_wide_ring_proximal_link">
    <material>Gazebo/Gray</material>
    <selfCollide>0</selfCollide>
  </gazebo>
  <!-- GAZEBO REF -->
  <gazebo reference="right_hand_v1_wide_ring_proximal_virtual_joint">
    <implicitSpringDamper>true</implicitSpringDamper>
    <springStiffness>0.4</springStiffness>
    <springReference>0</springReference>
  </gazebo>
  <!-- GAZEBO REF -->
  <gazebo reference="right_hand_v1_wide_ring_proximal_joint">
    <implicitSpringDamper>true</implicitSpringDamper>
    <springStiffness>0.4</springStiffness>
    <springReference>0</springReference>
  </gazebo>
  <!-- Virtual joint from knuckle->proximal or proximal->middle   -->
  <joint name="right_hand_v1_wide_ring_middle_virtual_joint" type="revolute">
    <axis xyz="0 0 1"/>
    <limit effort="30" lower="0" upper="0.785398" velocity="0.0"/>
    <origin rpy="0 0 0" xyz="41e-3 0 0"/>
    <parent link="right_hand_v1_wide_ring_proximal_link"/>
    <child link="right_hand_v1_wide_ring_middle_virtual_link"/>
    <dynamics damping="3e-2" friction="0.0"/>
  </joint>
  <link name="right_hand_v1_wide_ring_middle_virtual_link">
    <inertial>
      <origin rpy="0 0 0" xyz="0 0 0"/>
      <mass value="0.024190505"/>
      <inertia ixx="1.9981795e-06" ixy="-6.0806048e-08" ixz="0.0" iyy="4.7810654e-06" iyz="0.0" izz="5.0961924e-06"/>
    </inertial>
  </link>
  <!-- Proximal phalanx -->
  <joint name="right_hand_v1_wide_ring_middle_joint" type="revolute">
    <axis xyz="0 0 1"/>
    <limit effort="30" lower="0" upper="0.785398" velocity="0.0"/>
    <origin rpy="0 0 0" xyz="9e-3 0 0"/>
    <parent link="right_hand_v1_wide_ring_middle_virtual_link"/>
    <child link="right_hand_v1_wide_ring_middle_link"/>
    <dynamics damping="3e-2" friction="0.0"/>
  </joint>
  <link name="right_hand_v1_wide_ring_middle_link">
    <visual>
      <material name="grey"/>
      <geometry>
        <mesh filename="package://softhands_description/meshes/v1_wide/right/phalanx.stl" scale="0.001 0.001 0.001"/>
      </geometry>
      <origin rpy="0 0 0" xyz="0 0 0"/>
    </visual>
    <inertial>
      <mass value="0.024190505"/>
      <inertia ixx="1.9981795e-06" ixy="-6.0806048e-08" ixz="0.0" iyy="4.7810654e-06" iyz="0.0" izz="5.0961924e-06"/>
      <origin rpy="0 0 0" xyz=" 2.0923634e-02  8.4162795e-04 -5.2131884e-05"/>
    </inertial>
    <collision>
      <geometry>
        <mesh filename="package://softhands_description/meshes/v1_wide/right/phalanx_collision.stl" scale="0.0009 0.0009 0.0009"/>
      </geometry>
      <origin rpy="0 0 0" xyz="0 0 0"/>
    </collision>
  </link>
  <gazebo reference="right_hand_v1_wide_ring_middle_link">
    <material>Gazebo/Gray</material>
    <selfCollide>0</selfCollide>
  </gazebo>
  <!-- GAZEBO REF -->
  <gazebo reference="right_hand_v1_wide_ring_middle_virtual_joint">
    <implicitSpringDamper>true</implicitSpringDamper>
    <springStiffness>0.4</springStiffness>
    <springReference>0</springReference>
  </gazebo>
  <!-- GAZEBO REF -->
  <gazebo reference="right_hand_v1_wide_ring_middle_joint">
    <implicitSpringDamper>true</implicitSpringDamper>
    <springStiffness>0.4</springStiffness>
    <springReference>0</springReference>
  </gazebo>
  <!-- Virtual joint from middle->distal   -->
  <joint name="right_hand_v1_wide_ring_distal_virtual_joint" type="revolute">
    <axis xyz="0 0 1"/>
    <limit effort="30" lower="0" upper="0.785398" velocity="0.0"/>
    <origin rpy="0 0 0" xyz="41e-3 0 0"/>
    <parent link="right_hand_v1_wide_ring_middle_link"/>
    <child link="right_hand_v1_wide_ring_distal_virtual_link"/>
    <dynamics damping="3e-2" friction="0.0"/>
  </joint>
  <link name="right_hand_v1_wide_ring_distal_virtual_link">
    <inertial>
      <origin rpy="0 0 0" xyz="0 0 0"/>
      <mass value="0.012475845"/>
      <inertia ixx="7.5548908e-07" ixy="0.0" ixz="0.0" iyy="1.2532982e-06" iyz="0.0" izz="1.3218760e-06"/>
    </inertial>
  </link>
  <!-- Proximal phalanx -->
  <joint name="right_hand_v1_wide_ring_distal_joint" type="revolute">
    <axis xyz="0 0 1"/>
    <limit effort="30" lower="0" upper="0.785398" velocity="0.0"/>
    <origin rpy="0 0 0" xyz="9e-3 0 0"/>
    <parent link="right_hand_v1_wide_ring_distal_virtual_link"/>
    <child link="right_hand_v1_wide_ring_distal_link"/>
    <dynamics damping="3e-2" friction="0.0"/>
  </joint>
  <link name="right_hand_v1_wide_ring_distal_link">
    <visual>
      <material name="grey"/>
      <geometry>
        <mesh filename="package://softhands_description/meshes/v1_wide/right/phalanx_dist.stl" scale="0.001 0.001 0.001"/>
      </geometry>
      <origin rpy="0 0 0" xyz="0 0 0"/>
    </visual>
    <inertial>
      <mass value="0.012475845"/>
      <inertia ixx="7.5548908e-07" ixy="0.0" ixz="0.0" iyy="1.2532982e-06" iyz="0.0" izz="1.3218760e-06"/>
      <origin rpy="0 0 0" xyz="1.2887396e-02 6.2001804e-05 -1.1041989e-03"/>
    </inertial>
    <collision>
      <geometry>
        <mesh filename="package://softhands_description/meshes/v1_wide/right/phalanx_dist_collision.stl" scale="0.0009 0.0009 0.0009"/>
      </geometry>
      <origin rpy="0 0 0" xyz="0 0 0"/>
    </collision>
  </link>
  <gazebo reference="right_hand_v1_wide_ring_distal_link">
    <material>Gazebo/Gray</material>
    <selfCollide>0</selfCollide>
  </gazebo>
  <!-- GAZEBO REF -->
  <gazebo reference="right_hand_v1_wide_ring_distal_virtual_joint">
    <implicitSpringDamper>true</implicitSpringDamper>
    <springStiffness>0.4</springStiffness>
    <springReference>0</springReference>
  </gazebo>
  <!-- GAZEBO REF -->
  <gazebo reference="right_hand_v1_wide_ring_distal_joint">
    <implicitSpringDamper>true</implicitSpringDamper>
    <springStiffness>0.4</springStiffness>
    <springReference>0</springReference>
  </gazebo>
  <!-- Support -->
  <joint name="right_hand_v1_wide_little_knuckle_joint" type="revolute">
    <axis xyz="0 1 0"/>
    <limit effort="30" lower="0.0" upper="0.01" velocity="0.0"/>
    <origin rpy="0 -1.221731 0" xyz="39.2985e-3 5e-3 34.8419e-3"/>
    <parent link="right_hand_v1_wide_palm_little_link"/>
    <child link="right_hand_v1_wide_little_knuckle_link"/>
  </joint>
  <link name="right_hand_v1_wide_little_knuckle_link">
    <visual>
      <material name="grey"/>
      <geometry>
        <mesh filename="package://softhands_description/meshes/v1_wide/right/phalanx_pros_sup.stl" scale="0.001 0.001 0.001"/>
      </geometry>
      <origin rpy="0 0 0" xyz="0 0 0"/>
    </visual>
    <inertial>
      <mass value="7.4913242e-03"/>
      <origin rpy="0 0 0" xyz="1.8035857e-02 -4.0351343e-03 -4.4165266e-05 "/>
      <inertia ixx="5.3708642e-07" ixy="0.0" ixz="1.5304482e-07" iyy="6.1466440e-07" iyz="-4.4383298e-09" izz="5.5136271e-07"/>
    </inertial>
    <collision>
      <geometry>
        <mesh filename="package://softhands_description/meshes/v1_wide/right/phalanx_pros_sup_collision.stl" scale="0.0009 0.0009 0.0009"/>
      </geometry>
      <origin rpy="0 0 0" xyz="0 0 0"/>
    </collision>
  </link>
  <gazebo reference="right_hand_v1_wide_little_knuckle_link">
    <selfCollide>0</selfCollide>
    <material>Gazebo/White</material>
  </gazebo>
  <!-- Virtual joint from knuckle->proximal or proximal->middle   -->
  <joint name="right_hand_v1_wide_little_proximal_virtual_joint" type="revolute">
    <axis xyz="0 0 1"/>
    <limit effort="30" lower="0" upper="0.785398" velocity="0.0"/>
    <origin rpy="0 0 0" xyz="24e-3 -6.5e-3 0"/>
    <parent link="right_hand_v1_wide_little_knuckle_link"/>
    <child link="right_hand_v1_wide_little_proximal_virtual_link"/>
    <dynamics damping="3e-2" friction="0.0"/>
  </joint>
  <link name="right_hand_v1_wide_little_proximal_virtual_link">
    <inertial>
      <origin rpy="0 0 0" xyz="0 0 0"/>
      <mass value="0.024190505"/>
      <inertia ixx="1.9981795e-06" ixy="-6.0806048e-08" ixz="0.0" iyy="4.7810654e-06" iyz="0.0" izz="5.0961924e-06"/>
    </inertial>
  </link>
  <!-- Proximal phalanx -->
  <joint name="right_hand_v1_wide_little_proximal_joint" type="revolute">
    <axis xyz="0 0 1"/>
    <limit effort="30" lower="0" upper="0.785398" velocity="0.0"/>
    <origin rpy="0 0 0" xyz="9e-3 0 0"/>
    <parent link="right_hand_v1_wide_little_proximal_virtual_link"/>
    <child link="right_hand_v1_wide_little_proximal_link"/>
    <dynamics damping="3e-2" friction="0.0"/>
  </joint>
  <link name="right_hand_v1_wide_little_proximal_link">
    <visual>
      <material name="grey"/>
      <geometry>
        <mesh filename="package://softhands_description/meshes/v1_wide/right/phalanx.stl" scale="0.001 0.001 0.001"/>
      </geometry>
      <origin rpy="0 0 0" xyz="0 0 0"/>
    </visual>
    <inertial>
      <mass value="0.024190505"/>
      <inertia ixx="1.9981795e-06" ixy="-6.0806048e-08" ixz="0.0" iyy="4.7810654e-06" iyz="0.0" izz="5.0961924e-06"/>
      <origin rpy="0 0 0" xyz=" 2.0923634e-02  8.4162795e-04 -5.2131884e-05"/>
    </inertial>
    <collision>
      <geometry>
        <mesh filename="package://softhands_description/meshes/v1_wide/right/phalanx_collision.stl" scale="0.0009 0.0009 0.0009"/>
      </geometry>
      <origin rpy="0 0 0" xyz="0 0 0"/>
    </collision>
  </link>
  <gazebo reference="right_hand_v1_wide_little_proximal_link">
    <material>Gazebo/Gray</material>
    <selfCollide>0</selfCollide>
  </gazebo>
  <!-- GAZEBO REF -->
  <gazebo reference="right_hand_v1_wide_little_proximal_virtual_joint">
    <implicitSpringDamper>true</implicitSpringDamper>
    <springStiffness>0.4</springStiffness>
    <springReference>0</springReference>
  </gazebo>
  <!-- GAZEBO REF -->
  <gazebo reference="right_hand_v1_wide_little_proximal_joint">
    <implicitSpringDamper>true</implicitSpringDamper>
    <springStiffness>0.4</springStiffness>
    <springReference>0</springReference>
  </gazebo>
  <!-- Virtual joint from knuckle->proximal or proximal->middle   -->
  <joint name="right_hand_v1_wide_little_middle_virtual_joint" type="revolute">
    <axis xyz="0 0 1"/>
    <limit effort="30" lower="0" upper="0.785398" velocity="0.0"/>
    <origin rpy="0 0 0" xyz="41e-3 0 0"/>
    <parent link="right_hand_v1_wide_little_proximal_link"/>
    <child link="right_hand_v1_wide_little_middle_virtual_link"/>
    <dynamics damping="3e-2" friction="0.0"/>
  </joint>
  <link name="right_hand_v1_wide_little_middle_virtual_link">
    <inertial>
      <origin rpy="0 0 0" xyz="0 0 0"/>
      <mass value="0.024190505"/>
      <inertia ixx="1.9981795e-06" ixy="-6.0806048e-08" ixz="0.0" iyy="4.7810654e-06" iyz="0.0" izz="5.0961924e-06"/>
    </inertial>
  </link>
  <!-- Proximal phalanx -->
  <joint name="right_hand_v1_wide_little_middle_joint" type="revolute">
    <axis xyz="0 0 1"/>
    <limit effort="30" lower="0" upper="0.785398" velocity="0.0"/>
    <origin rpy="0 0 0" xyz="9e-3 0 0"/>
    <parent link="right_hand_v1_wide_little_middle_virtual_link"/>
    <child link="right_hand_v1_wide_little_middle_link"/>
    <dynamics damping="3e-2" friction="0.0"/>
  </joint>
  <link name="right_hand_v1_wide_little_middle_link">
    <visual>
      <material name="grey"/>
      <geometry>
        <mesh filename="package://softhands_description/meshes/v1_wide/right/phalanx.stl" scale="0.001 0.001 0.001"/>
      </geometry>
      <origin rpy="0 0 0" xyz="0 0 0"/>
    </visual>
    <inertial>
      <mass value="0.024190505"/>
      <inertia ixx="1.9981795e-06" ixy="-6.0806048e-08" ixz="0.0" iyy="4.7810654e-06" iyz="0.0" izz="5.0961924e-06"/>
      <origin rpy="0 0 0" xyz=" 2.0923634e-02  8.4162795e-04 -5.2131884e-05"/>
    </inertial>
    <collision>
      <geometry>
        <mesh filename="package://softhands_description/meshes/v1_wide/right/phalanx_collision.stl" scale="0.0009 0.0009 0.0009"/>
      </geometry>
      <origin rpy="0 0 0" xyz="0 0 0"/>
    </collision>
  </link>
  <gazebo reference="right_hand_v1_wide_little_middle_link">
    <material>Gazebo/Gray</material>
    <selfCollide>0</selfCollide>
  </gazebo>
  <!-- GAZEBO REF -->
  <gazebo reference="right_hand_v1_wide_little_middle_virtual_joint">
    <implicitSpringDamper>true</implicitSpringDamper>
    <springStiffness>0.4</springStiffness>
    <springReference>0</springReference>
  </gazebo>
  <!-- GAZEBO REF -->
  <gazebo reference="right_hand_v1_wide_little_middle_joint">
    <implicitSpringDamper>true</implicitSpringDamper>
    <springStiffness>0.4</springStiffness>
    <springReference>0</springReference>
  </gazebo>
  <!-- Virtual joint from middle->distal   -->
  <joint name="right_hand_v1_wide_little_distal_virtual_joint" type="revolute">
    <axis xyz="0 0 1"/>
    <limit effort="30" lower="0" upper="0.785398" velocity="0.0"/>
    <origin rpy="0 0 0" xyz="41e-3 0 0"/>
    <parent link="right_hand_v1_wide_little_middle_link"/>
    <child link="right_hand_v1_wide_little_distal_virtual_link"/>
    <dynamics damping="3e-2" friction="0.0"/>
  </joint>
  <link name="right_hand_v1_wide_little_distal_virtual_link">
    <inertial>
      <origin rpy="0 0 0" xyz="0 0 0"/>
      <mass value="0.012475845"/>
      <inertia ixx="7.5548908e-07" ixy="0.0" ixz="0.0" iyy="1.2532982e-06" iyz="0.0" izz="1.3218760e-06"/>
    </inertial>
  </link>
  <!-- Proximal phalanx -->
  <joint name="right_hand_v1_wide_little_distal_joint" type="revolute">
    <axis xyz="0 0 1"/>
    <limit effort="30" lower="0" upper="0.785398" velocity="0.0"/>
    <origin rpy="0 0 0" xyz="9e-3 0 0"/>
    <parent link="right_hand_v1_wide_little_distal_virtual_link"/>
    <child link="right_hand_v1_wide_little_distal_link"/>
    <dynamics damping="3e-2" friction="0.0"/>
  </joint>
  <link name="right_hand_v1_wide_little_distal_link">
    <visual>
      <material name="grey"/>
      <geometry>
        <mesh filename="package://softhands_description/meshes/v1_wide/right/phalanx_dist.stl" scale="0.001 0.001 0.001"/>
      </geometry>
      <origin rpy="0 0 0" xyz="0 0 0"/>
    </visual>
    <inertial>
      <mass value="0.012475845"/>
      <inertia ixx="7.5548908e-07" ixy="0.0" ixz="0.0" iyy="1.2532982e-06" iyz="0.0" izz="1.3218760e-06"/>
      <origin rpy="0 0 0" xyz="1.2887396e-02 6.2001804e-05 -1.1041989e-03"/>
    </inertial>
    <collision>
      <geometry>
        <mesh filename="package://softhands_description/meshes/v1_wide/right/phalanx_dist_collision.stl" scale="0.0009 0.0009 0.0009"/>
      </geometry>
      <origin rpy="0 0 0" xyz="0 0 0"/>
    </collision>
  </link>
  <gazebo reference="right_hand_v1_wide_little_distal_link">
    <material>Gazebo/Gray</material>
    <selfCollide>0</selfCollide>
  </gazebo>
  <!-- GAZEBO REF -->
  <gazebo reference="right_hand_v1_wide_little_distal_virtual_joint">
    <implicitSpringDamper>true</implicitSpringDamper>
    <springStiffness>0.4</springStiffness>
    <springReference>0</springReference>
  </gazebo>
  <!-- GAZEBO REF -->
  <gazebo reference="right_hand_v1_wide_little_distal_joint">
    <implicitSpringDamper>true</implicitSpringDamper>
    <springStiffness>0.4</springStiffness>
    <springReference>0</springReference>
  </gazebo>
  <!-- <gazebo reference="table_top_link">
        <selfCollide> 1 </selfCollide>
    </gazebo> -->
  <!-- <xacro:repair_hand_transmission id="left" />

    <xacro:repair_hand_transmission id="right" /> -->
</robot>
